Workbook

Sheet Cover
C2: COPART, INC.
C3: Equity Valuation Model
C5: CPRT · NASDAQ · Automotive Remarketing & Online Vehicle Auctions
C13: MODEL OVERVIEW | H13: KEY DETAILS
C14: Methodology | D14: DCF + Trading Comps | H14: Sector | I14: Financials / Industrials
C15: Fiscal Year End | D15: 46234 | H15: Market Cap | I15: ~$48B
C16: Historical Period | D16: FY2019 – FY2024 | H16: Recommendation | I16: BUY
C17: Projection Period | D17: FY2025E – FY2029E | H17: Price Target | I17: $ ___
C18: Currency | D18: USD (millions) | H18: Current Price | I18: $ ___
C19: Prepared By | D19: Divij Budhiraja | H19: Date
C27: ABOUT COPART
C29: Copart, Inc. (CPRT) is the global leader in online vehicle auctions and remarketing services, connecting sellers of damaged and low-value vehicles with buyers across 170+ countries. Operating through its proprietary VB2® platform, Copart provides end-to-end vehicle lifecycle solutions to insurance carriers, fleet operators, banks, and dealers. Its asset-light, high-margin business model and powerful network effects create durable competitive advantages and strong free cash flow generation.
C32: For educational & analytical purposes only. Not investment advice. | I32: Copart Equity Valuation Model · Confidential

Sheet TOC
B1: COPART INC.
B2: Comprehensive Valuation Model — Table of Contents
B4: Tab # | C4: Tab Name | D4: Description | E4: Status
B5: SECTION 1: EXECUTIVE SUMMARY & OVERVIEW
B6: 1 | C6: Cover | D6: Title page, version control, confidentiality notice | E6: Complete
B7: 2 | C7: TOC | D7: Table of contents & model map | E7: Complete
B8: 3 | C8: Executive Summary | D8: Investment thesis, highlights, key findings, target price | E8: Complete
B10: SECTION 2: HISTORICAL FINANCIALS & ANALYSIS
B11: 4 | C11: Historical Financials | D11: Historical IS + BS + CF (vertical 3-statement model) | E11: Complete
B12: 5 | C12: Historical Analysis | D12: Margins, growth rates, ratio analysis, trends | E12: Complete
B14: SECTION 3: ASSUMPTIONS & OTHER INPUTS
B15: 6 | C15: Master Assumptions | D15: Key drivers: revenue growth, margins, CapEx, tax, WACC | E15: Complete
B16: 7 | C16: Supporting Schedules | D16: Supporting analysis: TAM, benchmarks, comps backup | E16: Complete
B18: SECTION 4: FORECASTS & PROJECTIONS
B19: 8 | C19: Forecast Model | D19: Projected IS + BS + CF (vertical 3-statement model) | E19: Complete
B21: SECTION 5: VALUATION
B22: 9 | C22: DCF Valuation | D22: Discounted Cash Flow analysis (WACC, terminal value) | E22: Complete
B23: 10 | C23: Trading Comps | D23: Public comparable company analysis (EV/Revenue, EV/EBITDA) | E23: Complete
B24: 11 | C24: Valuation Summary | D24: Combined valuation range across all methodologies | E24: Complete
B26: SECTION 6: OUTPUTS & ANALYSIS
B27: 12 | C27: Sensitivity Tables | D27: WACC vs. growth, revenue vs. margin data tables | E27: Complete
B29: SECTION 7: REFERENCE & DATA
B30: 13 | C30: Sources & Footnotes | D30: Data sources, methodology notes, disclaimers | E30: Complete
B33: COLOR CODING LEGEND
B34: 🔵 | C34: BLUE cells | D34: Hardcoded inputs / assumptions (user changes these)
B35: ⬛ | C35: BLACK cells | D35: Formulas & calculations (model calculates these)
B36: 🟢 | C36: GREEN cells | D36: Links from other worksheets within workbook
B37: 🟡 | C37: YELLOW cells | D37: Flags / checks / key assumptions needing attention
B38: 🔴 | C38: RED cells | D38: External links to other files

Sheet Executive Summary
C2: COPART, INC. (CPRT) — EXECUTIVE SUMMARY | L2: Equity Research | Initiating Coverage
C3: Automotive Remarketing & Online Vehicle Auctions | NASDAQ: CPRT | Current Price: $32.43 | Blended Target: $36.36 | Upside: +12.1% | Rating: BUY
C6: INVESTMENT THESIS
C7: 1 | G7: 2 | K7: 3
C8: Structural Market Leadership | G8: Capital-Light Compounding Machine | K8: Secular Tailwinds Underappreciated
C9: Copart commands ~40% U.S. market share in salvage auctions with a 42%+ gross margin — nearly 3x the closest peer. VB2® platform creates a two-sided marketplace moat that deepens with scale. | G9: CPRT converts ~67% of NOPAT to unlevered FCF. Zero net debt, $4.8B cash, and consistent 8–10% revenue growth fund global expansion while compounding tangible book value per share at a double-digit CAGR. | K9: Rising vehicle complexity, higher repair costs & insurance outsourcing accelerate total loss rates. Global expansion into UK, Germany, Brazil, and UAE provides a long runway underweighted by consensus.
C14: KEY FINANCIALS ($ millions)
C15: Metric | E15: ◀ ACTUALS ▶ | F15: FY2023A | G15: FY2024A | H15: FY2025A | I15: ◀ ESTIMATES ▶ | J15: FY2027E | K15: FY2028E | L15: FY2029E
E16: FY22A | F16: FY23A | G16: FY24A | H16: FY25A | I16: FY26E | J16: FY27E | K16: FY28E | L16: FY29E
C17: Revenue | E17: 3500.9 | F17: 3869.5 | G17: 4236.8 | H17: 4647 | I17: 5085.2 | J17: 5523.7 | K17: 5954.3 | L17: 6442.2
C18: YoY Growth | E18: — | F18: 0.1054 | G18: 0.0952 | H18: 0.0966 | I18: 0.0943 | J18: 0.0862 | K18: 0.078 | L18: 0.0819
C19: Gross Profit | E19: 1724.1 | F19: 1879.1 | G19: 2077.9 | H19: 2291.4 | I19: 2493.8 | J19: 2708.8 | K19: 2920 | L19: 3159.3
C20: Gross Margin | E20: 0.4925 | F20: 0.4856 | G20: 0.4904 | H20: 0.4931 | I20: 0.4904 | J20: 0.4904 | K20: 0.4904 | L20: 0.4904
C21: EBIT | E21: 1375 | F21: 1486.6 | G21: 1572 | H21: 1696.7 | I21: 1843.7 | J21: 1991.9 | K21: 2137.9 | L21: 2305.8
C22: EBIT Margin | E22: 0.3928 | F22: 0.384 | G22: 0.3711 | H22: 0.3652 | I22: 0.3626 | J22: 0.3606 | K22: 0.359 | L22: 0.3579
C23: EBITDA | E23: 1513 | F23: 1646 | G23: 1761.8 | H23: 1912.6 | I23: 2079.3 | J23: 2258.5 | K23: 2434.6 | L23: 2634.1
C24: EBITDA Margin | E24: 0.4322 | F24: 0.4253 | G24: 0.4159 | H24: 0.4116 | I24: 0.4089 | J24: 0.4089 | K24: 0.4089 | L24: 0.4089
C25: Net Income | E25: 1090.1 | F25: 1237.7 | G25: 1361.6 | H25: 1544.3 | I25: 1617.8 | J25: 1737.1 | K25: 1854.7 | L25: 1989.9
C26: EPS (Diluted) | E26: 1.12 | F26: 1.27 | G26: 1.4 | H26: 1.58 | I26: 1.66 | J26: 1.78 | K26: 1.9 | L26: 2.04
C27: FCF | E27: 838 | F27: 847.6 | G27: 961.6 | H27: 1230.8 | I27: 998.4 | J27: 1121.7 | K27: 1184.7 | L27: 1251.1
C28: Capex | E28: 337.4 | F28: 516.6 | G28: 511 | H28: 569 | I28: 671.1 | J28: 726.6 | K28: 811.7 | L28: 909.2
C29: FINANCIAL PERFORMANCE & VALUATION OVERVIEW
B31: Year | C31: Revenue ($M) | D31: EBITDA ($M) | E31: EBIT Margin % | G31: Methodology | H31: Low | I31: Mid | J31: High | K31: Current | L31: Upside
B32: FY2022A | C32: 3501 | D32: 1513 | E32: 0.3928 | G32: DCF - Perp. Growth | H32: 18.06 | I32: 21.24 | J32: 26.62 | K32: 32.43 | L32: -0.345
B33: FY2023A | C33: 3870 | D33: 1646 | E33: 0.384 | G33: DCF - Exit Multiple | H33: 36.28 | I33: 44.43 | J33: 48.51 | K33: 32.43 | L33: 0.37
B34: FY2024A | C34: 4237 | D34: 1762 | E34: 0.3711 | G34: Trading Comps | H34: 24.84 | I34: 43.42 | J34: 69.63 | K34: 32.43 | L34: 0.339
B35: FY2025A | C35: 4647 | D35: 1913 | E35: 0.3652 | G35: Blended Target | I35: 36.36 | K35: 32.43 | L35: 0.121
B36: FY2026E | C36: 5085 | D36: 2079 | E36: 0.3626
B37: FY2027E | C37: VALUATION SUMMARY — IMPLIED SHARE PRICE ($) | D37: 2259 | E37: 0.3606
B38: FY2028E | C38: Methodology | D38: 2435 | E38: Low | F38: Mid (Base) | G38: High | H38: Current Price | I38: vs. Current | J38: Upside / (Downside) | L38: Recommendation
B39: FY2029E | C39: DCF – Perpetuity Growth | D39: 2634 | E39: 18.06 | F39: 21.24 | G39: 26.62 | H39: 32.43 | I39: -0.345 | J39: ▼ -34.5% | L39: UNDERPERFORM
C40: DCF – Exit Multiple | E40: 36.28 | F40: 44.43 | G40: 48.51 | H40: 32.43 | I40: 0.37 | J40: ▲ 37.0% | L40: BUY
C41: Trading Comps (EV/EBITDA) | E41: 27.82 | F41: 43.42 | G41: 49.41 | H41: 32.43 | I41: 0.339 | J41: ▲ 33.9% | L41: BUY
C42: Blended Valuation | E42: — | F42: 36.36 | G42: — | H42: 32.43 | I42: 0.121 | J42: ▲ 12.1% | L42: BUY
C45: KEY METRICS & CREDIT PROFILE
C48: 0.09 | E48: 0.412 | G48: (2.5x) | I48: ~67% | K48: 0.188 | M48: 13.6x
C49: Revenue CAGR (FY22–FY29E) | E49: EBITDA Margin (FY25A) | G49: Net Debt / EBITDA | I49: FCF Conversion (NOPAT) | K49: Return on Equity (FY25A) | M49: EV / EBITDA (NTM)
C50: Consistent compounder | E50: Industry-leading | G50: Net cash position | I50: FY26E avg | K50: vs. 15.2% peers | M50: vs. peer median 22.2x
B53: Revenue & EBITDA Trend (FY22–FY29E) | I53: Football Field — Implied Share Price by Methodology
C72: Sources: Company filings (10-K, 10-Q), Bloomberg, Internal Model Estimates. This analysis is for informational purposes only and does not constitute investment advice. | M72: CPRT | Equity Valuation | Confidential
...

Sheet Historical Financials
B3: INCOME STATEMENT
F6: 2022A | G6: 2023A | H6: 2024A | I6: 2025A
B9: Revenue | F9: 3500.921 | G9: 3869.518 | H9: 4236.823 | I9: 4646.958
B10: COGS | F10: -1776.787 | G10: -1990.43 | H10: -2158.921 | I10: -2355.54
B11: Gross Profit | F11: =SUM(F9:F10) -> 1724.134 | G11: =SUM(G9:G10) -> 1879.088 | H11: =SUM(H9:H10) -> 2077.902 | I11: =SUM(I9:I10) -> 2291.418
B13: SG&A Expense | F13: -211.152 | G13: -233.041 | H13: -316.118 | I13: -378.855
B14: D&A Expense | F14: -137.985 | G14: -159.478 | H14: -189.761 | I14: -215.849
B15: EBIT | F15: =SUM(F11:F14) -> 1374.997 | G15: =SUM(G11:G14) -> 1486.569 | H15: =SUM(H11:H14) -> 1572.023 | I15: =SUM(I11:I14) -> 1696.714
B17: Unusual Expense | F17: -16.8 | G17: 0 | H17: 0 | I17: 0
B18: Interest Expense | F18: -16.7 | G18: 0 | H18: 0 | I18: 0
B19: Other Income (Expense) | F19: -0.596 | G19: 67.759 | H19: 142.578 | I19: 198.867
B20: EBT | F20: =SUM(F15:F19) -> 1340.901 | G20: =SUM(G15:G19) -> 1554.328 | H20: =SUM(H15:H19) -> 1714.601 | I20: =SUM(I15:I19) -> 1895.581
B22: Income Taxes | F22: -250.824 | G22: -316.587 | H22: -352.254 | I22: -347.218
B23: Consolidated Net Income | F23: =SUM(F20:F22) -> 1090.077 | G23: =SUM(G20:G22) -> 1237.741 | H23: =SUM(H20:H22) -> 1362.347 | I23: =SUM(I20:I22) -> 1548.363
B25: Minority Interests | F25: 0 | G25: 0 | H25: -0.7 | I25: -4.1
B26: Net Income | F26: =SUM(F23:F25) -> 1090.077 | G26: =SUM(G23:G25) -> 1237.741 | H26: =SUM(H23:H25) -> 1361.647 | I26: =SUM(I23:I25) -> 1544.263
B28: BALANCE STATEMENT
F32: 2022A | G32: 2023A | H32: 2024A | I32: 2025A
B35: Assets
B36: Cash & Short-Term Investments | F36: 1384.236 | G36: 2363.984 | H36: 3422.158 | I36: 4789.07
B37: Accounts Receivable | F37: 571.316 | G37: 685.704 | H37: 759.924 | I37: 728.771
B38: Other Receivables | F38: 57.139 | G38: 22.908 | H38: 25.953 | I38: 34.62
B39: Inventories | F39: 58.791 | G39: 39.973 | H39: 43.639 | I39: 39.661
B40: Other Current Assets | F40: 18.731 | G40: 26.31 | H40: 33.872 | I40: 46.361
B41: Total Current Assets | F41: =SUM(F36:F40) -> 2090.213 | G41: =SUM(G36:G40) -> 3138.879 | H41: =SUM(H36:H40) -> 4285.546 | I41: =SUM(I36:I40) -> 5638.483
B43: Net PP&E | F43: 2602.067 | G43: 2952.478 | H43: 3292.139 | I43: 3697.801
B44: Goodwill | F44: 401.954 | G44: 394.289 | H44: 513.909 | I44: 517.779
B45: Other Intangible Assets | F45: 54.68 | G45: 62.702 | H45: 74.088 | I45: 62.832
B46: Other Non-Current Assets | F46: 159.95 | G46: 189.531 | H46: 262.082 | I46: 174.007
B47: Total Non-Current Assets | F47: =SUM(F43:F46) -> 3218.651 | G47: =SUM(G43:G46) -> 3599 | H47: =SUM(H43:H46) -> 4142.218 | I47: =SUM(I43:I46) -> 4452.419
B48: Total Assets | F48: =F41+F47 -> 5308.864 | G48: =G41+G47 -> 6737.879 | H48: =H41+H47 -> 8427.764 | I48: =I41+I47 -> 10090.902
B50: Liabilities
B51: Accounts Payable | F51: 187.17 | G51: 180.016 | H51: 193.333 | I51: 214.402
B52: Short-Term Debt | F52: 21.794 | G52: 21.468 | H52: 21.304 | I52: 19.869
B53: Income Tax Payable | F53: 6.906 | G53: 3.862 | H53: 69.214 | I53: 53.93
B54: Other Current Liabilities | F54: 225.019 | G54: 287.423 | H54: 344.716 | I54: 395.08
B55: Total Current Liabilities | F55: =SUM(F51:F54) -> 440.889 | G55: =SUM(G51:G54) -> 492.769 | H55: =SUM(H51:H54) -> 628.567 | I55: =SUM(I51:I54) -> 683.281
B57: Long-Term Debt | F57: 97.679 | G57: 98.985 | H57: 97.429 | I57: 83.87
B58: Deferred Tax Liabilities | F58: 80.06 | G58: 89.492 | H58: 93.653 | I58: 80.625
B59: Other Non-Current Liabilities | F59: 64.637 | G59: 69.193 | H59: 59.56 | I59: 35.635
...

Sheet Historical Analysis
B3: SECTION A: GROWTH AND MARGIN ANALYSIS
B5: REVENUE GROWTH:
F6: 2022A | G6: 2023A | H6: 2024A | I6: 2025A | K6: Trend
B7: Total Revenue ($M) | F7: ='Historical Financials'!F9 -> 3500.921 | G7: ='Historical Financials'!G9 -> 3869.518 | H7: ='Historical Financials'!H9 -> 4236.823 | I7: ='Historical Financials'!I9 -> 4646.958
B8: YoY Growth % | G8: =G7/F7-1 -> 0.10528572 | H8: =H7/G7-1 -> 0.094922675 | I8: =I7/H7-1 -> 0.096802486
B9: CAGR | I9: =(I7/F7)^(1/4)-1 -> 0.073362972 | K9: YoY Growth
B11: GROSS MARGIN:
F12: 2022A | G12: 2023A | H12: 2024A | I12: 2025A | K12: Trend
B13: Gross Profit ($M) | F13: ='Historical Financials'!F11 -> 1724.134 | G13: ='Historical Financials'!G11 -> 1879.088 | H13: ='Historical Financials'!H11 -> 2077.902 | I13: ='Historical Financials'!I11 -> 2291.418
B14: Gross Profit % | F14: =F13/F7 -> 0.49248012 | G14: =G13/G7 -> 0.48561294 | H14: =H13/H7 -> 0.49043871 | I14: =I13/I7 -> 0.49310065
B17: OPEX ANALYSIS:
F18: 2022A | G18: 2023A | H18: 2024A | I18: 2025A | K18: Trend
B19: SG&A % of Revenue | F19: =-'Historical Financials'!F13/'Historical Financials'!F9 -> 0.060313272 | G19: =-'Historical Financials'!G13/'Historical Financials'!G9 -> 0.060224814 | H19: =-'Historical Financials'!H13/'Historical Financials'!H9 -> 0.074612038 | I19: =-'Historical Financials'!I13/'Historical Financials'!I9 -> 0.081527528
B20: D&A % of Revenue | F20: =-'Historical Financials'!F14/'Historical Financials'!F9 -> 0.039413914 | G20: =-'Historical Financials'!G14/'Historical Financials'!G9 -> 0.041213919 | H20: =-'Historical Financials'!H14/'Historical Financials'!H9 -> 0.044788513 | I20: =-'Historical Financials'!I14/'Historical Financials'!I9 -> 0.046449527
B21: Total Opex % of Revenue | F21: =(-'Historical Financials'!F13-'Historical Financials'!F14)/'Historical Financials'!F9 -> 0.099727186 | G21: =(-'Historical Financials'!G13-'Historical Financials'!G14)/'Historical Financials'!G9 -> 0.10143873 | H21: =(-'Historical Financials'!H13-'Historical Financials'!H14)/'Historical Financials'!H9 -> 0.11940055 | I21: =(-'Historical Financials'!I13-'Historical Financials'!I14)/'Historical Financials'!I9 -> 0.12797706
B24: PROFITABILITY:
F25: 2022A | G25: 2023A | H25: 2024A | I25: 2025A | K25: Trend
B26: Operating Margin % | F26: ='Historical Financials'!F15/'Historical Financials'!F9 -> 0.39275294 | G26: ='Historical Financials'!G15/'Historical Financials'!G9 -> 0.3841742 | H26: ='Historical Financials'!H15/'Historical Financials'!H9 -> 0.37103816 | I26: ='Historical Financials'!I15/'Historical Financials'!I9 -> 0.36512359
B27: EBITDA Margin % | F27: =('Historical Financials'!F15-'Historical Financials'!F14)/'Historical Financials'!F9 -> 0.43216685 | G27: =('Historical Financials'!G15-'Historical Financials'!G14)/'Historical Financials'!G9 -> 0.42538812 | H27: =('Historical Financials'!H15-'Historical Financials'!H14)/'Historical Financials'!H9 -> 0.41582667 | I27: =('Historical Financials'!I15-'Historical Financials'!I14)/'Historical Financials'!I9 -> 0.41157312
B28: Net Margin % | F28: ='Historical Financials'!F26/'Historical Financials'!F9 -> 0.31136864 | G28: ='Historical Financials'!G26/'Historical Financials'!G9 -> 0.31986955 | H28: ='Historical Financials'!H26/'Historical Financials'!H9 -> 0.32138397 | I28: ='Historical Financials'!I26/'Historical Financials'!I9 -> 0.33231697
B32: SECTION B: CASH GENERATION AND CAPITAL EFFICIENCY
B35: CASH FLOW QUALITY:
F36: 2022A | G36: 2023A | H36: 2024A | I36: 2025A | K36: Trend
B37: OCF | F37: ='Historical Financials'!F91 -> 1175.471 | G37: ='Historical Financials'!G91 -> 1364.21 | H37: ='Historical Financials'!H91 -> 1472.564 | I37: ='Historical Financials'!I91 -> 1799.75
B38: FCF | F38: ='Historical Financials'!F91-'Historical Financials'!F94 -> 1512.919 | G38: ='Historical Financials'!G91-'Historical Financials'!G94 -> 1880.846 | H38: ='Historical Financials'!H91-'Historical Financials'!H94 -> 1983.554 | I38: ='Historical Financials'!I91-'Historical Financials'!I94 -> 2368.74
B41: WC DYNAMICS:
F42: 2022A | G42: 2023A | H42: 2024A | I42: 2025A | K42: Trend
B43: Changes in WC ($M):
B44: Changes in AR | F44: ='Historical Financials'!F86 -> -127.634 | G44: ='Historical Financials'!G86 -> -90.014 | H44: ='Historical Financials'!H86 -> -138.824 | I44: ='Historical Financials'!I86 -> -34.525
B45: Changes in AP | F45: ='Historical Financials'!F88 -> 36.306 | G45: ='Historical Financials'!G88 -> 18.01 | H45: ='Historical Financials'!H88 -> 59.528 | I45: ='Historical Financials'!I88 -> 69.599
B46: Changes in Inventory | F46: ='Historical Financials'!F87 -> -10.851 | G46: ='Historical Financials'!G87 -> 26.549 | H46: ='Historical Financials'!H87 -> -3.698 | I46: ='Historical Financials'!I87 -> 4.655
B47: Other WC changes | F47: =SUM('Historical Financials'!F89:F90) -> -23.308 | G47: =SUM('Historical Financials'!G89:G90) -> -42.826 | H47: =SUM('Historical Financials'!H89:H90) -> -31.143 | I47: =SUM('Historical Financials'!I89:I90) -> -17.169
B49: Net WC Impact | F49: =SUM(F44:F47) -> -125.487 | G49: =SUM(G44:G47) -> -88.281 | H49: =SUM(H44:H47) -> -114.137 | I49: =SUM(I44:I47) -> 22.56
B51: DSO | F51: ='Historical Financials'!F37/('Historical Financials'!F9/365) -> 59.564423 | G51: ='Historical Financials'!G37/('Historical Financials'!G9/365) -> 64.680397 | H51: ='Historical Financials'!H37/('Historical Financials'!H9/365) -> 65.46704 | I51: ='Historical Financials'!I37/('Historical Financials'!I9/365) -> 57.242053
B52: DIO | F52: ='Historical Financials'!F39/(-'Historical Financials'!F10/365) -> 12.077258 | G52: ='Historical Financials'!G39/(-'Historical Financials'!G10/365) -> 7.3301473 | H52: ='Historical Financials'!H39/(-'Historical Financials'!H10/365) -> 7.3778684 | I52: ='Historical Financials'!I39/(-'Historical Financials'!I10/365) -> 6.1456248
B53: DPO | F53: ='Historical Financials'!F51/(-'Historical Financials'!F10/365) -> 38.449769 | G53: ='Historical Financials'!G51/(-'Historical Financials'!G10/365) -> 33.010877 | H53: ='Historical Financials'!H51/(-'Historical Financials'!H10/365) -> 32.686025 | I53: ='Historical Financials'!I51/(-'Historical Financials'!I10/365) -> 33.222416
B55: CCC | F55: =F51+F53-F52 -> 85.936934 | G55: =G51+G53-G52 -> 90.361127 | H55: =H51+H53-H52 -> 90.775196 | I55: =I51+I53-I52 -> 84.318844
B57: CAPEX REQUIREMENTS:
F58: 2022A | G58: 2023A | H58: 2024A | I58: 2025A
B60: CapEx ($M) | F60: =-'Historical Financials'!F94 -> 337.448 | G60: =-'Historical Financials'!G94 -> 516.636 | H60: =-'Historical Financials'!H94 -> 510.99 | I60: =-'Historical Financials'!I94 -> 568.99
...

Sheet Master Assumptions
B2: MASTER ASSUMPTIONS
B3: Copart Inc. (CPRT) | Forecast Assumptions
B5: SCENARIO SELECTOR
B6: Active Scenario: | C6: Base
B7: Scenario Code: | C7: =IF(C6="Bull",1,IF(C6="Base",2,3)) -> 2 | D7: (1=Bull, 2=Base, 3=Bear)
B9: ACTIVE ASSUMPTIONS | F9: 2026E | G9: 2027E | H9: 2028E | I9: 2029E | J9: 2030E
B10: REVENUE & MARGINS
B11: Revenue Growth % | F11: ='Supporting Schedules'!C11 -> 0.094317069 | G11: ='Supporting Schedules'!D11 -> 0.086213777 | H11: ='Supporting Schedules'!E11 -> 0.077964584 | I11: ='Supporting Schedules'!F11 -> 0.081943279 | J11: ='Supporting Schedules'!G11 -> 0.085921975
B12: Gross Margin % | F12: ='Supporting Schedules'!C35 -> 0.4904081 | G12: ='Supporting Schedules'!D35 -> 0.4904081 | H12: ='Supporting Schedules'!E35 -> 0.4904081 | I12: ='Supporting Schedules'!F35 -> 0.4904081 | J12: ='Supporting Schedules'!G35 -> 0.4904081
B14: OPERATING EXPENSES (% of Revenue)
B15: SG&A % | F15: ='Supporting Schedules'!G60 -> 0.081527528 | G15: =F15 -> 0.081527528 | H15: =G15 -> 0.081527528 | I15: =H15 -> 0.081527528 | J15: =I15 -> 0.081527528
B17: Depreciation (% of Beg. PPE )
B18: Depreciation % | F18: ='Supporting Schedules'!G143 -> 0.063708571 | G18: ='Supporting Schedules'!H143 -> 0.064515106 | H18: ='Supporting Schedules'!I143 -> 0.064596216 | I18: ='Supporting Schedules'!J143 -> 0.064273298 | J18: ='Supporting Schedules'!K143 -> 0.06446154
B20: TAX & OTHER
B21: Effective Tax Rate % | F21: ='Supporting Schedules'!C67 -> 0.19483833 | G21: =F21 -> 0.19483833 | H21: =G21 -> 0.19483833 | I21: =H21 -> 0.19483833 | J21: =I21 -> 0.19483833
B23: BALANCE SHEET & CAPEX
B24: DSO (Days) | F24: ='Supporting Schedules'!C88 -> 57.242053 | G24: ='Supporting Schedules'!D88 -> 57.242053 | H24: ='Supporting Schedules'!E88 -> 57.242053 | I24: ='Supporting Schedules'!F88 -> 57.242053 | J24: ='Supporting Schedules'!G88 -> 57.242053
B25: DIO (Days) | F25: ='Supporting Schedules'!C90 -> 6.1456248 | G25: ='Supporting Schedules'!D90 -> 6.1456248 | H25: ='Supporting Schedules'!E90 -> 6.1456248 | I25: ='Supporting Schedules'!F90 -> 6.1456248 | J25: ='Supporting Schedules'!G90 -> 6.1456248
B26: DPO (Days) | F26: ='Supporting Schedules'!C89 -> 33.222416 | G26: ='Supporting Schedules'!D89 -> 33.222416 | H26: ='Supporting Schedules'!E89 -> 33.222416 | I26: ='Supporting Schedules'!F89 -> 33.222416 | J26: ='Supporting Schedules'!G89 -> 33.222416
B27: Other Current Assets % of Revenue | F27: ='Supporting Schedules'!E129 -> 0.0075302267 | G27: =F27 -> 0.0075302267 | H27: =G27 -> 0.0075302267 | I27: =H27 -> 0.0075302267 | J27: =I27 -> 0.0075302267
B28: Capex as % of Beg. PPE | F28: ='Supporting Schedules'!G142 -> 0.18148427 | G28: ='Supporting Schedules'!H142 -> 0.17579625 | H28: ='Supporting Schedules'!I142 -> 0.17670448 | I28: ='Supporting Schedules'!J142 -> 0.177995 | J28: ='Supporting Schedules'!K142 -> 0.17683191
B29: Other Current Liabilities % of Revenue | F29: =AVERAGE('Forecast Model'!F53/'Forecast Model'!F8,'Forecast Model'!G53/'Forecast Model'!G8,'Forecast Model'!H53/'Forecast Model'!H8,'Forecast Model'!I53/'Forecast Model'!I8) -> 0.076233489 | G29: =F29 -> 0.076233489 | H29: =G29 -> 0.076233489 | I29: =H29 -> 0.076233489 | J29: =I29 -> 0.076233489
B31: VALUATION PARAMETERS
B32: Terminal Growth Rate | J32: 0.025

Sheet Supporting Schedules
B2: SUPPORTING SCHEDULES
B3: Copart Inc. (CPRT)
B5: REVENUE SCHEDULE
B7: Scenario Assumptions — Revenue Growth Rates
C8: 2026E | D8: 2027E | E8: 2028E | F8: 2029E | G8: 2030E
B9: Service Revenue Growth | C9: =G26-0.5% -> 0.10957456 | D9: =C9-1% -> 0.099574558 | E9: =D9-1% -> 0.089574558 | F9: =E9+0.5% -> 0.094574558 | G9: =F9+0.5% -> 0.099574558
B10: Vehicle Sales Growth | C10: 0.005 | D10: 0.008 | E10: 0.01 | F10: 0.008 | G10: 0.006
B11: Total Revenue Growth | C11: =C9*$G$18 + $G$21*C10 -> 0.094317069 | D11: =D9*$G$18 + $G$21*D10 -> 0.086213777 | E11: =E9*$G$18 + $G$21*E10 -> 0.077964584 | F11: =F9*$G$18 + $G$21*F10 -> 0.081943279 | G11: =G9*$G$18 + $G$21*G10 -> 0.085921975
B12: (implied)
B14: Section A : Segment Wise Historical Data
D16: 2022A | E16: 2023A | F16: 2024A | G16: 2025A
B17: Service | D17: 2853 | E17: 3198 | F17: 3561 | G17: 3969
B18: % of Total | D18: =D17/D23 -> 0.81491003 | E18: =E17/E23 -> 0.82657017 | F18: =F17/F23 -> 0.84045315 | G18: =G17/G23 -> 0.85409942
B20: Vehicle | D20: 648 | E20: 671 | F20: 676 | G20: 678
B21: % of Total | D21: =1-D18 -> 0.18508997 | E21: =1-E18 -> 0.17342983 | F21: =1-F18 -> 0.15954685 | G21: =1-G18 -> 0.14590058
D23: =D17+D20 -> 3501 | E23: =E17+E20 -> 3869 | F23: =F17+F20 -> 4237 | G23: =G17+G20 -> 4647
B25: YoY Growth %
B26: Service | E26: =E17/D17-1 -> 0.12092534 | F26: =F17/E17-1 -> 0.11350844 | G26: =G17/F17-1 -> 0.11457456
B27: Vehicle | E27: =E20/D20-1 -> 0.035493827 | F27: =F20/E20-1 -> 0.0074515648 | G27: =G20/F20-1 -> 0.0029585799
B31: GROSS MARGIN ASSUMPTIONS
B33: Scenario Assumptions - Gross Margins
C34: 2026E | D34: 2027E | E34: 2028E | F34: 2029E | G34: 2030E
C35: =AVERAGE(D46:G46) -> 0.4904081 | D35: =C35 -> 0.4904081 | E35: =D35 -> 0.4904081 | F35: =E35 -> 0.4904081 | G35: =F35 -> 0.4904081
B38: Section A : Historical Gross Margin
D41: 2022A | E41: 2023A | F41: 2024A | G41: 2025A
B43: Gross Profit | D43: ='Forecast Model'!F10 -> 1724.134 | E43: ='Forecast Model'!G10 -> 1879.088 | F43: ='Forecast Model'!H10 -> 2077.902 | G43: ='Forecast Model'!I10 -> 2291.418
B44: Revenue | D44: ='Forecast Model'!F8 -> 3500.921 | E44: ='Forecast Model'!G8 -> 3869.518 | F44: ='Forecast Model'!H8 -> 4236.823 | G44: ='Forecast Model'!I8 -> 4646.958
B46: Gross Margin | D46: =D43/D44 -> 0.49248012 | E46: =E43/E44 -> 0.48561294 | F46: =F43/F44 -> 0.49043871 | G46: =G43/G44 -> 0.49310065
B49: Operating Expenses Assumptions
B52: Section A : Historical SG&A
D55: 2022A | E55: 2023A | F55: 2024A | G55: 2025A
B57: SG&A | D57: =-'Forecast Model'!F12 -> 211.152 | E57: =-'Forecast Model'!G12 -> 233.041 | F57: =-'Forecast Model'!H12 -> 316.118 | G57: =-'Forecast Model'!I12 -> 378.855
B58: Revenue | D58: ='Forecast Model'!F8 -> 3500.921 | E58: ='Forecast Model'!G8 -> 3869.518 | F58: ='Forecast Model'!H8 -> 4236.823 | G58: ='Forecast Model'!I8 -> 4646.958
B60: SG&A as % of Revenue | D60: =D57/D58 -> 0.060313272 | E60: =E57/E58 -> 0.060224814 | F60: =F57/F58 -> 0.074612038 | G60: =G57/G58 -> 0.081527528
B62: * using recent year
B65: Tax Schedule
B67: Avg. Tax rate (Last 4 yrs ) | C67: =AVERAGE(D78:G78) -> 0.19483833
B70: Section A : Historical Tax Rate
D73: 2022A | E73: 2023A | F73: 2024A | G73: 2025A
B75: Taxes | D75: =-'Forecast Model'!F21 -> 250.824 | E75: =-'Forecast Model'!G21 -> 316.587 | F75: =-'Forecast Model'!H21 -> 352.254 | G75: =-'Forecast Model'!I21 -> 347.218
...

Sheet Forecast Model
B3: INCOME STATEMENT
B5: All figures in millions of euros | F5: 2022A | G5: 2023A | H5: 2024A | I5: 2025A | J5: 2026E | K5: 2027E | L5: 2028E | M5: 2029E | N5: 2030E
B6: unless stated otherwise
B8: Revenue | F8: 3500.921 | G8: 3869.518 | H8: 4236.823 | I8: 4646.958 | J8: =I8*(1+'Master Assumptions'!F11) -> 5085.2455 | K8: =J8*(1+'Master Assumptions'!G11) -> 5523.6637 | L8: =K8*(1+'Master Assumptions'!H11) -> 5954.3138 | M8: =L8*(1+'Master Assumptions'!I11) -> 6442.2298 | N8: =M8*(1+'Master Assumptions'!J11) -> 6995.7589
B9: COGS | F9: -1776.787 | G9: -1990.43 | H9: -2158.921 | I9: -2355.54 | J9: =J10-J8 -> -2591.3999 | K9: =K10-K8 -> -2814.8142 | L9: =L10-L8 -> -3034.2701 | M9: =M10-M8 -> -3282.9081 | N9: =N10-N8 -> -3564.9821
B10: Gross Profit | F10: =SUM(F8:F9) -> 1724.134 | G10: =SUM(G8:G9) -> 1879.088 | H10: =SUM(H8:H9) -> 2077.902 | I10: =SUM(I8:I9) -> 2291.418 | J10: =J8*'Master Assumptions'!F12 -> 2493.8456 | K10: =K8*'Master Assumptions'!G12 -> 2708.8494 | L10: =L8*'Master Assumptions'!H12 -> 2920.0437 | M10: =M8*'Master Assumptions'!I12 -> 3159.3217 | N10: =N8*'Master Assumptions'!J12 -> 3430.7769
B12: SG&A Expense | F12: -211.152 | G12: -233.041 | H12: -316.118 | I12: -378.855 | J12: =J8*'Master Assumptions'!F15*-1 -> -414.58749 | K12: =K8*'Master Assumptions'!G15*-1 -> -450.33065 | L12: =L8*'Master Assumptions'!H15*-1 -> -485.44049 | M12: =M8*'Master Assumptions'!I15*-1 -> -525.21907 | N12: =N8*'Master Assumptions'!J15*-1 -> -570.34693
B13: D&A Expense | F13: -137.985 | G13: -159.478 | H13: -189.761 | I13: -215.849 | J13: =-'Master Assumptions'!F18*'Forecast Model'!I42 -> -235.58162 | K13: =-'Master Assumptions'!G18*'Forecast Model'!J42 -> -266.66107 | L13: =-'Master Assumptions'!H18*'Forecast Model'!K42 -> -296.70798 | M13: =-'Master Assumptions'!I18*'Forecast Model'!L42 -> -328.32186 | N13: =-'Master Assumptions'!J18*'Forecast Model'!M42 -> -366.73011
B14: EBIT | F14: =SUM(F10:F13) -> 1374.997 | G14: =SUM(G10:G13) -> 1486.569 | H14: =SUM(H10:H13) -> 1572.023 | I14: =SUM(I10:I13) -> 1696.714 | J14: =SUM(J10:J13) -> 1843.6765 | K14: =SUM(K10:K13) -> 1991.8577 | L14: =SUM(L10:L13) -> 2137.8953 | M14: =SUM(M10:M13) -> 2305.7808 | N14: =SUM(N10:N13) -> 2493.6998
B16: Unusual Expense | F16: -16.8 | G16: 0 | H16: 0 | I16: 0 | J16: =I16 -> 0 | K16: =J16 -> 0 | L16: =K16 -> 0 | M16: =L16 -> 0 | N16: =M16 -> 0
B17: Interest Expense | F17: -16.7 | G17: 0 | H17: 0 | I17: 0 | J17: =I17 -> 0 | K17: =J17 -> 0 | L17: =K17 -> 0 | M17: =L17 -> 0 | N17: =M17 -> 0
B18: Other Income (Expense) | F18: -0.596 | G18: 67.759 | H18: 142.578 | I18: 198.867 | J18: =AVERAGE(H18:I18) -> 170.7225 | K18: =J18 -> 170.7225 | L18: =K18 -> 170.7225 | M18: =L18 -> 170.7225 | N18: =M18 -> 170.7225
B19: EBT | F19: =SUM(F14:F18) -> 1340.901 | G19: =SUM(G14:G18) -> 1554.328 | H19: =SUM(H14:H18) -> 1714.601 | I19: =SUM(I14:I18) -> 1895.581 | J19: =SUM(J14:J18) -> 2014.399 | K19: =SUM(K14:K18) -> 2162.5802 | L19: =SUM(L14:L18) -> 2308.6178 | M19: =SUM(M14:M18) -> 2476.5033 | N19: =SUM(N14:N18) -> 2664.4223
B21: Income Taxes | F21: -250.824 | G21: -316.587 | H21: -352.254 | I21: -347.218 | J21: =J19*-1*'Master Assumptions'!F21 -> -392.48213 | K21: =K19*-1*'Master Assumptions'!G21 -> -421.35351 | L21: =L19*-1*'Master Assumptions'!H21 -> -449.80723 | M21: =M19*-1*'Master Assumptions'!I21 -> -482.51776 | N21: =N19*-1*'Master Assumptions'!J21 -> -519.13159
B22: Consolidated Net Income | F22: =SUM(F19:F21) -> 1090.077 | G22: =SUM(G19:G21) -> 1237.741 | H22: =SUM(H19:H21) -> 1362.347 | I22: =SUM(I19:I21) -> 1548.363 | J22: =SUM(J19:J21) -> 1621.9168 | K22: =SUM(K19:K21) -> 1741.2267 | L22: =SUM(L19:L21) -> 1858.8106 | M22: =SUM(M19:M21) -> 1993.9855 | N22: =SUM(N19:N21) -> 2145.2907
B24: Minority Interests | F24: 0 | G24: 0 | H24: -0.7 | I24: -4.1 | J24: =I24 -> -4.1 | K24: =J24 -> -4.1 | L24: =K24 -> -4.1 | M24: =L24 -> -4.1 | N24: =M24 -> -4.1
B25: Net Income | F25: =SUM(F22:F24) -> 1090.077 | G25: =SUM(G22:G24) -> 1237.741 | H25: =SUM(H22:H24) -> 1361.647 | I25: =SUM(I22:I24) -> 1544.263 | J25: =SUM(J22:J24) -> 1617.8168 | K25: =SUM(K22:K24) -> 1737.1267 | L25: =SUM(L22:L24) -> 1854.7106 | M25: =SUM(M22:M24) -> 1989.8855 | N25: =SUM(N22:N24) -> 2141.1907
B29: BALANCE SHEET
B31: All figures in millions of euros | F31: 2022A | G31: 2023A | H31: 2024A | I31: 2025A | J31: 2026E | K31: 2027E | L31: 2028E | M31: 2029E | N31: 2030E
B32: unless stated otherwise
B34: Assets
B35: Cash & Short-Term Investments | F35: 1384.236 | G35: 2363.984 | H35: 3422.158 | I35: 4789.07 | J35: =I35+J107 -> 5920.791 | K35: =J35+K107 -> 7175.8962 | L35: =K35+L107 -> 8493.9922 | M35: =L35+M107 -> 9878.4102 | N35: =M35+N107 -> 11352.457
B36: Accounts Receivable | F36: 571.316 | G36: 685.704 | H36: 759.924 | I36: 728.771 | J36: ='Supporting Schedules'!H99 -> 797.50654 | K36: ='Supporting Schedules'!I99 -> 866.2626 | L36: ='Supporting Schedules'!J99 -> 933.8004 | M36: ='Supporting Schedules'!K99 -> 1010.3191 | N36: ='Supporting Schedules'!L99 -> 1097.1277
B37: Other Receivables | F37: 57.139 | G37: 22.908 | H37: 25.953 | I37: 34.62 | J37: =I37 -> 34.62 | K37: =J37 -> 34.62 | L37: =K37 -> 34.62 | M37: =L37 -> 34.62 | N37: =M37 -> 34.62
B38: Inventories | F38: 58.791 | G38: 39.973 | H38: 43.639 | I38: 39.661 | J38: ='Supporting Schedules'!H108 -> 43.63225 | K38: ='Supporting Schedules'!I108 -> 47.393951 | L38: ='Supporting Schedules'!J108 -> 51.089001 | M38: ='Supporting Schedules'!K108 -> 55.275401 | N38: ='Supporting Schedules'!L108 -> 60.024773
B39: Other Current Assets | F39: 18.731 | G39: 26.31 | H39: 33.872 | I39: 46.361 | J39: ='Master Assumptions'!F27*'Forecast Model'!J8 -> 38.293051 | K39: ='Master Assumptions'!G27*'Forecast Model'!K8 -> 41.594439 | L39: ='Master Assumptions'!H27*'Forecast Model'!L8 -> 44.837333 | M39: ='Master Assumptions'!I27*'Forecast Model'!M8 -> 48.511451 | N39: ='Master Assumptions'!J27*'Forecast Model'!N8 -> 52.67965
B40: Total Current Assets | F40: =SUM(F35:F39) -> 2090.213 | G40: =SUM(G35:G39) -> 3138.879 | H40: =SUM(H35:H39) -> 4285.546 | I40: =SUM(I35:I39) -> 5638.483 | J40: =SUM(J35:J39) -> 6834.8428 | K40: =SUM(K35:K39) -> 8165.7672 | L40: =SUM(L35:L39) -> 9558.3389 | M40: =SUM(M35:M39) -> 11027.136 | N40: =SUM(N35:N39) -> 12596.909
B42: Net PP&E | F42: 2602.067 | G42: 2952.478 | H42: 3292.139 | I42: 3697.801 | J42: ='Supporting Schedules'!G140 -> 4133.3121 | K42: ='Supporting Schedules'!H140 -> 4593.2718 | L42: ='Supporting Schedules'!I140 -> 5108.2155 | M42: ='Supporting Schedules'!J140 -> 5689.1305 | N42: ='Supporting Schedules'!K140 -> 6328.4202
B43: Goodwill | F43: 401.954 | G43: 394.289 | H43: 513.909 | I43: 517.779 | J43: =I43 -> 517.779 | K43: =J43 -> 517.779 | L43: =K43 -> 517.779 | M43: =L43 -> 517.779 | N43: =M43 -> 517.779
B44: Other Intangible Assets | F44: 54.68 | G44: 62.702 | H44: 74.088 | I44: 62.832 | J44: =I44 -> 62.832 | K44: =J44 -> 62.832 | L44: =K44 -> 62.832 | M44: =L44 -> 62.832 | N44: =M44 -> 62.832
B45: Other Non-Current Assets | F45: 159.95 | G45: 189.531 | H45: 262.082 | I45: 174.007 | J45: =I45 -> 174.007 | K45: =J45 -> 174.007 | L45: =K45 -> 174.007 | M45: =L45 -> 174.007 | N45: =M45 -> 174.007
B46: Total Non-Current Assets | F46: =SUM(F42:F45) -> 3218.651 | G46: =SUM(G42:G45) -> 3599 | H46: =SUM(H42:H45) -> 4142.218 | I46: =SUM(I42:I45) -> 4452.419 | J46: =SUM(J42:J45) -> 4887.9301 | K46: =SUM(K42:K45) -> 5347.8898 | L46: =SUM(L42:L45) -> 5862.8335 | M46: =SUM(M42:M45) -> 6443.7485 | N46: =SUM(N42:N45) -> 7083.0382
B47: Total Assets | F47: =F40+F46 -> 5308.864 | G47: =G40+G46 -> 6737.879 | H47: =H40+H46 -> 8427.764 | I47: =I40+I46 -> 10090.902 | J47: =J40+J46 -> 11722.773 | K47: =K40+K46 -> 13513.657 | L47: =L40+L46 -> 15421.172 | M47: =M40+M46 -> 17470.885 | N47: =N40+N46 -> 19679.947
B49: Liabilities
B50: Accounts Payable | F50: 187.17 | G50: 180.016 | H50: 193.333 | I50: 214.402 | J50: ='Supporting Schedules'!H116 -> 235.87004 | K50: ='Supporting Schedules'!I116 -> 256.20529 | L50: ='Supporting Schedules'!J116 -> 276.18023 | M50: ='Supporting Schedules'!K116 -> 298.81134 | N50: ='Supporting Schedules'!L116 -> 324.4858
B51: Short-Term Debt | F51: 21.794 | G51: 21.468 | H51: 21.304 | I51: 19.869 | J51: =I51 -> 19.869 | K51: =J51 -> 19.869 | L51: =K51 -> 19.869 | M51: =L51 -> 19.869 | N51: =M51 -> 19.869
B52: Income Tax Payable | F52: 6.906 | G52: 3.862 | H52: 69.214 | I52: 53.93 | J52: =I52 -> 53.93 | K52: =J52 -> 53.93 | L52: =K52 -> 53.93 | M52: =L52 -> 53.93 | N52: =M52 -> 53.93
B53: Other Current Liabilities | F53: 225.019 | G53: 287.423 | H53: 344.716 | I53: 395.08 | J53: =J8*'Master Assumptions'!F29 -> 387.666 | K53: =K8*'Master Assumptions'!G29 -> 421.08816 | L53: =L8*'Master Assumptions'!H29 -> 453.91812 | M53: =M8*'Master Assumptions'!I29 -> 491.11366 | N53: =N8*'Master Assumptions'!J29 -> 533.31111
B54: Total Current Liabilities | F54: =SUM(F50:F53) -> 440.889 | G54: =SUM(G50:G53) -> 492.769 | H54: =SUM(H50:H53) -> 628.567 | I54: =SUM(I50:I53) -> 683.281 | J54: =SUM(J50:J53) -> 697.33505 | K54: =SUM(K50:K53) -> 751.09244 | L54: =SUM(L50:L53) -> 803.89734 | M54: =SUM(M50:M53) -> 863.724 | N54: =SUM(N50:N53) -> 931.59591
B56: Long-Term Debt | F56: 97.679 | G56: 98.985 | H56: 97.429 | I56: 83.87 | J56: =I56 -> 83.87 | K56: =J56 -> 83.87 | L56: =K56 -> 83.87 | M56: =L56 -> 83.87 | N56: =M56 -> 83.87
...

Sheet DCF Valuation
B3: DCF VALUATION
B5: SECTION 1: CAPITAL STRUCTURE
B7: Cost of Equity (CAPM): | H7: Cost of Debt:
B9: Risk-Free Rate (Rf) | E9: 0.0443 | H9: Pre-tax Cost of Debt (Kd) | J9: 0
B10: Equity risk premium (ERP) | E10: 0.0446 | H10: Tax rate | J10: 0
B11: Beta (Levered) | E11: 0.9 | H11: After-Tax Cost of Debt | J11: 0
B12: Cost of Equity(Ke) | E12: =E9+E10*E11 -> 0.08444
B15: Weight of Equity | E15: 1 | H15: Weight of Debt | J15: =1-E15 -> 0
B18: Weighted Average Cost of Capital | E18: =IF('Sensitivity Tables'!K10="",E12*E15,'Sensitivity Tables'!K10) -> 0.08444
B21: SECTION 2: FREE CASH FLOW SCHEDULE
E24: 2026E | F24: 2027E | G24: 2028E | H24: 2029E | I24: 2030E
B26: EBIT | E26: ='Forecast Model'!J14 -> 1843.6765 | F26: ='Forecast Model'!K14 -> 1991.8577 | G26: ='Forecast Model'!L14 -> 2137.8953 | H26: ='Forecast Model'!M14 -> 2305.7808 | I26: ='Forecast Model'!N14 -> 2493.6998
B27: % Margin | E27: =E26/'Forecast Model'!J8 -> 0.36255408 | F27: =F26/'Forecast Model'!K8 -> 0.36060445 | G27: =G26/'Forecast Model'!L8 -> 0.35904982 | H27: =H26/'Forecast Model'!M8 -> 0.35791657 | I27: =I26/'Forecast Model'!N8 -> 0.3564588
B28: Less: Taxes on EBIT | E28: =-'Master Assumptions'!F21*'DCF Valuation'!E26 -> -359.21884 | F28: =-'Master Assumptions'!G21*'DCF Valuation'!F26 -> -388.09023 | G28: =-'Master Assumptions'!H21*'DCF Valuation'!G26 -> -416.54394 | H28: =-'Master Assumptions'!I21*'DCF Valuation'!H26 -> -449.25447 | I28: =-'Master Assumptions'!J21*'DCF Valuation'!I26 -> -485.86831
B29: NOPAT (EBIT x (1-Tax rate) | E29: =E26+E28 -> 1484.4576 | F29: =F26+F28 -> 1603.7675 | G29: =G26+G28 -> 1721.3513 | H29: =H26+H28 -> 1856.5263 | I29: =I26+I28 -> 2007.8315
B32: Plus: D&A | E32: =-'Forecast Model'!J13 -> 235.58162 | F32: =-'Forecast Model'!K13 -> 266.66107 | G32: =-'Forecast Model'!L13 -> 296.70798 | H32: =-'Forecast Model'!M13 -> 328.32186 | I32: =-'Forecast Model'!N13 -> 366.73011
B33: Less: CapEx | E33: ='Forecast Model'!J93 -> -671.0927 | F33: ='Forecast Model'!K93 -> -726.62077 | G33: ='Forecast Model'!L93 -> -811.6517 | H33: ='Forecast Model'!M93 -> -909.23682 | I33: ='Forecast Model'!N93 -> -1006.0198
B34: Less: Change in NWC | E34: =SUM('Forecast Model'!J85:J89) -> -50.5848 | F34: =SUM('Forecast Model'!K85:K89) -> -22.061743 | G34: =SUM('Forecast Model'!L85:L89) -> -21.670844 | H34: =SUM('Forecast Model'!M85:M89) -> -24.552533 | I34: =SUM('Forecast Model'!N85:N89) -> -27.854265
B37: Unlevered Free Cash Flow | E37: =SUM(E29:E34) -> 998.36175 | F37: =SUM(F29:F34) -> 1121.746 | G37: =SUM(G29:G34) -> 1184.7368 | H37: =SUM(H29:H34) -> 1251.0588 | I37: =SUM(I29:I34) -> 1340.6876
B38: % Conversion (UCF/NOPAT) | E38: =E37/E29 -> 0.67254311 | F38: =F37/F29 -> 0.69944431 | G38: =G37/G29 -> 0.68825971 | H38: =H37/H29 -> 0.67387077 | I38: =I37/I29 -> 0.66772911
B42: SECTION 3: DISCOUNTING & PRESENT VALUE
E43: 2025E | F43: 2026E | G43: 2027E | H43: 2028E | I43: 2029E
B44: Discount Period (Mid Year Convention) | E44: 0.5 | F44: =1+E44 -> 1.5 | G44: =1+F44 -> 2.5 | H44: =1+G44 -> 3.5 | I44: =1+H44 -> 4.5
B45: Discount Factor | E45: =1/(1+$E$18)^E44 -> 0.96027857 | F45: =1/(1+$E$18)^F44 -> 0.88550641 | G45: =1/(1+$E$18)^G44 -> 0.81655639 | H45: =1/(1+$E$18)^H44 -> 0.75297516 | I45: =1/(1+$E$18)^I44 -> 0.6943447
B47: PV of FCF | E47: =E37*E45 -> 958.70539 | F47: =F37*F45 -> 993.3133 | G47: =G37*G45 -> 967.40437 | H47: =H37*H45 -> 942.01621 | I47: =I37*I45 -> 930.89929
B49: Sum of FCF | E49: =SUM(E47:I47) -> 4792.3386
B52: SECTION 4: TERMINAL VALUE CALCULATION
B53: Perpetual Growth Method | G53: Exit multiple Method
B55: Terminal Year FCF (2029E) | E55: =I47 -> 930.89929 | G55: Terminal Year EBITDA (2029E) | I55: ='Forecast Model'!N14-'Forecast Model'!N13 -> 2860.4299
B56: Perpetual Growth Rate | E56: =IF('Sensitivity Tables'!K11="",2.5%,'Sensitivity Tables'!K11) -> 0.025 | G56: Exit EV/EBITDA Multiple | I56: =IF('Sensitivity Tables'!K23="",17,'Sensitivity Tables'!K23) -> 17
B57: Terminal Value (Perpetuity) | E57: =E55*(1+E56)/(E18-E56) -> 16052.688 | G57: Terminal Value | I57: =I55*I56 -> 48627.309
B58: PV of Terminal Value | E58: =E57*I45 -> 11146.099 | G58: PV of Terminal Value | I58: =I57*I45 -> 33764.114
B61: SECTION 5: ENTERPRISE VALUE TO EQUITY VALUE
B63: Perpetual Growth Method | G63: Exit multiple Method
B64: Sum of PV of FCF | E64: =E49 -> 4792.3386 | G64: Sum of PV of FCF | I64: =E49 -> 4792.3386
B65: PV of Terminal Value | E65: =E58 -> 11146.099 | G65: PV of Terminal Value | I65: =I58 -> 33764.114
B66: Enterprise Value | E66: =E64+E65 -> 15938.437 | G66: Enterprise Value | I66: =I64+I65 -> 38556.453
B68: Less: Total Debt | E68: 0 | G68: Less: Total Debt | I68: =0 -> 0
B69: Plus: Cash & Equivalents | E69: ='Forecast Model'!I35 -> 4789.07 | G69: Plus: Cash & Equivalents | I69: ='Forecast Model'!I35 -> 4789.07
B70: Less: Minority Interest | E70: =-'Forecast Model'!I66 -> -20.458 | G70: Less: Minority Interest | I70: =-'Forecast Model'!I66 -> -20.458
...

Sheet Trading Comps
A3: TRADING COMPARABLES ANALYSIS
A5: All figures in EUR millions unless stated otherwise
A8: SECTION 1: COMPANY OVERVIEW & MARKET DATA
B9: Company | C9: Ticker | D9: Exchange | E9: Currency | F9: Share Price($) | G9: Shares Out. (mm) | H9: Market Cap ($mm) | I9: (+) Total Debt ($mm) | J9: (-) Cash ($mm) | K9: (-)Inv in Unconsolidated Subs ($mm) | L9: Enterprise Value ($mm)
B11: Copart Inc. | C11: CPRT-US | D11: NYSE | E11: USD | F11: 32.43 | G11: 975.1 | H11: =F11*G11 -> 31622.493 | I11: 0 | J11: ='DCF Valuation'!E69 -> 4789.07 | K11: 0 | L11: =H11+I11-J11 -> 26833.423
B12: RB Global | C12: RBA-CA | D12: Toronto | E12: CAD | F12: 94.7 | G12: 186.9 | H12: =F12*G12 -> 17699.43 | I12: 2471.5 | J12: 694.8 | K12: 0 | L12: =H12+I12-J12 -> 19476.13
B13: CarMax | C13: KMX-US | D13: NYSE | E13: USD | F13: 40.86 | G13: 145.9 | H13: =F13*G13 -> 5961.474 | I13: 16838.61 | J13: 772.34 | K13: 0 | L13: =H13+I13-J13 -> 22027.744
B14: Carvana A | C14: CVNA-US | D14: NYSE | E14: USD | F14: 302.04 | G14: 224.3 | H14: =F14*G14 -> 67747.572 | I14: 4450 | J14: 2915 | K14: 0 | L14: =H14+I14-J14 -> 69282.572
A16: SECTION 2: FINANCIAL SUMMARY (LTM & 2026E)
B17: Company | D17: Revenue ($mm) | F17: EBITDA ($mm) | H17: EBITDA Margin | J17: EBIT ($mm) | L17: EBIT Margin | N17: Net Income ($mm) | P17: EPS-Diluted ($)
D18: NTM | E18: 2026E | F18: NTM | G18: 2026E | H18: NTM | I18: 2026E | J18: NTM | K18: 2026E | L18: NTM | M18: 2026E | N18: NTM | O18: 2026E | P18: NTM | Q18: 2026E
B19: Copart Inc. | D19: 4747.41 | E19: ='Forecast Model'!J8 -> 5085.2455 | F19: 1973.57 | G19: ='Forecast Model'!J14-'Forecast Model'!J13 -> 2079.2581 | H19: =F19/D19 -> 0.4157151 | I19: =G19/E19 -> 0.40888058 | J19: =1736.91 -> 1736.91 | K19: ='Forecast Model'!J14 -> 1843.6765 | L19: =J19/D19 -> 0.36586476 | M19: =K19/E19 -> 0.36255408 | N19: =1573.64 -> 1573.64 | O19: ='Forecast Model'!J25 -> 1617.8168 | P19: =N19/G11 -> 1.6138242 | Q19: =O19/G11 -> 1.6591292
B20: RB Global | D20: 4754.58 | E20: 4687.19 | F20: 1484.38 | G20: 1455.79 | H20: =F20/D20 -> 0.31220003 | I20: =G20/E20 -> 0.31058907 | J20: =985.13 -> 985.13 | K20: =960.88 -> 960.88 | L20: =J20/D20 -> 0.20719601 | M20: =K20/E20 -> 0.20500129 | N20: =844.29 -> 844.29 | O20: 820.84 | P20: =N20/G12 -> 4.5173355 | Q20: =O20/G12 -> 4.3918673
B21: CarMax | D21: 25718.01 | E21: 25593.47 | F21: 911.53 | G21: 973.06 | H21: =F21/D21 -> 0.035443256 | I21: =G21/E21 -> 0.038019854 | J21: =567.5 -> 567.5 | K21: =639.02 -> 639.02 | L21: =J21/D21 -> 0.022066249 | M21: =K21/E21 -> 0.024968088 | N21: =358.62 -> 358.62 | O21: =398.14 -> 398.14 | P21: =N21/G13 -> 2.4579849 | Q21: =O21/G13 -> 2.7288554
B22: =B14 -> Carvana A | D22: =28200.97 -> 28200.97 | E22: =26744.28 -> 26744.28 | F22: 3118.27 | G22: 2915.71 | H22: =F22/D22 -> 0.11057315 | I22: =G22/E22 -> 0.10902182 | J22: =2687.81 -> 2687.81 | K22: =2497.15 -> 2497.15 | L22: =J22/D22 -> 0.095309133 | M22: =K22/E22 -> 0.093371368 | N22: 1777.47 | O22: =1614.24 -> 1614.24 | P22: =N22/G14 -> 7.9245207 | Q22: =O22/G14 -> 7.19679
A24: SECTION 3: TRADING MULTIPLES
B25: Company | D25: EV / Revenue | F25: EV / EBITDA | H25: EV / EBIT | J25: P / E
D26: NTM | E26: 2026E | F26: NTM | G26: 2026E | H26: NTM | I26: 2026E | J26: NTM | K26: 2026E
B27: Copart Inc. | D27: =L11/D19 -> 5.6522236 | E27: =L11/E19 -> 5.2767213 | F27: =L11/F19 -> 13.596388 | G27: =L11/G19 -> 12.905287 | H27: =L11/J19 -> 15.448943 | I27: =L11/K19 -> 14.554301 | J27: =F11/P19 -> 20.095125 | K27: =F11/Q19 -> 19.546399
B28: RB Global | D28: =L12/D20 -> 4.0962882 | E28: =L12/E20 -> 4.1551825 | F28: =L12/F20 -> 13.120717 | G28: =L12/G20 -> 13.378392 | H28: =L12/J20 -> 19.770112 | I28: =L12/K20 -> 20.269055 | J28: =F12/P20 -> 20.963685 | K28: =F12/Q20 -> 21.562582
B29: CarMax | D29: =L13/D21 -> 0.85651044 | E29: =L13/E21 -> 0.86067829 | F29: =L13/F21 -> 24.165682 | G29: =L13/G21 -> 22.637601 | H29: =L13/J21 -> 38.815408 | I29: =L13/K21 -> 34.471134 | J29: =F13/P21 -> 16.623373 | K29: =F13/Q21 -> 14.973311
B30: Carvana A | D30: =L14/D22 -> 2.4567443 | E30: =L14/E22 -> 2.5905566 | F30: =L14/F22 -> 22.218272 | G30: =L14/G22 -> 23.761819 | H30: =L14/J22 -> 25.776588 | I30: =L14/K22 -> 27.744658 | J30: =F14/P22 -> 38.114608 | K30: =F14/Q22 -> 41.968711
A32: — Peer Summary Statistics (Comps Only) —
B33: Mean | D33: =IFERROR(AVERAGE(D28:D30),"-") -> 2.4698476 | E33: =IFERROR(AVERAGE(E28:E30),"-") -> 2.5354725 | F33: =IFERROR(AVERAGE(F28:F30),"-") -> 19.83489 | G33: =IFERROR(AVERAGE(G28:G30),"-") -> 19.925937 | H33: =IFERROR(AVERAGE(H28:H30),"-") -> 28.120703 | I33: =IFERROR(AVERAGE(I28:I30),"-") -> 27.494949 | J33: =IFERROR(AVERAGE(J28:J30),"-") -> 25.233889 | K33: =IFERROR(AVERAGE(K28:K30),"-") -> 26.168201
B34: Median | D34: =IFERROR(MEDIAN(D28:D30),"-") -> 2.4567443 | E34: =IFERROR(MEDIAN(E28:E30),"-") -> 2.5905566 | F34: =IFERROR(MEDIAN(F28:F30),"-") -> 22.218272 | G34: =IFERROR(MEDIAN(G28:G30),"-") -> 22.637601 | H34: =IFERROR(MEDIAN(H28:H30),"-") -> 25.776588 | I34: =IFERROR(MEDIAN(I28:I30),"-") -> 27.744658 | J34: =IFERROR(MEDIAN(J28:J30),"-") -> 20.963685 | K34: =IFERROR(MEDIAN(K28:K30),"-") -> 21.562582
B35: High | D35: =IFERROR(MAX(D28:D30),"-") -> 4.0962882 | E35: =IFERROR(MAX(E28:E30),"-") -> 4.1551825 | F35: =IFERROR(MAX(F28:F30),"-") -> 24.165682 | G35: =IFERROR(MAX(G28:G30),"-") -> 23.761819 | H35: =IFERROR(MAX(H28:H30),"-") -> 38.815408 | I35: =IFERROR(MAX(I28:I30),"-") -> 34.471134 | J35: =IFERROR(MAX(J28:J30),"-") -> 38.114608 | K35: =IFERROR(MAX(K28:K30),"-") -> 41.968711
B36: Low | D36: =IFERROR(MIN(D28:D30),"-") -> 0.85651044 | E36: =IFERROR(MIN(E28:E30),"-") -> 0.86067829 | F36: =IFERROR(MIN(F28:F30),"-") -> 13.120717 | G36: =IFERROR(MIN(G28:G30),"-") -> 13.378392 | H36: =IFERROR(MIN(H28:H30),"-") -> 19.770112 | I36: =IFERROR(MIN(I28:I30),"-") -> 20.269055 | J36: =IFERROR(MIN(J28:J30),"-") -> 16.623373 | K36: =IFERROR(MIN(K28:K30),"-") -> 14.973311
A39: SECTION 4: IMPLIED VALUATION FOR COPART
B40: Multiple Basis | D40: EV/Rev NTM | E40: EV/Rev 2026E | F40: EV/EBITDA NTM | G40: EV/EBITDA 2026E | H40: EV/EBIT NTM | I40: EV/EBIT 2026E | J40: P/E NTM | K40: P/E 2026E
B41: Avg. Multiple Applied | D41: =D33 -> 2.4698476 | E41: =E33 -> 2.5354725 | F41: =F33 -> 19.83489 | G41: =G33 -> 19.925937 | H41: =H33 -> 28.120703 | I41: =I33 -> 27.494949 | J41: =J33 -> 25.233889 | K41: =K33 -> 26.168201
B42: Copart Metric ($mm) | D42: =D19 -> 4747.41 | E42: =E19 -> 5085.2455 | F42: =F19 -> 1973.57 | G42: =G19 -> 2079.2581 | H42: =J19 -> 1736.91 | I42: =K19 -> 1843.6765 | J42: =P19 -> 1.6138242 | K42: =Q19 -> 1.6591292
B43: Implied Enterprise Value ($mm) | D43: =IFERROR(D41*D42,"-") -> 11725.379 | E43: =IFERROR(E41*E42,"-") -> 12893.5 | F43: =IFERROR(F41*F42,"-") -> 39145.545 | G43: =IFERROR(G41*G42,"-") -> 41431.166 | H43: =IFERROR(H41*H42,"-") -> 48843.13 | I43: =IFERROR(I41*I42,"-") -> 50691.791
B44: Implied Equity Value ($mm) | D44: =IFERROR(D43-I11+J11+$K$11,"-") -> 16514.449 | E44: =IFERROR(E43-I11+J11+K11,"-") -> 17682.57 | F44: =IFERROR(F43-I11+J11+K11,"-") -> 43934.615 | G44: =IFERROR(G43-I11+J11+K11,"-") -> 46220.236 | H44: =IFERROR(H43-I11+J11+K11,"-") -> 53632.2 | I44: =IFERROR(I43-I11+J11+K11,"-") -> 55480.861
B45: Implied Share Price ($) | D45: =IFERROR(D44/G11,"-") -> 16.93616 | E45: =IFERROR(E44/G11,"-") -> 18.134109 | F45: =IFERROR(F44/G11,"-") -> 45.056522 | G45: =IFERROR(G44/G11,"-") -> 47.400509 | H45: =IFERROR(H44/G11,"-") -> 55.001743 | I45: =IFERROR(I44/G11,"-") -> 56.897611 | J45: =J42*J41 -> 40.723061 | K45: =K42*K41 -> 43.416426
A48: Notes: (1) Blue cells = manual inputs. (2) Margin % and multiples auto-calculate upon data entry. (3) EV-based multiples = EV / respective metric. (4) P/E = Market Cap / Net Income.

Sheet Valuation Summary
B7: ENTERPRISE VALUE ($ millions)
B8: Methodology | C8: Low | D8: Mid | E8: High | F8: Source
B9: DCF - Perpetuity Growth | C9: 12839.4 | D9: 15938.437 | E9: 21187.66 | F9: WACC ±1%, TGR ±0.5%
B10: DCF - Exit Multiple | C10: 30611.955 | D10: 38556.453 | E10: 42528.701 | F10: Exit Multiple 13x-19x
B11: Trading Comps (EV/EBITDA:2026E) | C11: ='Trading Comps'!G36*'Trading Comps'!G42 -> 27817.131 | D11: ='Trading Comps'!G43 -> 41431.166 | E11: ='Trading Comps'!G35*'Trading Comps'!G42 -> 49406.953 | F11: Peer range
B12: Current Market EV | D12: ='Trading Comps'!L11 -> 26833.423 | F12: As of current price
B25: IMPLIED SHARE PRICE ($)
B26: Methodology | C26: Low | D26: Mid | E26: High | F26: Source
B27: DCF - Perpetuity Growth | C27: 18.057833 | D27: 21.236039 | E27: 26.61936 | F27: WACC ±1%, TGR ±0.5%
B28: DCF - Exit Multiple | C28: 36.284412 | D28: 44.431862 | E28: 48.505587 | F28: Exit Multiple 13x-19x
B29: Trading Comps (P/E-2026E) | C29: ='Trading Comps'!Q19*'Trading Comps'!K36 -> 24.842657 | D29: 43.416426 | E29: ='Trading Comps'!K35*'Trading Comps'!Q19 -> 69.631512 | F29: Peer range
B30: Current Share Price | D30: ='Trading Comps'!F11 -> 32.43 | F30: As of current price
B39: VALUATION SUMMARY
B40: Methodology | C40: Midpoint EV ($mm) | D40: Midpoint Price ($) | E40: V/S Current
B41: DCF - Perpetuity Growth | C41: =D9 -> 15938.437 | D41: =D27 -> 21.236039 | E41: =D41/D30-1 -> -0.34517302
B42: DCF - Exit Multiple | C42: =D10 -> 38556.453 | D42: =D28 -> 44.431862 | E42: =D42/D30-1 -> 0.37008518
B43: Trading Comps | C43: =D11 -> 41431.166 | D43: =D29 -> 43.416426 | E43: =D43/D30-1 -> 0.33877354
B45: Blended Valuation (Equal Weight) | C45: =AVERAGE(C41:C43) -> 31975.352 | D45: =AVERAGE(D41:D43) -> 36.361442 | E45: =D45/D30-1 -> 0.12122857

Sheet Sensitivity Tables
B3: SENSITIVITY ANALYSIS
B5: WACC vs. PERPETUAL GROWTH RATE
E8: Implied Price (Diluted) | F8: GROWTH RATE
E9: ='DCF Valuation'!E79 -> 21.236039 | F9: 0.015 | G9: 0.02 | H9: 0.025 | I9: 0.03 | J9: 0.035
D10: WACC | E10: 0.0644 | F10: 26.148794 | G10: 28.051204 | H10: 30.436459 | I10: 33.515101 | J10: 37.640901
E11: 0.0744 | F11: 22.236175 | G11: 23.434403 | H11: 24.875188 | I11: 26.640473 | J11: 28.853801
E12: 0.0844 | F12: 19.503685 | G12: 20.308121 | H12: 21.247984 | I12: 22.360616 | J12: 23.698476
E13: 0.0944 | F13: 17.49999 | G13: 18.065514 | H13: 18.712525 | I13: 19.460004 | J13: 20.333321
E14: 0.1044 | F14: 15.976254 | G14: 16.387936 | H14: 16.851467 | I14: 17.3773 | J14: 17.978902
B18: WACC vs EXIT MULTIPLE
E21: Implied Price (Diluted) | F21: EXIT MULTIPLE (EV/EBITDA)
E22: ='DCF Valuation'!I79 -> 44.431862 | F22: 15 | G22: 16 | H22: 17 | I22: 18 | J22: 19
D23: WACC | E23: 0.0644 | F23: 43.267574 | G23: 45.482783 | H23: 47.697992 | I23: 49.913201 | J23: 52.12841
E24: 0.0744 | F24: 41.779116 | G24: 43.903044 | H24: 46.026971 | I24: 48.150898 | J24: 50.274825
E25: 0.0844 | F25: 40.363658 | G25: 42.400859 | H25: 44.43806 | I25: 46.47526 | J25: 48.512461
E26: 0.0944 | F26: 39.016969 | G26: 40.971733 | H26: 42.926496 | I26: 44.88126 | J26: 46.836023
E27: 0.1044 | F27: 37.735101 | G27: 39.611468 | H27: 41.487835 | I27: 43.364202 | J27: 45.24057

Sheet Sources & Footnotes
B2: SOURCES & FOOTNOTES
B3: COPART, INC. | Data Sources, Market Inputs, Methodology & Audit Trail
B5: SECTION 1: PRIMARY DATA SOURCES
B6: # | C6: Source Name | D6: Type | E6: Data Used For | F6: Tabs Referenced | G6: Access Date | H6: URL / Reference
B7: S1 | C7: [e.g., SEC EDGAR - DUOL 10-K] | D7: [SEC Filing] | E7: [IS, BS, CF statements; footnotes] | F7: [Historical Financials] | G7: [Date] | H7: [https://sec.gov/...]
B8: S2 | C8: [e.g., SEC EDGAR - DUOL 10-Q] | D8: [SEC Filing] | E8: [Quarterly interim financials] | F8: [Historical Financials] | G8: [Date] | H8: [https://sec.gov/...]
B9: S3 | C9: [e.g., DUOL Investor Relations] | D9: [Company IR] | E9: [Earnings releases, investor decks, KPIs] | F9: [Key Metrics, Assumptions] | G9: [Date] | H9: [https://investors.duolingo.com/...]
B10: S4 | C10: [e.g., Bloomberg Terminal] | D10: [Terminal] | E10: [Beta, trading data, consensus] | F10: [DCF Valuation] | G10: [Date] | H10: [DUOL US Equity]
B11: S5 | C11: [e.g., Damodaran Online] | D11: [Academic] | E11: [ERP, sector betas, country risk] | F11: [DCF Valuation] | G11: [Date] | H11: [https://pages.stern.nyu.edu/...]
B12: S6 | C12: [e.g., FRED / U.S. Treasury] | D12: [Govt] | E12: [Risk-free rate, macro rates, CPI] | F12: [DCF Valuation] | G12: [Date] | H12: [https://fred.stlouisfed.org/...]
B13: S7 | C13: [e.g., Industry Research Report] | D13: [3rd Party] | E13: [TAM, market sizing, growth rates] | F13: [Forecast Model] | G13: [Date] | H13: [Publisher / Report Title]
B14: S8 | C14: [e.g., FactSet / Capital IQ] | D14: [Terminal] | E14: [Comps, multiples, consensus] | F14: [Valuation] | G14: [Date] | H14: [Screen / export ref]
B15: S9 | C15: [e.g., Duff & Phelps / Kroll] | D15: [Academic] | E15: [Size premium, ERP, cost of capital] | F15: [DCF Valuation] | G15: [Date] | H15: [Publication / Edition]
B16: S10 | C16: [Add more as needed]
B18: SECTION 2: EXTERNAL MARKET INPUTS USED
B19: Input | D19: Value Used | E19: Source / Basis | F19: Feeds Into | G19: As-Of Date | H19: Source Ref
B20: Risk-Free Rate (Rf) | D20: [Enter] | E20: [e.g., 10-Year UST Yield at close] | F20: [DCF: WACC] | G20: [Date] | H20: [S6]
B21: Equity Risk Premium (ERP) | D21: [Enter] | E21: [e.g., Damodaran implied ERP, Jan 2025] | F21: [DCF: WACC] | G21: [Date] | H21: [S5]
B22: Levered Beta | D22: [Enter] | E22: [e.g., 5Y monthly regression vs. S&P 500] | F22: [DCF: WACC] | G22: [Date] | H22: [S4]
B23: Terminal Growth Rate (g) | D23: [Enter] | E23: [e.g., Long-run nominal GDP proxy] | F23: [DCF: Terminal Value] | G23: [Date] | H23: [S6]
B24: Marginal Tax Rate | D24: [Enter] | E24: [e.g., Blended federal + state statutory] | F24: [DCF: NOPAT] | H24: [S1]
B25: EdTech TAM ($bn) | D25: [Enter] | E25: [e.g., HolonIQ / Grand View Research] | F25: [Forecast: Revenue] | G25: [Date] | H25: [S7]
B26: Consensus Revenue FY25E ($mm) | D26: [Enter] | E26: [e.g., Bloomberg / FactSet median] | F26: [Benchmark] | G26: [Date] | H26: [S4/S8]
B27: Consensus EPS FY25E | D27: [Enter] | E27: [e.g., Bloomberg / FactSet median] | F27: [Benchmark] | G27: [Date] | H27: [S4/S8]
B28: [Add rows as needed]
B30: SECTION 3: FOOTNOTES & ADJUSTMENTS
B31: Ref # | C31: Tab / Cell | D31: Footnote Description | E31: Source Ref | F31: Impact on Model
B32: [1] | C32: [e.g., Historical Financials, F10] | D32: [e.g., Revenue restated to reflect ASC 606 adoption; FY2020 adjusted] | E32: [S1] | F32: [e.g., +$2.3mm to FY2020 revenue]
B33: [2] | C33: [e.g., DCF Valuation, E11] | D33: [e.g., Beta sourced from 5Y monthly regression vs. S&P 500; R-sq = 0.42] | E33: [S4] | F33: [Affects Ke and WACC]
B34: [3] | C34: [e.g., Master Assumptions, F20] | D34: [e.g., Tax rate reflects blended state + federal; no NOL carryforward assumed] | E34: [S1] | F34: [Affects NOPAT / FCF]
B35: [4] | C35: [e.g., DCF Valuation, E35] | D35: [e.g., SBC added back to FCF as non-cash; dilution via diluted share count] | E35: [S1] | F35: [Increases UCF significantly]
B36: [5] | C36: [e.g., Forecast Model, H11] | D36: [e.g., Revenue growth assumes continued MAU expansion; no new product lines] | E36: [S3] | F36: [Core revenue driver]
B37: [6] | C37: [Tab / Cell] | D37: [Description] | E37: [Sn] | F37: [Impact]
B38: [7] | C38: [Tab / Cell] | D38: [Description] | E38: [Sn] | F38: [Impact]
B39: [8] | C39: [Tab / Cell] | D39: [Description] | E39: [Sn] | F39: [Impact]
B40: [9] | C40: [Tab / Cell] | D40: [Description] | E40: [Sn] | F40: [Impact]
B41: [10] | C41: [Add rows as needed]
B43: SECTION 4: METHODOLOGY NOTES
B44: Area | C44: Methodology Description | D44: Applicable Tab(s)
B45: Valuation Approach | C45: [e.g., Unlevered DCF; perpetuity growth terminal value; mid-year convention] | D45: [DCF Valuation]
...
