Workbook

Sheet Cover
F8: ASML Holding NV
F9: (Ticker: ASML-NL) | N9: Table of Contents
F11: ASML Holding N.V. is a Dutch multinational to the | N11: Assumptions
F12: global semiconductor industry headquartered in
F13: Veldhoven, the Netherlands, and a leading supplier.
F14: The company provides chipmakers with advanced
F15: lithography systems as well as related software
F16: and services that enable the mass production of
F17: integrated circuit patterns on silicon.
E34: Created By: Divij Budhiraja

Sheet Summary
B2: ASML HOLDING NV — VALUATION SUMMARY
B3: Confidential | For Discussion Purposes Only | All figures in €mm unless stated otherwise
B5: Current Price | D5: Market Cap | F5: Enterprise Value | H5: WACC | J5: LTM Revenue | L5: LTM EBIT Margin | N5: Levered Beta
B6: €652.00 | D6: €471,835mm | F6: €469,412mm | H6: 0.1 | J6: €28,263mm | L6: 0.319 | N6: 1.69x
B8: VALUATION FOOTBALL FIELD
B9: Methodology | C9: Low | D9: Range Width | E9: High | F9: Base Case
B10: DCF — Perpetuity Growth | C10: 418.4 | D10: =F10-C10 -> 136.39 | E10: 878.94 | F10: 554.79
B11: DCF — Exit Multiple | C11: 546.45 | D11: =F11-C11 -> 136.6 | E11: 840.99 | F11: 683.05
B12: Comps — EV/EBITDA | C12: 862.27 | D12: =F12-C12 -> 98.46 | E12: 1059.19 | F12: 960.73
B13: Comps — EV/Revenue | C13: 907.57 | D13: =F13-C13 -> 101.99 | E13: 1111.54 | F13: 1009.56
B14: Current Share Price | C14: 652
B17: REVENUE GROWTH SCENARIOS (€mm)
B18: Scenario | C18: 2024A | D18: 2025E | E18: 2026E | F18: 2027E | G18: 2028E | H18: 2029E
B19: Bull Case | C19: 28262.9 | D19: 33915.5 | E19: 40020.3 | F19: 46023.3 | G19: 51546.1 | H19: 56700.7
B20: Base Case | C20: 28262.9 | D20: 32502.3 | E20: 36402.6 | F20: 40042.9 | G20: 43246.3 | H20: 45841.1
B21: Bear Case | C21: 28262.9 | D21: 29676 | E21: 30566.3 | F21: 31789 | G21: 33378.4 | H21: 34713.6
B22: Bull / Base / Bear Growth | D22: 20% / 15% / 5% | E22: 18% / 12% / 3% | F22: 15% / 10% / 4% | G22: 12% / 8% / 5% | H22: 10% / 6% / 4%
B25: KEY FINANCIAL SUMMARY (€mm)
C26: 2022A | D26: 2023A | E26: 2024A | F26: 2025E | G26: 2026E | H26: 2027E | I26: 2028E | J26: 2029E
B27: Revenue | C27: 21173.4 | D27: 27558.5 | E27: 28262.9 | F27: 33915.5 | G27: 40020.3 | H27: 46023.3 | I27: 51546.1 | J27: 56700.7
B28: % Growth | D28: 0.302 | E28: 0.026 | F28: 0.2 | G28: 0.18 | H28: 0.15 | I28: 0.12 | J28: 0.1
B29: Gross Profit | C29: 11114.6 | D29: 14622.2 | E29: 15067.7 | F29: 18653.5 | G29: 22411.3 | H29: 26233.3 | I29: 29896.7 | J29: 32886.4
B30: % Margin | C30: 0.525 | D30: 0.531 | E30: 0.533 | F30: 0.55 | G30: 0.56 | H30: 0.57 | I30: 0.58 | J30: 0.58
B31: EBIT | C31: 6500.7 | D31: 9042.3 | E31: 9022.6 | F31: 11416 | G31: 14235.4 | H31: 17223.8 | I31: 20174.2 | J31: 22537.6
B32: % Margin | C32: 0.307 | D32: 0.328 | E32: 0.319 | F32: 0.337 | G32: 0.356 | H32: 0.374 | I32: 0.391 | J32: 0.397
B33: Net Income | C33: 5624.2 | D33: 7839 | E33: 7571.6 | F33: 9736.5 | G33: 12125.9 | H33: 14735.7 | I33: 17350.8 | J33: 19531.5
B34: % Margin | C34: 0.266 | D34: 0.284 | E34: 0.268 | F34: 0.287 | G34: 0.303 | H34: 0.32 | I34: 0.337 | J34: 0.344
B35: Unlevered FCF | E35: 8400.6 | F35: 9922.2 | G35: 11663.9 | H35: 13918.6 | I35: 16136.6 | J35: 17380.6
B36: FCF Conversion | E36: 1.129 | F36: 1.054 | G36: 0.993 | H36: 0.98 | I36: 0.97 | J36: 0.935
B39: DCF KEY ASSUMPTIONS | E39: ENTERPRISE VALUE TO EQUITY BRIDGE
B40: Risk-Free Rate | C40: 0.0291 | F40: Perpetuity Growth | G40: Exit Multiple
B41: Equity Risk Premium | C41: 0.0423 | E41: Sum of PV of FCF | F41: 53401 | G41: 53401
B42: Levered Beta | C42: 1.69x | E42: PV of Terminal Value | F42: 154372 | G42: 204817
B43: Cost of Equity (Ke) | C43: 0.1006 | E43: Enterprise Value | F43: 207773 | G43: 258219
B44: Pre-Tax Cost of Debt | C44: 0.0239 | E44: Less: Total Debt | F44: -4994 | G44: -4994
B45: After-Tax Cost of Debt | C45: 0.0197 | E45: Plus: Cash & Equivalents | F45: 12741 | G45: 12741
B46: Equity Weight | C46: 0.994 | E46: Plus: Equity Investments | F46: 2677 | G46: 2677
B47: Debt Weight | C47: 0.006 | E47: Equity Value | F47: 218198 | G47: 268643
B48: WACC | C48: 0.1001 | E48: Shares Outstanding (mm) | F48: 393.3 | G48: 393.3
B49: Perpetual Growth Rate | C49: 0.025 | E49: Implied Share Price (€) | F49: 554.79 | G49: 683.05
...

Sheet Assumptions and Inputs
B2: MODEL ASSUMPTIONS AND OTHER INPUTS
B6: SCENARIO SELECTOR
B8: Active Scenario (1=Base, 2=Bull, 3=Bear) | E8: 2
B10: Scenario Definitions:
B11: 1 = Base Case | E11: Management guidance, consensus estimates, normalized growth
B12: 2 = Bull Case | E12: Upside from AI/HPC demand, market share gains, margin expansion
B13: 3 = Bear Case | E13: Cyclical downturn, China restrictions, slower adoption
B16: REVENUE ASSUMPTIONS
E17: 2024A | F17: 2025E | G17: 2026E | H17: 2027E | I17: 2028E | J17: 2029E
B18: Revenue Growth Rate - Base | F18: 0.15 | G18: 0.12 | H18: 0.1 | I18: 0.08 | J18: 0.06
B19: Revenue Growth Rate - Bull | F19: 0.2 | G19: 0.18 | H19: 0.15 | I19: 0.12 | J19: 0.1
B20: Revenue Growth Rate - Bear | F20: 0.05 | G20: 0.03 | H20: 0.04 | I20: 0.05 | J20: 0.04
B21: Selected Revenue Growth | F21: =IF($E$8=1,F18,IF($E$8=2,F19,F20)) -> 0.2 | G21: =IF($E$8=1,G18,IF($E$8=2,G19,G20)) -> 0.18 | H21: =IF($E$8=1,H18,IF($E$8=2,H19,H20)) -> 0.15 | I21: =IF($E$8=1,I18,IF($E$8=2,I19,I20)) -> 0.12 | J21: =IF($E$8=1,J18,IF($E$8=2,J19,J20)) -> 0.1
B24: MARGIN ASSUMPTIONS
E25: 2024A | F25: 2025E | G25: 2026E | H25: 2027E | I25: 2028E | J25: 2029E
B26: COGS % of Revenue - Base | E26: ='3-Statement Model'!G11/'3-Statement Model'!G10*-1 -> 0.46687353 | F26: 0.465 | G26: 0.46 | H26: 0.455 | I26: 0.45 | J26: 0.45
B27: COGS % of Revenue - Bull | F27: 0.45 | G27: 0.44 | H27: 0.43 | I27: 0.42 | J27: 0.42
B28: COGS % of Revenue - Bear | F28: 0.5 | G28: 0.51 | H28: 0.52 | I28: 0.52 | J28: 0.52
B29: Selected COGS % | E29: =E26 -> 0.46687353 | F29: =IF($E$8=1,F26,IF($E$8=2,F27,F28)) -> 0.45 | G29: =IF($E$8=1,G26,IF($E$8=2,G27,G28)) -> 0.44 | H29: =IF($E$8=1,H26,IF($E$8=2,H27,H28)) -> 0.43 | I29: =IF($E$8=1,I26,IF($E$8=2,I27,I28)) -> 0.42 | J29: =IF($E$8=1,J26,IF($E$8=2,J27,J28)) -> 0.42
B31: R&D % of Revenue | E31: ='3-Statement Model'!G14/'3-Statement Model'!G10*-1 -> 0.13949029 | F31: 0.14 | G31: 0.135 | H31: 0.13 | I31: 0.125 | J31: 0.12
B32: SG&A % of Revenue | E32: ='3-Statement Model'!G15/'3-Statement Model'!G10*-1 -> 0.039482856 | F32: 0.04 | G32: 0.038 | H32: 0.036 | I32: 0.035 | J32: 0.035
B34: TAX & OTHER
E35: 2024A | F35: 2025E | G35: 2026E | H35: 2027E | I35: 2028E | J35: 2029E
B36: Effective Tax Rate | E36: ='3-Statement Model'!G24/'3-Statement Model'!G22*-1 -> 0.18585774 | F36: 0.175 | G36: 0.18 | H36: 0.18 | I36: 0.18 | J36: 0.18
B37: Interest Rate on Cash | F37: 0.025 | G37: 0.025 | H37: 0.025 | I37: 0.025 | J37: 0.025
B38: Interest Rate on Debt | F38: 0.04 | G38: 0.04 | H38: 0.04 | I38: 0.04 | J38: 0.04
B39: Equity in Affiliates Growth | F39: 0.05 | G39: 0.05 | H39: 0.05 | I39: 0.05 | J39: 0.05
B40: Other Income (Expense) | E40: ='3-Statement Model'!G21 -> -8.9 | F40: 0 | G40: 0 | H40: 0 | I40: 0 | J40: 0
B43: WORKING CAPITAL ASSUMPTIONS
E44: 2024A | F44: 2025E | G44: 2026E | H44: 2027E | I44: 2028E | J44: 2029E
B45: Days Sales Outstanding (DSO) | E45: 62 | F45: 60 | G45: 60 | H45: 60 | I45: 60 | J45: 60
B46: Days Inventory Outstanding (DIO) | E46: 324 | F46: 310 | G46: 300 | H46: 290 | I46: 280 | J46: 270
B47: Days Payable Outstanding (DPO) | E47: 97 | F47: 95 | G47: 95 | H47: 95 | I47: 95 | J47: 95
B48: Other Receivables % of Revenue | E48: ='3-Statement Model'!G37/'3-Statement Model'!G10 -> 0.022832052 | F48: 0.023 | G48: 0.023 | H48: 0.023 | I48: 0.023 | J48: 0.023
B49: Other Current Assets % of Revenue | E49: ='3-Statement Model'!G39/'3-Statement Model'!G10 -> 0.029912005 | F49: 0.03 | G49: 0.03 | H49: 0.03 | I49: 0.03 | J49: 0.03
B50: Other Current Liabilities % of Revenue | E50: ='3-Statement Model'!G55/'3-Statement Model'!G10 -> 0.53741124 | F50: 0.52 | G50: 0.5 | H50: 0.48 | I50: 0.46 | J50: 0.44
B52: CAPEX & D&A ASSUMPTIONS
E53: 2024A | F53: 2025E | G53: 2026E | H53: 2027E | I53: 2028E | J53: 2029E
B54: CapEx % of Revenue | E54: ='3-Statement Model'!G92/'3-Statement Model'!G10*-1 -> 0.073704397 | F54: 0.065 | G54: 0.06 | H54: 0.055 | I54: 0.05 | J54: 0.05
B55: D&A % of Prior Year Net PP&E | E55: ='3-Statement Model'!G16/'3-Statement Model'!F42*-1 -> 0.1701438 | F55: 0.14 | G55: 0.135 | H55: 0.13 | I55: 0.125 | J55: 0.12
...

Sheet 3-Statement Model
B4: INCOME STATEMENT
B6: All figures in millions of euros | E6: 2022A | F6: 2023A | G6: 2024A | H6: 2025E | I6: 2026E | J6: 2027E | K6: 2028E | L6: 2029E
B7: unless stated otherwise
B10: Revenue | E10: 21173.4 | F10: 27558.5 | G10: 28262.9 | H10: =G10*(1+'Assumptions and Inputs'!F21) -> 33915.48 | I10: =H10*(1+'Assumptions and Inputs'!G21) -> 40020.266 | J10: =I10*(1+'Assumptions and Inputs'!H21) -> 46023.306 | K10: =J10*(1+'Assumptions and Inputs'!I21) -> 51546.103 | L10: =K10*(1+'Assumptions and Inputs'!J21) -> 56700.713
B11: COGS (excl. D&A) | E11: -10058.8 | F11: -12936.3 | G11: -13195.2 | H11: =-H10*'Assumptions and Inputs'!F29 -> -15261.966 | I11: =-I10*'Assumptions and Inputs'!G29 -> -17608.917 | J11: =-J10*'Assumptions and Inputs'!H29 -> -19790.022 | K11: =-K10*'Assumptions and Inputs'!I29 -> -21649.363 | L11: =-L10*'Assumptions and Inputs'!J29 -> -23814.3
B12: Gross Profit (excl. D&A) | E12: =E10+E11 -> 11114.6 | F12: =F10+F11 -> 14622.2 | G12: =G10+G11 -> 15067.7 | H12: =H10+H11 -> 18653.514 | I12: =I10+I11 -> 22411.349 | J12: =J10+J11 -> 26233.285 | K12: =K10+K11 -> 29896.74 | L12: =L10+L11 -> 32886.414
B14: R&D Expense | E14: -3071.6 | F14: -3724.9 | G14: -3942.4 | H14: =-H10*'Assumptions and Inputs'!F31 -> -4748.1672 | I14: =-I10*'Assumptions and Inputs'!G31 -> -5402.736 | J14: =-J10*'Assumptions and Inputs'!H31 -> -5983.0298 | K14: =-K10*'Assumptions and Inputs'!I31 -> -6443.2629 | L14: =-L10*'Assumptions and Inputs'!J31 -> -6804.0856
B15: SG&A Expense | E15: -901.6 | F15: -1068.8 | G15: -1115.9 | H15: =-H10*'Assumptions and Inputs'!F32 -> -1356.6192 | I15: =-I10*'Assumptions and Inputs'!G32 -> -1520.7701 | J15: =-J10*'Assumptions and Inputs'!H32 -> -1656.839 | K15: =-K10*'Assumptions and Inputs'!I32 -> -1804.1136 | L15: =-L10*'Assumptions and Inputs'!J32 -> -1984.525
B16: D&A Expense | E16: -640.7 | F16: -786.2 | G16: -986.8 | H16: =-G42*'Assumptions and Inputs'!F55+'Assumptions and Inputs'!F57 -> -1132.76 | I16: =-H42*'Assumptions and Inputs'!G55+'Assumptions and Inputs'!G57 -> -1252.4757 | J16: =-I42*'Assumptions and Inputs'!H55+'Assumptions and Inputs'!H57 -> -1369.6332 | K16: =-J42*'Assumptions and Inputs'!I55+'Assumptions and Inputs'!I57 -> -1475.1419 | L16: =-K42*'Assumptions and Inputs'!J55+'Assumptions and Inputs'!J57 -> -1560.1958
B17: EBIT | E17: =E12+E14+E15+E16 -> 6500.7 | F17: =F12+F14+F15+F16 -> 9042.3 | G17: =G12+G14+G15+G16 -> 9022.6 | H17: =H12+H14+H15+H16 -> 11415.968 | I17: =I12+I14+I15+I16 -> 14235.367 | J17: =J12+J14+J15+J16 -> 17223.783 | K17: =K12+K14+K15+K16 -> 20174.221 | L17: =L12+L14+L15+L16 -> 22537.607
B19: Interest Income | E19: 16.2 | F19: 193.9 | G19: 182.4 | H19: =G35*'Assumptions and Inputs'!F37 -> 318.5325 | I19: =H35*'Assumptions and Inputs'!G37 -> 470.0257 | J19: =I35*'Assumptions and Inputs'!H37 -> 650.17308 | K19: =J35*'Assumptions and Inputs'!I37 -> 874.08025 | L19: =K35*'Assumptions and Inputs'!J37 -> 1154.4996
B20: Interest Expense | E20: -60.8 | F20: -152.1 | G20: -153.7 | H20: =-(G53+G58)*'Assumptions and Inputs'!F38 -> -199.744 | I20: =-(H53+H58)*'Assumptions and Inputs'!G38 -> -199.744 | J20: =-(I53+I58)*'Assumptions and Inputs'!H38 -> -199.744 | K20: =-(J53+J58)*'Assumptions and Inputs'!I38 -> -199.744 | L20: =-(K53+K58)*'Assumptions and Inputs'!J38 -> -199.744
B21: Other Income (Expense) | E21: 0 | F21: -0.6 | G21: -8.9 | H21: ='Assumptions and Inputs'!F40 -> 0 | I21: ='Assumptions and Inputs'!G40 -> 0 | J21: ='Assumptions and Inputs'!H40 -> 0 | K21: ='Assumptions and Inputs'!I40 -> 0 | L21: ='Assumptions and Inputs'!J40 -> 0
B22: EBT | E22: =E17+E19+E20+E21 -> 6456.1 | F22: =F17+F19+F20+F21 -> 9083.5 | G22: =G17+G19+G20+G21 -> 9042.4 | H22: =H17+H19+H20+H21 -> 11534.756 | I22: =I17+I19+I20+I21 -> 14505.649 | J22: =J17+J19+J20+J21 -> 17674.212 | K22: =K17+K19+K20+K21 -> 20848.558 | L22: =L17+L19+L20+L21 -> 23492.363
B24: Income Taxes | E24: -969.9 | F24: -1435.8 | G24: -1680.6 | H24: =-H22*'Assumptions and Inputs'!F36 -> -2018.5823 | I24: =-I22*'Assumptions and Inputs'!G36 -> -2611.0168 | J24: =-J22*'Assumptions and Inputs'!H36 -> -3181.3581 | K24: =-K22*'Assumptions and Inputs'!I36 -> -3752.7404 | L24: =-L22*'Assumptions and Inputs'!J36 -> -4228.6253
B25: Equity in Affiliates | E25: 138 | F25: 191.3 | G25: 209.8 | H25: =G25*(1+'Assumptions and Inputs'!F39) -> 220.29 | I25: =H25*(1+'Assumptions and Inputs'!G39) -> 231.3045 | J25: =I25*(1+'Assumptions and Inputs'!H39) -> 242.86973 | K25: =J25*(1+'Assumptions and Inputs'!I39) -> 255.01321 | L25: =K25*(1+'Assumptions and Inputs'!J39) -> 267.76387
B26: Net Income | E26: =E22+E24+E25 -> 5624.2 | F26: =F22+F24+F25 -> 7839 | G26: =G22+G24+G25 -> 7571.6 | H26: =H22+H24+H25 -> 9736.4638 | I26: =I22+I24+I25 -> 12125.937 | J26: =J22+J24+J25 -> 14735.723 | K26: =K22+K24+K25 -> 17350.831 | L26: =L22+L24+L25 -> 19531.502
B29: BALANCE STATEMENT
B31: All figures in millions of euros | E31: 2022A | F31: 2023A | G31: 2024A | H31: 2025E | I31: 2026E | J31: 2027E | K31: 2028E | L31: 2029E
B32: unless stated otherwise
B34: Assets
B35: Cash & Short-Term Investments | E35: 7376 | F35: 7010.1 | G35: 12741.3 | H35: =G35+H106 -> 18801.028 | I35: =H35+I106 -> 26006.923 | J35: =I35+J106 -> 34963.21 | K35: =J35+K106 -> 46179.985 | L35: =K35+L106 -> 58729.412
B36: Accounts Receivable | E36: 5455.7 | F36: 4574.2 | G36: 4798.1 | H36: =H10*'Assumptions and Inputs'!F45/365 -> 5575.1474 | I36: =I10*'Assumptions and Inputs'!G45/365 -> 6578.6739 | J36: =J10*'Assumptions and Inputs'!H45/365 -> 7565.475 | K36: =K10*'Assumptions and Inputs'!I45/365 -> 8473.332 | L36: =L10*'Assumptions and Inputs'!J45/365 -> 9320.6652
B37: Other Receivables | E37: 1591.3 | F37: 2682.6 | G37: 645.3 | H37: =H10*'Assumptions and Inputs'!F48 -> 780.05604 | I37: =I10*'Assumptions and Inputs'!G48 -> 920.46613 | J37: =J10*'Assumptions and Inputs'!H48 -> 1058.536 | K37: =K10*'Assumptions and Inputs'!I48 -> 1185.5604 | L37: =L10*'Assumptions and Inputs'!J48 -> 1304.1164
B38: Inventories | E38: 7679.6 | F38: 9542.6 | G38: 11707.3 | H38: =-H11*'Assumptions and Inputs'!F46/365 -> 12962.218 | I38: =-I11*'Assumptions and Inputs'!G46/365 -> 14473.083 | J38: =-J11*'Assumptions and Inputs'!H46/365 -> 15723.579 | K38: =-K11*'Assumptions and Inputs'!I46/365 -> 16607.731 | L38: =-L11*'Assumptions and Inputs'!J46/365 -> 17616.057
B39: Other Current Assets | E39: 962.3 | F39: 584.4 | G39: 845.4 | H39: =H10*'Assumptions and Inputs'!F49 -> 1017.4644 | I39: =I10*'Assumptions and Inputs'!G49 -> 1200.608 | J39: =J10*'Assumptions and Inputs'!H49 -> 1380.6992 | K39: =K10*'Assumptions and Inputs'!I49 -> 1546.3831 | L39: =L10*'Assumptions and Inputs'!J49 -> 1701.0214
B40: Total Current Assets | E40: =SUM(E35:E39) -> 23064.9 | F40: =SUM(F35:F39) -> 24393.9 | G40: =SUM(G35:G39) -> 30737.4 | H40: =SUM(H35:H39) -> 39135.914 | I40: =SUM(I35:I39) -> 49179.754 | J40: =SUM(J35:J39) -> 60691.499 | K40: =SUM(K35:K39) -> 73992.991 | L40: =SUM(L35:L39) -> 88671.272
B42: Net PP&E | E42: 4136.9 | F42: 5799.8 | G42: 7234 | H42: =G42-G42*'Assumptions and Inputs'!F55-H92 -> 8425.7462 | I42: =H42-H42*'Assumptions and Inputs'!G55-I92 -> 9689.4864 | J42: =I42-I42*'Assumptions and Inputs'!H55-J92 -> 10961.135 | K42: =J42-J42*'Assumptions and Inputs'!I55-K92 -> 12168.298 | L42: =K42-K42*'Assumptions and Inputs'!J55-L92 -> 13543.138
B43: Goodwill | E43: 4555.6 | F43: 4588.6 | G43: 4588.6 | H43: =G43 -> 4588.6 | I43: =H43 -> 4588.6 | J43: =I43 -> 4588.6 | K43: =J43 -> 4588.6 | L43: =K43 -> 4588.6
B44: Other Intangible Assets | E44: 842.4 | F44: 741.7 | G44: 621.3 | H44: =G44+'Assumptions and Inputs'!F57 -> 501.3 | I44: =H44+'Assumptions and Inputs'!G57 -> 386.3 | J44: =I44+'Assumptions and Inputs'!H57 -> 276.3 | K44: =J44+'Assumptions and Inputs'!I57 -> 171.3 | L44: =K44+'Assumptions and Inputs'!J57 -> 71.3
B45: Long-Term Investments | E45: 1288 | F45: 1920.7 | G45: 2676.8 | H45: =G45*(1+'Assumptions and Inputs'!F78) -> 2810.64 | I45: =H45*(1+'Assumptions and Inputs'!G78) -> 2951.172 | J45: =I45*(1+'Assumptions and Inputs'!H78) -> 3098.7306 | K45: =J45*(1+'Assumptions and Inputs'!I78) -> 3253.6671 | L45: =K45*(1+'Assumptions and Inputs'!J78) -> 3416.3505
B46: Deferred Tax Assets | E46: 1672.8 | F46: 1872.3 | G46: 1940.7 | H46: =G46*(1+'Assumptions and Inputs'!F79) -> 1998.921 | I46: =H46*(1+'Assumptions and Inputs'!G79) -> 2058.8886 | J46: =I46*(1+'Assumptions and Inputs'!H79) -> 2120.6553 | K46: =J46*(1+'Assumptions and Inputs'!I79) -> 2184.2749 | L46: =K46*(1+'Assumptions and Inputs'!J79) -> 2249.8032
B47: Other Non-Current Assets | E47: 739.8 | F47: 640.5 | G47: 790.8 | H47: =H10*'Assumptions and Inputs'!F80 -> 949.63344 | I47: =I10*'Assumptions and Inputs'!G80 -> 1120.5675 | J47: =J10*'Assumptions and Inputs'!H80 -> 1288.6526 | K47: =K10*'Assumptions and Inputs'!I80 -> 1443.2909 | L47: =L10*'Assumptions and Inputs'!J80 -> 1587.62
B48: Total Non-Current Assets | E48: =SUM(E42:E47) -> 13235.5 | F48: =SUM(F42:F47) -> 15563.6 | G48: =SUM(G42:G47) -> 17852.2 | H48: =SUM(H42:H47) -> 19274.841 | I48: =SUM(I42:I47) -> 20795.015 | J48: =SUM(J42:J47) -> 22334.074 | K48: =SUM(K42:K47) -> 23809.431 | L48: =SUM(L42:L47) -> 25456.812
B49: Total Assets | E49: =E40+E48 -> 36300.4 | F49: =F40+F48 -> 39957.5 | G49: =G40+G48 -> 48589.6 | H49: =H40+H48 -> 58410.754 | I49: =I40+I48 -> 69974.768 | J49: =J40+J48 -> 83025.573 | K49: =K40+K48 -> 97802.423 | L49: =L40+L48 -> 114128.08
B51: Liabilities
B52: Accounts Payable | E52: 2565.2 | F52: 2347.3 | G52: 3500.4 | H52: =-H11*'Assumptions and Inputs'!F47/365 -> 3972.2925 | I52: =-I11*'Assumptions and Inputs'!G47/365 -> 4583.1428 | J52: =-J11*'Assumptions and Inputs'!H47/365 -> 5150.8276 | K52: =-K11*'Assumptions and Inputs'!I47/365 -> 5634.7658 | L52: =-L11*'Assumptions and Inputs'!J47/365 -> 6198.2424
B53: Short-Term Debt | E53: 793.8 | F53: 46.8 | G53: 1078.9 | H53: =G53+'Assumptions and Inputs'!F74 -> 1078.9 | I53: =H53+'Assumptions and Inputs'!G74 -> 1078.9 | J53: =I53+'Assumptions and Inputs'!H74 -> 1078.9 | K53: =J53+'Assumptions and Inputs'!I74 -> 1078.9 | L53: =K53+'Assumptions and Inputs'!J74 -> 1078.9
B54: Income Tax Payable | E54: 315.3 | F54: 308.9 | G54: 283.3 | H54: =-H24*'Assumptions and Inputs'!F81 -> 343.15899 | I54: =-I24*'Assumptions and Inputs'!G81 -> 443.87286 | J54: =-J24*'Assumptions and Inputs'!H81 -> 540.83088 | K54: =-K24*'Assumptions and Inputs'!I81 -> 637.96587 | L54: =-L24*'Assumptions and Inputs'!J81 -> 718.86631
B55: Other Current Liabilities | E55: 14309.3 | F55: 13571.7 | G55: 15188.8 | H55: =H10*'Assumptions and Inputs'!F50 -> 17636.05 | I55: =I10*'Assumptions and Inputs'!G50 -> 20010.133 | J55: =J10*'Assumptions and Inputs'!H50 -> 22091.187 | K55: =K10*'Assumptions and Inputs'!I50 -> 23711.207 | L55: =L10*'Assumptions and Inputs'!J50 -> 24948.314
...

Sheet DCF
B2: ASML HOLDING NV - DISCOUNTED CASH FLOW ANALYSIS
B7: SECTION 1: WACC CALCULATION
B9: Cost of Equity (CAPM)
B10: Risk-Free Rate (Rf) | E10: 0.0291
B11: Equity Risk Premium (ERP) | E11: 0.0423
B12: Beta (Levered) | E12: 1.69
B13: Cost of Equity (Ke) | E13: =E10+E12*E11 -> 0.100587
B15: Cost of Debt
B16: Pre-Tax Cost of Debt (Kd) | E16: 0.0239
B17: Tax Rate | E17: 0.175
B18: After-Tax Cost of Debt | E18: =E16*(1-E17) -> 0.0197175
B20: Capital Structure
B21: Weight of Equity | E21: 0.9942
B22: Weight of Debt | E22: =1-E21 -> 0.0058
B24: WACC Calculation
B25: Weighted Average Cost of Capital | E25: =E13*E21+E18*E22 -> 0.10011796
B27: Terminal Value Assumptions
B28: Perpetual Growth Rate (g) | E28: 0.025
B29: Exit Multiple (EV/EBITDA) | E29: 15
B32: SECTION 2: FREE CASH FLOW SCHEDULE
E34: Projection Period
E35: 2024A | F35: 2025E | G35: 2026E | H35: 2027E | I35: 2028E | J35: 2029E
B37: Revenue | E37: ='3-Statement Model'!G10 -> 28262.9 | F37: ='3-Statement Model'!H10 -> 33915.48 | G37: ='3-Statement Model'!I10 -> 40020.266 | H37: ='3-Statement Model'!J10 -> 46023.306 | I37: ='3-Statement Model'!K10 -> 51546.103 | J37: ='3-Statement Model'!L10 -> 56700.713
B38: % Growth | F38: =F37/E37-1 -> 0.2 | G38: =G37/F37-1 -> 0.18 | H38: =H37/G37-1 -> 0.15 | I38: =I37/H37-1 -> 0.12 | J38: =J37/I37-1 -> 0.1
B40: EBIT | E40: ='3-Statement Model'!G17 -> 9022.6 | F40: ='3-Statement Model'!H17 -> 11415.968 | G40: ='3-Statement Model'!I17 -> 14235.367 | H40: ='3-Statement Model'!J17 -> 17223.783 | I40: ='3-Statement Model'!K17 -> 20174.221 | J40: ='3-Statement Model'!L17 -> 22537.607
B41: % Margin | E41: =E40/E37 -> 0.31923829 | F41: =F40/F37 -> 0.3366005 | G41: =G40/G37 -> 0.35570396 | H41: =H40/H37 -> 0.37424044 | I41: =I40/I37 -> 0.39138209 | J41: =J40/J37 -> 0.39748367
B42: Less: Taxes on EBIT | E42: =-E40*$E$17 -> -1578.955 | F42: =-F40*$E$17 -> -1997.7943 | G42: =-G40*$E$17 -> -2491.1893 | H42: =-H40*$E$17 -> -3014.1619 | I42: =-I40*$E$17 -> -3530.4888 | J42: =-J40*$E$17 -> -3944.0813
B43: NOPAT (EBIT × (1-t)) | E43: =E40+E42 -> 7443.645 | F43: =F40+F42 -> 9418.1733 | G43: =G40+G42 -> 11744.178 | H43: =H40+H42 -> 14209.621 | I43: =I40+I42 -> 16643.733 | J43: =J40+J42 -> 18593.526
B45: Plus: D&A | E45: =-'3-Statement Model'!G16 -> 986.8 | F45: =-'3-Statement Model'!H16 -> 1132.76 | G45: =-'3-Statement Model'!I16 -> 1252.4757 | H45: =-'3-Statement Model'!J16 -> 1369.6332 | I45: =-'3-Statement Model'!K16 -> 1475.1419 | J45: =-'3-Statement Model'!L16 -> 1560.1958
B46: Less: CapEx | E46: ='3-Statement Model'!G92 -> -2083.1 | F46: ='3-Statement Model'!H92 -> -2204.5062 | G46: ='3-Statement Model'!I92 -> -2401.216 | H46: ='3-Statement Model'!J92 -> -2531.2818 | I46: ='3-Statement Model'!K92 -> -2577.3052 | J46: ='3-Statement Model'!L92 -> -2835.0357
B47: Less: Change in NWC | E47: ='3-Statement Model'!G85+'3-Statement Model'!G86+'3-Statement Model'!G87+'3-Statement Model'!G88 -> 2053.3 | F47: ='3-Statement Model'!H85+'3-Statement Model'!H86+'3-Statement Model'!H87+'3-Statement Model'!H88 -> 1575.8116 | G47: ='3-Statement Model'!I85+'3-Statement Model'!I86+'3-Statement Model'!I87+'3-Statement Model'!I88 -> 1068.4572 | H47: ='3-Statement Model'!J85+'3-Statement Model'!J86+'3-Statement Model'!J87+'3-Statement Model'!J88 -> 870.58266 | I47: ='3-Statement Model'!K85+'3-Statement Model'!K86+'3-Statement Model'!K87+'3-Statement Model'!K88 -> 595.0189 | J47: ='3-Statement Model'!L85+'3-Statement Model'!L86+'3-Statement Model'!L87+'3-Statement Model'!L88 -> 61.906058
B49: Unlevered Free Cash Flow | E49: =E43+E45+E46+E47 -> 8400.645 | F49: =F43+F45+F46+F47 -> 9922.2386 | G49: =G43+G45+G46+G47 -> 11663.895 | H49: =H43+H45+H46+H47 -> 13918.555 | I49: =I43+I45+I46+I47 -> 16136.588 | J49: =J43+J45+J46+J47 -> 17380.592
B50: % Conversion (UFCF/NOPAT) | E50: =E49/E43 -> 1.128566 | F50: =F49/F43 -> 1.0535205 | G50: =G49/G43 -> 0.99316402 | H50: =H49/H43 -> 0.97951628 | I50: =I49/I43 -> 0.96952941 | J50: =J49/J43 -> 0.9347658
B53: SECTION 3: DISCOUNTING & PRESENT VALUE
B55: Discount Period (Mid-Year Convention) | F55: =0.5 -> 0.5 | G55: =F55+1 -> 1.5 | H55: =G55+1 -> 2.5 | I55: =H55+1 -> 3.5 | J55: =I55+1 -> 4.5
B56: Discount Factor | F56: =1/(1+$E$25)^F55 -> 0.95341147 | G56: =1/(1+$E$25)^G55 -> 0.86664477 | H56: =1/(1+$E$25)^H55 -> 0.7877744 | I56: =1/(1+$E$25)^I55 -> 0.71608176 | J56: =1/(1+$E$25)^J55 -> 0.65091362
B58: Present Value of FCF | F58: =F49*F56 -> 9459.9762 | G58: =G49*G56 -> 10108.454 | H58: =H49*H56 -> 10964.681 | I58: =I49*I56 -> 11555.117 | J58: =J49*J56 -> 11313.264
B60: Sum of PV of FCF | F60: =SUM(F58:J58) -> 53401.492
B63: SECTION 4: TERMINAL VALUE CALCULATION
B65: Method 1: Perpetuity Growth Method
...

Sheet Comps Analysis
B2: ASML HOLDING NV - COMPARABLE COMPANIES ANALYSIS
B7: SECTION 1: MARKET DATA & CAPITALIZATION
B9: Company | C9: Ticker | D9: Share Price (€) | E9: Shares Out (mm) | F9: Market Cap (€mm) | G9: Cash & ST Inv (€mm) | H9: Total Debt (€mm) | I9: Enterprise Value (€mm) | J9: LTM Revenue (€mm) | K9: LTM EBITDA (€mm) | L9: LTM EBIT (€mm) | M9: Net Debt / EBITDA
B10: ASML Holding NV | C10: ASML-NL | D10: 1215.6 | E10: 388.15 | F10: =D10*E10 -> 471835.14 | G10: 5128.2 | H10: 2704.7 | I10: =F10-G10+H10 -> 469411.64 | J10: 28262.9 | K10: 10009.4 | L10: 9022.6 | M10: =(H10-G10)/K10 -> -0.2421224
B11: KLA Corporation | C11: KLAC-US | D11: 1200.3 | E11: 131.39 | F11: =D11*E11 -> 157707.42 | G11: 4433.96 | H11: 5201.99 | I11: =F11-G11+H11 -> 158475.45 | J11: 11243.45 | K11: 5102.35 | L11: 4814.98 | M11: =(H11-G11)/K11 -> 0.15052476
B12: Applied Materials Inc | C12: AMAT-US | D12: 270.94 | E12: 792.94 | F12: =D12*E12 -> 214839.16 | G12: 7427.66 | H12: 6108.13 | I12: =F12-G12+H12 -> 213519.63 | J12: 24526.38 | K12: 7762.35 | L12: 7360.33 | M12: =(H12-G12)/K12 -> -0.16999105
B14: Mean | D14: =AVERAGE(D11:D12) -> 735.62 | E14: =AVERAGE(E11:E12) -> 462.165 | F14: =AVERAGE(F11:F12) -> 186273.29 | G14: =AVERAGE(G11:G12) -> 5930.81 | H14: =AVERAGE(H11:H12) -> 5655.06 | I14: =AVERAGE(I11:I12) -> 185997.54 | J14: =AVERAGE(J11:J12) -> 17884.915 | K14: =AVERAGE(K11:K12) -> 6432.35 | ... M14: =AVERAGE(M11:M12) -> -0.0097331442
B15: Median | D15: =MEDIAN(D11:D12) -> 735.62 | E15: =MEDIAN(E11:E12) -> 462.165 | F15: =MEDIAN(F11:F12) -> 186273.29 | G15: =MEDIAN(G11:G12) -> 5930.81 | H15: =MEDIAN(H11:H12) -> 5655.06 | I15: =MEDIAN(I11:I12) -> 185997.54 | J15: =MEDIAN(J11:J12) -> 17884.915 | K15: =MEDIAN(K11:K12) -> 6432.35 | ... M15: =MEDIAN(M11:M12) -> -0.0097331442
B17: SECTION 2: TRADING MULTIPLES
B19: Company | C19: Ticker | D19: EV / Revenue | E19: EV / EBITDA | F19: EV / EBIT | G19: P / E (FY1) | H19: P / E (FY2) | I19: P / FCF (FY1) | J19: P / FCF (FY2) | K19: Dividend Yield (%) | L19: FCF Yield (%)
B20: ASML Holding NV | C20: ASML-NL | D20: =I10/J10 -> 16.608757 | E20: =I10/K10 -> 46.897081 | F20: =I10/L10 -> 52.026205 | G20: 41.7 | H20: 32.6 | I20: 49.5 | J20: 36.5 | K20: 0.62 | L20: 3.41
B21: KLA Corporation | C21: KLAC-US | D21: =I11/J11 -> 14.094913 | E21: =I11/K11 -> 31.059305 | F21: =I11/L11 -> 32.913002 | G21: 39.1 | H21: 31.1 | I21: 42.5 | J21: 35 | K21: 0.53 | L21: 3.12
B22: Applied Materials Inc | C22: AMAT-US | D22: =I12/J12 -> 8.7057133 | E22: =I12/K12 -> 27.507087 | F22: =I12/L12 -> 29.009519 | G22: 33.3 | H22: 26.8 | I22: 51.7 | J22: 46.5 | K22: 0.57 | L22: 3.08
B24: Mean | D24: =AVERAGE(D21:D22) -> 11.400313 | E24: =AVERAGE(E21:E22) -> 29.283196 | F24: =AVERAGE(F21:F22) -> 30.961261 | G24: =AVERAGE(G21:G22) -> 36.2 | H24: =AVERAGE(H21:H22) -> 28.95 | I24: =AVERAGE(I21:I22) -> 47.1 | J24: =AVERAGE(J21:J22) -> 40.75 | K24: =AVERAGE(K21:K22) -> 0.55 | L24: =AVERAGE(L21:L22) -> 3.1
B25: Median | D25: =MEDIAN(D21:D22) -> 11.400313 | E25: =MEDIAN(E21:E22) -> 29.283196 | F25: =MEDIAN(F21:F22) -> 30.961261 | G25: =MEDIAN(G21:G22) -> 36.2 | H25: =MEDIAN(H21:H22) -> 28.95 | I25: =MEDIAN(I21:I22) -> 47.1 | J25: =MEDIAN(J21:J22) -> 40.75 | K25: =MEDIAN(K21:K22) -> 0.55 | L25: =MEDIAN(L21:L22) -> 3.1
B27: SECTION 3: OPERATING METRICS & MARGINS
B29: Company | C29: Ticker | D29: Revenue Growth (YoY %) | E29: Gross Margin (%) | F29: EBITDA Margin (%) | G29: EBIT Margin (%) | H29: Net Income Margin (%) | I29: ROE (%) | J29: ROIC (%) | K29: Asset Turnover (x) | L29: D/E Ratio (x) | M29: Current Ratio (x)
B30: ASML Holding NV | C30: ASML-NL | D30: 0.029 | E30: 0.512 | F30: =K10/J10 -> 0.35415332 | G30: =L10/J10 -> 0.31923829 | H30: 0.258 | I30: 0.565 | J30: 0.318 | K30: 0.63 | L30: 0.15 | M30: 1.52
B31: KLA Corporation | C31: KLAC-US | D31: 0.172 | E31: 0.614 | F31: =K11/J11 -> 0.45380644 | G31: =L11/J11 -> 0.42824756 | H31: 0.282 | I31: 0.893 | J31: 0.261 | K31: 0.52 | L31: 4.75 | M31: 2.43
B32: Applied Materials Inc | C32: AMAT-US | D32: 0.029 | E32: 0.477 | F32: =K12/J12 -> 0.31648984 | G32: =L12/J12 -> 0.30009851 | H32: 0.254 | I32: 0.407 | J32: 0.268 | K32: 0.72 | L32: 0.35 | M32: 2.86
B34: Mean | D34: =AVERAGE(D31:D32) -> 0.1005 | E34: =AVERAGE(E31:E32) -> 0.5455 | F34: =AVERAGE(F31:F32) -> 0.38514814 | G34: =AVERAGE(G31:G32) -> 0.36417303 | H34: =AVERAGE(H31:H32) -> 0.268 | I34: =AVERAGE(I31:I32) -> 0.65 | J34: =AVERAGE(J31:J32) -> 0.2645 | K34: =AVERAGE(K31:K32) -> 0.62 | ... M34: =AVERAGE(M31:M32) -> 2.645
B35: Median | D35: =MEDIAN(D31:D32) -> 0.1005 | E35: =MEDIAN(E31:E32) -> 0.5455 | F35: =MEDIAN(F31:F32) -> 0.38514814 | G35: =MEDIAN(G31:G32) -> 0.36417303 | H35: =MEDIAN(H31:H32) -> 0.268 | I35: =MEDIAN(I31:I32) -> 0.65 | J35: =MEDIAN(J31:J32) -> 0.2645 | K35: =MEDIAN(K31:K32) -> 0.62 | ... M35: =MEDIAN(M31:M32) -> 2.645
