Workbook

Sheet Cover

Sheet TOC
B1: L'OREAL S.A
B2: Comprehensive Valuation Model — Table of Contents
B4: Tab # | C4: Tab Name | D4: Description | E4: Status
B5: SECTION 1: EXECUTIVE SUMMARY & OVERVIEW
B6: 1 | C6: Cover | D6: Title page, version control, confidentiality notice | E6: Complete
B7: 2 | C7: TOC | D7: Table of contents & model map | E7: Complete
B8: 3 | C8: Executive Summary | D8: Investment thesis, highlights, key findings, target price | E8: Complete
B10: SECTION 2: HISTORICAL FINANCIALS & ANALYSIS
B11: 4 | C11: Historical Financials | D11: Historical IS + BS + CF (vertical 3-statement model) | E11: Complete
B12: 5 | C12: Historical Analysis | D12: Margins, growth rates, ratio analysis, trends | E12: Complete
B14: SECTION 3: ASSUMPTIONS & OTHER INPUTS
B15: 6 | C15: Master Assumptions | D15: Key drivers: revenue growth, margins, CapEx, tax, WACC | E15: Complete
B16: 7 | C16: Supporting Schedules | D16: Supporting analysis: TAM, benchmarks, comps backup | E16: Complete
B18: SECTION 4: FORECASTS & PROJECTIONS
B19: 8 | C19: Forecast Model | D19: Projected IS + BS + CF (vertical 3-statement model) | E19: Complete
B20: 9 | C20: Integration Check | D20: BS balances, CF reconciliation, error checks | E20: Complete
B22: SECTION 5: VALUATION
B23: 11 | C23: DCF Valuation | D23: Discounted Cash Flow analysis (WACC, terminal value) | E23: Complete
B24: 12 | C24: Trading Comps | D24: Public comparable company analysis (EV/Revenue, EV/EBITDA) | E24: Complete
B25: 13 | C25: Valuation Summary | D25: Combined valuation range across all methodologies | E25: Complete
B27: SECTION 6: OUTPUTS & ANALYSIS
B28: 14 | C28: Sensitivity Tables | D28: WACC vs. growth, revenue vs. margin data tables | E28: Complete
B30: SECTION 7: REFERENCE & DATA
B31: 15 | C31: Sources & Footnotes | D31: Data sources, methodology notes, disclaimers | E31: Complete
B34: COLOR CODING LEGEND
B35: 🔵 | C35: BLUE cells | D35: Hardcoded inputs / assumptions (user changes these)
B36: ⬛ | C36: BLACK cells | D36: Formulas & calculations (model calculates these)
B37: 🟢 | C37: GREEN cells | D37: Links from other worksheets within workbook
B38: 🟡 | C38: YELLOW cells | D38: Flags / checks / key assumptions needing attention
B39: 🔴 | C39: RED cells | D39: External links to other files

Sheet Executive Summary

Sheet Historical Financials
B4: INCOME STATEMENT
F7: 2021A | G7: 2022A | H7: 2023A | I7: 2024A
B10: Revenue | F10: 32287.6 | G10: 38260.6 | H10: 41182.5 | I10: 43486.8
B11: COGS (excl. D&A) | F11: -7011.4 | G11: -9427.4 | H11: -9386.5 | I11: -9640.7
B12: Gross Profit (excl. D&A) | F12: =SUM(F10:F11) -> 25276.2 | G12: =SUM(G10:G11) -> 28833.2 | H12: =SUM(H10:H11) -> 31796 | I12: =SUM(I10:I11) -> 33846.1
B14: SG&A Expense | F14: -17709.5 | G14: -20317 | H14: -22303.6 | I14: -23572.6
B15: D&A Expense | F15: -1459.1 | G15: -1474.2 | H15: -1429.7 | I15: -1586.7
B16: Other Operating Expense | F16: 46 | G16: 0 | H16: 0 | I16: 0
B17: EBIT | F17: =SUM(F12:F16) -> 6153.6 | G17: =SUM(G12:G16) -> 7042 | H17: =SUM(H12:H16) -> 8062.7 | I17: =SUM(I12:I16) -> 8686.8
B19: Interest Income | F19: 18.5 | G19: 69.8 | H19: 162.1 | I19: 148.7
B20: Interest Expense | F20: -38 | G20: -70.4 | H20: -226.7 | I20: -373.4
B21: Other Income (Expense) | F21: 458.9 | G21: 820.4 | H21: 408 | I21: 379.3
B22: Unusual Expense | F22: -545.7 | G22: -251.2 | H22: -405.1 | I22: -408.5
B23: EBT | F23: =SUM(F17:F22) -> 6047.3 | G23: =SUM(G17:G22) -> 7610.6 | H23: =SUM(H17:H22) -> 8001 | I23: =SUM(I17:I22) -> 8432.9
B25: Income Taxes | F25: -1445.3 | G25: -1899.4 | H25: -1810.7 | I25: -2015.1
B26: Equity in Affiliates | F26: 0.6 | G26: 1.4 | H26: 0.2 | I26: -1.3
B27: Consolidated Net Income | F27: =SUM(F23:F26) -> 4602.6 | G27: =SUM(G23:G26) -> 5712.6 | H27: =SUM(H23:H26) -> 6190.5 | I27: =SUM(I23:I26) -> 6416.5
B29: Minority Interests | F29: -5.1 | G29: -6 | H29: -6.5 | I29: -7.8
B30: Net Income | F30: =SUM(F27:F29) -> 4597.5 | G30: =SUM(G27:G29) -> 5706.6 | H30: =SUM(H27:H29) -> 6184 | I30: =SUM(I27:I29) -> 6408.7
B32: BALANCE STATEMENT
F36: 2021A | G36: 2022A | H36: 2023A | I36: 2024A
B39: Assets
B40: Cash & Short-Term Investments | F40: 2713.8 | G40: 2617.7 | H40: 4288.1 | I40: 4052.3
B41: Accounts Receivable | F41: 4021 | G41: 4755.5 | H41: 5092.7 | I41: 5601.8
B42: Other Receivables | F42: 844.1 | G42: 1005.5 | H42: 1056 | I42: 902.3
B43: Inventories | F43: 3166.9 | G43: 4079.4 | H43: 4482.4 | I43: 4630.1
B44: Other Current Assets | F44: 1330 | G44: 1591.5 | H44: 1406.2 | I44: 1287
B45: Total Current Assets | F45: =SUM(F40:F44) -> 12075.8 | G45: =SUM(G40:G44) -> 14049.6 | H45: =SUM(H40:H44) -> 16325.4 | I45: =SUM(I40:I44) -> 16473.5
B47: Net PP&E | F47: 4773.8 | G47: 4964.4 | H47: 5560.1 | I47: 5965.2
B48: Goodwill | F48: 11074.5 | G48: 11717.7 | H48: 13102.6 | I48: 13382
B49: Other Intangible Assets | F49: 3462.8 | G49: 3640.1 | H49: 4287.1 | I49: 4594.8
B50: Long-Term Investments | F50: 10930 | G50: 11271.2 | H50: 11329.3 | I50: 14493.1
B51: Deferred Tax Assets | F51: 696.5 | G51: 801.1 | H51: 921.2 | I51: 973.3
B52: Other Non-Current Assets | F52: 0 | G52: 400.1 | H52: 329.4 | I52: 471.5
B53: Total Non-Current Assets | F53: =SUM(F47:F52) -> 30937.6 | G53: =SUM(G47:G52) -> 32794.6 | H53: =SUM(H47:H52) -> 35529.7 | I53: =SUM(I47:I52) -> 39879.9
B54: Total Assets | F54: =F45+F53 -> 43013.4 | G54: =G45+G53 -> 46844.2 | H54: =H45+H53 -> 51855.1 | I54: =I45+I53 -> 56353.4
B56: Liabilities
B57: Accounts Payable | F57: 6068.1 | G57: 6345.6 | H57: 6347 | I57: 6468.5
B58: Short-Term Debt | F58: 5042.2 | G58: 1419.8 | H58: 2551.3 | I58: 1849.9
B59: Income Tax Payable | F59: 268.9 | G59: 264.2 | H59: 208.1 | I59: 275.1
...

Sheet Historical Analysis
B3: SECTION A: GROWTH AND MARGIN ANALYSIS
B5: REVENUE GROWTH:
F6: 2021A | G6: 2022A | H6: 2023A | I6: 2024A | K6: Trend
B7: Total Revenue ($M) | F7: ='Historical Financials'!F10 -> 32287.6 | G7: ='Historical Financials'!G10 -> 38260.6 | H7: ='Historical Financials'!H10 -> 41182.5 | I7: ='Historical Financials'!I10 -> 43486.8
B8: YoY Growth % | G8: =(G7/F7-1) -> 0.18499362 | H8: =(H7/G7-1) -> 0.076368379 | I8: =(I7/H7-1) -> 0.055953378
B9: 4Y CAGR | I9: =(I7/F7)^(1/3)-1 -> 0.10435125 | K9: YoY Growth
B11: GROSS MARGIN:
F12: 2021A | G12: 2022A | H12: 2023A | I12: 2024A | K12: Trend
B13: Gross Profit ($M) | F13: ='Historical Financials'!F12 -> 25276.2 | G13: ='Historical Financials'!G12 -> 28833.2 | H13: ='Historical Financials'!H12 -> 31796 | I13: ='Historical Financials'!I12 -> 33846.1
B14: Gross Profit % | F14: =F13/'Historical Financials'!F10 -> 0.78284543 | G14: =G13/'Historical Financials'!G10 -> 0.75360031 | H14: =H13/'Historical Financials'!H10 -> 0.77207552 | I14: =I13/'Historical Financials'!I10 -> 0.77830744
B17: OPEX ANALYSIS:
F18: 2021A | G18: 2022A | H18: 2023A | I18: 2024A | K18: Trend
B19: SG&A % of Revenue | F19: =-'Historical Financials'!F14/'Historical Financials'!F10 -> 0.5484923 | G19: =-'Historical Financials'!G14/'Historical Financials'!G10 -> 0.53101624 | H19: =-'Historical Financials'!H14/'Historical Financials'!H10 -> 0.54157955 | I19: =-'Historical Financials'!I14/'Historical Financials'!I10 -> 0.54206334
B20: D&A % of Revenue | F20: =-'Historical Financials'!F15/'Historical Financials'!F10 -> 0.045190723 | G20: =-'Historical Financials'!G15/'Historical Financials'!G10 -> 0.038530499 | H20: =-'Historical Financials'!H15/'Historical Financials'!H10 -> 0.034716202 | I20: =-'Historical Financials'!I15/'Historical Financials'!I10 -> 0.036486934
B21: Total Opex % of Revenue | F21: =-('Historical Financials'!F14+'Historical Financials'!F15)/'Historical Financials'!F10 -> 0.59368302 | G21: =-('Historical Financials'!G14+'Historical Financials'!G15)/'Historical Financials'!G10 -> 0.56954674 | H21: =-('Historical Financials'!H14+'Historical Financials'!H15)/'Historical Financials'!H10 -> 0.57629576 | I21: =-('Historical Financials'!I14+'Historical Financials'!I15)/'Historical Financials'!I10 -> 0.57855027
B24: PROFITABILITY:
F25: 2021A | G25: 2022A | H25: 2023A | I25: 2024A | K25: Trend
B26: Operating Margin % | F26: ='Historical Financials'!F17/'Historical Financials'!F10 -> 0.1905871 | G26: ='Historical Financials'!G17/'Historical Financials'!G10 -> 0.18405357 | H26: ='Historical Financials'!H17/'Historical Financials'!H10 -> 0.19577976 | I26: ='Historical Financials'!I17/'Historical Financials'!I10 -> 0.19975717
B27: EBITDA Margin % | F27: =('Historical Financials'!F17-'Historical Financials'!F15)/'Historical Financials'!F10 -> 0.23577782 | G27: =('Historical Financials'!G17-'Historical Financials'!G15)/'Historical Financials'!G10 -> 0.22258407 | H27: =('Historical Financials'!H17-'Historical Financials'!H15)/'Historical Financials'!H10 -> 0.23049596 | I27: =('Historical Financials'!I17-'Historical Financials'!I15)/'Historical Financials'!I10 -> 0.2362441
B28: Net Margin % | F28: ='Historical Financials'!F30/'Historical Financials'!F10 -> 0.14239213 | G28: ='Historical Financials'!G30/'Historical Financials'!G10 -> 0.14915082 | H28: ='Historical Financials'!H30/'Historical Financials'!H10 -> 0.15016087 | I28: ='Historical Financials'!I30/'Historical Financials'!I10 -> 0.14737116
B32: SECTION B: CASH GENERATION AND CAPITAL EFFICIENCY
B35: CASH FLOW QUALITY:
F36: 2021A | G36: 2022A | H36: 2023A | I36: 2024A | K36: Trend
B37: OCF | F37: ='Historical Financials'!F99 -> 6728.4 | G37: ='Historical Financials'!G99 -> 6278.3 | H37: ='Historical Financials'!H99 -> 7604.6 | I37: ='Historical Financials'!I99 -> 8286
B38: FCF | F38: ='Historical Financials'!F99+'Historical Financials'!F102 -> 5653.2 | G38: ='Historical Financials'!G99+'Historical Financials'!G102 -> 4935 | H38: ='Historical Financials'!H99+'Historical Financials'!H102 -> 6116 | I38: ='Historical Financials'!I99+'Historical Financials'!I102 -> 6644.4
B41: WC DYNAMICS:
F42: 2021A | G42: 2022A | H42: 2023A | I42: 2024A | K42: Trend
B43: Changes in WC ($M):
B44: Changes in AR | F44: ='Historical Financials'!F95 -> -407.1 | G44: ='Historical Financials'!G95 -> -717.6 | H44: ='Historical Financials'!H95 -> -427.3 | I44: ='Historical Financials'!I95 -> -506.7
B45: Changes in AP | F45: ='Historical Financials'!F97 -> 1086.8 | G45: ='Historical Financials'!G97 -> 247.9 | H45: ='Historical Financials'!H97 -> 138.7 | I45: ='Historical Financials'!I97 -> 78.8
B46: Changes in Inventory | F46: ='Historical Financials'!F96 -> -373.3 | G46: ='Historical Financials'!G96 -> -865.4 | H46: ='Historical Financials'!H96 -> -438.3 | I46: ='Historical Financials'!I96 -> -121.2
B47: Other WC changes | F47: ='Historical Financials'!F98 -> -218.4 | G47: ='Historical Financials'!G98 -> 323.8 | H47: ='Historical Financials'!H98 -> 332 | I47: ='Historical Financials'!I98 -> 322.5
B49: Net WC Impact | F49: =SUM(F44:F47) -> 88 | G49: =SUM(G44:G47) -> -1011.3 | H49: =SUM(H44:H47) -> -394.9 | I49: =SUM(I44:I47) -> -226.6
B51: DSO | F51: ='Historical Financials'!F41/('Historical Financials'!F10/365) -> 45.455995 | G51: ='Historical Financials'!G41/('Historical Financials'!G10/365) -> 45.366709 | H51: ='Historical Financials'!H41/('Historical Financials'!H10/365) -> 45.136539 | I51: ='Historical Financials'!I41/('Historical Financials'!I10/365) -> 47.017877
B52: DPO | F52: ='Historical Financials'!F57/(-'Historical Financials'!F11/365) -> 315.89362 | G52: ='Historical Financials'!G57/(-'Historical Financials'!G11/365) -> 245.68216 | H52: ='Historical Financials'!H57/(-'Historical Financials'!H11/365) -> 246.80712 | I52: ='Historical Financials'!I57/(-'Historical Financials'!I11/365) -> 244.89949
B53: DIO | F53: ='Historical Financials'!F43/(-'Historical Financials'!F11/365) -> 164.86272 | G53: ='Historical Financials'!G43/(-'Historical Financials'!G11/365) -> 157.94185 | H53: ='Historical Financials'!H43/(-'Historical Financials'!H11/365) -> 174.30096 | I53: ='Historical Financials'!I43/(-'Historical Financials'!I11/365) -> 175.29707
B55: CCC | F55: =F51+F53-F52 -> -105.5749 | G55: =G51+G53-G52 -> -42.373601 | H55: =H51+H53-H52 -> -27.369614 | I55: =I51+I53-I52 -> -22.584538
B57: CAPEX REQUIREMENTS:
F58: 2021A | G58: 2022A | H58: 2023A | I58: 2024A
B60: CapEx ($M) | F60: =-'Historical Financials'!F102 -> 1075.2 | G60: =-'Historical Financials'!G102 -> 1343.3 | H60: =-'Historical Financials'!H102 -> 1488.6 | I60: =-'Historical Financials'!I102 -> 1641.6
...

Sheet Master Assumptions
B2: MASTER ASSUMPTIONS
B3: Hermes International S.A. (RMS-FR) | Forecast Assumptions
B5: SCENARIO SELECTOR
B6: Active Scenario: | C6: Base
B7: Scenario Code: | C7: =IF(C6="Bull",1,IF(C6="Base",2,3)) -> 2 | D7: (1=Bull, 2=Base, 3=Bear)
B9: ACTIVE ASSUMPTIONS | F9: 2025E | G9: 2026E | H9: 2027E | I9: 2028E | J9: 2029E
B10: REVENUE & MARGINS
B11: Revenue Growth % | F11: ='Supporting Schedules'!C9 -> 0.058124569 | G11: ='Supporting Schedules'!D9 -> 0.06209243 | H11: ='Supporting Schedules'!E9 -> 0.060472722 | I11: ='Supporting Schedules'!F9 -> 0.057392569 | J11: ='Supporting Schedules'!G9 -> 0.054809492
B12: Gross Margin % | F12: =AVERAGE('Historical Analysis'!H14:I14) -> 0.77519148 | G12: =F12 -> 0.77519148 | H12: =G12 -> 0.77519148 | I12: =H12 -> 0.77519148 | J12: =I12 -> 0.77519148
B14: OPERATING EXPENSES (% of Revenue)
B15: SG&A % | F15: =AVERAGE('Historical Analysis'!H19:I19) -> 0.54182145 | G15: =F15 -> 0.54182145 | H15: =G15 -> 0.54182145 | I15: =H15 -> 0.54182145 | J15: =I15 -> 0.54182145
B17: Interest Expense
B18: Implied Rate | F18: ='Supporting Schedules'!G64 -> 0.043955268 | G18: =F18 -> 0.043955268 | H18: =G18 -> 0.043955268 | I18: =H18 -> 0.043955268 | J18: =I18 -> 0.043955268
B20: Depreciation (% of Beg. PPE )
B21: Depreciation % | F21: ='Supporting Schedules'!G146 -> 0.22238809 | G21: =F21 -> 0.22238809 | H21: =G21 -> 0.22238809 | I21: =H21 -> 0.22238809 | J21: =I21 -> 0.22238809
B23: TAX & OTHER
B24: Effective Tax Rate % | F24: ='Supporting Schedules'!G75 -> 0.23895694 | G24: =F24 -> 0.23895694 | H24: =G24 -> 0.23895694 | I24: =H24 -> 0.23895694 | J24: =I24 -> 0.23895694
B26: BALANCE SHEET & CAPEX
B27: Other Receivables as % of Revenue | F27: ='Supporting Schedules'!G122 -> 0.020748825 | G27: =F27 -> 0.020748825 | H27: =G27 -> 0.020748825 | I27: =H27 -> 0.020748825 | J27: =I27 -> 0.020748825
B28: Other Current Assets % of Revenue | F28: ='Supporting Schedules'!G119 -> 0.029595188 | G28: =F28 -> 0.029595188 | H28: =G28 -> 0.029595188 | I28: =H28 -> 0.029595188 | J28: =I28 -> 0.029595188
B29: Income Tax Payable % of Tax Expense | F29: =AVERAGE('Supporting Schedules'!F80:G80) -> 0.1257236 | G29: =F29 -> 0.1257236 | H29: =G29 -> 0.1257236 | I29: =H29 -> 0.1257236 | J29: =I29 -> 0.1257236
B30: Other CL % of Revenue | F30: ='Supporting Schedules'!G127 -> 0.13895021 | G30: =F30 -> 0.13895021 | H30: =G30 -> 0.13895021 | I30: =H30 -> 0.13895021 | J30: =I30 -> 0.13895021
B31: Capex as % of Revenue | F31: ='Supporting Schedules'!D156 -> 0.036947904 | G31: =F31 -> 0.036947904 | H31: =G31 -> 0.036947904 | I31: =H31 -> 0.036947904 | J31: =I31 -> 0.036947904
B32: DTA as % of Revenue | F32: ='Supporting Schedules'!G177 -> 0.022381504 | G32: =F32 -> 0.022381504 | H32: =G32 -> 0.022381504 | I32: =H32 -> 0.022381504 | J32: =I32 -> 0.022381504
B33: Other Non-current Assets % of Revenue | F33: ='Supporting Schedules'!G184 -> 0.010842371 | G33: =F33 -> 0.010842371 | H33: =G33 -> 0.010842371 | I33: =H33 -> 0.010842371 | J33: =I33 -> 0.010842371
B34: DTL as % of Revenue | F34: ='Supporting Schedules'!G191 -> 0.022179144 | G34: =F34 -> 0.022179144 | H34: =G34 -> 0.022179144 | I34: =H34 -> 0.022179144 | J34: =I34 -> 0.022179144
B35: Other NC Liabilities as % of Revenue | F35: ='Supporting Schedules'!G198 -> 0.005157887 | G35: =F35 -> 0.005157887 | H35: =G35 -> 0.005157887 | I35: =H35 -> 0.005157887 | J35: =I35 -> 0.005157887
B37: Other Assumptions
B38: Divident Payout % | F38: ='Supporting Schedules'!D211 -> 0.55900351 | G38: =F38 -> 0.55900351 | H38: =G38 -> 0.55900351 | I38: =H38 -> 0.55900351 | J38: =I38 -> 0.55900351
B39: Operating Leases(% of D&A)
B41: VALUATION PARAMETERS
B42: Terminal Growth Rate

Sheet Supporting Schedules
B2: SUPPORTING SCHEDULES
B3: L'Oreal S.A.
B5: REVENUE SCHEDULE -SEGMENT BASED APPROACH
B7: Scenario Assumptions — Revenue Growth Rates
C8: 2025E | D8: 2026E | E8: 2027E | F8: 2028E | G8: 2029E
C9: =J54 -> 0.058124569 | D9: =K54 -> 0.06209243 | E9: =L54 -> 0.060472722 | F9: =M54 -> 0.057392569 | G9: =N54 -> 0.054809492
B12: Section A: Segment wise Revenue Data
B13: All figures in millions
B14: of Euro | E14: 2021A | F14: 2022A | G14: 2023A | H14: 2024A
B16: Consumer Products | E16: 12233.5 | F16: 14021.3 | G16: 15172.7 | H16: 15982.4
B17: YoY Growth % | F17: =(F16/E16)-1 -> 0.1461397 | G17: =(G16/F16)-1 -> 0.082117921 | H17: =(H16/G16)-1 -> 0.053365584
B19: Luxe | E19: 12346.2 | F19: 14638.1 | G19: 14924 | H19: 15591.1
B20: YoY Growth % | F20: =(F19/E19)-1 -> 0.18563607 | G20: =(G19/F19)-1 -> 0.019531223 | H20: =(H19/G19)-1 -> 0.044699812
B22: Dermatological Beauty | E22: 3924 | F22: 5124.5 | G22: 6432 | H22: 7027.1
B23: YoY Growth % | F23: =(F22/E22)-1 -> 0.30593782 | G23: =(G22/F22)-1 -> 0.25514684 | H23: =(H22/G22)-1 -> 0.092521766
B25: Professional Products | E25: 3783.9 | F25: 4476.8 | G25: 4653.9 | H25: 4886.2
B26: YoY Growth % | F26: =(F25/E25)-1 -> 0.18311795 | G26: =(G25/F25)-1 -> 0.039559507 | H26: =(H25/G25)-1 -> 0.049915125
B29: Total | E29: =E16+E19+E22+E25 -> 32287.6 | F29: =F16+F19+F22+F25 -> 38260.7 | G29: =G16+G19+G22+G25 -> 41182.6 | H29: =H16+H19+H22+H25 -> 43486.8
B32: Section B: Segment Wise Growth Assumptions
B33: Growth Rate Assumptions
B34: (Blue = Input)
E36: 2025E | F36: 2026E | G36: 2027E | H36: 2028E | I36: 2029E | K36: Rationale
B37: Consumer Products | E37: 0.055 | F37: =E37 -> 0.055 | G37: =F37-0.5% -> 0.05 | H37: =G37 -> 0.05 | I37: =H37 -> 0.05 | K37: Stable slight moderation to long term
B38: Luxe | E38: 0.045 | F38: 0.06 | G38: =F38+0.5% -> 0.065 | H38: =F38 -> 0.06 | I38: =H38-0.5% -> 0.055 | K38: Recovery path in china
B39: Dermatological Beauty | E39: 0.1 | F39: 0.09 | G39: 0.08 | H39: 0.075 | I39: 0.07 | K39: Convergence to LT
B40: Professional Products | E40: 0.05 | F40: 0.05 | G40: 0.05 | H40: 0.045 | I40: 0.045 | K40: Almost Constant
B43: Section C: Projected Segment Revenue
B45: Revenue by Segment (€M) | E45: 2021A | F45: 2022A | G45: 2023A | H45: 2024A | J45: 2025E | K45: 2026E | L45: 2027E | M45: 2028E | N45: 2029E
B47: Consumer Products | E47: =E16 -> 12233.5 | F47: =F16 -> 14021.3 | G47: =G16 -> 15172.7 | H47: =H16 -> 15982.4 | J47: =H47*(1+E37) -> 16861.432 | K47: =J47*(1+F37) -> 17788.811 | L47: =K47*(1+G37) -> 18678.251 | M47: =L47*(1+H37) -> 19612.164 | N47: =M47*(1+I37) -> 20592.772
B48: Luxe | E48: =E19 -> 12346.2 | F48: =F19 -> 14638.1 | G48: =G19 -> 14924 | H48: =H19 -> 15591.1 | J48: =H48*(1+E38) -> 16292.699 | K48: =J48*(1+F38) -> 17270.261 | L48: =K48*(1+G38) -> 18392.828 | M48: =L48*(1+H38) -> 19496.398 | N48: =M48*(1+I38) -> 20568.7
B49: Dermatological Beauty | E49: =E22 -> 3924 | F49: =F22 -> 5124.5 | G49: =G22 -> 6432 | H49: =H22 -> 7027.1 | J49: =H49*(1+E39) -> 7729.81 | K49: =J49*(1+F39) -> 8425.4929 | L49: =K49*(1+G39) -> 9099.5323 | M49: =L49*(1+H39) -> 9781.9973 | N49: =M49*(1+I39) -> 10466.737
B50: Professional Products | E50: =E25 -> 3783.9 | F50: =F25 -> 4476.8 | G50: =G25 -> 4653.9 | H50: =H25 -> 4886.2 | J50: =H50*(1+E40) -> 5130.51 | K50: =J50*(1+F40) -> 5387.0355 | L50: =K50*(1+G40) -> 5656.3873 | M50: =L50*(1+H40) -> 5910.9247 | N50: =M50*(1+I40) -> 6176.9163
B52: Total Revenue | J52: =SUM(J47:J50) -> 46014.452 | K52: =SUM(K47:K50) -> 48871.601 | L52: =SUM(L47:L50) -> 51826.999 | M52: =SUM(M47:M50) -> 54801.484 | N52: =SUM(N47:N50) -> 57805.126
B54: YoY Growth (%) | J54: =(J52/H29)-1 -> 0.058124569 | K54: =(K52/J52)-1 -> 0.06209243 | L54: =(L52/K52)-1 -> 0.060472722 | M54: =(M52/L52)-1 -> 0.057392569 | N54: =(N52/M52)-1 -> 0.054809492
B57: Interest Expense Assumptions
B59: Section A: Historical Data
D61: 2021A | E61: 2022A | F61: 2023A | G61: 2024A
B62: Total Debt | D62: ='Historical Financials'!F58+'Historical Financials'!F63 -> 6300.4 | E62: ='Historical Financials'!G58+'Historical Financials'!G63 -> 5650.9 | F62: ='Historical Financials'!H58+'Historical Financials'!H63 -> 8692.2 | G62: ='Historical Financials'!I58+'Historical Financials'!I63 -> 8495
B63: Interest Expense | D63: =-'Historical Financials'!F20 -> 38 | E63: =-'Historical Financials'!G20 -> 70.4 | F63: =-'Historical Financials'!H20 -> 226.7 | G63: =-'Historical Financials'!I20 -> 373.4
B64: Implied Rate | D64: =D63/D62 -> 0.0060313631 | E64: =E63/E62 -> 0.012458193 | F64: =F63/F62 -> 0.026080854 | G64: =G63/G62 -> 0.043955268
...

Sheet Forecast Model
B3: INCOME STATEMENT
B5: All figures in millions of euros | F5: 2021A | G5: 2022A | H5: 2023A | I5: 2024A | J5: 2025E | K5: 2026E | L5: 2027E | M5: 2028E | N5: 2029E
B6: unless stated otherwise
B8: Revenue | F8: 32287.6 | G8: 38260.6 | H8: 41182.5 | I8: 43486.8 | J8: ='Supporting Schedules'!J52 -> 46014.452 | K8: ='Supporting Schedules'!K52 -> 48871.601 | L8: ='Supporting Schedules'!L52 -> 51826.999 | M8: ='Supporting Schedules'!M52 -> 54801.484 | N8: ='Supporting Schedules'!N52 -> 57805.126
B9: COGS (excl. D&A) | F9: -7011.4 | G9: -9427.4 | H9: -9386.5 | I9: -9640.7 | J9: =J10-J8 -> -10344.441 | K9: =K10-K8 -> -10986.752 | L9: =L10-L8 -> -11651.151 | M9: =M10-M8 -> -12319.841 | N9: =N10-N8 -> -12995.085
B10: Gross Profit (excl. D&A) | F10: =SUM(F8:F9) -> 25276.2 | G10: =SUM(G8:G9) -> 28833.2 | H10: =SUM(H8:H9) -> 31796 | I10: =SUM(I8:I9) -> 33846.1 | J10: =J8*'Master Assumptions'!F12 -> 35670.011 | K10: =K8*'Master Assumptions'!G12 -> 37884.848 | L10: =L8*'Master Assumptions'!H12 -> 40175.848 | M10: =M8*'Master Assumptions'!I12 -> 42481.643 | N10: =N8*'Master Assumptions'!J12 -> 44810.041
B12: SG&A Expense | F12: -17709.5 | G12: -20317 | H12: -22303.6 | I12: -23572.6 | J12: =-J8*'Master Assumptions'!F15 -> -24931.617 | K12: =-K8*'Master Assumptions'!G15 -> -26479.681 | L12: =-L8*'Master Assumptions'!H15 -> -28080.98 | M12: =-M8*'Master Assumptions'!I15 -> -29692.619 | N12: =-N8*'Master Assumptions'!J15 -> -31320.057
B13: D&A Expense | F13: -1459.1 | G13: -1474.2 | H13: -1429.7 | I13: -1586.7 | J13: ='Supporting Schedules'!H165 -> -1326.5894 | K13: ='Supporting Schedules'!I165 -> -1409.6621 | L13: ='Supporting Schedules'!J165 -> -1497.7369 | M13: ='Supporting Schedules'!K165 -> -1590.5088 | N13: ='Supporting Schedules'!L165 -> -1687.09
B14: Other Operating Expense | F14: 46 | G14: 0 | H14: 0 | I14: 0 | J14: =I14 -> 0 | K14: =J14 -> 0 | L14: =K14 -> 0 | M14: =L14 -> 0 | N14: =M14 -> 0
B15: EBIT | F15: =SUM(F10:F14) -> 6153.6 | G15: =SUM(G10:G14) -> 7042 | H15: =SUM(H10:H14) -> 8062.7 | I15: =SUM(I10:I14) -> 8686.8 | J15: =SUM(J10:J14) -> 9411.8046 | K15: =SUM(K10:K14) -> 9995.505 | L15: =SUM(L10:L14) -> 10597.132 | M15: =SUM(M10:M14) -> 11198.515 | N15: =SUM(N10:N14) -> 11802.894
B17: Interest Income | F17: 18.5 | G17: 69.8 | H17: 162.1 | I17: 148.7
B18: Interest Expense | F18: -38 | G18: -70.4 | H18: -226.7 | I18: -373.4 | J18: -295.12553 | K18: -295.12553 | L18: -295.12553 | M18: -295.12553 | N18: -295.12553
B19: Other Income (Expense) | F19: 458.9 | G19: 820.4 | H19: 408 | I19: 379.3 | J19: =I19*(1+1%) -> 383.093 | K19: =J19*(1+1%) -> 386.92393 | L19: =K19*(1+1%) -> 390.79317 | M19: =L19*(1+1%) -> 394.7011 | N19: =M19*(1+1%) -> 398.64811
B20: Unusual Expense | F20: -545.7 | G20: -251.2 | H20: -405.1 | I20: -408.5 | J20: =AVERAGE(H20:I20) -> -406.8 | K20: =J20 -> -406.8 | L20: =K20 -> -406.8 | M20: =L20 -> -406.8 | N20: =M20 -> -406.8
B21: EBT | F21: =SUM(F15:F20) -> 6047.3 | G21: =SUM(G15:G20) -> 7610.6 | H21: =SUM(H15:H20) -> 8001 | I21: =SUM(I15:I20) -> 8432.9 | J21: =SUM(J15:J20) -> 9092.9721 | K21: =SUM(K15:K20) -> 9680.5034 | L21: =SUM(L15:L20) -> 10285.999 | M21: =SUM(M15:M20) -> 10891.291 | N21: =SUM(N15:N20) -> 11499.617
B23: Income Taxes | F23: -1445.3 | G23: -1899.4 | H23: -1810.7 | I23: -2015.1 | J23: =-J21*'Master Assumptions'!F24 -> -2172.8288 | K23: =-K21*'Master Assumptions'!G24 -> -2313.2235 | L23: =-L21*'Master Assumptions'!H24 -> -2457.9109 | M23: =-M21*'Master Assumptions'!I24 -> -2602.5496 | N23: =-N21*'Master Assumptions'!J24 -> -2747.9132
B24: Equity in Affiliates | F24: 0.6 | G24: 1.4 | H24: 0.2 | I24: -1.3 | J24: =0 -> 0 | K24: =0 -> 0 | L24: =0 -> 0 | M24: =0 -> 0 | N24: =0 -> 0
B25: Consolidated Net Income | F25: =SUM(F21:F24) -> 4602.6 | G25: =SUM(G21:G24) -> 5712.6 | H25: =SUM(H21:H24) -> 6190.5 | I25: =SUM(I21:I24) -> 6416.5 | J25: =SUM(J21:J24) -> 6920.1433 | K25: =SUM(K21:K24) -> 7367.2799 | L25: =SUM(L21:L24) -> 7828.0883 | M25: =SUM(M21:M24) -> 8288.7413 | N25: =SUM(N21:N24) -> 8751.7034
B27: Minority Interests | F27: -5.1 | G27: -6 | H27: -6.5 | I27: -7.8 | J27: =-J28*J25 -> -8.4122368 | K27: =-K28*K25 -> -8.9557832 | L27: =-L28*L25 -> -9.5159494 | M27: =-M28*M25 -> -10.075926 | N27: =-N28*N25 -> -10.638711
B28: as % of PBT | F28: =-F27/F25 -> 0.0011080694 | G28: =-G27/G25 -> 0.0010503098 | H28: =-H27/H25 -> 0.001049996 | I28: =-I27/I25 -> 0.001215616 | J28: =I28 -> 0.001215616 | K28: =J28 -> 0.001215616 | L28: =K28 -> 0.001215616 | M28: =L28 -> 0.001215616 | N28: =M28 -> 0.001215616
B29: Net Income | F29: =SUM(F25:F27) -> 4597.5 | G29: =SUM(G25:G27) -> 5706.6 | H29: =SUM(H25:H27) -> 6184 | I29: =SUM(I25:I27) -> 6408.7 | J29: =J25+J27 -> 6911.7311 | K29: =K25+K27 -> 7358.3241 | L29: =L25+L27 -> 7818.5724 | M29: =M25+M27 -> 8278.6654 | N29: =N25+N27 -> 8741.0647
B32: BALANCE SHEET
B34: All figures in millions of euros | F34: 2021A | G34: 2022A | H34: 2023A | I34: 2024A | J34: 2025E | K34: 2026E | L34: 2027E | M34: 2028E | N34: 2029E
B35: unless stated otherwise
B37: Assets
B38: Cash & Short-Term Investments | F38: 2713.8 | G38: 2617.7 | H38: 4288.1 | I38: 4052.3 | J38: =I38+J122 -> 7251.5867 | K38: =J38+K122 -> 10354.387 | L38: =K38+L122 -> 13801.553 | M38: =L38+M122 -> 17437.632 | N38: =M38+N122 -> 21340.134
B39: Accounts Receivable | F39: 4021 | G39: 4755.5 | H39: 5092.7 | I39: 5601.8 | J39: ='Supporting Schedules'!H92 -> 5808.8149 | K39: ='Supporting Schedules'!I92 -> 6232.4737 | L39: ='Supporting Schedules'!J92 -> 6575.9765 | M39: ='Supporting Schedules'!K92 -> 6971.0428 | N39: ='Supporting Schedules'!L92 -> 7343.8113
B40: Other Receivables | F40: 844.1 | G40: 1005.5 | H40: 1056 | I40: 902.3 | J40: ='Master Assumptions'!F27*'Forecast Model'!J8 -> 954.7458 | K40: ='Master Assumptions'!G27*'Forecast Model'!K8 -> 1014.0283 | L40: ='Master Assumptions'!H27*'Forecast Model'!L8 -> 1075.3493 | M40: ='Master Assumptions'!I27*'Forecast Model'!M8 -> 1137.0664 | N40: ='Master Assumptions'!J27*'Forecast Model'!N8 -> 1199.3884
B41: Inventories | F41: 3166.9 | G41: 4079.4 | H41: 4482.4 | I41: 4630.1 | J41: ='Supporting Schedules'!H99 -> 4953.9674 | K41: ='Supporting Schedules'!I99 -> 5269.0672 | L41: ='Supporting Schedules'!J99 -> 5583.7274 | M41: ='Supporting Schedules'!K99 -> 5906.2932 | N41: ='Supporting Schedules'!L99 -> 6228.9059
B42: Other Current Assets | F42: 1330 | G42: 1591.5 | H42: 1406.2 | I42: 1287 | J42: =J8*'Master Assumptions'!F28 -> 1361.8063 | K42: =K8*'Master Assumptions'!G28 -> 1446.3642 | L42: =L8*'Master Assumptions'!H28 -> 1533.8298 | M42: =M8*'Master Assumptions'!I28 -> 1621.8602 | N42: =N8*'Master Assumptions'!J28 -> 1710.7535
B43: Total Current Assets | F43: =SUM(F38:F42) -> 12075.8 | G43: =SUM(G38:G42) -> 14049.6 | H43: =SUM(H38:H42) -> 16325.4 | I43: =SUM(I38:I42) -> 16473.5 | J43: =SUM(J38:J42) -> 20330.921 | K43: =SUM(K38:K42) -> 24316.32 | L43: =SUM(L38:L42) -> 28570.436 | M43: =SUM(M38:M42) -> 33073.895 | N43: =SUM(N38:N42) -> 37822.993
B45: Net PP&E | F45: 4773.8 | G45: 4964.4 | H45: 5560.1 | I45: 5965.2 | J45: ='Supporting Schedules'!H167 -> 6338.7481 | K45: ='Supporting Schedules'!I167 -> 6734.7892 | L45: ='Supporting Schedules'!J167 -> 7151.9513 | M45: ='Supporting Schedules'!K167 -> 7586.2425 | N45: ='Supporting Schedules'!L167 -> 8034.9308
B46: Goodwill | F46: 11074.5 | G46: 11717.7 | H46: 13102.6 | I46: 13382 | J46: =I46 -> 13382 | K46: =J46 -> 13382 | L46: =K46 -> 13382 | M46: =L46 -> 13382 | N46: =M46 -> 13382
B47: Other Intangible Assets | F47: 3462.8 | G47: 3640.1 | H47: 4287.1 | I47: 4594.8 | J47: =I47 -> 4594.8 | K47: =J47 -> 4594.8 | L47: =K47 -> 4594.8 | M47: =L47 -> 4594.8 | N47: =M47 -> 4594.8
B48: Long-Term Investments | F48: 10930 | G48: 11271.2 | H48: 11329.3 | I48: 14493.1 | J48: =I48 -> 14493.1 | K48: =J48 -> 14493.1 | L48: =K48 -> 14493.1 | M48: =L48 -> 14493.1 | N48: =M48 -> 14493.1
B49: Deferred Tax Assets | F49: 696.5 | G49: 801.1 | H49: 921.2 | I49: 973.3 | J49: =J8*'Master Assumptions'!F32 -> 1029.8726 | K49: =K8*'Master Assumptions'!G32 -> 1093.8199 | L49: =L8*'Master Assumptions'!H32 -> 1159.9662 | M49: =M8*'Master Assumptions'!I32 -> 1226.5396 | N49: =N8*'Master Assumptions'!J32 -> 1293.7657
B50: Other Non-Current Assets | F50: 0 | G50: 400.1 | H50: 329.4 | I50: 471.5 | J50: =I50 -> 471.5 | K50: =J50 -> 471.5 | L50: =K50 -> 471.5 | M50: =L50 -> 471.5 | N50: =M50 -> 471.5
B51: Total Non-Current Assets | F51: =SUM(F45:F50) -> 30937.6 | G51: =SUM(G45:G50) -> 32794.6 | H51: =SUM(H45:H50) -> 35529.7 | I51: =SUM(I45:I50) -> 39879.9 | J51: =SUM(J45:J50) -> 40310.021 | K51: =SUM(K45:K50) -> 40770.009 | L51: =SUM(L45:L50) -> 41253.318 | M51: =SUM(M45:M50) -> 41754.182 | N51: =SUM(N45:N50) -> 42270.096
B53: Total Assets | F53: =F43+F51 -> 43013.4 | G53: =G43+G51 -> 46844.2 | H53: =H43+H51 -> 51855.1 | I53: =I43+I51 -> 56353.4 | J53: =J43+J51 -> 60640.942 | K53: =K43+K51 -> 65086.329 | L53: =L43+L51 -> 69823.753 | M53: =M43+M51 -> 74828.077 | N53: =N43+N51 -> 80093.089
B56: Liabilities
...

Sheet Integration Check

Sheet DCF Valuation
B2: DCF VALUATION
B3: L'Oréal S.A. | Unlevered Free Cash Flow to Firm
B4: All figures in millions of euros unless stated otherwise
B6: WACC CALCULATION
B8: Cost of Equity (CAPM)
B9: Risk-Free Rate (France 10Y OAT) | E9: 0.0355
B10: Equity Risk Premium (Damodaran, France) | E10: 0.045
B11: Levered Beta (5Y Monthly) | E11: 0.95
B12: Cost of Equity (Ke) | E12: =E9+E11*E10 -> 0.07825
B14: Cost of Debt
B15: Pre-Tax Cost of Debt | E15: ='Master Assumptions'!F18 -> 0.043955268
B16: Effective Tax Rate | E16: ='Master Assumptions'!F24 -> 0.23895694
B17: After-Tax Cost of Debt (Kd) | E17: =E15*(1-E16) -> 0.033451851
B19: Capital Structure
B20: Market Cap of Equity (€M) | E20: 184315
B21: Total Debt (€M) | E21: ='Historical Financials'!I58+'Historical Financials'!I63 -> 8495
B22: Total Capital | E22: =E20+E21 -> 192810
B23: Equity Weight | E23: =E20/E22 -> 0.95594108
B24: Debt Weight | E24: =E21/E22 -> 0.044058918
B26: WACC | E26: =E23*E12+E24*E17 -> 0.076276242
B29: UNLEVERED FREE CASH FLOW
F30: 2025E | G30: 2026E | H30: 2027E | I30: 2028E | J30: 2029E
B31: EBIT | F31: ='Forecast Model'!J15 -> 9411.8046 | G31: ='Forecast Model'!K15 -> 9995.505 | H31: ='Forecast Model'!L15 -> 10597.132 | I31: ='Forecast Model'!M15 -> 11198.515 | J31: ='Forecast Model'!N15 -> 11802.894
B32: Less: Taxes on EBIT | F32: =-F31*$E$16 -> -2249.0161 | G32: =-G31*$E$16 -> -2388.4953 | H32: =-H31*$E$16 -> -2532.2582 | I32: =-I31*$E$16 -> -2675.963 | J32: =-J31*$E$16 -> -2820.3835
B33: NOPAT (EBIT × (1 - Tax Rate)) | F33: =F31+F32 -> 7162.7886 | G33: =G31+G32 -> 7607.0097 | H33: =H31+H32 -> 8064.8735 | I33: =I31+I32 -> 8522.5523 | J33: =J31+J32 -> 8982.5106
B34: Plus: D&A | F34: =-'Forecast Model'!J13 -> 1326.5894 | G34: =-'Forecast Model'!K13 -> 1409.6621 | H34: =-'Forecast Model'!L13 -> 1497.7369 | I34: =-'Forecast Model'!M13 -> 1590.5088 | J34: =-'Forecast Model'!N13 -> 1687.09
B35: Less: CapEx | F35: ='Forecast Model'!J107 -> -1700.1375 | G35: ='Forecast Model'!K107 -> -1805.7032 | H35: ='Forecast Model'!L107 -> -1914.899 | I35: ='Forecast Model'!M107 -> -2024.8 | J35: ='Forecast Model'!N107 -> -2135.7782
B36: Less: Change in Working Capital | F36: ='Forecast Model'!J100+'Forecast Model'!J101+'Forecast Model'!J102+'Forecast Model'!J103 -> 272.63173 | G36: ='Forecast Model'!K100+'Forecast Model'!K101+'Forecast Model'!K102+'Forecast Model'!K103 -> -49.279685 | H36: ='Forecast Model'!L100+'Forecast Model'!L101+'Forecast Model'!L102+'Forecast Model'!L103 -> 60.660561 | I36: ='Forecast Model'!M100+'Forecast Model'!M101+'Forecast Model'!M102+'Forecast Model'!M103 -> 11.226638 | J36: ='Forecast Model'!N100+'Forecast Model'!N101+'Forecast Model'!N102+'Forecast Model'!N103 -> 35.290556
B37: Unlevered Free Cash Flow | F37: =F33+F34+F35+F36 -> 7061.8722 | G37: =G33+G34+G35+G36 -> 7161.6888 | H37: =H33+H34+H35+H36 -> 7708.3719 | I37: =I33+I34+I35+I36 -> 8099.4878 | J37: =J33+J34+J35+J36 -> 8569.1129
B39: TERMINAL VALUE
B40: Terminal Growth Rate (g) | E40: 0.025
B41: Exit EV/EBITDA Multiple | E41: 18
B43: Gordon Growth Model
B44: Terminal Year UFCF (2029E) | E44: =J37 -> 8569.1129
B45: Terminal Value (Gordon Growth) | E45: =E44*(1+E40)/(E26-E40) -> 171294.55
B47: Exit Multiple Method
B48: Terminal Year EBITDA (2029E) | E48: =J31+J34 -> 13489.984
B49: Terminal Value (Exit Multiple) | E49: =E48*E41 -> 242819.71
B51: Blended Terminal Value (50/50) | E51: =(E45+E49)/2 -> 207057.13
B53: ENTERPRISE VALUE BRIDGE | F53: 2025E | G53: 2026E | H53: 2027E | I53: 2028E | J53: 2029E
...

Sheet Trading Comps
B2: TRADING COMPARABLES ANALYSIS
B3: L'Oréal S.A. | Global Beauty & Personal Care Peer Set
B4: All financial figures in millions of local currency (converted to EUR where noted). Data as of latest available filings.
B6: Company | C6: Ticker | D6: Currency | E6: Market Cap (€M) | F6: Enterprise Value (€M) | G6: Revenue LTM (€M) | H6: EBITDA LTM (€M) | I6: Net Income LTM (€M) | J6: Gross Margin | K6: EBITDA Margin | L6: Net Margin | M6: EV/Revenue | N6: EV/EBITDA | O6: P/E (TTM) | P6: P/E (Fwd)
B7: L'Oréal S.A. | C7: OR.PA | D7: EUR | E7: 184315 | F7: 188980 | G7: 44052 | H7: 10486 | I7: 6128 | J7: 0.7432 | K7: 0.2381 | L7: 0.1391 | M7: =F7/G7 -> 4.2899301 | N7: =F7/H7 -> 18.022125 | O7: =E7/I7 -> 30.077513
B8: Estée Lauder | C8: EL | D8: USD→EUR | E8: 35200 | F8: 42600 | G8: 13500 | H8: 1890 | I8: 430 | J8: 0.73 | K8: 0.14 | L8: 0.0319 | M8: =F8/G8 -> 3.1555556 | N8: =F8/H8 -> 22.539683 | O8: =E8/I8 -> 81.860465
B9: Procter & Gamble | C9: PG | D9: USD→EUR | E9: 355000 | F9: 380000 | G9: 79800 | H9: 22300 | I9: 14400 | J9: 0.512 | K9: 0.2794 | L9: 0.1805 | M9: =F9/G9 -> 4.7619048 | N9: =F9/H9 -> 17.040359 | O9: =E9/I9 -> 24.652778
B10: Unilever PLC | C10: ULVR.L | D10: EUR | E10: 135000 | F10: 155000 | G10: 59600 | H10: 12800 | I10: 7300 | J10: 0.435 | K10: 0.2148 | L10: 0.1225 | M10: =F10/G10 -> 2.6006711 | N10: =F10/H10 -> 12.109375 | O10: =E10/I10 -> 18.493151
B11: Beiersdorf AG | C11: BEI.DE | D11: EUR | E11: 15900 | F11: 13500 | G11: 9360 | H11: 1630 | I11: 900 | J11: 0.602 | K11: 0.1741 | L11: 0.0962 | M11: =F11/G11 -> 1.4423077 | N11: =F11/H11 -> 8.2822086 | O11: =E11/I11 -> 17.666667
B12: Shiseido Co. | C12: 4911.T | D12: JPY→EUR | E12: 16800 | F12: 19200 | G12: 9100 | H12: 1050 | I12: 290 | J12: 0.75 | K12: 0.1154 | L12: 0.0319 | M12: =F12/G12 -> 2.1098901 | N12: =F12/H12 -> 18.285714 | O12: =E12/I12 -> 57.931034
B13: Henkel AG | C13: HEN3.DE | D13: EUR | E13: 31500 | F13: 36800 | G13: 21500 | H13: 3600 | I13: 1750 | J13: 0.475 | K13: 0.1674 | L13: 0.0814 | M13: =F13/G13 -> 1.7116279 | N13: =F13/H13 -> 10.222222 | O13: =E13/I13 -> 18
B14: Colgate-Palmolive | C14: CL | D14: USD→EUR | E14: 64500 | F14: 79000 | G14: 18200 | H14: 4700 | I14: 2700 | J14: 0.605 | K14: 0.2582 | L14: 0.1484 | M14: =F14/G14 -> 4.3406593 | N14: =F14/H14 -> 16.808511 | O14: =E14/I14 -> 23.888889
B15: Church & Dwight | C15: CHD | D15: USD→EUR | E15: 23000 | F15: 26500 | G15: 5700 | H15: 1320 | I15: 730 | J15: 0.45 | K15: 0.2316 | L15: 0.1281 | M15: =F15/G15 -> 4.6491228 | N15: =F15/H15 -> 20.075758 | O15: =E15/I15 -> 31.506849
B17: PEER STATISTICS (Excl. L'Oréal)
B18: Mean | J18: =AVERAGE(J8:J15) -> 0.569875 | K18: =AVERAGE(K8:K15) -> 0.1976125 | L18: =AVERAGE(L8:L15) -> 0.1026125 | M18: =AVERAGE(M8:M15) -> 3.0964674 | N18: =AVERAGE(N8:N15) -> 15.670479 | O18: =AVERAGE(O8:O15) -> 34.249979
B19: Median | J19: =MEDIAN(J8:J15) -> 0.557 | K19: =MEDIAN(K8:K15) -> 0.19445 | L19: =MEDIAN(L8:L15) -> 0.10935 | M19: =MEDIAN(M8:M15) -> 2.8781133 | N19: =MEDIAN(N8:N15) -> 16.924435 | O19: =MEDIAN(O8:O15) -> 24.270833
B20: High | J20: =MAX(J8:J15) -> 0.75 | K20: =MAX(K8:K15) -> 0.2794 | L20: =MAX(L8:L15) -> 0.1805 | M20: =MAX(M8:M15) -> 4.7619048 | N20: =MAX(N8:N15) -> 22.539683 | O20: =MAX(O8:O15) -> 81.860465
B21: Low | J21: =MIN(J8:J15) -> 0.435 | K21: =MIN(K8:K15) -> 0.1154 | L21: =MIN(L8:L15) -> 0.0319 | M21: =MIN(M8:M15) -> 1.4423077 | N21: =MIN(N8:N15) -> 8.2822086 | O21: =MIN(O8:O15) -> 17.666667
B23: IMPLIED L'ORÉAL VALUATION FROM COMPS
C24: L'Oréal Metric | D24: Peer Mean | E24: Peer Median | F24: Implied EV (Mean) | G24: Implied EV (Median) | H24: Impl. Equity (Mean) | I24: Impl. Equity (Median) | J24: Price (Mean) | K24: Price (Median)
B25: EV / Revenue | C25: =G7 -> 44052 | D25: =M18 -> 3.0964674 | E25: =M19 -> 2.8781133 | F25: =C25*D25 -> 136405.58 | G25: =C25*E25 -> 126786.65 | H25: =F25+C28 -> 131958.38 | I25: =G25+C28 -> 122339.45 | J25: =H25/'DCF Valuation'!E69 -> 246.97433 | K25: =I25/'DCF Valuation'!E69 -> 228.97146
B26: EV / EBITDA | C26: =H7 -> 10486 | D26: =N18 -> 15.670479 | E26: =N19 -> 16.924435 | F26: =C26*D26 -> 164320.64 | G26: =C26*E26 -> 177469.62 | H26: =F26+C28 -> 159873.44 | I26: =G26+C28 -> 173022.42 | J26: =H26/'DCF Valuation'!E69 -> 299.22036 | K26: =I26/'DCF Valuation'!E69 -> 323.8301
B27: P / E | C27: =I7 -> 6128 | D27: =O18 -> 34.249979 | E27: =O19 -> 24.270833 | F27: n/a | G27: n/a | H27: =C27*D27 -> 209883.87 | I27: =C27*E27 -> 148731.67 | J27: =H27/'DCF Valuation'!E69 -> 392.82027 | K27: =I27/'DCF Valuation'!E69 -> 278.36733
B28: Net Debt (for EV→Equity bridge) | C28: ='DCF Valuation'!E64+'DCF Valuation'!E65+'DCF Valuation'!E66 -> -4447.2

Sheet Precedent Txns

Sheet Valuation Summary

Sheet Sensitivity Tables
B2: SENSITIVITY ANALYSIS
B3: L'Oréal S.A. | Implied Share Price Sensitivity
B5: TABLE 1: WACC vs. Terminal Growth Rate — Implied Share Price (€)
B7: WACC ↓ | C7: Terminal Growth Rate → | D7: 0.01 | E7: 0.015 | F7: 0.02 | G7: 0.025 | H7: 0.03 | I7: 0.035 | J7: 0.04
B8: 0.065 | D8: =('DCF Valuation'!F37/(1+$B$8)^0.5+'DCF Valuation'!G37/(1+$B$8)^1.5+'DCF Valuation'!H37/(1+$B$8)^2.5+'DCF Valuation'!I37/(1+$B$8)^3.5+'DCF Valuation'!J37/(1+$B$8)^4.5+('DCF Valuation'!J37*(1+D$7)/($B$8-D$7))/(1+$B$8)^4.5+'DCF Valuation'!E65+'DCF Valuation'!E64+'DCF Valuation'!E66)/'DCF Valuation'!E69 -> 275.08392 | E8: =('DCF Valuation'!F37/(1+$B$8)^0.5+'DCF Valuation'!G37/(1+$B$8)^1.5+'DCF Valuation'!H37/(1+$B$8)^2.5+'DCF Valuation'!I37/(1+$B$8)^3.5+'DCF Valuation'!J37/(1+$B$8)^4.5+('DCF Valuation'!J37*(1+E$7)/($B$8-E$7))/(1+$B$8)^4.5+'DCF Valuation'!E65+'DCF Valuation'!E64+'DCF Valuation'!E66)/'DCF Valuation'!E69 -> 298.47576 | F8: =('DCF Valuation'!F37/(1+$B$8)^0.5+'DCF Valuation'!G37/(1+$B$8)^1.5+'DCF Valuation'!H37/(1+$B$8)^2.5+'DCF Valuation'!I37/(1+$B$8)^3.5+'DCF Valuation'!J37/(1+$B$8)^4.5+('DCF Valuation'!J37*(1+F$7)/($B$8-F$7))/(1+$B$8)^4.5+'DCF Valuation'!E65+'DCF Valuation'!E64+'DCF Valuation'!E66)/'DCF Valuation'!E69 -> 327.06578 | G8: =('DCF Valuation'!F37/(1+$B$8)^0.5+'DCF Valuation'!G37/(1+$B$8)^1.5+'DCF Valuation'!H37/(1+$B$8)^2.5+'DCF Valuation'!I37/(1+$B$8)^3.5+'DCF Valuation'!J37/(1+$B$8)^4.5+('DCF Valuation'!J37*(1+G$7)/($B$8-G$7))/(1+$B$8)^4.5+'DCF Valuation'!E65+'DCF Valuation'!E64+'DCF Valuation'!E66)/'DCF Valuation'!E69 -> 362.80332 | H8: =('DCF Valuation'!F37/(1+$B$8)^0.5+'DCF Valuation'!G37/(1+$B$8)^1.5+'DCF Valuation'!H37/(1+$B$8)^2.5+'DCF Valuation'!I37/(1+$B$8)^3.5+'DCF Valuation'!J37/(1+$B$8)^4.5+('DCF Valuation'!J37*(1+H$7)/($B$8-H$7))/(1+$B$8)^4.5+'DCF Valuation'!E65+'DCF Valuation'!E64+'DCF Valuation'!E66)/'DCF Valuation'!E69 -> 408.75157 | I8: =('DCF Valuation'!F37/(1+$B$8)^0.5+'DCF Valuation'!G37/(1+$B$8)^1.5+'DCF Valuation'!H37/(1+$B$8)^2.5+'DCF Valuation'!I37/(1+$B$8)^3.5+'DCF Valuation'!J37/(1+$B$8)^4.5+('DCF Valuation'!J37*(1+I$7)/($B$8-I$7))/(1+$B$8)^4.5+'DCF Valuation'!E65+'DCF Valuation'!E64+'DCF Valuation'!E66)/'DCF Valuation'!E69 -> 470.01591 | J8: =('DCF Valuation'!F37/(1+$B$8)^0.5+'DCF Valuation'!G37/(1+$B$8)^1.5+'DCF Valuation'!H37/(1+$B$8)^2.5+'DCF Valuation'!I37/(1+$B$8)^3.5+'DCF Valuation'!J37/(1+$B$8)^4.5+('DCF Valuation'!J37*(1+J$7)/($B$8-J$7))/(1+$B$8)^4.5+'DCF Valuation'!E65+'DCF Valuation'!E64+'DCF Valuation'!E66)/'DCF Valuation'!E69 -> 555.78599
B9: 0.07 | D9: =('DCF Valuation'!F37/(1+$B$9)^0.5+'DCF Valuation'!G37/(1+$B$9)^1.5+'DCF Valuation'!H37/(1+$B$9)^2.5+'DCF Valuation'!I37/(1+$B$9)^3.5+'DCF Valuation'!J37/(1+$B$9)^4.5+('DCF Valuation'!J37*(1+D$7)/($B$9-D$7))/(1+$B$9)^4.5+'DCF Valuation'!E65+'DCF Valuation'!E64+'DCF Valuation'!E66)/'DCF Valuation'!E69 -> 251.64765 | E9: =('DCF Valuation'!F37/(1+$B$9)^0.5+'DCF Valuation'!G37/(1+$B$9)^1.5+'DCF Valuation'!H37/(1+$B$9)^2.5+'DCF Valuation'!I37/(1+$B$9)^3.5+'DCF Valuation'!J37/(1+$B$9)^4.5+('DCF Valuation'!J37*(1+E$7)/($B$9-E$7))/(1+$B$9)^4.5+'DCF Valuation'!E65+'DCF Valuation'!E64+'DCF Valuation'!E66)/'DCF Valuation'!E69 -> 270.82389 | F9: =('DCF Valuation'!F37/(1+$B$9)^0.5+'DCF Valuation'!G37/(1+$B$9)^1.5+'DCF Valuation'!H37/(1+$B$9)^2.5+'DCF Valuation'!I37/(1+$B$9)^3.5+'DCF Valuation'!J37/(1+$B$9)^4.5+('DCF Valuation'!J37*(1+F$7)/($B$9-F$7))/(1+$B$9)^4.5+'DCF Valuation'!E65+'DCF Valuation'!E64+'DCF Valuation'!E66)/'DCF Valuation'!E69 -> 293.83538 | G9: =('DCF Valuation'!F37/(1+$B$9)^0.5+'DCF Valuation'!G37/(1+$B$9)^1.5+'DCF Valuation'!H37/(1+$B$9)^2.5+'DCF Valuation'!I37/(1+$B$9)^3.5+'DCF Valuation'!J37/(1+$B$9)^4.5+('DCF Valuation'!J37*(1+G$7)/($B$9-G$7))/(1+$B$9)^4.5+'DCF Valuation'!E65+'DCF Valuation'!E64+'DCF Valuation'!E66)/'DCF Valuation'!E69 -> 321.96054 | H9: =('DCF Valuation'!F37/(1+$B$9)^0.5+'DCF Valuation'!G37/(1+$B$9)^1.5+'DCF Valuation'!H37/(1+$B$9)^2.5+'DCF Valuation'!I37/(1+$B$9)^3.5+'DCF Valuation'!J37/(1+$B$9)^4.5+('DCF Valuation'!J37*(1+H$7)/($B$9-H$7))/(1+$B$9)^4.5+'DCF Valuation'!E65+'DCF Valuation'!E64+'DCF Valuation'!E66)/'DCF Valuation'!E69 -> 357.11699 | I9: =('DCF Valuation'!F37/(1+$B$9)^0.5+'DCF Valuation'!G37/(1+$B$9)^1.5+'DCF Valuation'!H37/(1+$B$9)^2.5+'DCF Valuation'!I37/(1+$B$9)^3.5+'DCF Valuation'!J37/(1+$B$9)^4.5+('DCF Valuation'!J37*(1+I$7)/($B$9-I$7))/(1+$B$9)^4.5+'DCF Valuation'!E65+'DCF Valuation'!E64+'DCF Valuation'!E66)/'DCF Valuation'!E69 -> 402.31813 | J9: =('DCF Valuation'!F37/(1+$B$9)^0.5+'DCF Valuation'!G37/(1+$B$9)^1.5+'DCF Valuation'!H37/(1+$B$9)^2.5+'DCF Valuation'!I37/(1+$B$9)^3.5+'DCF Valuation'!J37/(1+$B$9)^4.5+('DCF Valuation'!J37*(1+J$7)/($B$9-J$7))/(1+$B$9)^4.5+'DCF Valuation'!E65+'DCF Valuation'!E64+'DCF Valuation'!E66)/'DCF Valuation'!E69 -> 462.58632
B10: 0.075 | D10: =('DCF Valuation'!F37/(1+$B$10)^0.5+'DCF Valuation'!G37/(1+$B$10)^1.5+'DCF Valuation'!H37/(1+$B$10)^2.5+'DCF Valuation'!I37/(1+$B$10)^3.5+'DCF Valuation'!J37/(1+$B$10)^4.5+('DCF Valuation'!J37*(1+D$7)/($B$10-D$7))/(1+$B$10)^4.5+'DCF Valuation'!E65+'DCF Valuation'!E64+'DCF Valuation'!E66)/'DCF Valuation'!E69 -> 231.82133 | E10: =('DCF Valuation'!F37/(1+$B$10)^0.5+'DCF Valuation'!G37/(1+$B$10)^1.5+'DCF Valuation'!H37/(1+$B$10)^2.5+'DCF Valuation'!I37/(1+$B$10)^3.5+'DCF Valuation'!J37/(1+$B$10)^4.5+('DCF Valuation'!J37*(1+E$7)/($B$10-E$7))/(1+$B$10)^4.5+'DCF Valuation'!E65+'DCF Valuation'!E64+'DCF Valuation'!E66)/'DCF Valuation'!E69 -> 247.78477 | F10: =('DCF Valuation'!F37/(1+$B$10)^0.5+'DCF Valuation'!G37/(1+$B$10)^1.5+'DCF Valuation'!H37/(1+$B$10)^2.5+'DCF Valuation'!I37/(1+$B$10)^3.5+'DCF Valuation'!J37/(1+$B$10)^4.5+('DCF Valuation'!J37*(1+F$7)/($B$10-F$7))/(1+$B$10)^4.5+'DCF Valuation'!E65+'DCF Valuation'!E64+'DCF Valuation'!E66)/'DCF Valuation'!E69 -> 266.65065 | G10: =('DCF Valuation'!F37/(1+$B$10)^0.5+'DCF Valuation'!G37/(1+$B$10)^1.5+'DCF Valuation'!H37/(1+$B$10)^2.5+'DCF Valuation'!I37/(1+$B$10)^3.5+'DCF Valuation'!J37/(1+$B$10)^4.5+('DCF Valuation'!J37*(1+G$7)/($B$10-G$7))/(1+$B$10)^4.5+'DCF Valuation'!E65+'DCF Valuation'!E64+'DCF Valuation'!E66)/'DCF Valuation'!E69 -> 289.28971 | H10: =('DCF Valuation'!F37/(1+$B$10)^0.5+'DCF Valuation'!G37/(1+$B$10)^1.5+'DCF Valuation'!H37/(1+$B$10)^2.5+'DCF Valuation'!I37/(1+$B$10)^3.5+'DCF Valuation'!J37/(1+$B$10)^4.5+('DCF Valuation'!J37*(1+H$7)/($B$10-H$7))/(1+$B$10)^4.5+'DCF Valuation'!E65+'DCF Valuation'!E64+'DCF Valuation'!E66)/'DCF Valuation'!E69 -> 316.95967 | I10: =('DCF Valuation'!F37/(1+$B$10)^0.5+'DCF Valuation'!G37/(1+$B$10)^1.5+'DCF Valuation'!H37/(1+$B$10)^2.5+'DCF Valuation'!I37/(1+$B$10)^3.5+'DCF Valuation'!J37/(1+$B$10)^4.5+('DCF Valuation'!J37*(1+I$7)/($B$10-I$7))/(1+$B$10)^4.5+'DCF Valuation'!E65+'DCF Valuation'!E64+'DCF Valuation'!E66)/'DCF Valuation'!E69 -> 351.54712 | J10: =('DCF Valuation'!F37/(1+$B$10)^0.5+'DCF Valuation'!G37/(1+$B$10)^1.5+'DCF Valuation'!H37/(1+$B$10)^2.5+'DCF Valuation'!I37/(1+$B$10)^3.5+'DCF Valuation'!J37/(1+$B$10)^4.5+('DCF Valuation'!J37*(1+J$7)/($B$10-J$7))/(1+$B$10)^4.5+'DCF Valuation'!E65+'DCF Valuation'!E64+'DCF Valuation'!E66)/'DCF Valuation'!E69 -> 396.0167
B11: 0.077 | D11: =('DCF Valuation'!F37/(1+$B$11)^0.5+'DCF Valuation'!G37/(1+$B$11)^1.5+'DCF Valuation'!H37/(1+$B$11)^2.5+'DCF Valuation'!I37/(1+$B$11)^3.5+'DCF Valuation'!J37/(1+$B$11)^4.5+('DCF Valuation'!J37*(1+D$7)/($B$11-D$7))/(1+$B$11)^4.5+'DCF Valuation'!E65+'DCF Valuation'!E64+'DCF Valuation'!E66)/'DCF Valuation'!E69 -> 224.72053 | E11: =('DCF Valuation'!F37/(1+$B$11)^0.5+'DCF Valuation'!G37/(1+$B$11)^1.5+'DCF Valuation'!H37/(1+$B$11)^2.5+'DCF Valuation'!I37/(1+$B$11)^3.5+'DCF Valuation'!J37/(1+$B$11)^4.5+('DCF Valuation'!J37*(1+E$7)/($B$11-E$7))/(1+$B$11)^4.5+'DCF Valuation'!E65+'DCF Valuation'!E64+'DCF Valuation'!E66)/'DCF Valuation'!E69 -> 239.61068 | F11: =('DCF Valuation'!F37/(1+$B$11)^0.5+'DCF Valuation'!G37/(1+$B$11)^1.5+'DCF Valuation'!H37/(1+$B$11)^2.5+'DCF Valuation'!I37/(1+$B$11)^3.5+'DCF Valuation'!J37/(1+$B$11)^4.5+('DCF Valuation'!J37*(1+F$7)/($B$11-F$7))/(1+$B$11)^4.5+'DCF Valuation'!E65+'DCF Valuation'!E64+'DCF Valuation'!E66)/'DCF Valuation'!E69 -> 257.11315 | G11: =('DCF Valuation'!F37/(1+$B$11)^0.5+'DCF Valuation'!G37/(1+$B$11)^1.5+'DCF Valuation'!H37/(1+$B$11)^2.5+'DCF Valuation'!I37/(1+$B$11)^3.5+'DCF Valuation'!J37/(1+$B$11)^4.5+('DCF Valuation'!J37*(1+G$7)/($B$11-G$7))/(1+$B$11)^4.5+'DCF Valuation'!E65+'DCF Valuation'!E64+'DCF Valuation'!E66)/'DCF Valuation'!E69 -> 277.98147 | H11: =('DCF Valuation'!F37/(1+$B$11)^0.5+'DCF Valuation'!G37/(1+$B$11)^1.5+'DCF Valuation'!H37/(1+$B$11)^2.5+'DCF Valuation'!I37/(1+$B$11)^3.5+'DCF Valuation'!J37/(1+$B$11)^4.5+('DCF Valuation'!J37*(1+H$7)/($B$11-H$7))/(1+$B$11)^4.5+'DCF Valuation'!E65+'DCF Valuation'!E64+'DCF Valuation'!E66)/'DCF Valuation'!E69 -> 303.28986 | I11: =('DCF Valuation'!F37/(1+$B$11)^0.5+'DCF Valuation'!G37/(1+$B$11)^1.5+'DCF Valuation'!H37/(1+$B$11)^2.5+'DCF Valuation'!I37/(1+$B$11)^3.5+'DCF Valuation'!J37/(1+$B$11)^4.5+('DCF Valuation'!J37*(1+I$7)/($B$11-I$7))/(1+$B$11)^4.5+'DCF Valuation'!E65+'DCF Valuation'!E64+'DCF Valuation'!E66)/'DCF Valuation'!E69 -> 334.62406 | J11: =('DCF Valuation'!F37/(1+$B$11)^0.5+'DCF Valuation'!G37/(1+$B$11)^1.5+'DCF Valuation'!H37/(1+$B$11)^2.5+'DCF Valuation'!I37/(1+$B$11)^3.5+'DCF Valuation'!J37/(1+$B$11)^4.5+('DCF Valuation'!J37*(1+J$7)/($B$11-J$7))/(1+$B$11)^4.5+'DCF Valuation'!E65+'DCF Valuation'!E64+'DCF Valuation'!E66)/'DCF Valuation'!E69 -> 374.42696
B12: 0.08 | D12: =('DCF Valuation'!F37/(1+$B$12)^0.5+'DCF Valuation'!G37/(1+$B$12)^1.5+'DCF Valuation'!H37/(1+$B$12)^2.5+'DCF Valuation'!I37/(1+$B$12)^3.5+'DCF Valuation'!J37/(1+$B$12)^4.5+('DCF Valuation'!J37*(1+D$7)/($B$12-D$7))/(1+$B$12)^4.5+'DCF Valuation'!E65+'DCF Valuation'!E64+'DCF Valuation'!E66)/'DCF Valuation'!E69 -> 214.8313 | E12: =('DCF Valuation'!F37/(1+$B$12)^0.5+'DCF Valuation'!G37/(1+$B$12)^1.5+'DCF Valuation'!H37/(1+$B$12)^2.5+'DCF Valuation'!I37/(1+$B$12)^3.5+'DCF Valuation'!J37/(1+$B$12)^4.5+('DCF Valuation'!J37*(1+E$7)/($B$12-E$7))/(1+$B$12)^4.5+'DCF Valuation'!E65+'DCF Valuation'!E64+'DCF Valuation'!E66)/'DCF Valuation'!E69 -> 228.29381 | F12: =('DCF Valuation'!F37/(1+$B$12)^0.5+'DCF Valuation'!G37/(1+$B$12)^1.5+'DCF Valuation'!H37/(1+$B$12)^2.5+'DCF Valuation'!I37/(1+$B$12)^3.5+'DCF Valuation'!J37/(1+$B$12)^4.5+('DCF Valuation'!J37*(1+F$7)/($B$12-F$7))/(1+$B$12)^4.5+'DCF Valuation'!E65+'DCF Valuation'!E64+'DCF Valuation'!E66)/'DCF Valuation'!E69 -> 244.00008 | G12: =('DCF Valuation'!F37/(1+$B$12)^0.5+'DCF Valuation'!G37/(1+$B$12)^1.5+'DCF Valuation'!H37/(1+$B$12)^2.5+'DCF Valuation'!I37/(1+$B$12)^3.5+'DCF Valuation'!J37/(1+$B$12)^4.5+('DCF Valuation'!J37*(1+G$7)/($B$12-G$7))/(1+$B$12)^4.5+'DCF Valuation'!E65+'DCF Valuation'!E64+'DCF Valuation'!E66)/'DCF Valuation'!E69 -> 262.56203 | H12: =('DCF Valuation'!F37/(1+$B$12)^0.5+'DCF Valuation'!G37/(1+$B$12)^1.5+'DCF Valuation'!H37/(1+$B$12)^2.5+'DCF Valuation'!I37/(1+$B$12)^3.5+'DCF Valuation'!J37/(1+$B$12)^4.5+('DCF Valuation'!J37*(1+H$7)/($B$12-H$7))/(1+$B$12)^4.5+'DCF Valuation'!E65+'DCF Valuation'!E64+'DCF Valuation'!E66)/'DCF Valuation'!E69 -> 284.83637 | I12: =('DCF Valuation'!F37/(1+$B$12)^0.5+'DCF Valuation'!G37/(1+$B$12)^1.5+'DCF Valuation'!H37/(1+$B$12)^2.5+'DCF Valuation'!I37/(1+$B$12)^3.5+'DCF Valuation'!J37/(1+$B$12)^4.5+('DCF Valuation'!J37*(1+I$7)/($B$12-I$7))/(1+$B$12)^4.5+'DCF Valuation'!E65+'DCF Valuation'!E64+'DCF Valuation'!E66)/'DCF Valuation'!E69 -> 312.06056 | J12: =('DCF Valuation'!F37/(1+$B$12)^0.5+'DCF Valuation'!G37/(1+$B$12)^1.5+'DCF Valuation'!H37/(1+$B$12)^2.5+'DCF Valuation'!I37/(1+$B$12)^3.5+'DCF Valuation'!J37/(1+$B$12)^4.5+('DCF Valuation'!J37*(1+J$7)/($B$12-J$7))/(1+$B$12)^4.5+'DCF Valuation'!E65+'DCF Valuation'!E64+'DCF Valuation'!E66)/'DCF Valuation'!E69 -> 346.0908
B13: 0.085 | D13: =('DCF Valuation'!F37/(1+$B$13)^0.5+'DCF Valuation'!G37/(1+$B$13)^1.5+'DCF Valuation'!H37/(1+$B$13)^2.5+'DCF Valuation'!I37/(1+$B$13)^3.5+'DCF Valuation'!J37/(1+$B$13)^4.5+('DCF Valuation'!J37*(1+D$7)/($B$13-D$7))/(1+$B$13)^4.5+'DCF Valuation'!E65+'DCF Valuation'!E64+'DCF Valuation'!E66)/'DCF Valuation'!E69 -> 200.11019 | E13: =('DCF Valuation'!F37/(1+$B$13)^0.5+'DCF Valuation'!G37/(1+$B$13)^1.5+'DCF Valuation'!H37/(1+$B$13)^2.5+'DCF Valuation'!I37/(1+$B$13)^3.5+'DCF Valuation'!J37/(1+$B$13)^4.5+('DCF Valuation'!J37*(1+E$7)/($B$13-E$7))/(1+$B$13)^4.5+'DCF Valuation'!E65+'DCF Valuation'!E64+'DCF Valuation'!E66)/'DCF Valuation'!E69 -> 211.5906 | F13: =('DCF Valuation'!F37/(1+$B$13)^0.5+'DCF Valuation'!G37/(1+$B$13)^1.5+'DCF Valuation'!H37/(1+$B$13)^2.5+'DCF Valuation'!I37/(1+$B$13)^3.5+'DCF Valuation'!J37/(1+$B$13)^4.5+('DCF Valuation'!J37*(1+F$7)/($B$13-F$7))/(1+$B$13)^4.5+'DCF Valuation'!E65+'DCF Valuation'!E64+'DCF Valuation'!E66)/'DCF Valuation'!E69 -> 224.83723 | G13: =('DCF Valuation'!F37/(1+$B$13)^0.5+'DCF Valuation'!G37/(1+$B$13)^1.5+'DCF Valuation'!H37/(1+$B$13)^2.5+'DCF Valuation'!I37/(1+$B$13)^3.5+'DCF Valuation'!J37/(1+$B$13)^4.5+('DCF Valuation'!J37*(1+G$7)/($B$13-G$7))/(1+$B$13)^4.5+'DCF Valuation'!E65+'DCF Valuation'!E64+'DCF Valuation'!E66)/'DCF Valuation'!E69 -> 240.29162 | H13: =('DCF Valuation'!F37/(1+$B$13)^0.5+'DCF Valuation'!G37/(1+$B$13)^1.5+'DCF Valuation'!H37/(1+$B$13)^2.5+'DCF Valuation'!I37/(1+$B$13)^3.5+'DCF Valuation'!J37/(1+$B$13)^4.5+('DCF Valuation'!J37*(1+H$7)/($B$13-H$7))/(1+$B$13)^4.5+'DCF Valuation'!E65+'DCF Valuation'!E64+'DCF Valuation'!E66)/'DCF Valuation'!E69 -> 258.5559 | I13: =('DCF Valuation'!F37/(1+$B$13)^0.5+'DCF Valuation'!G37/(1+$B$13)^1.5+'DCF Valuation'!H37/(1+$B$13)^2.5+'DCF Valuation'!I37/(1+$B$13)^3.5+'DCF Valuation'!J37/(1+$B$13)^4.5+('DCF Valuation'!J37*(1+I$7)/($B$13-I$7))/(1+$B$13)^4.5+'DCF Valuation'!E65+'DCF Valuation'!E64+'DCF Valuation'!E66)/'DCF Valuation'!E69 -> 280.47305 | J13: =('DCF Valuation'!F37/(1+$B$13)^0.5+'DCF Valuation'!G37/(1+$B$13)^1.5+'DCF Valuation'!H37/(1+$B$13)^2.5+'DCF Valuation'!I37/(1+$B$13)^3.5+'DCF Valuation'!J37/(1+$B$13)^4.5+('DCF Valuation'!J37*(1+J$7)/($B$13-J$7))/(1+$B$13)^4.5+'DCF Valuation'!E65+'DCF Valuation'!E64+'DCF Valuation'!E66)/'DCF Valuation'!E69 -> 307.26066
B14: 0.09 | D14: =('DCF Valuation'!F37/(1+$B$14)^0.5+'DCF Valuation'!G37/(1+$B$14)^1.5+'DCF Valuation'!H37/(1+$B$14)^2.5+'DCF Valuation'!I37/(1+$B$14)^3.5+'DCF Valuation'!J37/(1+$B$14)^4.5+('DCF Valuation'!J37*(1+D$7)/($B$14-D$7))/(1+$B$14)^4.5+'DCF Valuation'!E65+'DCF Valuation'!E64+'DCF Valuation'!E66)/'DCF Valuation'!E69 -> 187.23251 | E14: =('DCF Valuation'!F37/(1+$B$14)^0.5+'DCF Valuation'!G37/(1+$B$14)^1.5+'DCF Valuation'!H37/(1+$B$14)^2.5+'DCF Valuation'!I37/(1+$B$14)^3.5+'DCF Valuation'!J37/(1+$B$14)^4.5+('DCF Valuation'!J37*(1+E$7)/($B$14-E$7))/(1+$B$14)^4.5+'DCF Valuation'!E65+'DCF Valuation'!E64+'DCF Valuation'!E66)/'DCF Valuation'!E69 -> 197.11751 | F14: =('DCF Valuation'!F37/(1+$B$14)^0.5+'DCF Valuation'!G37/(1+$B$14)^1.5+'DCF Valuation'!H37/(1+$B$14)^2.5+'DCF Valuation'!I37/(1+$B$14)^3.5+'DCF Valuation'!J37/(1+$B$14)^4.5+('DCF Valuation'!J37*(1+F$7)/($B$14-F$7))/(1+$B$14)^4.5+'DCF Valuation'!E65+'DCF Valuation'!E64+'DCF Valuation'!E66)/'DCF Valuation'!E69 -> 208.41465 | G14: =('DCF Valuation'!F37/(1+$B$14)^0.5+'DCF Valuation'!G37/(1+$B$14)^1.5+'DCF Valuation'!H37/(1+$B$14)^2.5+'DCF Valuation'!I37/(1+$B$14)^3.5+'DCF Valuation'!J37/(1+$B$14)^4.5+('DCF Valuation'!J37*(1+G$7)/($B$14-G$7))/(1+$B$14)^4.5+'DCF Valuation'!E65+'DCF Valuation'!E64+'DCF Valuation'!E66)/'DCF Valuation'!E69 -> 221.44982 | H14: =('DCF Valuation'!F37/(1+$B$14)^0.5+'DCF Valuation'!G37/(1+$B$14)^1.5+'DCF Valuation'!H37/(1+$B$14)^2.5+'DCF Valuation'!I37/(1+$B$14)^3.5+'DCF Valuation'!J37/(1+$B$14)^4.5+('DCF Valuation'!J37*(1+H$7)/($B$14-H$7))/(1+$B$14)^4.5+'DCF Valuation'!E65+'DCF Valuation'!E64+'DCF Valuation'!E66)/'DCF Valuation'!E69 -> 236.65751 | I14: =('DCF Valuation'!F37/(1+$B$14)^0.5+'DCF Valuation'!G37/(1+$B$14)^1.5+'DCF Valuation'!H37/(1+$B$14)^2.5+'DCF Valuation'!I37/(1+$B$14)^3.5+'DCF Valuation'!J37/(1+$B$14)^4.5+('DCF Valuation'!J37*(1+I$7)/($B$14-I$7))/(1+$B$14)^4.5+'DCF Valuation'!E65+'DCF Valuation'!E64+'DCF Valuation'!E66)/'DCF Valuation'!E69 -> 254.63024 | J14: =('DCF Valuation'!F37/(1+$B$14)^0.5+'DCF Valuation'!G37/(1+$B$14)^1.5+'DCF Valuation'!H37/(1+$B$14)^2.5+'DCF Valuation'!I37/(1+$B$14)^3.5+'DCF Valuation'!J37/(1+$B$14)^4.5+('DCF Valuation'!J37*(1+J$7)/($B$14-J$7))/(1+$B$14)^4.5+'DCF Valuation'!E65+'DCF Valuation'!E64+'DCF Valuation'!E66)/'DCF Valuation'!E69 -> 276.19751
B17: TABLE 2: WACC vs. Exit EV/EBITDA Multiple — Implied Share Price (€)
B19: WACC ↓ | C19: Exit EV/EBITDA → | D19: 14 | E19: 15 | F19: 16 | G19: 18 | H19: 20 | I19: 22 | J19: 24
B20: 0.065 | D20: =('DCF Valuation'!F37/(1+$B$20)^0.5+'DCF Valuation'!G37/(1+$B$20)^1.5+'DCF Valuation'!H37/(1+$B$20)^2.5+'DCF Valuation'!I37/(1+$B$20)^3.5+'DCF Valuation'!J37/(1+$B$20)^4.5+('DCF Valuation'!E48*D$19)/(1+$B$20)^4.5+'DCF Valuation'!E65+'DCF Valuation'!E64+'DCF Valuation'!E66)/'DCF Valuation'!E69 -> 319.49057 | E20: =('DCF Valuation'!F37/(1+$B$20)^0.5+'DCF Valuation'!G37/(1+$B$20)^1.5+'DCF Valuation'!H37/(1+$B$20)^2.5+'DCF Valuation'!I37/(1+$B$20)^3.5+'DCF Valuation'!J37/(1+$B$20)^4.5+('DCF Valuation'!E48*E$19)/(1+$B$20)^4.5+'DCF Valuation'!E65+'DCF Valuation'!E64+'DCF Valuation'!E66)/'DCF Valuation'!E69 -> 338.50805 | F20: =('DCF Valuation'!F37/(1+$B$20)^0.5+'DCF Valuation'!G37/(1+$B$20)^1.5+'DCF Valuation'!H37/(1+$B$20)^2.5+'DCF Valuation'!I37/(1+$B$20)^3.5+'DCF Valuation'!J37/(1+$B$20)^4.5+('DCF Valuation'!E48*F$19)/(1+$B$20)^4.5+'DCF Valuation'!E65+'DCF Valuation'!E64+'DCF Valuation'!E66)/'DCF Valuation'!E69 -> 357.52554 | G20: =('DCF Valuation'!F37/(1+$B$20)^0.5+'DCF Valuation'!G37/(1+$B$20)^1.5+'DCF Valuation'!H37/(1+$B$20)^2.5+'DCF Valuation'!I37/(1+$B$20)^3.5+'DCF Valuation'!J37/(1+$B$20)^4.5+('DCF Valuation'!E48*G$19)/(1+$B$20)^4.5+'DCF Valuation'!E65+'DCF Valuation'!E64+'DCF Valuation'!E66)/'DCF Valuation'!E69 -> 395.5605 | H20: =('DCF Valuation'!F37/(1+$B$20)^0.5+'DCF Valuation'!G37/(1+$B$20)^1.5+'DCF Valuation'!H37/(1+$B$20)^2.5+'DCF Valuation'!I37/(1+$B$20)^3.5+'DCF Valuation'!J37/(1+$B$20)^4.5+('DCF Valuation'!E48*H$19)/(1+$B$20)^4.5+'DCF Valuation'!E65+'DCF Valuation'!E64+'DCF Valuation'!E66)/'DCF Valuation'!E69 -> 433.59547 | I20: =('DCF Valuation'!F37/(1+$B$20)^0.5+'DCF Valuation'!G37/(1+$B$20)^1.5+'DCF Valuation'!H37/(1+$B$20)^2.5+'DCF Valuation'!I37/(1+$B$20)^3.5+'DCF Valuation'!J37/(1+$B$20)^4.5+('DCF Valuation'!E48*I$19)/(1+$B$20)^4.5+'DCF Valuation'!E65+'DCF Valuation'!E64+'DCF Valuation'!E66)/'DCF Valuation'!E69 -> 471.63043 | J20: =('DCF Valuation'!F37/(1+$B$20)^0.5+'DCF Valuation'!G37/(1+$B$20)^1.5+'DCF Valuation'!H37/(1+$B$20)^2.5+'DCF Valuation'!I37/(1+$B$20)^3.5+'DCF Valuation'!J37/(1+$B$20)^4.5+('DCF Valuation'!E48*J$19)/(1+$B$20)^4.5+'DCF Valuation'!E65+'DCF Valuation'!E64+'DCF Valuation'!E66)/'DCF Valuation'!E69 -> 509.6654
B21: 0.07 | D21: =('DCF Valuation'!F37/(1+$B$21)^0.5+'DCF Valuation'!G37/(1+$B$21)^1.5+'DCF Valuation'!H37/(1+$B$21)^2.5+'DCF Valuation'!I37/(1+$B$21)^3.5+'DCF Valuation'!J37/(1+$B$21)^4.5+('DCF Valuation'!E48*D$19)/(1+$B$21)^4.5+'DCF Valuation'!E65+'DCF Valuation'!E64+'DCF Valuation'!E66)/'DCF Valuation'!E69 -> 313.22906 | E21: =('DCF Valuation'!F37/(1+$B$21)^0.5+'DCF Valuation'!G37/(1+$B$21)^1.5+'DCF Valuation'!H37/(1+$B$21)^2.5+'DCF Valuation'!I37/(1+$B$21)^3.5+'DCF Valuation'!J37/(1+$B$21)^4.5+('DCF Valuation'!E48*E$19)/(1+$B$21)^4.5+'DCF Valuation'!E65+'DCF Valuation'!E64+'DCF Valuation'!E66)/'DCF Valuation'!E69 -> 331.8499 | F21: =('DCF Valuation'!F37/(1+$B$21)^0.5+'DCF Valuation'!G37/(1+$B$21)^1.5+'DCF Valuation'!H37/(1+$B$21)^2.5+'DCF Valuation'!I37/(1+$B$21)^3.5+'DCF Valuation'!J37/(1+$B$21)^4.5+('DCF Valuation'!E48*F$19)/(1+$B$21)^4.5+'DCF Valuation'!E65+'DCF Valuation'!E64+'DCF Valuation'!E66)/'DCF Valuation'!E69 -> 350.47074 | G21: =('DCF Valuation'!F37/(1+$B$21)^0.5+'DCF Valuation'!G37/(1+$B$21)^1.5+'DCF Valuation'!H37/(1+$B$21)^2.5+'DCF Valuation'!I37/(1+$B$21)^3.5+'DCF Valuation'!J37/(1+$B$21)^4.5+('DCF Valuation'!E48*G$19)/(1+$B$21)^4.5+'DCF Valuation'!E65+'DCF Valuation'!E64+'DCF Valuation'!E66)/'DCF Valuation'!E69 -> 387.71242 | H21: =('DCF Valuation'!F37/(1+$B$21)^0.5+'DCF Valuation'!G37/(1+$B$21)^1.5+'DCF Valuation'!H37/(1+$B$21)^2.5+'DCF Valuation'!I37/(1+$B$21)^3.5+'DCF Valuation'!J37/(1+$B$21)^4.5+('DCF Valuation'!E48*H$19)/(1+$B$21)^4.5+'DCF Valuation'!E65+'DCF Valuation'!E64+'DCF Valuation'!E66)/'DCF Valuation'!E69 -> 424.9541 | I21: =('DCF Valuation'!F37/(1+$B$21)^0.5+'DCF Valuation'!G37/(1+$B$21)^1.5+'DCF Valuation'!H37/(1+$B$21)^2.5+'DCF Valuation'!I37/(1+$B$21)^3.5+'DCF Valuation'!J37/(1+$B$21)^4.5+('DCF Valuation'!E48*I$19)/(1+$B$21)^4.5+'DCF Valuation'!E65+'DCF Valuation'!E64+'DCF Valuation'!E66)/'DCF Valuation'!E69 -> 462.19578 | J21: =('DCF Valuation'!F37/(1+$B$21)^0.5+'DCF Valuation'!G37/(1+$B$21)^1.5+'DCF Valuation'!H37/(1+$B$21)^2.5+'DCF Valuation'!I37/(1+$B$21)^3.5+'DCF Valuation'!J37/(1+$B$21)^4.5+('DCF Valuation'!E48*J$19)/(1+$B$21)^4.5+'DCF Valuation'!E65+'DCF Valuation'!E64+'DCF Valuation'!E66)/'DCF Valuation'!E69 -> 499.43746
