Workbook

Sheet Cover
E7: LEVERAGED BUYOUT ANALYSIS
E9: AutoStore Holdings Ltd.
E10: (OSLO: AUTO)
E13: Transaction Summary
E15: Enterprise Value: NOK 43,311mm | Entry Multiple: 20.8x EBITDA
E16: Sponsor Equity: NOK 34,360mm | Total Debt: NOK 11,430mm
E17: Exit Multiple: 18.0x | 5-Year Holding Period
E19: Projected Returns
E21: IRR: 19.2% | MOIC: 2.4x
E24: 46082

Sheet ToC
C3: TABLE OF CONTENTS
B6: Section | C6: Description | D6: Tab Name
B7: 1 | C7: Dashboard overview with key metrics, returns, and value creation summary | D7: Executive Summary
B8: 2 | C8: Transaction structure, sources & uses, purchase price, credit metrics | D8: Entry Assumptions
B9: 3 | C9: 3-year historical P&L, balance sheet, cash flow, and key metrics | D9: Historical Financials
B10: 4 | C10: Revenue projections, margin analysis, working capital, CapEx, UFCF | D10: Operating Model
B11: 5 | C11: Integrated income statement, balance sheet, and cash flow projections | D11: 3-Statement Model (Forecast)
B12: 6 | C12: Debt tranches, interest calculations, amortization, and paydown schedule | D12: Debt Schedule
B13: 7 | C13: Exit valuation, net debt, equity proceeds, value creation bridge | D13: Exit Assumptions
B14: 8 | C14: IRR, MOIC, cash flows, returns by exit year, value creation attribution | D14: Returns
B15: 9 | C15: IRR/MOIC sensitivities across exit multiples, CAGR, leverage scenarios | D15: Sensitivity Analysis
B16: 10 | C16: Data sources, methodology notes, and disclaimers | D16: Sources and Footnotes
C19: Click on tab names to navigate directly to each section

Sheet Executive Summary 
B1: LBO Analysis | Executive Summary | AutoStore Holdings Ltd. | Q1: AUTO-NO | Oslo Børs
B4: INTERNAL RATE OF RETURN | F4: MONEY ON INVESTED CAPITAL | J4: ENTERPRISE VALUE (NOK mm) | O4: ENTRY EV/EBITDA | S4: EXIT EV/EBITDA
B5: 19.2% | F5: 2.40x | J5: 43,311 | O5: 20.8x | S5: 18.0x
B6: 5-Year Base Case | F6: Total Return: 140% | J6: Equity: 34,360 | Debt: 11,431 | O6: LTM EBITDA: 2,080 | S6: Exit EBITDA: 3,246
B9: REVENUE & EBITDA TRAJECTORY (NOK mm) | M9: RETURNS & VALUE CREATION
C10: FY22A | D10: FY23A | E10: FY24A | F10: FY25E | G10: FY26E | H10: FY27E | I10: FY28E | J10: FY29E | M10: Returns by Exit Year | O10: Year 3 | P10: Year 4 | Q10: Year 5 | R10: Year 6 | S10: Year 7
B11: Revenue | C11: ='Historical Financials'!D10 -> 5628.0849 | D11: ='Historical Financials'!E10 -> 6833.8038 | E11: ='Historical Financials'!F10 -> 6477.4953 | F11: ='Operating Model'!H13 -> 7124.9261 | G11: ='Operating Model'!I13 -> 7837.0107 | H11: ='Operating Model'!J13 -> 8620.2166 | I11: ='Operating Model'!K13 -> 9309.3968 | J11: ='Operating Model'!L13 -> 9774.5694 | M11: MOIC | O11: ='Returns '!G8 -> 2.2001682 | P11: ='Returns '!G9 -> 2.3294139 | Q11: ='Returns '!G10 -> 2.4041595 | R11: ='Returns '!G11 -> 2.6359923 | S11: ='Returns '!G12 -> 2.8420708
B12: EBITDA | C12: ='Historical Financials'!D23 -> 2463.9002 | D12: ='Historical Financials'!E23 -> 3038.9594 | E12: ='Historical Financials'!F23 -> 3079.0114 | F12: ='Operating Model'!H41 -> 2572.6205 | G12: ='Operating Model'!I41 -> 2759.2021 | H12: ='Operating Model'!J41 -> 2965.9862 | I12: ='Operating Model'!K41 -> 3137.949 | J12: ='Operating Model'!L41 -> 3245.8734 | M12: IRR | O12: ='Returns '!H8 -> 0.30062459 | P12: ='Returns '!H9 -> 0.23541157 | Q12: ='Returns '!H10 -> 0.19177057 | R12: ='Returns '!H11 -> 0.17532333 | S12: ='Returns '!H12 -> 0.16092719
B13: EBITDA Margin | C13: =C12/C11 -> 0.4377866 | D13: =D12/D11 -> 0.44469515 | E13: =E12/E11 -> 0.47533981 | F13: =F12/F11 -> 0.36107329 | G13: =G12/G11 -> 0.35207329 | H13: =H12/H11 -> 0.34407329 | I13: =I12/I11 -> 0.33707329 | J13: =J12/J11 -> 0.33207329 | M13: Value Creation | O13: EBITDA Growth | Q13: ='Exit Assumptions'!C29 -> 24332.626 | S13: Debt Paydown | U13: ='Exit Assumptions'!C30 -> 70855.343
B14: Revenue Growth | C14: - | D14: =D11/C11-1 -> 0.21423254 | E14: =E11/D11-1 -> -0.052139118 | F14: =F11/E11-1 -> 0.09995079 | G14: =G11/F11-1 -> 0.099942725 | H14: =H11/G11-1 -> 0.09993682 | I14: =I11/H11-1 -> 0.079949289 | J14: =J11/I11-1 -> 0.049968069 | O14: Multiple Chg | Q14: ='Exit Assumptions'!C28 -> -9217.645 | S14: Total Value | U14: ='Exit Assumptions'!C31 -> 85970.323
B16: SOURCES & USES (NOK mm) | G16: CREDIT METRICS | N16: KEY INVESTMENT HIGHLIGHTS
B17: Sources | D17: Uses | G17: Metric | I17: Entry | K17: Exit | N17: ▸ | O17: Global leader in cube storage automation with 25%+ market share
B18: Term Loan B | C18: ='Entry Assumptions'!G9 -> 8313.08 | D18: Purchase Equity | E18: ='Entry Assumptions'!K7 -> 42095.28 | G18: Total Debt / EBITDA | I18: ='Entry Assumptions'!G32 -> 5.5 | K18: ='Debt Schedule'!H46/'Operating Model'!L41 -> 3.3950217 | N18: ▸ | O18: Recurring revenue approaching 40%; driving margin expansion
B19: Senior Notes | C19: ='Entry Assumptions'!G10 -> 3117.405 | D19: Refinance Debt | E19: ='Entry Assumptions'!K8 -> 2124.29 | G19: Net Debt / EBITDA | I19: =('Entry Assumptions'!G9+'Entry Assumptions'!G10-'Historical Financials'!F43)/'Entry Assumptions'!C23 -> 3.8824142 | K19: ='Exit Assumptions'!C17/'Exit Assumptions'!C12 -> -7.7221822 | N19: ▸ | O19: EBITDA margins of 35%+ with operating leverage upside
B20: Sponsor Equity | C20: ='Entry Assumptions'!G16 -> 34359.632 | D20: Fees & Cash | E20: ='Entry Assumptions'!K9+'Entry Assumptions'!K10+'Entry Assumptions'!K11 -> 1570.5471 | G20: Interest Coverage | I20: ='Entry Assumptions'!G34 -> 2.401537 | K20: ='Operating Model'!L41/'Debt Schedule'!H48 -> 3.873595 | N20: ▸ | O20: Capital-light model; cash exceeds debt by exit Year 3
B21: Total Sources | C21: ='Entry Assumptions'!G18 -> 45790.117 | D21: Total Uses | E21: ='Entry Assumptions'!K18 -> 45790.117 | G21: Equity / Total Cap | I21: ='Entry Assumptions'!G16/'Entry Assumptions'!G18 -> 0.75037223 | K21: - | N21: ▸ | O21: Multiple exit paths: strategic sale or secondary IPO
B22: ✓ Balanced | G22: Total Debt (NOK mm) | I22: ='Entry Assumptions'!G9+'Entry Assumptions'!G10 -> 11430.485 | K22: ='Debt Schedule'!H46 -> 11019.811 | N22: ▸ | O22: 19.2% IRR / 2.4x driven by growth + debt paydown
B25: REVENUE & EBITDA (NOK mm) | M25: EBITDA MARGIN EVOLUTION
C41: FY22A | D41: FY23A | E41: FY24A | F41: FY25E | G41: FY26E | H41: FY27E | I41: FY28E | J41: FY29E | N41: FY22A | O41: FY23A | P41: FY24A | Q41: FY25E | R41: FY26E | S41: FY27E | T41: FY28E | U41: FY29E | X41: Year 3 | Y41: Year 4 | Z41: Year 5 | AA41: Year 6 | AB41: Year 7
B42: Revenue | C42: =C11 -> 5628.0849 | D42: =D11 -> 6833.8038 | E42: =E11 -> 6477.4953 | F42: =F11 -> 7124.9261 | G42: =G11 -> 7837.0107 | H42: =H11 -> 8620.2166 | I42: =I11 -> 9309.3968 | J42: =J11 -> 9774.5694 | M42: EBITDA Margin | N42: =C13 -> 0.4377866 | O42: =D13 -> 0.44469515 | P42: =E13 -> 0.47533981 | Q42: =F13 -> 0.36107329 | R42: =G13 -> 0.35207329 | S42: =H13 -> 0.34407329 | T42: =I13 -> 0.33707329 | U42: =J13 -> 0.33207329 | W42: MOIC | X42: =O11 -> 2.2001682 | Y42: =P11 -> 2.3294139 | Z42: =Q11 -> 2.4041595 | AA42: =R11 -> 2.6359923 | AB42: =S11 -> 2.8420708
B43: EBITDA | C43: =C12 -> 2463.9002 | D43: =D12 -> 3038.9594 | E43: =E12 -> 3079.0114 | F43: =F12 -> 2572.6205 | G43: =G12 -> 2759.2021 | H43: =H12 -> 2965.9862 | I43: =I12 -> 3137.949 | J43: =J12 -> 3245.8734 | W43: IRR | X43: =O12 -> 0.30062459 | Y43: =P12 -> 0.23541157 | Z43: =Q12 -> 0.19177057 | AA43: =R12 -> 0.17532333 | AB43: =S12 -> 0.16092719
B45: Source | C45: Amount | E45: Component | F45: Amount | W45: Component | X45: Amount (NOK mm)
B46: Term Loan B | C46: ='Entry Assumptions'!G9 -> 8313.08 | E46: EBITDA Growth | F46: ='Exit Assumptions'!C29 -> 24332.626 | W46: =E46 -> EBITDA Growth | X46: =F46 -> 24332.626
B47: Senior Notes | C47: ='Entry Assumptions'!G10 -> 3117.405 | E47: Multiple Chg | F47: =ABS('Exit Assumptions'!C28) -> 9217.645 | W47: =E47 -> Multiple Chg | X47: =F47 -> 9217.645
B48: Sponsor Equity | C48: ='Entry Assumptions'!G16 -> 34359.632 | E48: Debt Paydown | F48: ='Exit Assumptions'!C30 -> 70855.343 | W48: =E48 -> Debt Paydown | X48: =F48 -> 70855.343

Sheet Entry Assumptions
B2: ENTRY ASSUMPTIONS
B3: AutoStore Holdings Ltd. : Leveraged Buyout Analysis
B5: TRANSACTION OVERVIEW | F5: SOURCES | J5: USES
B6: Transaction Date | C6: 46112 | F6: Source | G6: Amount | H6: % of Total | J6: Use | K6: Amount | L6: % of Total
B7: Target Company | C7: AUTOSTORE HOLDINGS LTD. | F7: Revolving Credit Facility | G7: 0 | H7: =G7/G18 -> 0 | J7: Purchase Equity | K7: =C17 -> 42095.28 | L7: =K7/K18 -> 0.91930929
B8: Target Ticker | C8: AUTO-NO | F8: Term Loan A | G8: 0 | H8: =G8/G18 -> 0 | J8: Refinance Existing Debt | K8: =C19 -> 2124.29 | L8: =K8/K18 -> 0.046391888
B9: Acquirer / Sponsor | F9: Term Loan B | G9: =C23*4 -> 8313.08 | H9: =G9/G18 -> 0.18154747 | J9: Cash to Balance Sheet | K9: =-C20 -> 908.83 | L9: =K9/K18 -> 0.019847733
B10: Transaction Type | C10: LBO | F10: Senior Secured Notes | G10: =C23*1.5 -> 3117.405 | H10: =G10/G18 -> 0.068080302 | J10: Financing Fees | K10: =SUM(G7:G13)*C31 -> 228.6097 | L10: =K10/K18 -> 0.0049925555
F11: Senior Unsecured Notes | G11: =0 -> 0 | H11: =G11/G18 -> 0 | J11: Transaction Fees | K11: =C21*0.01 -> 433.1074 | L11: =K11/K18 -> 0.0094585344
B12: VALUATION & PURCHASE PRICE | F12: Subordinated / Mezzanine | G12: 0 | H12: =G12/G18 -> 0 | J12: Other Fees & Expenses | K12: 0 | L12: =K12/K18 -> 0
B13: Share Price (Offer) | C13: 12 | D13: NOK | F13: Rollover Equity | G13: 0 | H13: =G13/G18 -> 0
B14: Current Share Price | C14: 9.98 | D14: NOK
B15: Acquisition Premium | C15: =IF(C14=0,"",C13/C14-1) -> 0.20240481
B16: Shares Outstanding (Diluted) | C16: 3507.94 | D16: mm | F16: Sponsor Equity | G16: =K18-SUM(G7:G13) -> 34359.632 | H16: =G16/G18 -> 0.75037223
B17: Equity Value | C17: =C13*C16 -> 42095.28 | D17: NOK mm
F18: Total Sources | G18: =SUM(G7:G17) -> 45790.117 | J18: Total Uses | K18: =SUM(K7:K12) -> 45790.117 | L18: =SUM(L7:L12) -> 1
B19: (+) Total Debt | C19: 2124.29 | D19: NOK mm
B20: (-) Cash & Cash Equivalents | C20: -908.83 | D20: NOK mm | F20: DEBT STRUCTURE
B21: Enterprise Value | C21: =SUM(C17:C20) -> 43310.74 | D21: NOK mm | F21: Instrument | G21: Amount | H21: Rate | I21: Type | J21: Maturity(in yrs) | K21: Amort. | L21: Commitment Fee
F22: Revolving Credit Facility | G22: 0 | H22: 0.07 | I22: Floating | J22: 5 | K22: 0
B23: LTM EBITDA | C23: 2078.27 | D23: NOK mm | F23: Term Loan A | G23: 0 | H23: 0 | I23: Floating | J23: n/a | K23: 0 | L23: n/a
B24: Entry EV / EBITDA Multiple | C24: =C21/C23 -> 20.839804 | D24: x | F24: Term Loan B | G24: =G9 -> 8313.08 | H24: =3.66%+3.75% -> 0.0741 | I24: Floating | J24: 7 | K24: 0.01 | L24: n/a
F25: Senior Secured Notes | G25: =G10 -> 3117.405 | H25: 0.08 | I25: Fixed | J25: 8 | K25: 0 | L25: n/a
B26: NOK/USD Exchange Rate | C26: 0.1 | F26: Senior Unsecured Notes | G26: 0 | H26: 0 | I26: Fixed | J26: n/a | K26: 0 | L26: n/a
B27: Enterprise Value (USD) | C27: =C17*C26 -> 4209.528 | D27: $mm | F27: Subordinated / Mezzanine | G27: 0 | H27: 0 | I27: PIK/Cash | J27: n/a | K27: 0 | L27: n/a
B28: Equity Value (USD) | C28: =C21*C26 -> 4331.074 | D28: $mm
F29: Total Debt | G29: =SUM(G22:G27) -> 11430.485
B30: TRANSACTION FEES & EXPENSES
B31: Financing Fees (% of Debt) | C31: 0.02 | F31: KEY CREDIT METRICS (Entry)
B32: Financing Fees ($) | C32: =(G9+G10)*C26*C31 -> 22.86097 | D32: $mm | F32: Total Debt / EBITDA | G32: =G29/C23 -> 5.5
F33: Senior Debt / EBITDA | G33: =G24/C23 -> 4
B34: M&A Advisory Fee | C34: =C21*C26*0.5% -> 21.65537 | D34: $mm | F34: EBITDA / Interest Expense | G34: =C23/(G24*H24+G25*H25) -> 2.401537
B35: Legal & Accounting | C35: =C21*0.4%*C26 -> 17.324296 | D35: $mm | F35: Equity / Total Capitalization | G35: =G16/(G16+G29) -> 0.75037223
B36: Other Transaction Costs | C36: =C26*C21*0.1% -> 4.331074 | D36: $mm | F36: Debt / Total Capitalization | G36: =G29/(G29+G16) -> 0.24962777
B37: Total Transaction Fees | C37: =SUM(C32:C36) -> 66.17171 | D37: $mm
B40: COLOR LEGEND
B41: ● Blue | C41: Hardcoded Input
B42: ● Black | C42: Calculated Formula
B43: ● Green | C43: Link to Other Sheet

Sheet Historical Financials
B2: HISTORICAL FINANCIALS
B3: AutoStore Holdings Ltd. — Audited Historical Data
C5: Units | D5: FY2022A | E5: FY2023A | F5: FY2024A
B7: INCOME STATEMENT
B8: Systems Revenue (Hardware) | C8: NOK mm
B9: Software & Services Revenue | C9: NOK mm
B10: Total Revenue | C10: NOK mm | D10: 5628.0849 | E10: 6833.8038 | F10: 6477.4953
B11: Revenue Growth % | C11: %
B13: Cost of Goods Sold | C13: NOK mm | D13: -2714.9 | E13: -3030.6 | F13: -2617.7
B14: Gross Profit | C14: NOK mm | D14: =D10+D13 -> 2913.1849 | E14: =E10+E13 -> 3803.2038 | F14: =F10+F13 -> 3859.7953
B15: Gross Margin % | C15: % | D15: =D14/D10 -> 0.51761566 | E15: =E14/E10 -> 0.5565281 | F15: =F14/F10 -> 0.59587775
B17: D&A Expenses | C17: NOK mm | D17: -555.11196 | E17: -656.42571 | F17: -675.38886
B18: SG&A Expenses | C18: NOK mm | D18: -398.29524 | E18: -754.731 | F18: -768.95387
B19: Other Operating Expenses | C19: NOK mm | D19: -50.98949 | E19: -9.51342 | F19: -11.83006
B20: Total Operating Expenses | C20: NOK mm | D20: =SUM(D17:D19) -> -1004.3967 | E20: =SUM(E17:E19) -> -1420.6701 | F20: =SUM(F17:F19) -> -1456.1728
B21: OpEx % of Revenue | C21: % | D21: =D20/D10 -> -0.17846154 | E21: =E20/E10 -> -0.20788863 | F21: =F20/F10 -> -0.22480491
B23: EBITDA | C23: NOK mm | D23: =D14+D18+D19 -> 2463.9002 | E23: =E14+E18+E19 -> 3038.9594 | F23: =F14+F18+F19 -> 3079.0114
B24: EBITDA Margin % | C24: % | D24: =D23/D10 -> 0.4377866 | E24: =E23/E10 -> 0.44469515 | F24: =F23/F10 -> 0.47533981
B26: Depreciation & Amortization | C26: NOK mm | D26: =D17 -> -555.11196 | E26: =E17 -> -656.42571 | F26: =F17 -> -675.38886
B27: EBIT | C27: NOK mm | D27: =D23+D26 -> 1908.7882 | E27: =E23+E26 -> 2382.5337 | F27: =F23+F26 -> 2403.6226
B28: EBIT Margin % | C28: % | D28: =D27/D10 -> 0.33915412 | E28: =E27/E10 -> 0.34863947 | F28: =F27/F10 -> 0.37107283
B30: Interest Expense | C30: NOK mm | D30: -219.351 | E30: -455.58692 | F30: -528.05084
B31: Unsual Expense | C31: NOK mm | D31: -290.54387 | E31: -2526.3405 | F31: -11.83006
B32: Non operating Income (Expense) | C32: NOK mm | D32: -175.09598 | E32: 109.9328 | F32: 30.112876
B33: EBT | C33: NOK mm | D33: =D27+SUM(D30:D32) -> 1223.7974 | E33: =E27+SUM(E30:E32) -> -489.46088 | F33: =F27+SUM(F30:F32) -> 1893.8545
B35: Income Tax Expense | C35: NOK mm | D35: -264.56809 | E35: =144.815333 -> 144.81533 | F35: -424.80669
B36: Effective Tax Rate | C36: % | D36: =-D35/D33 -> 0.21618619 | E36: =-E35/E33 -> 0.29586702 | F36: =-F35/F33 -> 0.22430798
B38: Net Income | C38: NOK mm | D38: =D33+D35 -> 959.22926 | E38: =E33+E35 -> -344.64555 | F38: =F33+F35 -> 1469.0478
B39: Net Income Margin % | C39: %
B41: BALANCE SHEET
B42: ASSETS
B43: Cash & Cash Equivalents | C43: NOK mm | D43: 1721.95 | E43: 2572.44 | F43: 3361.78
B44: Accounts Receivable | C44: NOK mm | D44: 886.59 | E44: 1124.24 | F44: 1541.19
B45: Inventory | C45: NOK mm | D45: 822.56 | E45: 841.91 | F45: 991.5
B46: Prepaid & Other Current Assets | C46: NOK mm | D46: 6.9 | E46: 0 | F46: 23.85
B47: Total Current Assets | C47: NOK mm | D47: =SUM(D43:D46) -> 3438 | E47: =SUM(E43:E46) -> 4538.59 | F47: =SUM(F43:F46) -> 5918.32
B49: Property, Plant & Equipment (Net) | C49: NOK mm | D49: 478.76 | E49: 822.61 | F49: 1071
B50: Goodwill | C50: NOK mm | D50: 10800.64 | E50: 10784.34 | F50: 10823.55
B51: Other Intangible Assets | C51: NOK mm | D51: 5167.83 | E51: 4996.6 | F51: 4957.48
B52: Other Long-Term Assets | C52: NOK mm | D52: 30.54 | E52: 77.18 | F52: 86.32
...

Sheet Operating Model
B2: OPERATING MODEL
B3: AutoStore Holdings Ltd. — Driver-Based Projections
C5: Units | D5: FY2022A | E5: FY2023A | F5: FY2024A | H5: FY2025E | I5: FY2026E | J5: FY2027E | K5: FY2028E | L5: FY2029E
B7: REVENUE DRIVERS
B8: Systems Revenue (Hardware) | C8: NOK mm | D8: =D17*D13 -> 5622.4719 | E8: =E17*E13 -> 6812.6007 | F8: =F17*F13 -> 6471.0225 | H8: =F8*(1+H9) -> 7118.1248 | I8: =H8*(1+I9) -> 7829.9372 | J8: =I8*(1+J9) -> 8612.9309 | K8: =J8*(1+K9) -> 9301.9654 | L8: =K8*(1+L9) -> 9767.0637
B9: % Growth | C9: % | E9: =E8/D8-1 -> 0.21167359 | F9: =F8/E8-1 -> -0.050139178 | H9: =10% -> 0.1 | I9: =10% -> 0.1 | J9: =10% -> 0.1 | K9: =8% -> 0.08 | L9: 0.05
B10: Software & Services Revenue | C10: NOK mm | D10: =D13*D18 -> 5.6281 | E10: =E13*E18 -> 20.4993 | F10: =F13*F18 -> 6.4775 | H10: =F10*(1+H11) -> 6.801375 | I10: =H10*(1+I11) -> 7.07343 | J10: =I10*(1+J11) -> 7.2856329 | K10: =J10*(1+K11) -> 7.4313456 | L10: =K10*(1+L11) -> 7.505659
B11: % Growth | C11: % | E11: =E10/D10-1 -> 2.6423127 | F11: =F10/E10-1 -> -0.6840136 | H11: =5% -> 0.05 | I11: 0.04 | J11: =I11-1% -> 0.03 | K11: =J11-1% -> 0.02 | L11: =K11-1% -> 0.01
B13: Total Revenue | C13: NOK mm | D13: =5628.1 -> 5628.1 | E13: =6833.1 -> 6833.1 | F13: 6477.5 | H13: =H8+H10 -> 7124.9261 | I13: =I8+I10 -> 7837.0107 | J13: =J8+J10 -> 8620.2166 | K13: =K8+K10 -> 9309.3968 | L13: =L8+L10 -> 9774.5694
B14: % Growth | C14: % | E14: =E13/D13-1 -> 0.21410423 | F14: =F13/E13-1 -> -0.052040801 | H14: =H13/F13-1 -> 0.09995 | I14: =I13/H13-1 -> 0.099942725 | J14: =J13/I13-1 -> 0.09993682 | K14: =K13/J13-1 -> 0.079949289 | L14: =L13/K13-1 -> 0.049968069
B16: Revenue Mix:
B17: Systems % | C17: % | D17: =99.9% -> 0.999 | E17: =99.7% -> 0.997 | F17: =99.9% -> 0.999 | H17: =H8/H13 -> 0.99904541 | I17: =I8/I13 -> 0.99909743 | J17: =J8/J13 -> 0.99915482 | K17: =K8/K13 -> 0.99920174 | L17: =L8/L13 -> 0.99923212
B18: Software & Services % | C18: % | D18: =1-D17 -> 0.001 | E18: =1-E17 -> 0.003 | F18: =1-F17 -> 0.001 | H18: =H10/H13 -> 0.00095458884 | I18: =I10/I13 -> 0.00090256736 | J18: =J10/J13 -> 0.0008451798 | K18: =K10/K13 -> 0.00079826285 | L18: =L10/L13 -> 0.00076787618
B20: GROSS PROFIT
B21: Cost of Goods Sold (COGS) | C21: NOK mm | D21: ='Historical Financials'!D13 -> -2714.9 | E21: ='Historical Financials'!E13 -> -3030.6 | F21: ='Historical Financials'!F13 -> -2617.7 | H21: =H13*H22 -> -2914.9637 | I21: =I13*I22 -> -3245.4782 | J21: =J13*J22 -> -3612.9221 | K21: =K13*K22 -> -3948.3196 | L21: =L13*L22 -> -4174.9332
B22: COGS % of Revenue | C22: % | D22: =D21/D13 -> -0.48238304 | E22: =E21/E13 -> -0.44351758 | F22: =F21/F13 -> -0.40412196 | H22: =F22-0.5% -> -0.40912196 | I22: =H22-0.5% -> -0.41412196 | J22: =I22-0.5% -> -0.41912196 | K22: =J22-0.5% -> -0.42412196 | L22: =K22-0.3% -> -0.42712196
B24: Gross Profit | C24: NOK mm | D24: =D13+D21 -> 2913.2 | E24: =E13+E21 -> 3802.5 | F24: =F13+F21 -> 3859.8 | H24: =H13+H21 -> 4209.9624 | I24: =I13+I21 -> 4591.5324 | J24: =J13+J21 -> 5007.2945 | K24: =K13+K21 -> 5361.0772 | L24: =L13+L21 -> 5599.6361
B25: Gross Margin % | C25: % | D25: =D24/D13 -> 0.51761696 | E25: =E24/E13 -> 0.55648242 | F25: =F24/F13 -> 0.59587804 | H25: =H24/H13 -> 0.59087804 | I25: =I24/I13 -> 0.58587804 | J25: =J24/J13 -> 0.58087804 | K25: =K24/K13 -> 0.57587804 | L25: =L24/L13 -> 0.57287804
B28: OPERATING EXPENSES
B29: Research & Development | C29: NOK mm | D29: ='Historical Financials'!D17 -> -555.11196 | E29: ='Historical Financials'!E17 -> -656.42571 | F29: ='Historical Financials'!F17 -> -675.38886 | H29: =H13*H30 -> -764.26875 | I29: =I13*I30 -> -856.32587 | J29: =J13*J30 -> -959.14479 | K29: =K13*K30 -> -1045.1371 | L29: =L13*L30 -> -1107.1352
B30: R&D % of Revenue | C30: % | D30: =D29/D13 -> -0.098632214 | E30: =E29/E13 -> -0.096065579 | F30: =F29/F13 -> -0.1042669 | H30: =F30-0.3% -> -0.1072669 | I30: =H30-0.2% -> -0.1092669 | J30: =I30-0.2% -> -0.1112669 | K30: =J30-0.1% -> -0.1122669 | L30: =K30-0.1% -> -0.1132669
B31: Sales & Marketing | C31: NOK mm | D31: ='Historical Financials'!D18 -> -398.29524 | E31: ='Historical Financials'!E18 -> -754.731 | F31: ='Historical Financials'!F18 -> -768.95387 | H31: =H13*H32 -> -860.06066 | I31: =I13*I32 -> -961.69149 | J31: =J13*J32 -> -1066.4201 | K31: =K13*K32 -> -1160.989 | L31: =L13*L32 -> -1228.776
B32: S&M % of Revenue | C32: % | D32: =D31/D13 -> -0.070769041 | E32: =E31/E13 -> -0.11045221 | F32: =F31/F13 -> -0.11871152 | H32: =F32-0.2% -> -0.12071152 | I32: =H32-0.2% -> -0.12271152 | J32: =I32-0.1% -> -0.12371152 | K32: =J32-0.1% -> -0.12471152 | L32: =K32-0.1% -> -0.12571152
B33: General & Administrative | C33: NOK mm | D33: ='Historical Financials'!D19 -> -50.98949 | E33: ='Historical Financials'!E19 -> -9.51342 | F33: ='Historical Financials'!F19 -> -11.83006 | H33: =H13*H34 -> -13.012474 | I33: =I13*I34 -> -14.312977 | J33: =J13*J34 -> -15.74337 | K33: =K13*K34 -> -17.002041 | L33: =L13*L34 -> -17.8516
B34: G&A % of Revenue | C34: % | D34: =D33/D13 -> -0.0090598053 | E34: =E33/E13 -> -0.0013922553 | F34: =F33/F13 -> -0.0018263311 | H34: =F34 -> -0.0018263311 | I34: =H34 -> -0.0018263311 | J34: =I34 -> -0.0018263311 | K34: =J34 -> -0.0018263311 | L34: =K34 -> -0.0018263311
B36: Total Operating Expenses | C36: NOK mm | D36: =D29+D31+D33 -> -1004.3967 | E36: =E29+E31+E33 -> -1420.6701 | F36: =F29+F31+F33 -> -1456.1728 | H36: =H29+H31+H33 -> -1637.3419 | I36: =I29+I31+I33 -> -1832.3303 | J36: =J29+J31+J33 -> -2041.3083 | K36: =K29+K31+K33 -> -2223.1282 | L36: =L29+L31+L33 -> -2353.7628
B37: OpEx % of Revenue | C37: % | D37: =D36/D13 -> -0.17846106 | E37: =E36/E13 -> -0.20791005 | F37: =F36/F13 -> -0.22480475 | H37: =H36/H13 -> -0.22980475 | I37: =I36/I13 -> -0.23380475 | J37: =J36/J13 -> -0.23680475 | K37: =K36/K13 -> -0.23880475 | L37: =L36/L13 -> -0.24080475
B40: EBITDA
B41: EBITDA | C41: NOK mm | D41: =D24+D36 -> 1908.8033 | E41: =E24+E36 -> 2381.8299 | F41: =F24+F36 -> 2403.6272 | H41: =H24+H36 -> 2572.6205 | I41: =I24+I36 -> 2759.2021 | J41: =J24+J36 -> 2965.9862 | K41: =K24+K36 -> 3137.949 | L41: =L24+L36 -> 3245.8734
B42: EBITDA Margin % | C42: % | D42: =D41/D13 -> 0.3391559 | E42: =E41/E13 -> 0.34857237 | F42: =F41/F13 -> 0.37107329 | H42: =H41/H13 -> 0.36107329 | I42: =I41/I13 -> 0.35207329 | J42: =J41/J13 -> 0.34407329 | K42: =K41/K13 -> 0.33707329 | L42: =L41/L13 -> 0.33207329
B44: EBITDA Growth % | C44: % | D44: ="n/a" -> n/a | E44: =E41/D41-1 -> 0.24781315 | F44: =F41/E41-1 -> 0.0091515113 | H44: =H41/F41-1 -> 0.070307607 | I44: =I41/H41-1 -> 0.072525896 | J44: =J41/I41-1 -> 0.07494346 | K44: =K41/J41-1 -> 0.057978258 | L44: =L41/K41-1 -> 0.034393295
B47: WORKING CAPITAL ASSUMPTIONS
B48: Days Sales Outstanding (DSO) | C48: days | D48: ='Historical Financials'!D104 -> 57.498306 | E48: ='Historical Financials'!E104 -> 60.046734 | F48: ='Historical Financials'!F104 -> 86.844424 | H48: =F48 -> 86.844424 | I48: =H48 -> 86.844424 | J48: =I48 -> 86.844424 | K48: =J48 -> 86.844424 | L48: =K48 -> 86.844424
B49: Days Inventory Outstanding (DIO) | C49: days | D49: ='Historical Financials'!D105 -> 110.58765 | E49: ='Historical Financials'!E105 -> 101.39812 | F49: ='Historical Financials'!F105 -> 138.25018 | H49: =F49-5 -> 133.25018 | I49: =H49-3 -> 130.25018 | J49: =I49-2 -> 128.25018 | K49: =J49-2 -> 126.25018 | L49: =K49-1 -> 125.25018
B50: Days Payables Outstanding (DPO) | C50: days | D50: ='Historical Financials'!D106 -> 64.89576 | E50: ='Historical Financials'!E106 -> 53.573319 | F50: ='Historical Financials'!F106 -> 65.244604 | H50: =F50 -> 65.244604 | I50: =H50 -> 65.244604 | J50: =I50 -> 65.244604 | K50: =J50 -> 65.244604 | L50: =K50 -> 65.244604
B52: Accounts Receivable | C52: NOK mm | D52: ='Historical Financials'!D44 -> 886.59 | E52: ='Historical Financials'!E44 -> 1124.24 | F52: ='Historical Financials'!F44 -> 1541.19 | H52: =H48*H13/365 -> 1695.2332 | I52: =I48*I13/365 -> 1864.6594 | J52: =J48*J13/365 -> 2051.0075 | K52: =K48*K13/365 -> 2214.9841 | L52: =L48*L13/365 -> 2325.6626
B53: Inventory | C53: NOK mm | D53: ='Historical Financials'!D45 -> 822.56 | E53: ='Historical Financials'!E45 -> 841.91 | F53: ='Historical Financials'!F45 -> 991.5 | H53: =-H49*H21/365 -> 1064.1629 | I53: =-I49*I21/365 -> 1158.1483 | J53: =-J49*J21/365 -> 1269.4737 | K53: =-K49*K21/365 -> 1365.6879 | L53: =-L49*L21/365 -> 1432.6333
B54: Accounts Payable | C54: NOK mm | D54: ='Historical Financials'!D56 -> 482.7 | E54: ='Historical Financials'!E56 -> 444.82 | F54: ='Historical Financials'!F56 -> 467.92 | H54: =-H50*H21/365 -> 521.05659 | I54: =-I50*I21/365 -> 580.13683 | J54: =-J50*J21/365 -> 645.81827 | K54: =-K50*K21/365 -> 705.77137 | L54: =-L50*L21/365 -> 746.27908
B56: Net Working Capital | C56: NOK mm | D56: =D52+D53-D54 -> 1226.45 | E56: =E52+E53-E54 -> 1521.33 | F56: =F52+F53-F54 -> 2064.77 | H56: =H52+H53-H54 -> 2238.3394 | I56: =I52+I53-I54 -> 2442.6708 | J56: =J52+J53-J54 -> 2674.663 | K56: =K52+K53-K54 -> 2874.9006 | L56: =L52+L53-L54 -> 3012.0168
B57: NWC % of Revenue | C57: % | D57: =D56/D13 -> 0.21791546 | E57: =E56/E13 -> 0.22264126 | F57: =F56/F13 -> 0.31876032 | H57: =H56/H13 -> 0.31415616 | I57: =I56/I13 -> 0.311684 | J57: =J56/J13 -> 0.31027793 | K57: =K56/K13 -> 0.30881707 | L57: =L56/L13 -> 0.30814828
...

Sheet 3-Statement Model (Forecast)
B2: 3-STATEMENT MODEL
B3: AutoStore Holdings Ltd. — Integrated Financial Statements
C5: Entry | D5: Year 1 | E5: Year 2 | F5: Year 3 | G5: Year 4 | H5: Year 5
B7: INCOME STATEMENT
B8: Revenue | D8: ='Operating Model'!H13 -> 7124.9261 | E8: ='Operating Model'!I13 -> 7837.0107 | F8: ='Operating Model'!J13 -> 8620.2166 | G8: ='Operating Model'!K13 -> 9309.3968 | H8: ='Operating Model'!L13 -> 9774.5694
B9: Cost of Goods Sold | D9: ='Operating Model'!H21 -> -2914.9637 | E9: ='Operating Model'!I21 -> -3245.4782 | F9: ='Operating Model'!J21 -> -3612.9221 | G9: ='Operating Model'!K21 -> -3948.3196 | H9: ='Operating Model'!L21 -> -4174.9332
B10: Gross Profit | D10: =D8+D9 -> 4209.9624 | E10: =E8+E9 -> 4591.5324 | F10: =F8+F9 -> 5007.2945 | G10: =G8+G9 -> 5361.0772 | H10: =H8+H9 -> 5599.6361
B11: Gross Margin % | D11: =D10/D8 -> 0.59087804 | E11: =E10/E8 -> 0.58587804 | F11: =F10/F8 -> 0.58087804 | G11: =G10/G8 -> 0.57587804 | H11: =H10/H8 -> 0.57287804
B13: Operating Expenses | D13: ='Operating Model'!H36 -> -1637.3419 | E13: ='Operating Model'!I36 -> -1832.3303 | F13: ='Operating Model'!J36 -> -2041.3083 | G13: ='Operating Model'!K36 -> -2223.1282 | H13: ='Operating Model'!L36 -> -2353.7628
B14: EBITDA | D14: =D10+D13 -> 2572.6205 | E14: =E10+E13 -> 2759.2021 | F14: =F10+F13 -> 2965.9862 | G14: =G10+G13 -> 3137.949 | H14: =H10+H13 -> 3245.8734
B15: EBITDA Margin % | D15: =D14/D8 -> 0.36107329 | E15: =E14/E8 -> 0.35207329 | F15: =F14/F8 -> 0.34407329 | G15: =G14/G8 -> 0.33707329 | H15: =H14/H8 -> 0.33207329
B17: Depreciation & Amortization | D17: ='Operating Model'!H70 -> 356.24631 | E17: ='Operating Model'!I70 -> 391.85053 | F17: ='Operating Model'!J70 -> 387.90975 | G17: ='Operating Model'!K70 -> 372.37587 | H17: ='Operating Model'!L70 -> 342.10993
B18: EBIT | D18: =D14-D17 -> 2216.3742 | E18: =E14-E17 -> 2367.3516 | F18: =F14-F17 -> 2578.0765 | G18: =G14-G17 -> 2765.5731 | H18: =H14-H17 -> 2903.7634
B19: EBIT Margin % | D19: =D18/D8 -> 0.31107329 | E19: =E18/E8 -> 0.30207329 | F19: =F18/F8 -> 0.29907329 | G19: =G18/G8 -> 0.29707329 | H19: =H18/H8 -> 0.29707329
B21: Interest Expense | D21: ='Debt Schedule'!D48 -> 862.31163 | E21: ='Debt Schedule'!E48 -> 856.15164 | F21: ='Debt Schedule'!F48 -> 850.02245 | G21: ='Debt Schedule'!G48 -> 843.95485 | H21: ='Debt Schedule'!H48 -> 837.94855
B22: Interest Income | D22: 0 | E22: 0 | F22: 0 | G22: 0 | H22: 0
B23: EBT (Earnings Before Tax) | D23: =D18-D21+D22 -> 1354.0626 | E23: =E18-E21+E22 -> 1511.1999 | F23: =F18-F21+F22 -> 1728.0541 | G23: =G18-G21+G22 -> 1921.6182 | H23: =H18-H21+H22 -> 2065.8149
B25: Income Tax Expense | D25: =-D23*D26 -> -297.89376 | E25: =-E23*E26 -> -332.46398 | F25: =-F23*F26 -> -380.17189 | G25: =-G23*G26 -> -422.75601 | H25: =-H23*H26 -> -454.47927
B26: Effective Tax Rate | D26: ='Operating Model'!H75 -> 0.22 | E26: ='Operating Model'!I75 -> 0.22 | F26: ='Operating Model'!J75 -> 0.22 | G26: ='Operating Model'!K75 -> 0.22 | H26: ='Operating Model'!L75 -> 0.22
B28: Net Income | D28: =D23+D25 -> 1056.1688 | E28: =E23+E25 -> 1178.7359 | F28: =F23+F25 -> 1347.8822 | G28: =G23+G25 -> 1498.8622 | H28: =H23+H25 -> 1611.3356
B29: Net Income Margin % | D29: =D28/D8 -> 0.14823575 | E29: =E28/E8 -> 0.15040632 | F29: =F28/F8 -> 0.15636291 | G29: =G28/G8 -> 0.1610053 | H29: =H28/H8 -> 0.16484978
B31: BALANCE SHEET
B32: ASSETS
B33: Cash & Cash Equivalents | C33: 3361.78 | D33: =D62+D56-(D34+D35+D36+D39+D40+D41+D42) -> 31375.295 | E33: =E62+E56-(E34+E35+E36+E39+E40+E41+E42) -> 32305.79 | F33: =F62+F56-(F34+F35+F36+F39+F40+F41+F42) -> 33391.141 | G33: =G62+G56-(G34+G35+G36+G39+G40+G41+G42) -> 34655.178 | H33: =H62+H56-(H34+H35+H36+H39+H40+H41+H42) -> 36085.036
B34: Accounts Receivable | C34: 1541.19 | D34: ='Operating Model'!H52 -> 1695.2332 | E34: ='Operating Model'!I52 -> 1864.6594 | F34: ='Operating Model'!J52 -> 2051.0075 | G34: ='Operating Model'!K52 -> 2214.9841 | H34: ='Operating Model'!L52 -> 2325.6626
B35: Inventory | C35: 991.5 | D35: ='Operating Model'!H53 -> 1064.1629 | E35: ='Operating Model'!I53 -> 1158.1483 | F35: ='Operating Model'!J53 -> 1269.4737 | G35: ='Operating Model'!K53 -> 1365.6879 | H35: ='Operating Model'!L53 -> 1432.6333
B36: Prepaid Expenses & Other CA | C36: 23.85 | D36: =C36 -> 23.85 | E36: =D36 -> 23.85 | F36: =E36 -> 23.85 | G36: =F36 -> 23.85 | H36: =G36 -> 23.85
B37: Total Current Assets | C37: =SUM(C33:C36) -> 5918.32 | D37: =SUM(D33:D36) -> 34158.541 | E37: =SUM(E33:E36) -> 35352.448 | F37: =SUM(F33:F36) -> 36735.472 | G37: =SUM(G33:G36) -> 38259.7 | H37: =SUM(H33:H36) -> 39867.182
B39: Property, Plant & Equipment | C39: 1071 | D39: =C39+'Operating Model'!H67-'Operating Model'!H70 -> 1106.6246 | E39: =D39+'Operating Model'!I67-'Operating Model'!I70 -> 1106.6246 | F39: =E39+'Operating Model'!J67-'Operating Model'!J70 -> 1106.6246 | G39: =F39+'Operating Model'!K67-'Operating Model'!K70 -> 1106.6246 | H39: =G39+'Operating Model'!L67-'Operating Model'!L70 -> 1106.6246
B40: Goodwill | C40: 10823.55 | D40: =C40 -> 10823.55 | E40: =D40 -> 10823.55 | F40: =E40 -> 10823.55 | G40: =F40 -> 10823.55 | H40: =G40 -> 10823.55
B41: Other Intangibles | C41: 4957.48 | D41: =C41 -> 4957.48 | E41: =D41 -> 4957.48 | F41: =E41 -> 4957.48 | G41: =F41 -> 4957.48 | H41: =G41 -> 4957.48
B42: Other Long-Term Assets | C42: 86.32 | D42: =C42 -> 86.32 | E42: =D42 -> 86.32 | F42: =E42 -> 86.32 | G42: =F42 -> 86.32 | H42: =G42 -> 86.32
B43: Total Assets | C43: =C37+C39+C40+C41+C42 -> 22856.67 | D43: =D37+D39+D40+D41+D42 -> 51132.516 | E43: =E37+E39+E40+E41+E42 -> 52326.422 | F43: =F37+F39+F40+F41+F42 -> 53709.447 | G43: =G37+G39+G40+G41+G42 -> 55233.674 | H43: =H37+H39+H40+H41+H42 -> 56841.157
B45: LIABILITIES
B46: Accounts Payable | C46: 467.92 | D46: ='Operating Model'!H54 -> 521.05659 | E46: ='Operating Model'!I54 -> 580.13683 | F46: ='Operating Model'!J54 -> 645.81827 | G46: ='Operating Model'!K54 -> 705.77137 | H46: ='Operating Model'!L54 -> 746.27908
B47: Accrued Expenses | C47: 88.59 | D47: =C47*(1+0.05) -> 93.0195 | E47: =D47*(1+0.05) -> 97.670475 | F47: =E47*(1+0.05) -> 102.554 | G47: =F47*(1+0.05) -> 107.6817 | H47: =G47*(1+0.05) -> 113.06578
B48: Deferred Revenue | C48: 961.97 | D48: =C48 -> 961.97 | E48: =D48 -> 961.97 | F48: =E48 -> 961.97 | G48: =F48 -> 961.97 | H48: =G48 -> 961.97
B49: Current Portion of Debt | C49: 132.88 | D49: ='Debt Schedule'!D49 -> 83.1308 | E49: ='Debt Schedule'!E49 -> 83.1308 | F49: ='Debt Schedule'!F49 -> 82.299492 | G49: ='Debt Schedule'!G49 -> 81.468184 | H49: ='Debt Schedule'!H49 -> 80.645189
B50: Other Current Liabilities | C50: 538.34 | D50: =-D25 -> 297.89376 | E50: =-E25 -> 332.46398 | F50: =-F25 -> 380.17189 | G50: =-G25 -> 422.75601 | H50: =-H25 -> 454.47927
B51: Total Current Liabilities | C51: =SUM(C46:C50) -> 2189.7 | D51: =SUM(D46:D50) -> 1957.0707 | E51: =SUM(E46:E50) -> 2055.3721 | F51: =SUM(F46:F50) -> 2172.8137 | G51: =SUM(G46:G50) -> 2279.6473 | H51: =SUM(H46:H50) -> 2356.4393
...

Sheet Debt Schedule
B2: DEBT SCHEDULE
B3: AutoStore Holdings Ltd. — Debt Amortization & Interest
C5: Entry | D5: Year 1 | E5: Year 2 | F5: Year 3 | G5: Year 4 | H5: Year 5 | I5: Exit
B7: REVOLVING CREDIT FACILITY
B8: Revolver Capacity
B9: Beginning Balance
B10: Drawdown / (Paydown)
B11: Ending Balance
B13: Interest Rate (SOFR + Spread)
B14: Interest Expense
B15: Commitment Fee Rate
B16: Commitment Fee
B18: TERM LOAN A
B19: Beginning Balance
B20: Mandatory Amortization
... B27: TERM LOAN B
B28: Beginning Balance | C28: ='Entry Assumptions'!G24 -> 8313.08 | D28: =C31 -> 8313.08 | E28: =D31 -> 8229.9492 | F28: =E31 -> 8146.8184 | G28: =F31 -> 8064.5189 | H28: =G31 -> 7983.0507
B29: Mandatory Amortization (1% p.a.) | C29: 0 | D29: =-C28*0.01 -> -83.1308 | E29: =-D28*0.01 -> -83.1308 | F29: =-E28*0.01 -> -82.299492 | G29: =-F28*0.01 -> -81.468184 | H29: =-G28*0.01 -> -80.645189
B30: Optional Prepayment | C30: 0 | D30: =0 -> 0 | E30: =0 -> 0 | F30: =0 -> 0 | G30: =0 -> 0 | H30: =0 -> 0
B31: Ending Balance | C31: =C28 -> 8313.08 | D31: =D28+D29+D30 -> 8229.9492 | E31: =E28+E29+E30 -> 8146.8184 | F31: =F28+F29+F30 -> 8064.5189 | G31: =G28+G29+G30 -> 7983.0507 | H31: =H28+H29+H30 -> 7902.4055
B33: Interest Rate (SOFR + Spread) | C33: ='Entry Assumptions'!H24 -> 0.0741 | D33: =C33 -> 0.0741 | E33: =D33 -> 0.0741 | F33: =E33 -> 0.0741 | G33: =F33 -> 0.0741 | H33: =G33 -> 0.0741
B34: Interest Expense | C34: 0 | D34: =(C31+D31)/2*D33 -> 612.91923 | E34: =(D31+E31)/2*E33 -> 606.75924 | F34: =(E31+F31)/2*F33 -> 600.63005 | G34: =(F31+G31)/2*G33 -> 594.56245 | H34: =(G31+H31)/2*H33 -> 588.55615
B36: SENIOR SECURED NOTES
B37: Beginning Balance | C37: ='Entry Assumptions'!G25 -> 3117.405 | D37: =C39 -> 3117.405 | E37: =D39 -> 3117.405 | F37: =E39 -> 3117.405 | G37: =F39 -> 3117.405 | H37: =G39 -> 3117.405
B38: Redemption | C38: 0 | D38: 0 | E38: 0 | F38: 0 | G38: 0 | H38: 0
B39: Ending Balance | C39: =C37 -> 3117.405 | D39: =D37+D38 -> 3117.405 | E39: =E37+E38 -> 3117.405 | F39: =F37+F38 -> 3117.405 | G39: =G37+G38 -> 3117.405 | H39: =H37+H38 -> 3117.405
B41: Coupon Rate | C41: ='Entry Assumptions'!H25 -> 0.08 | D41: =C41 -> 0.08 | E41: =D41 -> 0.08 | F41: =E41 -> 0.08 | G41: =F41 -> 0.08 | H41: =G41 -> 0.08
B42: Interest Expense | C42: 0 | D42: =(C39+D39)/2*D41 -> 249.3924 | E42: =(D39+E39)/2*E41 -> 249.3924 | F42: =(E39+F39)/2*F41 -> 249.3924 | G42: =(F39+G39)/2*G41 -> 249.3924 | H42: =(G39+H39)/2*H41 -> 249.3924
B44: TOTAL DEBT SUMMARY
B45: Total Beginning Debt | C45: =C28+C37 -> 11430.485 | D45: =D28+D37 -> 11430.485 | E45: =E28+E37 -> 11347.354 | F45: =F28+F37 -> 11264.223 | G45: =G28+G37 -> 11181.924 | H45: =H28+H37 -> 11100.456
B46: Total Ending Debt | C46: =C31+C39 -> 11430.485 | D46: =D31+D39 -> 11347.354 | E46: =E31+E39 -> 11264.223 | F46: =F31+F39 -> 11181.924 | G46: =G31+G39 -> 11100.456 | H46: =H31+H39 -> 11019.811
B48: Total Interest Expense | D48: =D34+D42 -> 862.31163 | E48: =E34+E42 -> 856.15164 | F48: =F34+F42 -> 850.02245 | G48: =G34+G42 -> 843.95485 | H48: =H34+H42 -> 837.94855
B49: Total Mandatory Amortization | D49: =-D29 -> 83.1308 | E49: =-E29 -> 83.1308 | F49: =-F29 -> 82.299492 | G49: =-G29 -> 81.468184 | H49: =-H29 -> 80.645189
B50: Total Cash Available for Prepayment
B51: Total Optional Prepayment
B53: CREDIT METRICS
B54: EBITDA | D54: ='Operating Model'!H41 -> 2572.6205 | E54: ='Operating Model'!I41 -> 2759.2021 | F54: ='Operating Model'!J41 -> 2965.9862 | G54: ='Operating Model'!K41 -> 3137.949 | H54: ='Operating Model'!L41 -> 3245.8734
B55: Total Debt / EBITDA | D55: =D46/D54 -> 4.4108154 | E55: =E46/E54 -> 4.0824206 | F55: =F46/F54 -> 3.7700525 | G55: =G46/G54 -> 3.5374877 | H55: =H46/H54 -> 3.3950217
B56: Senior Debt / EBITDA | D56: =D31/D54 -> 3.199053 | E56: =E31/E54 -> 2.9525994 | F56: =F31/F54 -> 2.7190008 | G56: =G31/G54 -> 2.5440346 | H56: =H31/H54 -> 2.4346007
B57: EBITDA / Interest Expense | D57: =D54/D48 -> 2.9834 | E57: =E54/E48 -> 3.222796 | F57: =F54/F48 -> 3.4893034 | G57: =G54/G48 -> 3.7181479 | H57: =H54/H48 -> 3.873595
...

Sheet Exit Assumptions
B2: EXIT ASSUMPTIONS
B3: AutoStore Holdings Ltd. — Exit Valuation & Proceeds
B6: EXIT TIMING | F6: EXIT TRANSACTION COSTS
B7: Investment Date | C7: ='Entry Assumptions'!C6 -> 46112 | F7: M&A Advisory Fee | G7: 0.01 | H7: %
B8: Exit Date | C8: 47938 | F8: Legal & Other Costs | G8: 50 | H8: NOK mm
B9: Holding Period (Years) | C9: 5
F10: Total Exit Costs | G10: =C21*G7+G8 -> 884.90946 | H10: NOK mm
B11: EXIT VALUATION
B12: Exit Year EBITDA | C12: ='Operating Model'!L41 -> 3245.8734 | D12: NOK mm | F12: PROCEEDS TO SPONSOR
B13: Exit EV / EBITDA Multiple | C13: 18 | D13: x | F13: Equity Value at Exit | G13: =C21 -> 83490.946 | H13: NOK mm
F14: (-) Exit Transaction Costs | G14: =-G10 -> -884.90946 | H14: NOK mm
B15: Enterprise Value at Exit | C15: =C12*C13 -> 58425.721 | D15: NOK mm | F15: (-) Management Rollover | G15: 0 | H15: NOK mm
B17: (-) Net Debt at Exit | C17: =C18-C19 -> -25065.226 | D17: NOK mm | F17: Gross Proceeds to Sponsor | G17: =G13+G14+G15 -> 82606.037 | H17: NOK mm
B18: Total Debt | C18: ='Debt Schedule'!H46 -> 11019.811 | D18: NOK mm
B19: (-) Cash | C19: ='3-Statement Model (Forecast)'!H33 -> 36085.036 | D19: NOK mm | F19: Sponsor Ownership % | G19: 1 | H19: %
F20: Net Proceeds to Sponsor | G20: =G17*G19 -> 82606.037 | H20: NOK mm
B21: Equity Value at Exit | C21: =C15-C17 -> 83490.946 | D21: NOK mm
B23: MULTIPLE EXPANSION ANALYSIS
B24: Entry EV / EBITDA Multiple | C24: ='Entry Assumptions'!C24 -> 20.839804 | D24: x
B25: Exit EV / EBITDA Multiple | C25: =C13 -> 18 | D25: x
B26: Multiple Expansion / (Contraction) | C26: =C25-C24 -> -2.8398043 | D26: x
B28: Value Creation from Multiple Expansion | C28: =C12*(C25-C24) -> -9217.645 | D28: NOK mm
B29: Value Creation from EBITDA Growth | C29: =C24*(C12-'Entry Assumptions'!C23) -> 24332.626 | D29: NOK mm
B30: Value Creation from Debt Paydown | C30: ='Entry Assumptions'!G18-C17 -> 70855.343 | D30: NOK mm
B31: Total Value Creation | C31: =C28+C29+C30 -> 85970.323 | D31: NOK mm

Sheet Returns 
B2: RETURNS ANALYSIS
B3: AutoStore Holdings Ltd. — IRR & MOIC Analysis
B6: INVESTMENT SUMMARY | F6: RETURNS BY EXIT YEAR
B7: Initial Sponsor Equity Investment | C7: ='Entry Assumptions'!G16 -> 34359.632 | D7: NOK mm | G7: MOIC | H7: IRR
B8: Holding Period | C8: ='Exit Assumptions'!C9 -> 5 | D8: Years | F8: Exit Year 3 | G8: =('Operating Model'!J41*'Exit Assumptions'!$C$13-('Debt Schedule'!F46-'3-Statement Model (Forecast)'!F33))/C7 -> 2.2001682 | H8: =G8^(1/3)-1 -> 0.30062459
B9: Exit Proceeds to Sponsor | C9: ='Exit Assumptions'!G20 -> 82606.037 | D9: NOK mm | F9: Exit Year 4 | G9: =('Operating Model'!K41*'Exit Assumptions'!$C$13-('Debt Schedule'!G46-'3-Statement Model (Forecast)'!G33))/C7 -> 2.3294139 | H9: =G9^(1/4)-1 -> 0.23541157
F10: Exit Year 5 (Base Case) | G10: ='Exit Assumptions'!G20/C7 -> 2.4041595 | H10: =C13 -> 0.19177057
B11: RETURNS METRICS | F11: Exit Year 6 | G11: =('Operating Model'!L41*1.05*'Exit Assumptions'!$C$13-('Debt Schedule'!H46*0.95-'3-Statement Model (Forecast)'!H33*1.1))/C7 -> 2.6359923 | H11: =G11^(1/6)-1 -> 0.17532333
B12: Money-on-Money (MOIC) | C12: =C9/C7 -> 2.4041595 | D12: x | F12: Exit Year 7 | G12: =('Operating Model'!L41*1.1*'Exit Assumptions'!$C$13-('Debt Schedule'!H46*0.9-'3-Statement Model (Forecast)'!H33*1.2))/C7 -> 2.8420708 | H12: =G12^(1/7)-1 -> 0.16092719
B13: Internal Rate of Return (IRR) | C13: =(C9/C7)^(1/C8)-1 -> 0.19177057 | D13: %
F14: VALUE CREATION BRIDGE
B15: Cash-on-Cash Return | C15: =C12 -> 2.4041595 | D15: x | F15: Initial Equity Investment | G15: =C7 -> 34359.632 | H15: NOK mm
B16: Total Return | C16: =C9/C7-1 -> 1.4041595 | D16: % | F16: (+) EBITDA Growth Impact | G16: ='Exit Assumptions'!C29 -> 24332.626 | H16: NOK mm
F17: (+) Multiple Expansion Impact | G17: ='Exit Assumptions'!C28 -> -9217.645 | H17: NOK mm
B18: CASH FLOWS FOR IRR CALCULATION | F18: (+) Debt Paydown Impact | G18: ='Exit Assumptions'!C30 -> 70855.343 | H18: NOK mm
B19: Year 0 (Initial Investment) | C19: =-C7 -> -34359.632 | D19: NOK mm | F19: (-) Dividends / Distributions | G19: 0 | H19: NOK mm
B20: Year 1 | C20: 0 | D20: NOK mm
B21: Year 2 | C21: 0 | D21: NOK mm | F21: Exit Equity Value | G21: =SUM(G15:G19) -> 120329.96 | H21: NOK mm
B22: Year 3 | C22: 0 | D22: NOK mm
B23: Year 4 | C23: 0 | D23: NOK mm
B24: Year 5 (Exit) | C24: =C9 -> 82606.037 | D24: NOK mm
B26: IRR (=XIRR) | C26: =IRR(C19:C24) -> 0.19177057 | D26: %

Sheet Sensitivity Analysis
B2: SENSITIVITY ANALYSIS
B3: AutoStore Holdings Ltd. — IRR & MOIC Sensitivity Tables
B6: IRR SENSITIVITY: Exit Multiple vs. EBITDA CAGR | I6: MOIC SENSITIVITY: Exit Multiple vs. EBITDA CAGR
B7: IRR | C7: 0.05 | D7: 0.075 | E7: 0.1 | F7: 0.125 | G7: 0.15 | I7: MOIC | J7: 0.05 | K7: 0.075 | L7: 0.1 | M7: 0.125 | N7: 0.15
B8: 14.0x | C8: 0.12590029 | D8: 0.14222793 | E8: 0.15913421 | F8: 0.17658369 | G8: 0.19454119 | I8: 14.0x | J8: 1.8092545 | K8: 1.9443027 | L8: 2.0925152 | M8: 2.2548316 | N8: 2.4322356
B9: 15.0x | C9: 0.13535606 | D9: 0.15226129 | E9: 0.16973959 | F9: 0.18775412 | G9: 0.2062686 | I9: 15.0x | J9: 1.8865157 | K9: 2.0312102 | L9: 2.1900092 | M9: 2.3639198 | N9: 2.5539955
B10: 16.0x | C10: 0.14450693 | D10: 0.16195689 | E10: 0.17997375 | F10: 0.19851949 | G10: 0.21755693 | I10: 16.0x | J10: 1.9637769 | K10: 2.1181177 | L10: 2.2875033 | M10: 2.4730079 | N10: 2.6757553
B11: 17.0x | C11: 0.15337417 | D11: 0.17133929 | E11: 0.18986471 | F11: 0.20891141 | G11: 0.22844152 | I11: 17.0x | J11: 2.041038 | K11: 2.2050252 | L11: 2.3849974 | M11: 2.582096 | N11: 2.7975151
B12: 18.0x | C12: 0.16197681 | D12: 0.18043036 | E12: 0.19943731 | F12: 0.21895783 | G12: 0.23895348 | I12: 18.0x | J12: 2.1182992 | K12: 2.2919326 | L12: 2.4824915 | M12: 2.6911841 | N12: 2.9192749
B15: IRR SENSITIVITY: Entry Multiple vs. Exit Multiple | I15: IRR SENSITIVITY: Leverage (Debt/EBITDA) vs. Exit Multiple
B16: IRR | C16: 14.0x | D16: 15.0x | E16: 16.0x | F16: 17.0x | G16: 18.0x | I16: IRR | J16: 14.0x | K16: 15.0x | L16: 16.0x | M16: 17.0x | N16: 18.0x
B17: 12.0x | C17: 0.21641997 | D17: 0.19849573 | E17: 0.18204792 | F17: 0.16686785 | G17: 0.15278714 | I17: 4.0x | J17: 0.15057353 | K17: 0.16068451 | L17: 0.17045499 | M17: 0.17990971 | N17: 0.18907075
B18: 13.0x | C18: 0.22754948 | D18: 0.20946125 | E18: 0.19286296 | F18: 0.17754399 | G18: 0.16333445 | I18: 4.5x | J18: 0.15402479 | K18: 0.16430069 | L18: 0.17422613 | M18: 0.1838269 | N18: 0.19312597
B19: 14.0x | C19: 0.23828942 | D19: 0.22004294 | E19: 0.20329942 | F19: 0.18784643 | G19: 0.17351257 | I19: 5.0x | J19: 0.15763626 | K19: 0.16808297 | L19: 0.17816879 | M19: 0.18792064 | N19: 0.1973624
B20: 15.0x | C20: 0.2486692 | D20: 0.23026977 | E20: 0.2133859 | F20: 0.19780338 | G20: 0.18334936 | I20: 5.5x | J20: 0.16141981 | K20: 0.17204356 | L20: 0.18229552 | M20: 0.19220375 | N20: 0.20179314
B21: 16.0x | C21: 0.25871489 | D21: 0.24016743 | E21: 0.22314774 | F21: 0.20743985 | G21: 0.19286955 | I21: 6.0x | J21: 0.16538858 | K21: 0.17619596 | L21: 0.18662015 | M21: 0.1966904 | N21: 0.20643268
B24: SCENARIO ANALYSIS
B25: Scenario | C25: Exit Multiple | D25: EBITDA CAGR | E25: IRR | F25: MOIC | G25: Equity Value
B26: Downside | C26: 15 | D26: 0.05 | E26: 0.12 | F26: 1.65 | G26: 56700
B27: Base Case | C27: 18 | D27: 0.1 | E27: 0.192 | F27: 2.4 | G27: 82606
B28: Upside | C28: 20 | D28: 0.12 | E28: 0.25 | F28: 3.05 | G28: 104800
B29: Management Case | C29: 22 | D29: 0.15 | E29: 0.32 | F29: 4 | G29: 137500
B31: ■ Yellow = Base Case

Sheet Sources and Footnotes
C2: SOURCES & FOOTNOTES
C3: AutoStore Holdings Ltd. — Data Sources & Key Assumptions
C6: DATA SOURCES
B7: # | C7: Category | D7: Description | E7: Source | F7: Date
B8: 1 | C8: Company Financials | D8: Historical income statement, balance sheet, cash flow | E8: AutoStore Annual Report 2024 | F8: FY 2024
B9: 2 | C9: Share Price | D9: Current share price and shares outstanding | E9: Oslo Børs / Bloomberg | F9: 46082
B10: 3 | C10: Debt Details | D10: Existing debt facilities, maturities, rates | E10: Company 20-F / Bond Prospectus | F10: FY 2024
B11: 4 | C11: Industry Data | D11: Warehouse automation market size, growth rates | E11: Industry Reports | F11: 2025
B12: 5 | C12: Comparable Companies | D12: Trading multiples for peer group | E12: Capital IQ / FactSet | F12: 46082
B13: 6 | C13: Precedent Transactions | D13: M&A multiples in automation sector | E13: Capital IQ / Dealogic | F13: 2020-2025
B14: 7 | C14: Financing Terms | D14: Market rates for leveraged loans / HY bonds | E14: LCD / Refinitiv LPC | F14: 46082
C16: KEY ASSUMPTIONS & NOTES
B17: # | C17: Assumption | D17: Value | E17: Rationale
B18: 1 | C18: Projection Period | D18: 5 years | E18: Standard LBO holding period
B19: 2 | C19: Revenue Growth (Y1-Y5) | D19: 10% → 5% | E19: Based on management guidance / market growth
B20: 3 | C20: EBITDA Margin Expansion | D20: 33% → 35% | E20: Operational improvements post-acquisition
B21: 4 | C21: Entry Multiple | D21: 20.8x EBITDA | E21: Based on precedent transactions and current trading
B22: 5 | C22: Exit Multiple | D22: 18.0x EBITDA | E22: Assumes no multiple expansion/contraction vs entry
B23: 6 | C23: Senior Debt Spread | D23: S+300 bps | E23: Based on current leveraged loan market
B24: 7 | C24: Tax Rate | D24: 0.22 | E24: Norwegian corporate tax rate
B25: 8 | C25: Minimum Cash Balance | D25: NOK 500mm | E25: Operational requirement
