Workbook

Sheet Cover Page
A1: PRADA S.p.A.
A2: Acquisition of Versace
A4: M&A Financial Model
A6: Prepared by: | B6: Investment Banking Division
A7: Date: | B7: 46054
A10: TRANSACTION OVERVIEW
A12: Acquirer: | B12: Prada S.p.A. (1913:HK)
A13: Target: | B13: Versace (Capri Holdings - NYSE: CPRI)
A14: Transaction Type: | B14: 100% Acquisition - All Cash
A15: Enterprise Value: | B15: $1.375 billion (€1.25 billion)
A16: Deal Status: | B16: Closed - December 2, 2025
A19: MODEL CONTENTS
A21: 1 | B21: Summary & Sensitivity Analysis
A22: 2 | B22: Accretion / Dilution Analysis
A23: 3 | B23: Transaction Assumptions
A24: 4 | B24: Standalone Acquirer Model (Prada)
A25: 5 | B25: Standalone Target Model (Versace)
A26: 6 | B26: Pro-Forma Combined Model
A27: 7 | B27: Sources & Uses of Funds
A28: 8 | B28: Synergy Schedule
A30: CONFIDENTIAL - FOR DISCUSSION PURPOSES ONLY

Sheet Summary & Sensitivity

Sheet Accretion and Dilution Analysis

Sheet Assumptions
A1: TRANSACTION ASSUMPTIONS
A2: Prada S.p.A. Acquisition of Versace
A4: DEAL STRUCTURE
A6: Enterprise Value | C6: 1375 | D6: $mm | F6: Enterprise Value (EUR) | H6: =C6/C10 -> 1252.2769 | I6: €mm
A7: Cash Consideration % | C7: 1 | F7: Stock Consideration % | H7: =1-C7 -> 0
A8: Transaction Costs | C8: 35 | D8: $mm | F8: % of EV | H8: =C8/C6 -> 0.025454545
A10: USD/EUR Exchange Rate | C10: 1.098 | F10: As of deal announcement (April 10, 2025)
A12: FINANCING STRUCTURE
A14: New Term Loan | C14: 1098 | D14: $mm (€1.0bn) | F14: Interest Rate | H14: 0.055
A15: Bridge Facility | C15: 549 | D15: $mm (€0.5bn) | F15: Interest Rate | H15: 0.06
A16: Total New Debt | C16: =C14+C15 -> 1647 | D16: $mm | F16: Blended Rate | H16: =(C14*H14+C15*H15)/C16 -> 0.056666667
A17: Cash from Balance Sheet | C17: =C6+C8-C16 -> -237 | D17: $mm
A19: ACQUIRER PROFILE - PRADA S.p.A.
A21: Fiscal Year End | C21: 46387 | F21: Currency | H21: EUR
A22: Share Price (HKD) | C22: 44.5 | D22: HKD | F22: Share Price (USD) | H22: =C22/7.8 -> 5.7051282 | I22: USD
A23: Shares Outstanding (mm) | C23: 2560 | D23: mm | F23: Market Cap (USD) | H23: =C23*H22 -> 14605.128 | I23: $mm
A25: FY2024 Financials (€mm)
A26: Revenue | C26: 5430 | D26: €mm | F26: YoY Growth | H26: 0.15
A27: EBIT | C27: =C26*H28 -> 1281.48 | D27: €mm | F27: EBIT Margin | H27: 0.15
A28: Net Income | C28: 0.236 | D28: €mm | F28: Net Margin | H28: 0.236
A29: EPS (€) | C29: 839 | F29: P/E Ratio | H29: =C29/C26 -> 0.15451197
C30: =C29/C23*1000 -> 327.73438 | H30: =H22*C10/C30 -> 0.019113743
A31: TARGET PROFILE - VERSACE
A33: Parent Company | C33: Capri Holdings (NYSE: CPRI) | F33: Fiscal Year End | H33: 46112
A35: FY2024 Financials ($mm)
A36: Revenue | C36: 1030 | D36: $mm | F36: % of Capri Total | H36: 0.2
A37: Gross Profit | C37: =C36*H39 -> 669.5 | D37: $mm | F37: Gross Margin | H37: 0.65
A38: Operating Income | C38: =C40 -> 50 | D38: $mm | F38: Operating Margin | H38: 0.2
C39: 0.65 | H39: 0.65
A40: FY2025 Financials ($mm) | C40: 50 | H40: =C40/C36 -> 0.048543689
A41: Revenue | C41: 810 | D41: $mm | F41: YoY Decline | H41: =C41/C36-1 -> -0.21359223
A42: Operating Income | C42: -50 | D42: $mm | F42: Operating Margin | H42: =C42/C41 -> -0.061728395
A44: VALUATION METRICS
A46: EV / FY2024 Revenue | C46: =C6/C36 -> 1.3349515 | F46: EV / FY2025 Revenue | H46: =C6/C41 -> 1.6975309
A47: Capri 2018 Purchase Price | C47: 2150 | D47: $mm | F47: Discount to 2018 Price | H47: =1-C6/C47 -> 0.36046512
A49: SYNERGY ASSUMPTIONS
A51: Cost Synergies (% of Target Rev) | C51: 0.05 | F51: Annual Cost Synergies ($mm) | H51: =C51*C41 -> 40.5
A52: Revenue Synergies (% of Target Rev) | C52: 0.02 | F52: Annual Revenue Synergies ($mm) | H52: =C52*C41 -> 16.2
A53: Synergy Phase-in (Years) | C53: 3 | D53: years | F53: Year 1 Realization | H53: 0.33
A54: Integration Costs | C54: 75 | D54: $mm | F54: Spread over (years) | H54: 2
...

Sheet Pro-Forma Model
A1: PRO-FORMA COMBINED MODEL
A2: Prada + Versace Combined Entity
A4: COMBINED INCOME STATEMENT
A6: ($mm) | B6: FY2025E | C6: FY2026E | D6: FY2027E | E6: FY2028E | F6: FY2029E
A8: Prada Revenue (converted to $) | B8: ='Acquirer Modelling'!D9*Assumptions!$C$10 -> 6498.7326 | C8: ='Acquirer Modelling'!E9*Assumptions!$C$10 -> 7018.6312 | D8: ='Acquirer Modelling'!F9*Assumptions!$C$10 -> 7509.9354 | E8: ='Acquirer Modelling'!G9*Assumptions!$C$10 -> 7960.5315 | F8: ='Acquirer Modelling'!H9*Assumptions!$C$10 -> 8438.1634
A9: Versace Revenue | B9: ='Target Modelling'!D9 -> 810 | C9: ='Target Modelling'!E9 -> 826.2 | D9: ='Target Modelling'!F9 -> 867.51 | E9: ='Target Modelling'!G9 -> 928.2357 | F9: ='Target Modelling'!H9 -> 1002.4946
A10: Revenue Synergies | B10: =Assumptions!$H$52*Assumptions!$H$55 -> 0 | C10: =Assumptions!$H$52*Assumptions!$H$55*2 -> 0 | D10: =Assumptions!$H$52 -> 16.2 | E10: =Assumptions!$H$52 -> 16.2 | F10: =Assumptions!$H$52 -> 16.2 | H10: Phase-in: 33% Y1, 67% Y2, 100% Y3+
A11: Combined Revenue | B11: =SUM(B8:B10) -> 7308.7326 | C11: =SUM(C8:C10) -> 7844.8312 | D11: =SUM(D8:D10) -> 8393.6454 | E11: =SUM(E8:E10) -> 8904.9672 | F11: =SUM(F8:F10) -> 9456.858
A12: Revenue Growth % | C12: =(C11-B11)/B11 -> 0.07335042 | D12: =(D11-C11)/C11 -> 0.069958699 | E12: =(E11-D11)/D11 -> 0.06091773 | F12: =(F11-E11)/E11 -> 0.061975607
A14: Prada EBIT (converted to $) | B14: ='Acquirer Modelling'!D20*Assumptions!$C$10 -> 1592.1895 | C14: ='Acquirer Modelling'!E20*Assumptions!$C$10 -> 1754.6578 | D14: ='Acquirer Modelling'!F20*Assumptions!$C$10 -> 1952.5832 | E14: ='Acquirer Modelling'!G20*Assumptions!$C$10 -> 2109.5409 | F14: ='Acquirer Modelling'!H20*Assumptions!$C$10 -> 2320.4949
A15: Versace EBIT | B15: ='Target Modelling'!D20 -> 24.3 | C15: ='Target Modelling'!E20 -> 66.096 | D15: ='Target Modelling'!F20 -> 104.1012 | E15: ='Target Modelling'!G20 -> 148.51771 | F15: ='Target Modelling'!H20 -> 190.47397
A16: Cost Synergies | B16: =Assumptions!$H$51*Assumptions!$H$55 -> 0 | C16: =Assumptions!$H$51*Assumptions!$H$55*2 -> 0 | D16: =Assumptions!$H$51 -> 40.5 | E16: =Assumptions!$H$51 -> 40.5 | F16: =Assumptions!$H$51 -> 40.5 | H16: 5% of Versace revenue
A17: Integration Costs | B17: =-Assumptions!$C$56/Assumptions!$H$56 -> #DIV/0! | C17: =-Assumptions!$C$56/Assumptions!$H$56 -> #DIV/0! | D17: 0 | E17: 0 | F17: 0 | H17: $75mm over 2 years
A18: Combined EBIT | B18: =SUM(B14:B17) -> #DIV/0! | C18: =SUM(C14:C17) -> #DIV/0! | D18: =SUM(D14:D17) -> 2097.1844 | E18: =SUM(E14:E17) -> 2298.5586 | F18: =SUM(F14:F17) -> 2551.4689
A19: EBIT Margin | B19: =B18/B11 -> #DIV/0! | C19: =C18/C11 -> #DIV/0! | D19: =D18/D11 -> 0.24985382 | E19: =E18/E11 -> 0.25812095 | F19: =F18/F11 -> 0.26980091
A21: NEW DEBT SERVICE
A23: New Term Loan Interest | B23: =-Assumptions!$C$14*Assumptions!$H$14 -> -60.39 | C23: =-Assumptions!$C$14*Assumptions!$H$14 -> -60.39 | D23: =-Assumptions!$C$14*Assumptions!$H$14*0.9 -> -54.351 | E23: =-Assumptions!$C$14*Assumptions!$H$14*0.8 -> -48.312 | F23: =-Assumptions!$C$14*Assumptions!$H$14*0.7 -> -42.273 | H23: Assumes 10% annual paydown
A24: Bridge Facility Interest | B24: =-Assumptions!$C$15*Assumptions!$H$15 -> -32.94 | C24: 0 | D24: 0 | E24: 0 | F24: 0 | H24: Bridge refinanced in Year 1
A25: Total New Interest Expense | B25: =B23+B24 -> -93.33 | C25: =C23+C24 -> -60.39 | D25: =D23+D24 -> -54.351 | E25: =E23+E24 -> -48.312 | F25: =F23+F24 -> -42.273
A27: PRO-FORMA NET INCOME
A29: Combined EBIT | B29: =B18 -> #DIV/0! | C29: =C18 -> #DIV/0! | D29: =D18 -> 2097.1844 | E29: =E18 -> 2298.5586 | F29: =F18 -> 2551.4689
A30: Prada Existing Interest | B30: ='Acquirer Modelling'!D23*Assumptions!$C$10 -> -19.764 | C30: ='Acquirer Modelling'!E23*Assumptions!$C$10 -> -16.47 | D30: ='Acquirer Modelling'!F23*Assumptions!$C$10 -> -13.176 | E30: ='Acquirer Modelling'!G23*Assumptions!$C$10 -> -10.98 | F30: ='Acquirer Modelling'!H23*Assumptions!$C$10 -> -8.784
A31: New Acquisition Interest | B31: =B25 -> -93.33 | C31: =C25 -> -60.39 | D31: =D25 -> -54.351 | E31: =E25 -> -48.312 | F31: =F25 -> -42.273
A32: EBT | B32: =SUM(B29:B31) -> #DIV/0! | C32: =SUM(C29:C31) -> #DIV/0! | D32: =SUM(D29:D31) -> 2029.6574 | E32: =SUM(E29:E31) -> 2239.2666 | F32: =SUM(F29:F31) -> 2500.4119
A33: Income Tax (25%) | B33: =-B32*0.25 -> #DIV/0! | C33: =-C32*0.25 -> #DIV/0! | D33: =-D32*0.25 -> -507.41435 | E33: =-E32*0.25 -> -559.81664 | F33: =-F32*0.25 -> -625.10298
A34: Pro-Forma Net Income | B34: =B32+B33 -> #DIV/0! | C34: =C32+C33 -> #DIV/0! | D34: =D32+D33 -> 1522.2431 | E34: =E32+E33 -> 1679.4499 | F34: =F32+F33 -> 1875.3089
A36: PRO-FORMA EPS ANALYSIS
A38: Shares Outstanding (mm) | B38: 2560 | C38: 2560 | D38: 2560 | E38: 2560 | F38: 2560 | H38: 100% cash deal - no dilution
A39: Pro-Forma EPS | B39: =B34/B38*1000 -> #DIV/0! | C39: =C34/C38*1000 -> #DIV/0! | D39: =D34/D38*1000 -> 594.62619 | E39: =E34/E38*1000 -> 656.03513 | F39: =F34/F38*1000 -> 732.54255
A41: Standalone Prada EPS ($) | B41: ='Acquirer Modelling'!D35*Assumptions!$C$10 -> 460.67153 | C41: ='Acquirer Modelling'!E35*Assumptions!$C$10 -> 509.23471 | D41: ='Acquirer Modelling'!F35*Assumptions!$C$10 -> 568.1857 | E41: ='Acquirer Modelling'!G35*Assumptions!$C$10 -> 614.81275 | F41: ='Acquirer Modelling'!H35*Assumptions!$C$10 -> 677.25906
A43: ACCRETION / (DILUTION)
A44: $ per Share | B44: =B39-B41 -> #DIV/0! | C44: =C39-C41 -> #DIV/0! | D44: =D39-D41 -> 26.440488 | E44: =E39-E41 -> 41.222377 | F44: =F39-F41 -> 55.283486
A45: % Accretion / (Dilution) | B45: =(B39-B41)/B41 -> #DIV/0! | C45: =(C39-C41)/C41 -> #DIV/0! | D45: =(D39-D41)/D41 -> 0.046534941 | E45: =(E39-E41)/E41 -> 0.067048669 | F45: =(F39-F41)/F41 -> 0.08162827
A47: SOURCES & USES OF FUNDS ($mm)
A49: SOURCES | B49: Amount | C49: % of Total | E49: USES | F49: Amount | G49: % of Total
A50: New Term Loan | B50: =Assumptions!C14 -> 1098 | C50: =B51/$B$53 -> #DIV/0! | E50: Purchase Price (EV) | F50: =Assumptions!C6 -> 1375 | G50: =F51/$F$53 -> #DIV/0!
A51: Bridge Facility | B51: =Assumptions!C15 -> 549 | C51: =B52/$B$53 -> #DIV/0! | E51: Transaction Costs | F51: =Assumptions!C8 -> 35 | G51: =F52/$F$53 -> #DIV/0!
A52: Total Sources | B52: =SUM(B51:B52) -> 0 | C52: =SUM(C51:C52) -> 0 | E52: Total Uses | F52: =SUM(F51:F52) -> 0 | G52: =SUM(G51:G52) -> 0
A54: Excess Cash / (Shortfall) | B54: =B53-F53 -> 0 | H54: Funded from Prada cash on hand

Sheet Acquirer Modelling
A1: PRADA S.p.A. - STANDALONE FINANCIAL MODEL
A2: Acquirer Projections (€mm)
A4: INCOME STATEMENT
B6: Historical | D6: Projected
A7: (€mm) | B7: FY2023 | C7: FY2024 | D7: FY2025E | E7: FY2026E | F7: FY2027E | G7: FY2028E | H7: FY2029E
A9: Revenue | B9: 4720 | C9: 5430 | D9: =C9*(1+D10) -> 5918.7 | E9: =D9*(1+E10) -> 6392.196 | F9: =E9*(1+F10) -> 6839.6497 | G9: =F9*(1+G10) -> 7250.0287 | H9: =G9*(1+H10) -> 7685.0304 | K9: CAGR FY24-29E: | L9: =(H9/C9)^(1/5)-1 -> 0.07193673
A10: Growth % | C10: =(C9-B9)/B9 -> 0.15042373 | D10: 0.09 | E10: 0.08 | F10: 0.07 | G10: 0.06 | H10: 0.06
A12: Cost of Goods Sold | B12: =-B9*B13 -> -1227.2 | C12: =-C9*C13 -> -1384.65 | D12: =-D9*D13 -> -1479.675 | E12: =-E9*E13 -> -1598.049 | F12: =-F9*F13 -> -1675.7142 | G12: =-G9*G13 -> -1776.257 | H12: =-H9*H13 -> -1844.4073
A13: COGS % Revenue | B13: 0.26 | C13: 0.255 | D13: 0.25 | E13: 0.25 | F13: 0.245 | G13: 0.245 | H13: 0.24
A14: Gross Profit | B14: =B9+B12 -> 3492.8 | C14: =C9+C12 -> 4045.35 | D14: =D9+D12 -> 4439.025 | E14: =E9+E12 -> 4794.147 | F14: =F9+F12 -> 5163.9355 | G14: =G9+G12 -> 5473.7717 | H14: =H9+H12 -> 5840.6231
A15: Gross Margin | B15: =B14/B9 -> 0.74 | C15: =C14/C9 -> 0.745 | D15: =D14/D9 -> 0.75 | E15: =E14/E9 -> 0.75 | F15: =F14/F9 -> 0.755 | G15: =G14/G9 -> 0.755 | H15: =H14/H9 -> 0.76
A17: Operating Expenses | B17: =-B9*B18 -> -2454.4 | C17: =-C9*C18 -> -2763.87 | D17: =-D9*D18 -> -2988.9435 | E17: =-E9*E18 -> -3196.098 | F17: =-F9*F18 -> -3385.6266 | G17: =-G9*G18 -> -3552.5141 | H17: =-H9*H18 -> -3727.2398
A18: OpEx % Revenue | B18: 0.52 | C18: 0.509 | D18: 0.505 | E18: 0.5 | F18: 0.495 | G18: 0.49 | H18: 0.485
A20: EBIT | B20: =B14+B17 -> 1038.4 | C20: =C14+C17 -> 1281.48 | D20: =D14+D17 -> 1450.0815 | E20: =E14+E17 -> 1598.049 | F20: =F14+F17 -> 1778.3089 | G20: =G14+G17 -> 1921.2576 | H20: =H14+H17 -> 2113.3834
A21: EBIT Margin | B21: =B20/B9 -> 0.22 | C21: =C20/C9 -> 0.236 | D21: =D20/D9 -> 0.245 | E21: =E20/E9 -> 0.25 | F21: =F20/F9 -> 0.26 | G21: =G20/G9 -> 0.265 | H21: =H20/H9 -> 0.275
A23: Interest Expense | B23: -25 | C23: -20 | D23: -18 | E23: -15 | F23: -12 | G23: -10 | H23: -8
A24: EBT | B24: =B20+B23 -> 1013.4 | C24: =C20+C23 -> 1261.48 | D24: =D20+D23 -> 1432.0815 | E24: =E20+E23 -> 1583.049 | F24: =F20+F23 -> 1766.3089 | G24: =G20+G23 -> 1911.2576 | H24: =H20+H23 -> 2105.3834
A26: Income Tax | B26: =-B24*$C$27 -> -253.35 | C26: =-C24*$C$27 -> -315.37 | D26: =-D24*$C$27 -> -358.02038 | E26: =-E24*$C$27 -> -395.76225 | F26: =-F24*$C$27 -> -441.57723 | G26: =-G24*$C$27 -> -477.8144 | H26: =-H24*$C$27 -> -526.34584
A27: Tax Rate | B27: 0.25 | C27: 0.25 | D27: 0.25
A29: Net Income | B29: =B24+B26 -> 760.05 | C29: =C24+C26 -> 946.11 | D29: =D24+D26 -> 1074.0611 | E29: =E24+E26 -> 1187.2868 | F29: =F24+F26 -> 1324.7317 | G29: =G24+G26 -> 1433.4432 | H29: =H24+H26 -> 1579.0375
A30: Net Margin | B30: =B29/B9 -> 0.16102754 | C30: =C29/C9 -> 0.17423757 | D30: =D29/D9 -> 0.18146909 | E30: =E29/E9 -> 0.18574004 | F30: =F29/F9 -> 0.19368414 | G30: =G29/G9 -> 0.19771552 | H30: =H29/H9 -> 0.20546926
A32: PER SHARE DATA
A34: Shares Outstanding (mm) | B34: 2560 | C34: 2560 | D34: 2560 | E34: 2560 | F34: 2560 | G34: 2560 | H34: 2560
A35: EPS | B35: =B29/B34*1000 -> 296.89453 | C35: =C29/C34*1000 -> 369.57422 | D35: =D29/D34*1000 -> 419.55513 | E35: =E29/E34*1000 -> 463.78389 | F35: =F29/F34*1000 -> 517.47332 | G35: =G29/G34*1000 -> 559.93875 | H35: =H29/H34*1000 -> 616.81153 | K35: EPS CAGR: | L35: =(H35/C35)^(1/5)-1 -> 0.10787347
A36: EPS Growth | C36: =(C35-B35)/B35 -> 0.24479968 | D36: =(D35-C35)/C35 -> 0.13523916 | E36: =(E35-D35)/D35 -> 0.10541823 | F36: =(F35-E35)/E35 -> 0.1157639 | G36: =(G35-F35)/F35 -> 0.082063039 | H36: =(H35-G35)/G35 -> 0.10156965
A38: KEY METRICS
A40: D&A (% of Revenue) | B40: 0.06 | C40: 0.06 | D40: 0.06 | E40: 0.06 | F40: 0.06 | G40: 0.06 | H40: 0.06
A41: D&A | B41: =B9*B40 -> 283.2 | C41: =C9*C40 -> 325.8 | D41: =D9*D40 -> 355.122 | E41: =E9*E40 -> 383.53176 | F41: =F9*F40 -> 410.37898 | G41: =G9*G40 -> 435.00172 | H41: =H9*H40 -> 461.10183
A42: EBITDA | B42: =B20+B41 -> 1321.6 | C42: =C20+C41 -> 1607.28 | D42: =D20+D41 -> 1805.2035 | E42: =E20+E41 -> 1981.5808 | F42: =F20+F41 -> 2188.6879 | G42: =G20+G41 -> 2356.2593 | H42: =H20+H41 -> 2574.4852
A43: EBITDA Margin | B43: =B42/B9 -> 0.28 | C43: =C42/C9 -> 0.296 | D43: =D42/D9 -> 0.305 | E43: =E42/E9 -> 0.31 | F43: =F42/F9 -> 0.32 | G43: =G42/G9 -> 0.325 | H43: =H42/H9 -> 0.335
A45: CapEx (% of Revenue) | B45: 0.09 | C45: 0.09 | D45: 0.085 | E45: 0.08 | F45: 0.08 | G45: 0.075 | H45: 0.075

Sheet Target Modelling
A1: VERSACE - STANDALONE FINANCIAL MODEL
A2: Target Projections ($mm)
A4: INCOME STATEMENT
B6: Historical | D6: Projected
A7: ($mm) | B7: FY2023 | C7: FY2024 | D7: FY2025E | E7: FY2026E | F7: FY2027E | G7: FY2028E | H7: FY2029E
A9: Revenue | B9: 1106 | C9: 1030 | D9: 810 | E9: =D9*(1+E10) -> 826.2 | F9: =E9*(1+F10) -> 867.51 | G9: =F9*(1+G10) -> 928.2357 | H9: =G9*(1+H10) -> 1002.4946 | K9: CAGR FY25-29E: | L9: =(H9/D9)^(1/4)-1 -> 0.054749313
A10: Growth % | C10: =(C9-B9)/B9 -> -0.068716094 | D10: =(D9-C9)/C9 -> -0.21359223 | E10: 0.02 | F10: 0.05 | G10: 0.07 | H10: 0.08 | J10: Turnaround assumptions under Prada
A12: Cost of Goods Sold | B12: =-B9*B13 -> -398.16 | C12: =-C9*C13 -> -360.5 | D12: =-D9*D13 -> -283.5 | E12: =-E9*E13 -> -280.908 | F12: =-F9*F13 -> -286.2783 | G12: =-G9*G13 -> -297.03542 | H12: =-H9*H13 -> -310.77331
A13: COGS % Revenue | B13: 0.36 | C13: 0.35 | D13: 0.35 | E13: 0.34 | F13: 0.33 | G13: 0.32 | H13: 0.31 | J13: Margin improvement from Prada synergies
A14: Gross Profit | B14: =B9+B12 -> 707.84 | C14: =C9+C12 -> 669.5 | D14: =D9+D12 -> 526.5 | E14: =E9+E12 -> 545.292 | F14: =F9+F12 -> 581.2317 | G14: =G9+G12 -> 631.20028 | H14: =H9+H12 -> 691.72124
A15: Gross Margin | B15: =B14/B9 -> 0.64 | C15: =C14/C9 -> 0.65 | D15: =D14/D9 -> 0.65 | E15: =E14/E9 -> 0.66 | F15: =F14/F9 -> 0.67 | G15: =G14/G9 -> 0.68 | H15: =H14/H9 -> 0.69
A17: Operating Expenses | B17: =-B9*B18 -> -641.48 | C17: =-C9*C18 -> -618 | D17: =-D9*D18 -> -502.2 | E17: =-E9*E18 -> -479.196 | F17: =-F9*F18 -> -477.1305 | G17: =-G9*G18 -> -482.68256 | H17: =-H9*H18 -> -501.24728
A18: OpEx % Revenue | B18: 0.58 | C18: 0.6 | D18: 0.62 | E18: 0.58 | F18: 0.55 | G18: 0.52 | H18: 0.5 | J18: Cost restructuring under new ownership
A20: EBIT | B20: =B14+B17 -> 66.36 | C20: =C14+C17 -> 51.5 | D20: =D14+D17 -> 24.3 | E20: =E14+E17 -> 66.096 | F20: =F14+F17 -> 104.1012 | G20: =G14+G17 -> 148.51771 | H20: =H14+H17 -> 190.47397
A21: EBIT Margin | B21: =B20/B9 -> 0.06 | C21: =C20/C9 -> 0.05 | D21: =D20/D9 -> 0.03 | E21: =E20/E9 -> 0.08 | F21: =F20/F9 -> 0.12 | G21: =G20/G9 -> 0.16 | H21: =H20/H9 -> 0.19
A23: Interest Expense | B23: -15 | C23: -12 | D23: 0 | E23: 0 | F23: 0 | G23: 0 | H23: 0 | J23: Debt free basis under Prada
A24: EBT | B24: =B20+B23 -> 51.36 | C24: =C20+C23 -> 39.5 | D24: =D20+D23 -> 24.3 | E24: =E20+E23 -> 66.096 | F24: =F20+F23 -> 104.1012 | G24: =G20+G23 -> 148.51771 | H24: =H20+H23 -> 190.47397
A26: Income Tax | B26: =IF(B24>0,-B24*$D$27,0) -> -12.84 | C26: =IF(C24>0,-C24*$D$27,0) -> -9.875 | D26: =IF(D24>0,-D24*$D$27,0) -> -6.075 | E26: =IF(E24>0,-E24*$D$27,0) -> -16.524 | F26: =IF(F24>0,-F24*$D$27,0) -> -26.0253 | G26: =IF(G24>0,-G24*$D$27,0) -> -37.129428 | H26: =IF(H24>0,-H24*$D$27,0) -> -47.618491
A27: Tax Rate | B27: 0.25 | C27: 0.25 | D27: 0.25 | E27: 0.25
A29: Net Income | B29: =B24+B26 -> 38.52 | C29: =C24+C26 -> 29.625 | D29: =D24+D26 -> 18.225 | E29: =E24+E26 -> 49.572 | F29: =F24+F26 -> 78.0759 | G29: =G24+G26 -> 111.38828 | H29: =H24+H26 -> 142.85547
A30: Net Margin | B30: =B29/B9 -> 0.03482821 | C30: =C29/C9 -> 0.028762136 | D30: =D29/D9 -> 0.0225 | E30: =E29/E9 -> 0.06 | F30: =F29/F9 -> 0.09 | G30: =G29/G9 -> 0.12 | H30: =H29/H9 -> 0.1425
A32: KEY METRICS
A34: D&A (% of Revenue) | B34: 0.07 | C34: 0.07 | D34: 0.07 | E34: 0.065 | F34: 0.06 | G34: 0.06 | H34: 0.055
A35: D&A | B35: =B9*B34 -> 77.42 | C35: =C9*C34 -> 72.1 | D35: =D9*D34 -> 56.7 | E35: =E9*E34 -> 53.703 | F35: =F9*F34 -> 52.0506 | G35: =G9*G34 -> 55.694142 | H35: =H9*H34 -> 55.137201
A36: EBITDA | B36: =B20+B35 -> 143.78 | C36: =C20+C35 -> 123.6 | D36: =D20+D35 -> 81 | E36: =E20+E35 -> 119.799 | F36: =F20+F35 -> 156.1518 | G36: =G20+G35 -> 204.21185 | H36: =H20+F35 -> 242.52457
A37: EBITDA Margin | B37: =B36/B9 -> 0.13 | C37: =C36/C9 -> 0.12 | D37: =D36/D9 -> 0.1 | E37: =E36/E9 -> 0.145 | F37: =F36/F9 -> 0.18 | G37: =G36/G9 -> 0.22 | H37: =H36/H9 -> 0.24192108
A39: VALUATION AT DEAL PRICE
A41: Enterprise Value | D41: 1375
A42: EV / Revenue | D42: =D41/D9 -> 1.6975309
A43: EV / EBITDA | D43: =IF(D36>0,D41/D36,"NM") -> 16.975309
A45: Notes:
A46: {=- Projections reflect turnaround under Prada ownership with operational improvements} -> #NAME?
