Workbook
Name AnnFactor: 'Risk Metrics'!$D$5
Name RiskFreeRate: 'Risk Metrics'!$B$5
Name w_BS: 'Factor Screen'!$G$5
Name w_Earn: 'Factor Screen'!$K$5
Name w_FCF: 'Factor Screen'!$I$5
Name w_GM: 'Factor Screen'!$E$5
Name w_ROIC: 'Factor Screen'!$C$5

Sheet Mandate
A1: GLOBAL QUALITY COMPOUNDER PORTFOLIO: INVESTMENT MANDATE
A2: Investment Policy Statement(IPS) : Defines the mandate, constraints and risk parameters governing portfolio construction and management.
A4: # | B4: MANDATE PARAMETER | C4: SPECIFICATION | D4: RATIONALE / NOTES | E4: STATUS
A5: 1 | B5: Portfolio Objective | C5: Outperform MSCI World Index by +200 bps per annum, net of all fees, over a full market cycle (5+ years). | D5: Target alpha generation through disciplined quality factor exposure and concentrated high-conviction portfolio construction. | E5: Active
A6: 2 | B6: Benchmark | C6: MSCI World Index (Net Total Return, USD) | D6: Broad global developed-market equity benchmark; representative of investment universe; widely used by institutional allocators. | E6: Defined
A7: 3 | B7: Investment Universe | C7: Global large-cap equities. Minimum market capitalisation of USD $10 billion at time of purchase. | D7: Ensures liquidity, institutional coverage and reliable financial data. Excludes micro/small-cap risk. | E7: Defined
A8: 4 | B8: Geographic Limits | C8: Maximum 40% exposure to any single geographic region (North America / Europe / Asia Pacific). | D8: Prevents undue concentration in any single economic bloc; ensures genuine global diversification. | E8: Compliant
A9: 5 | B9: Single Stock Position Limit | C9: Maximum 8% weight per holding at time of rebalance. Minimum 2% to ensure meaningful contribution. | D9: Balances concentration (for alpha) against idiosyncratic risk; prevents dilution of high-conviction names. | E9: Compliant
A10: 6 | B10: Number of Holdings | C10: 12 to 15 stocks at all times. | D10: Concentrated enough for active returns; diversified enough to manage stock-specific risk within tracking error budget. | E10: Compliant
A11: 7 | B11: Rebalancing Frequency | C11: Quarterly (Jan, Apr, Jul, Oct). Interim rebalance if any position breaches +/-3% of target weight. | D11: Balances turnover efficiency against drift risk. Interim trigger prevents unintended concentration. | E11: Quarterly
A12: 8 | B12: Risk Budget — Tracking Error | C12: Maximum 4.0% ex-ante tracking error versus MSCI World, measured monthly. | D12: Defines active risk budget. A 4% TE reflects high-conviction active management within typical AM mandates. | E12: Monitored
A13: 9 | B13: Permitted Instruments | C13: Equity only, ordinary shares and ADRs listed on NYSE, NASDAQ, LSE, Euronext, TSX or ASX. | D13: No derivatives, leverage, short selling or fixed income. Pure long-only equity for mandate transparency. | E13: Compliant
A14: 10 | B14: Currency Policy | C14: Unhedged. Portfolio denominated in USD for reporting purposes. | D14: Reflects natural currency exposure of a global equity mandate. Currency is an accepted source of return and risk. | E14: Unhedged
A15: 11 | B15: ESG / Exclusions | C15: Exclude companies deriving >10% revenue from tobacco, controversial weapons or thermal coal extraction. | D15: Reflects responsible investment principles; consistent with typical institutional AM client requirements. | E15: Screened
A16: 12 | B16: Quality Screen: ROIC | C16: Minimum 15% ROIC (5-year average) for inclusion in investable universe. | D16: Core quality factor: identifies businesses earning above their cost of capital consistently across cycles. | E16: Applied
... A19: 15 | B19: Portfolio Manager | C19: Senior Portfolio Manager : Global Quality Equities | D19: Single PM accountability with IC oversight required for positions exceeding 6% portfolio weight. | E19: Assigned
A21: This document is for internal portfolio management purposes only. All parameters subject to Investment Committee approval. Last reviewed: Q1 2026.

Sheet Universe
A1: GLOBAL QUALITY COMPOUNDER PORTFOLIO: INVESTMENT UNIVERSE
A2: Quality Compounder Screening Universe: 35 global large-cap candidates. Static data pre-filled; highlighted yellow columns require annual report inputs.
A4: # | B4: COMPANY | C4: TICKER | D4: COUNTRY | E4: SECTOR | F4: MKT CAP ($BN) (Mar 26) | G4: ROIC (%) (FY 25) | H4: GROSS MARGIN (%) (FY 25) | I4: NET DEBT / EBITDA (FY 25) | J4: FCF CONVERSION (%). (FY 25) | K4: 5Y REV AVG PER SH (FY 21-25) ($)
A5: 1 | B5: Microsoft Corporation | C5: MSFT | D5: United States | E5: Technology | F5: 2875.42 | G5: 0.256 | H5: 0.6882 | I5: =-0.03 -> -0.03 | J5: 0.4667 | K5: 29.46
A6: 2 | B6: Accenture plc | C6: ACN | D6: United States | E6: Technology | F6: 126.23 | G6: 0.221 | H6: 0.319 | I6: -0.51 | J6: 0.9348 | K6: 97.33
A7: 3 | B7: Automatic Data Processing | C7: ADP | D7: United States | E7: Technology | F7: 84.89 | G7: 0.4446 | H7: 0.5037 | I7: 0.16 | J7: 0.5814 | K7: 42.89
A8: 4 | B8: Veeva Systems | C8: VEEV | D8: United States | E8: Technology | F8: 30.51 | G8: 0.1377 | H8: 0.752 | I8: -6.58 | J8: 1.525 | K8: 14.98
A9: 5 | B9: Constellation Software | C9: CSU | D9: Canada | E9: Technology | F9: 38.5 | G9: 0.0707 | H9: 0.3958 | I9: 0.79 | J9: 4.764 | K9: 390
A10: 6 | B10: Wolters Kluwer | C10: WKL | D10: Netherlands | E10: Technology | F10: 16.74 | G10: 0.2565 | H10: 0.6591 | I10: 2.01 | J10: 0.8287 | K10: 26.31
A11: 7 | B11: Rightmove | C11: RMV | D11: United Kingdom | E11: Technology | F11: 4.3 | G11: 2.547 | H11: 0.984 | I11: -0.12 | J11: 0.7337 | K11: 0.6
A12: 8 | B12: Visa Inc. | C12: V | D12: United States | E12: Financials | F12: 586.8 | G12: 0.3339 | H12: 0.7731 | I12: 0.07 | J12: 0.8534 | K12: 15.69
A13: 9 | B13: Mastercard Incorporated | C13: MA | D13: United States | E13: Financials | F13: 447.81 | G13: 0.5841 | H13: 0.9603 | I13: 0.36 | J13: 0.9458 | K13: 27.02
A14: 10 | B14: S&P Global Inc. | C14: SPGI | D14: United States | E14: Financials | F14: 128.57 | G14: 0.1004 | H14: 0.6256 | I14: 1.48 | J14: 0.9586 | K14: 40.89
A15: 11 | B15: Moody's Corporation | C15: MCO | D15: United States | E15: Financials | F15: 78.89 | G15: 0.2254 | H15: 0.6815 | I15: 1.16 | J15: 0.7621 | K15: 35.31
A16: 12 | B16: MSCI Inc. | C16: MSCI | D16: United States | E16: Financials | F16: 42 | G16: 0.3273 | H16: 0.7629 | I16: 2.94 | J16: 0.8089 | K16: 32.18
A17: 13 | B17: Intercontinental Exchange | C17: ICE | D17: United States | E17: Financials | F17: 89.93 | G17: 0.0709 | H17: 0.6846 | I17: 2.64 | J17: 0.9605 | K17: 18.37
... A19: 15 | B19: Novo Nordisk A/S | C19: NOVO B | D19: Denmark | E19: Healthcare | F19: 162 | G19: 0.3751 | H19: 0.8034 | I19: 0.69 | J19: 0.0703 | K19: 7.94
A20: 16 | B20: Idexx Laboratories | C20: IDXX | D20: United States | E20: Healthcare | F20: =46.44 -> 46.44 | G20: 0.5016 | H20: 0.6182 | I20: 0.44 | J20: 0.9943 | K20: 44.09
A21: 17 | B21: Danaher Corporation | C21: DHR | D21: United States | E21: Healthcare | F21: =135.82 -> 135.82 | G21: 0.0522 | H21: 0.5923 | I21: 1.79 | J21: 1.2172 | K21: 36.3
A22: 18 | B22: Align Technology | C22: ALGN | D22: United States | E22: Healthcare | F22: =13.16 -> 13.16 | G22: =0.1017 -> 0.1017 | H22: 0.698 | I22: =-1.29 -> -1.29 | J22: 1.196 | K22: 51.32
A23: 19 | B23: West Pharmaceutical Services | C23: WST | D23: United States | E23: Healthcare | F23: =17.55 -> 17.55 | G23: 0.1532 | H23: 0.3592 | I23: =-0.72 -> -0.72 | J23: 0.8258 | K23: 39.18
A24: 20 | B24: LVMH Moët Hennessy | C24: MC | D24: France | E24: Consumer Discretionary | F24: =269.17 -> 269.17 | G24: 0.1159 | H24: 0.6624 | I24: 0.94 | J24: 0.7662 | K24: 157.79
A25: 21 | B25: Hermès International | C25: RMS | D25: France | E25: Consumer Discretionary | F25: =200.53 -> 200.53 | G25: =0.226 -> 0.226 | H25: 0.6655 | I25: =-1.32 -> -1.32 | J25: 0.3674 | K25: 144.1
A26: 22 | B26: L'Oréal S.A. | C26: OR | D26: France | E26: Consumer Staples | F26: =213.78 -> 213.78 | G26: 0.1456 | H26: 0.7432 | I26: 0.19 | J26: 0.5295 | K26: =85.6 -> 85.6
A27: 23 | B27: Ferrari N.V. | C27: RACE | D27: Italy | E27: Consumer Discretionary | F27: =56.88 -> 56.88 | G27: 0.2806 | H27: 0.5246 | I27: 0.48 | J27: 0.8356 | K27: 37.78
A28: 24 | B28: Diageo plc | C28: DGE | D28: United Kingdom | E28: Consumer Staples | F28: =41.18 -> 41.18 | G28: 0.0785 | H28: 0.6049 | I28: 3.16 | J28: 0.1644 | K28: 9.07
A29: 25 | B29: ASML Holding N.V. | C29: ASML | D29: Netherlands | E29: Technology | F29: =498.56 -> 498.56 | G29: 0.428 | H29: 0.5156 | I29: =-0.72 -> -0.72 | J29: 0.8882 | K29: 64.86
A30: 26 | B30: Fastenal Company | C30: FAST | D30: United States | E30: Industrials | F30: =51.19 -> 51.19 | G30: 0.3076 | H30: 0.4296 | I30: =-0.08 -> -0.08 | J30: 0.0369 | K30: 6.28
A31: 27 | B31: Copart Inc. | C31: CPRT | D31: United States | E31: Industrials | F31: =32.4 -> 32.4 | G31: 0.1838 | H31: 0.4467 | I31: -2.5 | J31: 0.7928 | K31: 3.91
A32: 28 | B32: Roper Technologies | C32: ROP | D32: United States | E32: Industrials | F32: =36.65 -> 36.65 | G32: 0.0566 | H32: 0.6924 | I32: 2.87 | J32: 1.3916 | K32: 60.06
A33: 29 | B33: Rational AG | C33: RAA | D33: Germany | E33: Industrials | F33: =8.13 -> 8.13 | G33: 0.2766 | H33: 0.5902 | I33: =-1.39 -> -1.39 | J33: 0.2348 | K33: 109.69
A34: 30 | B34: Verisk Analytics | C34: VRSK | D34: United States | E34: Industrials | F34: =27.69 -> 27.69 | G34: 0.2803 | H34: 0.5925 | I34: 1.5 | J34: 1.0358 | K34: 18.88
A35: 31 | B35: TransUnion | C35: TRU | D35: United States | E35: Financials | F35: 14 | G35: 0.0487 | H35: 0.4653 | I35: 2.84 | J35: 1.2541 | K35: 19.78
A36: 32 | B36: Taiwan Semiconductor | C36: 2330-TW | D36: Taiwan | E36: Technology | F36: =1490.22 -> 1490.22 | G36: 0.2956 | H36: 0.5872 | I36: =-0.76 -> -0.76 | J36: 0.3557 | K36: 3.05
A37: 33 | B37: Keyence Corporation | C37: 6861 | D37: Japan | E37: Technology | F37: =90.59 -> 90.59 | G37: 0.1348 | H37: 0.8381 | I37: =-2.16 -> -2.16 | J37: 0.7936 | K37: 23.3
A38: 34 | B38: EssilorLuxottica | C38: EL | D38: France | E38: Healthcare | F38: =104.6 -> 104.6 | G38: 0.047 | H38: 0.6061 | I38: =1.68 -> 1.68 | J38: 1.517 | K38: 63.68
A39: 35 | B39: Mettler-Toledo International | C39: MTD | D39: Switzerland | E39: Healthcare | F39: =25.28 -> 25.28 | G39: 0.4418 | H39: 0.5752 | I39: =1.68 -> 1.68 | J39: 0.9764 | K39: 175.97
A41: Input Legend: | B41: Yellow cells = user input required (fill from annual reports / Bloomberg)
B42: Quality Score = composite rank across 5 metrics (auto-calculated when all 5 inputs are filled)

Sheet Factor Screen
A1: GLOBAL QUALITY COMPOUNDER PORTFOLIO — FACTOR SCORING MODEL
A2: Quality Factor Screen — Each stock scored 1–5 per factor. Composite score = weighted average. Yellow cells = raw metric inputs. Scores auto-calculate via IF/PERCENTRANK logic.
A4: FACTOR WEIGHTS (must sum to 100%) | P4: RANKED SHORTLIST — TOP 20 BY COMPOSITE SCORE
A5: Factor: | B5: ROIC vs WACC Spread | C5: 0.3 | D5: Gross Margin Stability | E5: 0.2 | F5: Balance Sheet Strength | G5: 0.2 | H5: FCF Conversion | I5: 0.2 | J5: Earnings Consistency | K5: 0.1 | M5: Sum: | N5: =C5+E5+G5+I5+K5 -> 1 | P5: Auto-ranked from composite scores. 'In Portfolio?' links live to Portfolio tab. Top 15 scores = primary candidates.
A7: Scoring Scale: | B7: 5 = Top quintile (>80th pctile) | 4 = Second quintile (60–80th) | 3 = Middle (40–60th) | 2 = Below avg (20–40th) | 1 = Bottom quintile (<20th pctile) | P7: RANK | Q7: COMPANY | R7: TICKER | S7: COMPOSITE SCORE | T7: ROIC Score | U7: GM Score | V7: BS Score | W7: FCF Score | X7: EARN Score | Y7: IN PORTFOLIO?
A8: # | B8: COMPANY | C8: TICKER | D8: ROIC (%) [Input] | E8: ROIC Score | F8: GROSS MARGIN (%) [Input] | G8: GM Score | H8: NET DEBT/EBITDA [Input] | I8: BS Score | J8: FCF CONV (%) [Input] | K8: FCF Score | L8: 5Y REV AVG PER SH (FY 21-25) ($) | M8: Earn Score | N8: COMPOSITE SCORE | P8: 1 | Q8: {=IFERROR(INDEX($B$9:$B$43,MATCH(LARGE($N$9:$N$43+(ROW($N$9:$N$43)-ROW($N$9))/1000,1),$N$9:$N$43+(ROW($N$9:$N$43)-ROW($N$9))/1000,0)),"")} -> Mastercard Incorporated | R8: {=IFERROR(INDEX($C$9:$C$43,MATCH(LARGE($N$9:$N$43+(ROW($N$9:$N$43)-ROW($N$9))/1000,1),$N$9:$N$43+(ROW($N$9:$N$43)-ROW($N$9))/1000,0)),"")} -> MA | S8: {=IFERROR(INDEX($N$9:$N$43,MATCH(LARGE($N$9:$N$43+(ROW($N$9:$N$43)-ROW($N$9))/1000,1),$N$9:$N$43+(ROW($N$9:$N$43)-ROW($N$9))/1000,0)),"")} -> 4.2 | T8: {=IFERROR(INDEX($E$9:$E$43,MATCH(LARGE($N$9:$N$43+(ROW($N$9:$N$43)-ROW($N$9))/1000,1),$N$9:$N$43+(ROW($N$9:$N$43)-ROW($N$9))/1000,0)),"")} -> 5 | U8: {=IFERROR(INDEX($G$9:$G$43,MATCH(LARGE($N$9:$N$43+(ROW($N$9:$N$43)-ROW($N$9))/1000,1),$N$9:$N$43+(ROW($N$9:$N$43)-ROW($N$9))/1000,0)),"")} -> 5 | V8: {=IFERROR(INDEX($I$9:$I$43,MATCH(LARGE($N$9:$N$43+(ROW($N$9:$N$43)-ROW($N$9))/1000,1),$N$9:$N$43+(ROW($N$9:$N$43)-ROW($N$9))/1000,0)),"")} -> 3 | W8: {=IFERROR(INDEX($K$9:$K$43,MATCH(LARGE($N$9:$N$43+(ROW($N$9:$N$43)-ROW($N$9))/1000,1),$N$9:$N$43+(ROW($N$9:$N$43)-ROW($N$9))/1000,0)),"")} -> 4 | X8: {=IFERROR(INDEX($M$9:$M$43,MATCH(LARGE($N$9:$N$43+(ROW($N$9:$N$43)-ROW($N$9))/1000,1),$N$9:$N$43+(ROW($N$9:$N$43)-ROW($N$9))/1000,0)),"")} -> 3 | Y8: =IF(R8="","",IF(COUNTIF(Portfolio!$C$5:$C$19,R8)>0,"YES","-")) -> YES
A9: 1 | B9: Microsoft Corporation | C9: MSFT | D9: =Universe!G5 -> 0.256 | E9: =IF(D9="","",MAX(1,MIN(5,1+INT(IFERROR(PERCENTRANK(D$9:D$43,D9),0.5)*5)))) -> 3 | F9: =Universe!H5 -> 0.6882 | G9: =IF(F9="","",MAX(1,MIN(5,1+INT(IFERROR(PERCENTRANK(F$9:F$43,F9),0.5)*5)))) -> 4 | H9: =Universe!I5 -> -0.03 | I9: =IF(H9="","",MAX(1,MIN(5,5-INT(IFERROR(PERCENTRANK(H$9:H$43,H9),0.5)*5)))) -> 4 | J9: =Universe!J5 -> 0.4667 | K9: =IF(J9="","",MAX(1,MIN(5,1+INT(IFERROR(PERCENTRANK(J$9:J$43,J9),0.5)*5)))) -> 1 | L9: =Universe!K5 -> 29.46 | M9: =IF(L9="","",MAX(1,MIN(5,1+INT(IFERROR(PERCENTRANK(L$9:L$43,L9),0.5)*5)))) -> 3 | N9: =IF(COUNTA(D9,F9,H9,J9,L9)<5,"",E9*C5+G9*E5+I9*G5+K9*I5+M9*K5) -> 3 | P9: 2 | Q9: {=IFERROR(INDEX($B$9:$B$43,MATCH(LARGE($N$9:$N$43+(ROW($N$9:$N$43)-ROW($N$9))/1000,2),$N$9:$N$43+(ROW($N$9:$N$43)-ROW($N$9))/1000,0)),"")} -> Idexx Laboratories | R9: {=IFERROR(INDEX($C$9:$C$43,MATCH(LARGE($N$9:$N$43+(ROW($N$9:$N$43)-ROW($N$9))/1000,2),$N$9:$N$43+(ROW($N$9:$N$43)-ROW($N$9))/1000,0)),"")} -> IDXX | S9: {=IFERROR(INDEX($N$9:$N$43,MATCH(LARGE($N$9:$N$43+(ROW($N$9:$N$43)-ROW($N$9))/1000,2),$N$9:$N$43+(ROW($N$9:$N$43)-ROW($N$9))/1000,0)),"")} -> 3.9 | T9: {=IFERROR(INDEX($E$9:$E$43,MATCH(LARGE($N$9:$N$43+(ROW($N$9:$N$43)-ROW($N$9))/1000,2),$N$9:$N$43+(ROW($N$9:$N$43)-ROW($N$9))/1000,0)),"")} -> 5 | U9: {=IFERROR(INDEX($G$9:$G$43,MATCH(LARGE($N$9:$N$43+(ROW($N$9:$N$43)-ROW($N$9))/1000,2),$N$9:$N$43+(ROW($N$9:$N$43)-ROW($N$9))/1000,0)),"")} -> 3 | V9: {=IFERROR(INDEX($I$9:$I$43,MATCH(LARGE($N$9:$N$43+(ROW($N$9:$N$43)-ROW($N$9))/1000,2),$N$9:$N$43+(ROW($N$9:$N$43)-ROW($N$9))/1000,0)),"")} -> 3 | W9: {=IFERROR(INDEX($K$9:$K$43,MATCH(LARGE($N$9:$N$43+(ROW($N$9:$N$43)-ROW($N$9))/1000,2),$N$9:$N$43+(ROW($N$9:$N$43)-ROW($N$9))/1000,0)),"")} -> 4 | X9: {=IFERROR(INDEX($M$9:$M$43,MATCH(LARGE($N$9:$N$43+(ROW($N$9:$N$43)-ROW($N$9))/1000,2),$N$9:$N$43+(ROW($N$9:$N$43)-ROW($N$9))/1000,0)),"")} -> 4 | Y9: =IF(R9="","",IF(COUNTIF(Portfolio!$C$5:$C$19,R9)>0,"YES","-")) -> YES
A10: 2 | B10: Accenture plc | C10: ACN | D10: =Universe!G6 -> 0.221 | E10: =IF(D10="","",MAX(1,MIN(5,1+INT(IFERROR(PERCENTRANK(D$9:D$43,D10),0.5)*5)))) -> 3 | F10: =Universe!H6 -> 0.319 | G10: =IF(F10="","",MAX(1,MIN(5,1+INT(IFERROR(PERCENTRANK(F$9:F$43,F10),0.5)*5)))) -> 1 | H10: =Universe!I6 -> -0.51 | I10: =IF(H10="","",MAX(1,MIN(5,5-INT(IFERROR(PERCENTRANK(H$9:H$43,H10),0.5)*5)))) -> 4 | J10: =Universe!J6 -> 0.9348 | K10: =IF(J10="","",MAX(1,MIN(5,1+INT(IFERROR(PERCENTRANK(J$9:J$43,J10),0.5)*5)))) -> 3 | L10: =Universe!K6 -> 97.33 | M10: =IF(L10="","",MAX(1,MIN(5,1+INT(IFERROR(PERCENTRANK(L$9:L$43,L10),0.5)*5)))) -> 5 | N10: =IF(COUNTA(D10,F10,H10,J10,L10)<5,"",E10*C5+G10*E5+I10*G5+K10*I5+M10*K5) -> 3 | P10: 3 | Q10: {=IFERROR(INDEX($B$9:$B$43,MATCH(LARGE($N$9:$N$43+(ROW($N$9:$N$43)-ROW($N$9))/1000,3),$N$9:$N$43+(ROW($N$9:$N$43)-ROW($N$9))/1000,0)),"")} -> Visa Inc. | R10: {=IFERROR(INDEX($C$9:$C$43,MATCH(LARGE($N$9:$N$43+(ROW($N$9:$N$43)-ROW($N$9))/1000,3),$N$9:$N$43+(ROW($N$9:$N$43)-ROW($N$9))/1000,0)),"")} -> V | S10: {=IFERROR(INDEX($N$9:$N$43,MATCH(LARGE($N$9:$N$43+(ROW($N$9:$N$43)-ROW($N$9))/1000,3),$N$9:$N$43+(ROW($N$9:$N$43)-ROW($N$9))/1000,0)),"")} -> 3.8 | T10: {=IFERROR(INDEX($E$9:$E$43,MATCH(LARGE($N$9:$N$43+(ROW($N$9:$N$43)-ROW($N$9))/1000,3),$N$9:$N$43+(ROW($N$9:$N$43)-ROW($N$9))/1000,0)),"")} -> 4 | U10: {=IFERROR(INDEX($G$9:$G$43,MATCH(LARGE($N$9:$N$43+(ROW($N$9:$N$43)-ROW($N$9))/1000,3),$N$9:$N$43+(ROW($N$9:$N$43)-ROW($N$9))/1000,0)),"")} -> 5 | V10: {=IFERROR(INDEX($I$9:$I$43,MATCH(LARGE($N$9:$N$43+(ROW($N$9:$N$43)-ROW($N$9))/1000,3),$N$9:$N$43+(ROW($N$9:$N$43)-ROW($N$9))/1000,0)),"")} -> 4 | W10: {=IFERROR(INDEX($K$9:$K$43,MATCH(LARGE($N$9:$N$43+(ROW($N$9:$N$43)-ROW($N$9))/1000,3),$N$9:$N$43+(ROW($N$9:$N$43)-ROW($N$9))/1000,0)),"")} -> 3 | X10: {=IFERROR(INDEX($M$9:$M$43,MATCH(LARGE($N$9:$N$43+(ROW($N$9:$N$43)-ROW($N$9))/1000,3),$N$9:$N$43+(ROW($N$9:$N$43)-ROW($N$9))/1000,0)),"")} -> 2 | Y10: =IF(R10="","",IF(COUNTIF(Portfolio!$C$5:$C$19,R10)>0,"YES","-")) -> YES
A11: 3 | B11: Automatic Data Processing | C11: ADP | D11: =Universe!G7 -> 0.4446 | E11: =IF(D11="","",MAX(1,MIN(5,1+INT(IFERROR(PERCENTRANK(D$9:D$43,D11),0.5)*5)))) -> 5 | F11: =Universe!H7 -> 0.5037 | G11: =IF(F11="","",MAX(1,MIN(5,1+INT(IFERROR(PERCENTRANK(F$9:F$43,F11),0.5)*5)))) -> 1 | H11: =Universe!I7 -> 0.16 | I11: =IF(H11="","",MAX(1,MIN(5,5-INT(IFERROR(PERCENTRANK(H$9:H$43,H11),0.5)*5)))) -> 3 | J11: =Universe!J7 -> 0.5814 | K11: =IF(J11="","",MAX(1,MIN(5,1+INT(IFERROR(PERCENTRANK(J$9:J$43,J11),0.5)*5)))) -> 2 | L11: =Universe!K7 -> 42.89 | M11: =IF(L11="","",MAX(1,MIN(5,1+INT(IFERROR(PERCENTRANK(L$9:L$43,L11),0.5)*5)))) -> 4 | N11: =IF(COUNTA(D11,F11,H11,J11,L11)<5,"",E11*C5+G11*E5+I11*G5+K11*I5+M11*K5) -> 3.1 | P11: 4 | Q11: {=IFERROR(INDEX($B$9:$B$43,MATCH(LARGE($N$9:$N$43+(ROW($N$9:$N$43)-ROW($N$9))/1000,4),$N$9:$N$43+(ROW($N$9:$N$43)-ROW($N$9))/1000,0)),"")} -> Rightmove | R11: {=IFERROR(INDEX($C$9:$C$43,MATCH(LARGE($N$9:$N$43+(ROW($N$9:$N$43)-ROW($N$9))/1000,4),$N$9:$N$43+(ROW($N$9:$N$43)-ROW($N$9))/1000,0)),"")} -> RMV | S11: {=IFERROR(INDEX($N$9:$N$43,MATCH(LARGE($N$9:$N$43+(ROW($N$9:$N$43)-ROW($N$9))/1000,4),$N$9:$N$43+(ROW($N$9:$N$43)-ROW($N$9))/1000,0)),"")} -> 3.8 | T11: {=IFERROR(INDEX($E$9:$E$43,MATCH(LARGE($N$9:$N$43+(ROW($N$9:$N$43)-ROW($N$9))/1000,4),$N$9:$N$43+(ROW($N$9:$N$43)-ROW($N$9))/1000,0)),"")} -> 5 | U11: {=IFERROR(INDEX($G$9:$G$43,MATCH(LARGE($N$9:$N$43+(ROW($N$9:$N$43)-ROW($N$9))/1000,4),$N$9:$N$43+(ROW($N$9:$N$43)-ROW($N$9))/1000,0)),"")} -> 5 | V11: {=IFERROR(INDEX($I$9:$I$43,MATCH(LARGE($N$9:$N$43+(ROW($N$9:$N$43)-ROW($N$9))/1000,4),$N$9:$N$43+(ROW($N$9:$N$43)-ROW($N$9))/1000,0)),"")} -> 4 | W11: {=IFERROR(INDEX($K$9:$K$43,MATCH(LARGE($N$9:$N$43+(ROW($N$9:$N$43)-ROW($N$9))/1000,4),$N$9:$N$43+(ROW($N$9:$N$43)-ROW($N$9))/1000,0)),"")} -> 2 | X11: {=IFERROR(INDEX($M$9:$M$43,MATCH(LARGE($N$9:$N$43+(ROW($N$9:$N$43)-ROW($N$9))/1000,4),$N$9:$N$43+(ROW($N$9:$N$43)-ROW($N$9))/1000,0)),"")} -> 1 | Y11: =IF(R11="","",IF(COUNTIF(Portfolio!$C$5:$C$19,R11)>0,"YES","-")) -> YES
A12: 4 | B12: Veeva Systems | C12: VEEV | D12: =Universe!G8 -> 0.1377 | E12: =IF(D12="","",MAX(1,MIN(5,1+INT(IFERROR(PERCENTRANK(D$9:D$43,D12),0.5)*5)))) -> 2 | F12: =Universe!H8 -> 0.752 | G12: =IF(F12="","",MAX(1,MIN(5,1+INT(IFERROR(PERCENTRANK(F$9:F$43,F12),0.5)*5)))) -> 5 | H12: =Universe!I8 -> -6.58 | I12: =IF(H12="","",MAX(1,MIN(5,5-INT(IFERROR(PERCENTRANK(H$9:H$43,H12),0.5)*5)))) -> 5 | J12: =Universe!J8 -> 1.525 | K12: =IF(J12="","",MAX(1,MIN(5,1+INT(IFERROR(PERCENTRANK(J$9:J$43,J12),0.5)*5)))) -> 5 | L12: =Universe!K8 -> 14.98 | M12: =IF(L12="","",MAX(1,MIN(5,1+INT(IFERROR(PERCENTRANK(L$9:L$43,L12),0.5)*5)))) -> 1 | N12: =IF(COUNTA(D12,F12,H12,J12,L12)<5,"",E12*C5+G12*E5+I12*G5+K12*I5+M12*K5) -> 3.7 | P12: 5 | Q12: {=IFERROR(INDEX($B$9:$B$43,MATCH(LARGE($N$9:$N$43+(ROW($N$9:$N$43)-ROW($N$9))/1000,5),$N$9:$N$43+(ROW($N$9:$N$43)-ROW($N$9))/1000,0)),"")} -> ASML Holding N.V. | R12: {=IFERROR(INDEX($C$9:$C$43,MATCH(LARGE($N$9:$N$43+(ROW($N$9:$N$43)-ROW($N$9))/1000,5),$N$9:$N$43+(ROW($N$9:$N$43)-ROW($N$9))/1000,0)),"")} -> ASML | S12: {=IFERROR(INDEX($N$9:$N$43,MATCH(LARGE($N$9:$N$43+(ROW($N$9:$N$43)-ROW($N$9))/1000,5),$N$9:$N$43+(ROW($N$9:$N$43)-ROW($N$9))/1000,0)),"")} -> 3.7 | T12: {=IFERROR(INDEX($E$9:$E$43,MATCH(LARGE($N$9:$N$43+(ROW($N$9:$N$43)-ROW($N$9))/1000,5),$N$9:$N$43+(ROW($N$9:$N$43)-ROW($N$9))/1000,0)),"")} -> 5 | U12: {=IFERROR(INDEX($G$9:$G$43,MATCH(LARGE($N$9:$N$43+(ROW($N$9:$N$43)-ROW($N$9))/1000,5),$N$9:$N$43+(ROW($N$9:$N$43)-ROW($N$9))/1000,0)),"")} -> 2 | V12: {=IFERROR(INDEX($I$9:$I$43,MATCH(LARGE($N$9:$N$43+(ROW($N$9:$N$43)-ROW($N$9))/1000,5),$N$9:$N$43+(ROW($N$9:$N$43)-ROW($N$9))/1000,0)),"")} -> 4 | W12: {=IFERROR(INDEX($K$9:$K$43,MATCH(LARGE($N$9:$N$43+(ROW($N$9:$N$43)-ROW($N$9))/1000,5),$N$9:$N$43+(ROW($N$9:$N$43)-ROW($N$9))/1000,0)),"")} -> 3 | X12: {=IFERROR(INDEX($M$9:$M$43,MATCH(LARGE($N$9:$N$43+(ROW($N$9:$N$43)-ROW($N$9))/1000,5),$N$9:$N$43+(ROW($N$9:$N$43)-ROW($N$9))/1000,0)),"")} -> 4 | Y12: =IF(R12="","",IF(COUNTIF(Portfolio!$C$5:$C$19,R12)>0,"YES","-")) -> YES
A13: 5 | B13: Constellation Software | C13: CSU | D13: =Universe!G9 -> 0.0707 | E13: =IF(D13="","",MAX(1,MIN(5,1+INT(IFERROR(PERCENTRANK(D$9:D$43,D13),0.5)*5)))) -> 1 | F13: =Universe!H9 -> 0.3958 | G13: =IF(F13="","",MAX(1,MIN(5,1+INT(IFERROR(PERCENTRANK(F$9:F$43,F13),0.5)*5)))) -> 1 | H13: =Universe!I9 -> 0.79 | I13: =IF(H13="","",MAX(1,MIN(5,5-INT(IFERROR(PERCENTRANK(H$9:H$43,H13),0.5)*5)))) -> 3 | J13: =Universe!J9 -> 4.764 | K13: =IF(J13="","",MAX(1,MIN(5,1+INT(IFERROR(PERCENTRANK(J$9:J$43,J13),0.5)*5)))) -> 5 | L13: =Universe!K9 -> 390 | M13: =IF(L13="","",MAX(1,MIN(5,1+INT(IFERROR(PERCENTRANK(L$9:L$43,L13),0.5)*5)))) -> 5 | N13: =IF(COUNTA(D13,F13,H13,J13,L13)<5,"",E13*C5+G13*E5+I13*G5+K13*I5+M13*K5) -> 2.6 | P13: 6 | Q13: {=IFERROR(INDEX($B$9:$B$43,MATCH(LARGE($N$9:$N$43+(ROW($N$9:$N$43)-ROW($N$9))/1000,6),$N$9:$N$43+(ROW($N$9:$N$43)-ROW($N$9))/1000,0)),"")} -> Veeva Systems | R13: {=IFERROR(INDEX($C$9:$C$43,MATCH(LARGE($N$9:$N$43+(ROW($N$9:$N$43)-ROW($N$9))/1000,6),$N$9:$N$43+(ROW($N$9:$N$43)-ROW($N$9))/1000,0)),"")} -> VEEV | S13: {=IFERROR(INDEX($N$9:$N$43,MATCH(LARGE($N$9:$N$43+(ROW($N$9:$N$43)-ROW($N$9))/1000,6),$N$9:$N$43+(ROW($N$9:$N$43)-ROW($N$9))/1000,0)),"")} -> 3.7 | T13: {=IFERROR(INDEX($E$9:$E$43,MATCH(LARGE($N$9:$N$43+(ROW($N$9:$N$43)-ROW($N$9))/1000,6),$N$9:$N$43+(ROW($N$9:$N$43)-ROW($N$9))/1000,0)),"")} -> 2 | U13: {=IFERROR(INDEX($G$9:$G$43,MATCH(LARGE($N$9:$N$43+(ROW($N$9:$N$43)-ROW($N$9))/1000,6),$N$9:$N$43+(ROW($N$9:$N$43)-ROW($N$9))/1000,0)),"")} -> 5 | V13: {=IFERROR(INDEX($I$9:$I$43,MATCH(LARGE($N$9:$N$43+(ROW($N$9:$N$43)-ROW($N$9))/1000,6),$N$9:$N$43+(ROW($N$9:$N$43)-ROW($N$9))/1000,0)),"")} -> 5 | W13: {=IFERROR(INDEX($K$9:$K$43,MATCH(LARGE($N$9:$N$43+(ROW($N$9:$N$43)-ROW($N$9))/1000,6),$N$9:$N$43+(ROW($N$9:$N$43)-ROW($N$9))/1000,0)),"")} -> 5 | X13: {=IFERROR(INDEX($M$9:$M$43,MATCH(LARGE($N$9:$N$43+(ROW($N$9:$N$43)-ROW($N$9))/1000,6),$N$9:$N$43+(ROW($N$9:$N$43)-ROW($N$9))/1000,0)),"")} -> 1 | Y13: =IF(R13="","",IF(COUNTIF(Portfolio!$C$5:$C$19,R13)>0,"YES","-")) -> YES
A14: 6 | B14: Wolters Kluwer | C14: WKL | D14: =Universe!G10 -> 0.2565 | E14: =IF(D14="","",MAX(1,MIN(5,1+INT(IFERROR(PERCENTRANK(D$9:D$43,D14),0.5)*5)))) -> 3 | F14: =Universe!H10 -> 0.6591 | G14: =IF(F14="","",MAX(1,MIN(5,1+INT(IFERROR(PERCENTRANK(F$9:F$43,F14),0.5)*5)))) -> 3 | H14: =Universe!I10 -> 2.01 | I14: =IF(H14="","",MAX(1,MIN(5,5-INT(IFERROR(PERCENTRANK(H$9:H$43,H14),0.5)*5)))) -> 1 | J14: =Universe!J10 -> 0.8287 | K14: =IF(J14="","",MAX(1,MIN(5,1+INT(IFERROR(PERCENTRANK(J$9:J$43,J14),0.5)*5)))) -> 3 | L14: =Universe!K10 -> 26.31 | M14: =IF(L14="","",MAX(1,MIN(5,1+INT(IFERROR(PERCENTRANK(L$9:L$43,L14),0.5)*5)))) -> 2 | N14: =IF(COUNTA(D14,F14,H14,J14,L14)<5,"",E14*C5+G14*E5+I14*G5+K14*I5+M14*K5) -> 2.5 | P14: 7 | Q14: {=IFERROR(INDEX($B$9:$B$43,MATCH(LARGE($N$9:$N$43+(ROW($N$9:$N$43)-ROW($N$9))/1000,7),$N$9:$N$43+(ROW($N$9:$N$43)-ROW($N$9))/1000,0)),"")} -> Mettler-Toledo International | R14: {=IFERROR(INDEX($C$9:$C$43,MATCH(LARGE($N$9:$N$43+(ROW($N$9:$N$43)-ROW($N$9))/1000,7),$N$9:$N$43+(ROW($N$9:$N$43)-ROW($N$9))/1000,0)),"")} -> MTD | S14: {=IFERROR(INDEX($N$9:$N$43,MATCH(LARGE($N$9:$N$43+(ROW($N$9:$N$43)-ROW($N$9))/1000,7),$N$9:$N$43+(ROW($N$9:$N$43)-ROW($N$9))/1000,0)),"")} -> 3.6 | T14: {=IFERROR(INDEX($E$9:$E$43,MATCH(LARGE($N$9:$N$43+(ROW($N$9:$N$43)-ROW($N$9))/1000,7),$N$9:$N$43+(ROW($N$9:$N$43)-ROW($N$9))/1000,0)),"")} -> 5 | U14: {=IFERROR(INDEX($G$9:$G$43,MATCH(LARGE($N$9:$N$43+(ROW($N$9:$N$43)-ROW($N$9))/1000,7),$N$9:$N$43+(ROW($N$9:$N$43)-ROW($N$9))/1000,0)),"")} -> 2 | V14: {=IFERROR(INDEX($I$9:$I$43,MATCH(LARGE($N$9:$N$43+(ROW($N$9:$N$43)-ROW($N$9))/1000,7),$N$9:$N$43+(ROW($N$9:$N$43)-ROW($N$9))/1000,0)),"")} -> 2 | W14: {=IFERROR(INDEX($K$9:$K$43,MATCH(LARGE($N$9:$N$43+(ROW($N$9:$N$43)-ROW($N$9))/1000,7),$N$9:$N$43+(ROW($N$9:$N$43)-ROW($N$9))/1000,0)),"")} -> 4 | X14: {=IFERROR(INDEX($M$9:$M$43,MATCH(LARGE($N$9:$N$43+(ROW($N$9:$N$43)-ROW($N$9))/1000,7),$N$9:$N$43+(ROW($N$9:$N$43)-ROW($N$9))/1000,0)),"")} -> 5 | Y14: =IF(R14="","",IF(COUNTIF(Portfolio!$C$5:$C$19,R14)>0,"YES","-")) -> YES
A15: 7 | B15: Rightmove | C15: RMV | D15: =Universe!G11 -> 2.547 | E15: =IF(D15="","",MAX(1,MIN(5,1+INT(IFERROR(PERCENTRANK(D$9:D$43,D15),0.5)*5)))) -> 5 | F15: =Universe!H11 -> 0.984 | G15: =IF(F15="","",MAX(1,MIN(5,1+INT(IFERROR(PERCENTRANK(F$9:F$43,F15),0.5)*5)))) -> 5 | H15: =Universe!I11 -> -0.12 | I15: =IF(H15="","",MAX(1,MIN(5,5-INT(IFERROR(PERCENTRANK(H$9:H$43,H15),0.5)*5)))) -> 4 | J15: =Universe!J11 -> 0.7337 | K15: =IF(J15="","",MAX(1,MIN(5,1+INT(IFERROR(PERCENTRANK(J$9:J$43,J15),0.5)*5)))) -> 2 | L15: =Universe!K11 -> 0.6 | M15: =IF(L15="","",MAX(1,MIN(5,1+INT(IFERROR(PERCENTRANK(L$9:L$43,L15),0.5)*5)))) -> 1 | N15: =IF(COUNTA(D15,F15,H15,J15,L15)<5,"",E15*C5+G15*E5+I15*G5+K15*I5+M15*K5) -> 3.8 | P15: 8 | Q15: {=IFERROR(INDEX($B$9:$B$43,MATCH(LARGE($N$9:$N$43+(ROW($N$9:$N$43)-ROW($N$9))/1000,8),$N$9:$N$43+(ROW($N$9:$N$43)-ROW($N$9))/1000,0)),"")} -> Align Technology | R15: {=IFERROR(INDEX($C$9:$C$43,MATCH(LARGE($N$9:$N$43+(ROW($N$9:$N$43)-ROW($N$9))/1000,8),$N$9:$N$43+(ROW($N$9:$N$43)-ROW($N$9))/1000,0)),"")} -> ALGN | S15: {=IFERROR(INDEX($N$9:$N$43,MATCH(LARGE($N$9:$N$43+(ROW($N$9:$N$43)-ROW($N$9))/1000,8),$N$9:$N$43+(ROW($N$9:$N$43)-ROW($N$9))/1000,0)),"")} -> 3.6 | T15: {=IFERROR(INDEX($E$9:$E$43,MATCH(LARGE($N$9:$N$43+(ROW($N$9:$N$43)-ROW($N$9))/1000,8),$N$9:$N$43+(ROW($N$9:$N$43)-ROW($N$9))/1000,0)),"")} -> 2 | U15: {=IFERROR(INDEX($G$9:$G$43,MATCH(LARGE($N$9:$N$43+(ROW($N$9:$N$43)-ROW($N$9))/1000,8),$N$9:$N$43+(ROW($N$9:$N$43)-ROW($N$9))/1000,0)),"")} -> 4 | V15: {=IFERROR(INDEX($I$9:$I$43,MATCH(LARGE($N$9:$N$43+(ROW($N$9:$N$43)-ROW($N$9))/1000,8),$N$9:$N$43+(ROW($N$9:$N$43)-ROW($N$9))/1000,0)),"")} -> 5 | W15: {=IFERROR(INDEX($K$9:$K$43,MATCH(LARGE($N$9:$N$43+(ROW($N$9:$N$43)-ROW($N$9))/1000,8),$N$9:$N$43+(ROW($N$9:$N$43)-ROW($N$9))/1000,0)),"")} -> 4 | X15: {=IFERROR(INDEX($M$9:$M$43,MATCH(LARGE($N$9:$N$43+(ROW($N$9:$N$43)-ROW($N$9))/1000,8),$N$9:$N$43+(ROW($N$9:$N$43)-ROW($N$9))/1000,0)),"")} -> 4 | Y15: =IF(R15="","",IF(COUNTIF(Portfolio!$C$5:$C$19,R15)>0,"YES","-")) -> YES
A16: 8 | B16: Visa Inc. | C16: V | D16: =Universe!G12 -> 0.3339 | E16: =IF(D16="","",MAX(1,MIN(5,1+INT(IFERROR(PERCENTRANK(D$9:D$43,D16),0.5)*5)))) -> 4 | F16: =Universe!H12 -> 0.7731 | G16: =IF(F16="","",MAX(1,MIN(5,1+INT(IFERROR(PERCENTRANK(F$9:F$43,F16),0.5)*5)))) -> 5 | H16: =Universe!I12 -> 0.07 | I16: =IF(H16="","",MAX(1,MIN(5,5-INT(IFERROR(PERCENTRANK(H$9:H$43,H16),0.5)*5)))) -> 4 | J16: =Universe!J12 -> 0.8534 | K16: =IF(J16="","",MAX(1,MIN(5,1+INT(IFERROR(PERCENTRANK(J$9:J$43,J16),0.5)*5)))) -> 3 | L16: =Universe!K12 -> 15.69 | M16: =IF(L16="","",MAX(1,MIN(5,1+INT(IFERROR(PERCENTRANK(L$9:L$43,L16),0.5)*5)))) -> 2 | N16: =IF(COUNTA(D16,F16,H16,J16,L16)<5,"",E16*C5+G16*E5+I16*G5+K16*I5+M16*K5) -> 3.8 | P16: 9 | Q16: {=IFERROR(INDEX($B$9:$B$43,MATCH(LARGE($N$9:$N$43+(ROW($N$9:$N$43)-ROW($N$9))/1000,9),$N$9:$N$43+(ROW($N$9:$N$43)-ROW($N$9))/1000,0)),"")} -> Hermès International | R16: {=IFERROR(INDEX($C$9:$C$43,MATCH(LARGE($N$9:$N$43+(ROW($N$9:$N$43)-ROW($N$9))/1000,9),$N$9:$N$43+(ROW($N$9:$N$43)-ROW($N$9))/1000,0)),"")} -> RMS | S16: {=IFERROR(INDEX($N$9:$N$43,MATCH(LARGE($N$9:$N$43+(ROW($N$9:$N$43)-ROW($N$9))/1000,9),$N$9:$N$43+(ROW($N$9:$N$43)-ROW($N$9))/1000,0)),"")} -> 3.4 | T16: {=IFERROR(INDEX($E$9:$E$43,MATCH(LARGE($N$9:$N$43+(ROW($N$9:$N$43)-ROW($N$9))/1000,9),$N$9:$N$43+(ROW($N$9:$N$43)-ROW($N$9))/1000,0)),"")} -> 3 | U16: {=IFERROR(INDEX($G$9:$G$43,MATCH(LARGE($N$9:$N$43+(ROW($N$9:$N$43)-ROW($N$9))/1000,9),$N$9:$N$43+(ROW($N$9:$N$43)-ROW($N$9))/1000,0)),"")} -> 4 | V16: {=IFERROR(INDEX($I$9:$I$43,MATCH(LARGE($N$9:$N$43+(ROW($N$9:$N$43)-ROW($N$9))/1000,9),$N$9:$N$43+(ROW($N$9:$N$43)-ROW($N$9))/1000,0)),"")} -> 5 | W16: {=IFERROR(INDEX($K$9:$K$43,MATCH(LARGE($N$9:$N$43+(ROW($N$9:$N$43)-ROW($N$9))/1000,9),$N$9:$N$43+(ROW($N$9:$N$43)-ROW($N$9))/1000,0)),"")} -> 1 | X16: {=IFERROR(INDEX($M$9:$M$43,MATCH(LARGE($N$9:$N$43+(ROW($N$9:$N$43)-ROW($N$9))/1000,9),$N$9:$N$43+(ROW($N$9:$N$43)-ROW($N$9))/1000,0)),"")} -> 5 | Y16: =IF(R16="","",IF(COUNTIF(Portfolio!$C$5:$C$19,R16)>0,"YES","-")) -> YES
A17: 9 | B17: Mastercard Incorporated | C17: MA | D17: =Universe!G13 -> 0.5841 | E17: =IF(D17="","",MAX(1,MIN(5,1+INT(IFERROR(PERCENTRANK(D$9:D$43,D17),0.5)*5)))) -> 5 | F17: =Universe!H13 -> 0.9603 | G17: =IF(F17="","",MAX(1,MIN(5,1+INT(IFERROR(PERCENTRANK(F$9:F$43,F17),0.5)*5)))) -> 5 | H17: =Universe!I13 -> 0.36 | I17: =IF(H17="","",MAX(1,MIN(5,5-INT(IFERROR(PERCENTRANK(H$9:H$43,H17),0.5)*5)))) -> 3 | J17: =Universe!J13 -> 0.9458 | K17: =IF(J17="","",MAX(1,MIN(5,1+INT(IFERROR(PERCENTRANK(J$9:J$43,J17),0.5)*5)))) -> 4 | L17: =Universe!K13 -> 27.02 | M17: =IF(L17="","",MAX(1,MIN(5,1+INT(IFERROR(PERCENTRANK(L$9:L$43,L17),0.5)*5)))) -> 3 | N17: =IF(COUNTA(D17,F17,H17,J17,L17)<5,"",E17*C5+G17*E5+I17*G5+K17*I5+M17*K5) -> 4.2 | P17: 10 | Q17: {=IFERROR(INDEX($B$9:$B$43,MATCH(LARGE($N$9:$N$43+(ROW($N$9:$N$43)-ROW($N$9))/1000,10),$N$9:$N$43+(ROW($N$9:$N$43)-ROW($N$9))/1000,0)),"")} -> Novo Nordisk A/S | R17: {=IFERROR(INDEX($C$9:$C$43,MATCH(LARGE($N$9:$N$43+(ROW($N$9:$N$43)-ROW($N$9))/1000,10),$N$9:$N$43+(ROW($N$9:$N$43)-ROW($N$9))/1000,0)),"")} -> NOVO B | S17: {=IFERROR(INDEX($N$9:$N$43,MATCH(LARGE($N$9:$N$43+(ROW($N$9:$N$43)-ROW($N$9))/1000,10),$N$9:$N$43+(ROW($N$9:$N$43)-ROW($N$9))/1000,0)),"")} -> 3.4 | T17: {=IFERROR(INDEX($E$9:$E$43,MATCH(LARGE($N$9:$N$43+(ROW($N$9:$N$43)-ROW($N$9))/1000,10),$N$9:$N$43+(ROW($N$9:$N$43)-ROW($N$9))/1000,0)),"")} -> 5 | U17: {=IFERROR(INDEX($G$9:$G$43,MATCH(LARGE($N$9:$N$43+(ROW($N$9:$N$43)-ROW($N$9))/1000,10),$N$9:$N$43+(ROW($N$9:$N$43)-ROW($N$9))/1000,0)),"")} -> 5 | V17: {=IFERROR(INDEX($I$9:$I$43,MATCH(LARGE($N$9:$N$43+(ROW($N$9:$N$43)-ROW($N$9))/1000,10),$N$9:$N$43+(ROW($N$9:$N$43)-ROW($N$9))/1000,0)),"")} -> 3 | W17: {=IFERROR(INDEX($K$9:$K$43,MATCH(LARGE($N$9:$N$43+(ROW($N$9:$N$43)-ROW($N$9))/1000,10),$N$9:$N$43+(ROW($N$9:$N$43)-ROW($N$9))/1000,0)),"")} -> 1 | X17: {=IFERROR(INDEX($M$9:$M$43,MATCH(LARGE($N$9:$N$43+(ROW($N$9:$N$43)-ROW($N$9))/1000,10),$N$9:$N$43+(ROW($N$9:$N$43)-ROW($N$9))/1000,0)),"")} -> 1 | Y17: =IF(R17="","",IF(COUNTIF(Portfolio!$C$5:$C$19,R17)>0,"YES","-")) -> YES
A18: 10 | B18: S&P Global Inc. | C18: SPGI | D18: =Universe!G14 -> 0.1004 | E18: =IF(D18="","",MAX(1,MIN(5,1+INT(IFERROR(PERCENTRANK(D$9:D$43,D18),0.5)*5)))) -> 2 | F18: =Universe!H14 -> 0.6256 | G18: =IF(F18="","",MAX(1,MIN(5,1+INT(IFERROR(PERCENTRANK(F$9:F$43,F18),0.5)*5)))) -> 3 | H18: =Universe!I14 -> 1.48 | I18: =IF(H18="","",MAX(1,MIN(5,5-INT(IFERROR(PERCENTRANK(H$9:H$43,H18),0.5)*5)))) -> 2 | J18: =Universe!J14 -> 0.9586 | K18: =IF(J18="","",MAX(1,MIN(5,1+INT(IFERROR(PERCENTRANK(J$9:J$43,J18),0.5)*5)))) -> 4 | L18: =Universe!K14 -> 40.89 | M18: =IF(L18="","",MAX(1,MIN(5,1+INT(IFERROR(PERCENTRANK(L$9:L$43,L18),0.5)*5)))) -> 4 | N18: =IF(COUNTA(D18,F18,H18,J18,L18)<5,"",E18*C5+G18*E5+I18*G5+K18*I5+M18*K5) -> 2.8 | P18: 11 | Q18: {=IFERROR(INDEX($B$9:$B$43,MATCH(LARGE($N$9:$N$43+(ROW($N$9:$N$43)-ROW($N$9))/1000,11),$N$9:$N$43+(ROW($N$9:$N$43)-ROW($N$9))/1000,0)),"")} -> Rational AG | R18: {=IFERROR(INDEX($C$9:$C$43,MATCH(LARGE($N$9:$N$43+(ROW($N$9:$N$43)-ROW($N$9))/1000,11),$N$9:$N$43+(ROW($N$9:$N$43)-ROW($N$9))/1000,0)),"")} -> RAA | S18: {=IFERROR(INDEX($N$9:$N$43,MATCH(LARGE($N$9:$N$43+(ROW($N$9:$N$43)-ROW($N$9))/1000,11),$N$9:$N$43+(ROW($N$9:$N$43)-ROW($N$9))/1000,0)),"")} -> 3.3 | T18: {=IFERROR(INDEX($E$9:$E$43,MATCH(LARGE($N$9:$N$43+(ROW($N$9:$N$43)-ROW($N$9))/1000,11),$N$9:$N$43+(ROW($N$9:$N$43)-ROW($N$9))/1000,0)),"")} -> 4 | U18: {=IFERROR(INDEX($G$9:$G$43,MATCH(LARGE($N$9:$N$43+(ROW($N$9:$N$43)-ROW($N$9))/1000,11),$N$9:$N$43+(ROW($N$9:$N$43)-ROW($N$9))/1000,0)),"")} -> 2 | V18: {=IFERROR(INDEX($I$9:$I$43,MATCH(LARGE($N$9:$N$43+(ROW($N$9:$N$43)-ROW($N$9))/1000,11),$N$9:$N$43+(ROW($N$9:$N$43)-ROW($N$9))/1000,0)),"")} -> 5 | W18: {=IFERROR(INDEX($K$9:$K$43,MATCH(LARGE($N$9:$N$43+(ROW($N$9:$N$43)-ROW($N$9))/1000,11),$N$9:$N$43+(ROW($N$9:$N$43)-ROW($N$9))/1000,0)),"")} -> 1 | X18: {=IFERROR(INDEX($M$9:$M$43,MATCH(LARGE($N$9:$N$43+(ROW($N$9:$N$43)-ROW($N$9))/1000,11),$N$9:$N$43+(ROW($N$9:$N$43)-ROW($N$9))/1000,0)),"")} -> 5 | Y18: =IF(R18="","",IF(COUNTIF(Portfolio!$C$5:$C$19,R18)>0,"YES","-")) -> YES
A19: 11 | B19: Moody's Corporation | C19: MCO | D19: =Universe!G15 -> 0.2254 | E19: =IF(D19="","",MAX(1,MIN(5,1+INT(IFERROR(PERCENTRANK(D$9:D$43,D19),0.5)*5)))) -> 3 | F19: =Universe!H15 -> 0.6815 | G19: =IF(F19="","",MAX(1,MIN(5,1+INT(IFERROR(PERCENTRANK(F$9:F$43,F19),0.5)*5)))) -> 4 | H19: =Universe!I15 -> 1.16 | I19: =IF(H19="","",MAX(1,MIN(5,5-INT(IFERROR(PERCENTRANK(H$9:H$43,H19),0.5)*5)))) -> 2 | J19: =Universe!J15 -> 0.7621 | K19: =IF(J19="","",MAX(1,MIN(5,1+INT(IFERROR(PERCENTRANK(J$9:J$43,J19),0.5)*5)))) -> 2 | L19: =Universe!K15 -> 35.31 | M19: =IF(L19="","",MAX(1,MIN(5,1+INT(IFERROR(PERCENTRANK(L$9:L$43,L19),0.5)*5)))) -> 3 | N19: =IF(COUNTA(D19,F19,H19,J19,L19)<5,"",E19*C5+G19*E5+I19*G5+K19*I5+M19*K5) -> 2.8 | P19: 12 | Q19: {=IFERROR(INDEX($B$9:$B$43,MATCH(LARGE($N$9:$N$43+(ROW($N$9:$N$43)-ROW($N$9))/1000,12),$N$9:$N$43+(ROW($N$9:$N$43)-ROW($N$9))/1000,0)),"")} -> MSCI Inc. | R19: {=IFERROR(INDEX($C$9:$C$43,MATCH(LARGE($N$9:$N$43+(ROW($N$9:$N$43)-ROW($N$9))/1000,12),$N$9:$N$43+(ROW($N$9:$N$43)-ROW($N$9))/1000,0)),"")} -> MSCI | S19: {=IFERROR(INDEX($N$9:$N$43,MATCH(LARGE($N$9:$N$43+(ROW($N$9:$N$43)-ROW($N$9))/1000,12),$N$9:$N$43+(ROW($N$9:$N$43)-ROW($N$9))/1000,0)),"")} -> 3.3 | T19: {=IFERROR(INDEX($E$9:$E$43,MATCH(LARGE($N$9:$N$43+(ROW($N$9:$N$43)-ROW($N$9))/1000,12),$N$9:$N$43+(ROW($N$9:$N$43)-ROW($N$9))/1000,0)),"")} -> 4 | U19: {=IFERROR(INDEX($G$9:$G$43,MATCH(LARGE($N$9:$N$43+(ROW($N$9:$N$43)-ROW($N$9))/1000,12),$N$9:$N$43+(ROW($N$9:$N$43)-ROW($N$9))/1000,0)),"")} -> 5 | V19: {=IFERROR(INDEX($I$9:$I$43,MATCH(LARGE($N$9:$N$43+(ROW($N$9:$N$43)-ROW($N$9))/1000,12),$N$9:$N$43+(ROW($N$9:$N$43)-ROW($N$9))/1000,0)),"")} -> 1 | W19: {=IFERROR(INDEX($K$9:$K$43,MATCH(LARGE($N$9:$N$43+(ROW($N$9:$N$43)-ROW($N$9))/1000,12),$N$9:$N$43+(ROW($N$9:$N$43)-ROW($N$9))/1000,0)),"")} -> 3 | X19: {=IFERROR(INDEX($M$9:$M$43,MATCH(LARGE($N$9:$N$43+(ROW($N$9:$N$43)-ROW($N$9))/1000,12),$N$9:$N$43+(ROW($N$9:$N$43)-ROW($N$9))/1000,0)),"")} -> 3 | Y19: =IF(R19="","",IF(COUNTIF(Portfolio!$C$5:$C$19,R19)>0,"YES","-")) -> YES
A20: 12 | B20: MSCI Inc. | C20: MSCI | D20: =Universe!G16 -> 0.3273 | E20: =IF(D20="","",MAX(1,MIN(5,1+INT(IFERROR(PERCENTRANK(D$9:D$43,D20),0.5)*5)))) -> 4 | F20: =Universe!H16 -> 0.7629 | G20: =IF(F20="","",MAX(1,MIN(5,1+INT(IFERROR(PERCENTRANK(F$9:F$43,F20),0.5)*5)))) -> 5 | H20: =Universe!I16 -> 2.94 | I20: =IF(H20="","",MAX(1,MIN(5,5-INT(IFERROR(PERCENTRANK(H$9:H$43,H20),0.5)*5)))) -> 1 | J20: =Universe!J16 -> 0.8089 | K20: =IF(J20="","",MAX(1,MIN(5,1+INT(IFERROR(PERCENTRANK(J$9:J$43,J20),0.5)*5)))) -> 3 | L20: =Universe!K16 -> 32.18 | M20: =IF(L20="","",MAX(1,MIN(5,1+INT(IFERROR(PERCENTRANK(L$9:L$43,L20),0.5)*5)))) -> 3 | N20: =IF(COUNTA(D20,F20,H20,J20,L20)<5,"",E20*C5+G20*E5+I20*G5+K20*I5+M20*K5) -> 3.3 | P20: 13 | Q20: {=IFERROR(INDEX($B$9:$B$43,MATCH(LARGE($N$9:$N$43+(ROW($N$9:$N$43)-ROW($N$9))/1000,13),$N$9:$N$43+(ROW($N$9:$N$43)-ROW($N$9))/1000,0)),"")} -> Keyence Corporation | R20: {=IFERROR(INDEX($C$9:$C$43,MATCH(LARGE($N$9:$N$43+(ROW($N$9:$N$43)-ROW($N$9))/1000,13),$N$9:$N$43+(ROW($N$9:$N$43)-ROW($N$9))/1000,0)),"")} -> 6861 | S20: {=IFERROR(INDEX($N$9:$N$43,MATCH(LARGE($N$9:$N$43+(ROW($N$9:$N$43)-ROW($N$9))/1000,13),$N$9:$N$43+(ROW($N$9:$N$43)-ROW($N$9))/1000,0)),"")} -> 3.2 | T20: {=IFERROR(INDEX($E$9:$E$43,MATCH(LARGE($N$9:$N$43+(ROW($N$9:$N$43)-ROW($N$9))/1000,13),$N$9:$N$43+(ROW($N$9:$N$43)-ROW($N$9))/1000,0)),"")} -> 2 | U20: {=IFERROR(INDEX($G$9:$G$43,MATCH(LARGE($N$9:$N$43+(ROW($N$9:$N$43)-ROW($N$9))/1000,13),$N$9:$N$43+(ROW($N$9:$N$43)-ROW($N$9))/1000,0)),"")} -> 5 | V20: {=IFERROR(INDEX($I$9:$I$43,MATCH(LARGE($N$9:$N$43+(ROW($N$9:$N$43)-ROW($N$9))/1000,13),$N$9:$N$43+(ROW($N$9:$N$43)-ROW($N$9))/1000,0)),"")} -> 5 | W20: {=IFERROR(INDEX($K$9:$K$43,MATCH(LARGE($N$9:$N$43+(ROW($N$9:$N$43)-ROW($N$9))/1000,13),$N$9:$N$43+(ROW($N$9:$N$43)-ROW($N$9))/1000,0)),"")} -> 2 | X20: {=IFERROR(INDEX($M$9:$M$43,MATCH(LARGE($N$9:$N$43+(ROW($N$9:$N$43)-ROW($N$9))/1000,13),$N$9:$N$43+(ROW($N$9:$N$43)-ROW($N$9))/1000,0)),"")} -> 2 | Y20: =IF(R20="","",IF(COUNTIF(Portfolio!$C$5:$C$19,R20)>0,"YES","-")) -> YES
A21: 13 | B21: Intercontinental Exchange | C21: ICE | D21: =Universe!G17 -> 0.0709 | E21: =IF(D21="","",MAX(1,MIN(5,1+INT(IFERROR(PERCENTRANK(D$9:D$43,D21),0.5)*5)))) -> 1 | F21: =Universe!H17 -> 0.6846 | G21: =IF(F21="","",MAX(1,MIN(5,1+INT(IFERROR(PERCENTRANK(F$9:F$43,F21),0.5)*5)))) -> 4 | H21: =Universe!I17 -> 2.64 | I21: =IF(H21="","",MAX(1,MIN(5,5-INT(IFERROR(PERCENTRANK(H$9:H$43,H21),0.5)*5)))) -> 1 | J21: =Universe!J17 -> 0.9605 | K21: =IF(J21="","",MAX(1,MIN(5,1+INT(IFERROR(PERCENTRANK(J$9:J$43,J21),0.5)*5)))) -> 4 | L21: =Universe!K17 -> 18.37 | M21: =IF(L21="","",MAX(1,MIN(5,1+INT(IFERROR(PERCENTRANK(L$9:L$43,L21),0.5)*5)))) -> 2 | N21: =IF(COUNTA(D21,F21,H21,J21,L21)<5,"",E21*C5+G21*E5+I21*G5+K21*I5+M21*K5) -> 2.3 | P21: 14 | Q21: {=IFERROR(INDEX($B$9:$B$43,MATCH(LARGE($N$9:$N$43+(ROW($N$9:$N$43)-ROW($N$9))/1000,14),$N$9:$N$43+(ROW($N$9:$N$43)-ROW($N$9))/1000,0)),"")} -> Ferrari N.V. | R21: {=IFERROR(INDEX($C$9:$C$43,MATCH(LARGE($N$9:$N$43+(ROW($N$9:$N$43)-ROW($N$9))/1000,14),$N$9:$N$43+(ROW($N$9:$N$43)-ROW($N$9))/1000,0)),"")} -> RACE | S21: {=IFERROR(INDEX($N$9:$N$43,MATCH(LARGE($N$9:$N$43+(ROW($N$9:$N$43)-ROW($N$9))/1000,14),$N$9:$N$43+(ROW($N$9:$N$43)-ROW($N$9))/1000,0)),"")} -> 3.1 | T21: {=IFERROR(INDEX($E$9:$E$43,MATCH(LARGE($N$9:$N$43+(ROW($N$9:$N$43)-ROW($N$9))/1000,14),$N$9:$N$43+(ROW($N$9:$N$43)-ROW($N$9))/1000,0)),"")} -> 4 | U21: {=IFERROR(INDEX($G$9:$G$43,MATCH(LARGE($N$9:$N$43+(ROW($N$9:$N$43)-ROW($N$9))/1000,14),$N$9:$N$43+(ROW($N$9:$N$43)-ROW($N$9))/1000,0)),"")} -> 2 | V21: {=IFERROR(INDEX($I$9:$I$43,MATCH(LARGE($N$9:$N$43+(ROW($N$9:$N$43)-ROW($N$9))/1000,14),$N$9:$N$43+(ROW($N$9:$N$43)-ROW($N$9))/1000,0)),"")} -> 3 | W21: {=IFERROR(INDEX($K$9:$K$43,MATCH(LARGE($N$9:$N$43+(ROW($N$9:$N$43)-ROW($N$9))/1000,14),$N$9:$N$43+(ROW($N$9:$N$43)-ROW($N$9))/1000,0)),"")} -> 3 | X21: {=IFERROR(INDEX($M$9:$M$43,MATCH(LARGE($N$9:$N$43+(ROW($N$9:$N$43)-ROW($N$9))/1000,14),$N$9:$N$43+(ROW($N$9:$N$43)-ROW($N$9))/1000,0)),"")} -> 3 | Y21: =IF(R21="","",IF(COUNTIF(Portfolio!$C$5:$C$19,R21)>0,"YES","-")) -> YES
A22: 14 | B22: London Stock Exchange Group | C22: LSEG | D22: =Universe!G18 -> 0.0419 | E22: =IF(D22="","",MAX(1,MIN(5,1+INT(IFERROR(PERCENTRANK(D$9:D$43,D22),0.5)*5)))) -> 1 | F22: =Universe!H18 -> 0.6426 | G22: =IF(F22="","",MAX(1,MIN(5,1+INT(IFERROR(PERCENTRANK(F$9:F$43,F22),0.5)*5)))) -> 3 | H22: =Universe!I18 -> 1.73 | I22: =IF(H22="","",MAX(1,MIN(5,5-INT(IFERROR(PERCENTRANK(H$9:H$43,H22),0.5)*5)))) -> 2 | J22: =Universe!J18 -> 2.226 | K22: =IF(J22="","",MAX(1,MIN(5,1+INT(IFERROR(PERCENTRANK(J$9:J$43,J22),0.5)*5)))) -> 5 | L22: =Universe!K18 -> 20.3 | M22: =IF(L22="","",MAX(1,MIN(5,1+INT(IFERROR(PERCENTRANK(L$9:L$43,L22),0.5)*5)))) -> 2 | N22: =IF(COUNTA(D22,F22,H22,J22,L22)<5,"",E22*C5+G22*E5+I22*G5+K22*I5+M22*K5) -> 2.5 | P22: 15 | Q22: {=IFERROR(INDEX($B$9:$B$43,MATCH(LARGE($N$9:$N$43+(ROW($N$9:$N$43)-ROW($N$9))/1000,15),$N$9:$N$43+(ROW($N$9:$N$43)-ROW($N$9))/1000,0)),"")} -> Automatic Data Processing | R22: {=IFERROR(INDEX($C$9:$C$43,MATCH(LARGE($N$9:$N$43+(ROW($N$9:$N$43)-ROW($N$9))/1000,15),$N$9:$N$43+(ROW($N$9:$N$43)-ROW($N$9))/1000,0)),"")} -> ADP | S22: {=IFERROR(INDEX($N$9:$N$43,MATCH(LARGE($N$9:$N$43+(ROW($N$9:$N$43)-ROW($N$9))/1000,15),$N$9:$N$43+(ROW($N$9:$N$43)-ROW($N$9))/1000,0)),"")} -> 3.1 | T22: {=IFERROR(INDEX($E$9:$E$43,MATCH(LARGE($N$9:$N$43+(ROW($N$9:$N$43)-ROW($N$9))/1000,15),$N$9:$N$43+(ROW($N$9:$N$43)-ROW($N$9))/1000,0)),"")} -> 5 | U22: {=IFERROR(INDEX($G$9:$G$43,MATCH(LARGE($N$9:$N$43+(ROW($N$9:$N$43)-ROW($N$9))/1000,15),$N$9:$N$43+(ROW($N$9:$N$43)-ROW($N$9))/1000,0)),"")} -> 1 | V22: {=IFERROR(INDEX($I$9:$I$43,MATCH(LARGE($N$9:$N$43+(ROW($N$9:$N$43)-ROW($N$9))/1000,15),$N$9:$N$43+(ROW($N$9:$N$43)-ROW($N$9))/1000,0)),"")} -> 3 | W22: {=IFERROR(INDEX($K$9:$K$43,MATCH(LARGE($N$9:$N$43+(ROW($N$9:$N$43)-ROW($N$9))/1000,15),$N$9:$N$43+(ROW($N$9:$N$43)-ROW($N$9))/1000,0)),"")} -> 2 | X22: {=IFERROR(INDEX($M$9:$M$43,MATCH(LARGE($N$9:$N$43+(ROW($N$9:$N$43)-ROW($N$9))/1000,15),$N$9:$N$43+(ROW($N$9:$N$43)-ROW($N$9))/1000,0)),"")} -> 4 | Y22: =IF(R22="","",IF(COUNTIF(Portfolio!$C$5:$C$19,R22)>0,"YES","-")) -> YES
A23: 15 | B23: Novo Nordisk A/S | C23: NOVO B | D23: =Universe!G19 -> 0.3751 | E23: =IF(D23="","",MAX(1,MIN(5,1+INT(IFERROR(PERCENTRANK(D$9:D$43,D23),0.5)*5)))) -> 5 | F23: =Universe!H19 -> 0.8034 | G23: =IF(F23="","",MAX(1,MIN(5,1+INT(IFERROR(PERCENTRANK(F$9:F$43,F23),0.5)*5)))) -> 5 | H23: =Universe!I19 -> 0.69 | I23: =IF(H23="","",MAX(1,MIN(5,5-INT(IFERROR(PERCENTRANK(H$9:H$43,H23),0.5)*5)))) -> 3 | J23: =Universe!J19 -> 0.0703 | K23: =IF(J23="","",MAX(1,MIN(5,1+INT(IFERROR(PERCENTRANK(J$9:J$43,J23),0.5)*5)))) -> 1 | L23: =Universe!K19 -> 7.94 | M23: =IF(L23="","",MAX(1,MIN(5,1+INT(IFERROR(PERCENTRANK(L$9:L$43,L23),0.5)*5)))) -> 1 | N23: =IF(COUNTA(D23,F23,H23,J23,L23)<5,"",E23*C5+G23*E5+I23*G5+K23*I5+M23*K5) -> 3.4 | P23: 16 | Q23: {=IFERROR(INDEX($B$9:$B$43,MATCH(LARGE($N$9:$N$43+(ROW($N$9:$N$43)-ROW($N$9))/1000,16),$N$9:$N$43+(ROW($N$9:$N$43)-ROW($N$9))/1000,0)),"")} -> Verisk Analytics | R23: {=IFERROR(INDEX($C$9:$C$43,MATCH(LARGE($N$9:$N$43+(ROW($N$9:$N$43)-ROW($N$9))/1000,16),$N$9:$N$43+(ROW($N$9:$N$43)-ROW($N$9))/1000,0)),"")} -> VRSK | S23: {=IFERROR(INDEX($N$9:$N$43,MATCH(LARGE($N$9:$N$43+(ROW($N$9:$N$43)-ROW($N$9))/1000,16),$N$9:$N$43+(ROW($N$9:$N$43)-ROW($N$9))/1000,0)),"")} -> 3 | T23: {=IFERROR(INDEX($E$9:$E$43,MATCH(LARGE($N$9:$N$43+(ROW($N$9:$N$43)-ROW($N$9))/1000,16),$N$9:$N$43+(ROW($N$9:$N$43)-ROW($N$9))/1000,0)),"")} -> 4 | U23: {=IFERROR(INDEX($G$9:$G$43,MATCH(LARGE($N$9:$N$43+(ROW($N$9:$N$43)-ROW($N$9))/1000,16),$N$9:$N$43+(ROW($N$9:$N$43)-ROW($N$9))/1000,0)),"")} -> 2 | V23: {=IFERROR(INDEX($I$9:$I$43,MATCH(LARGE($N$9:$N$43+(ROW($N$9:$N$43)-ROW($N$9))/1000,16),$N$9:$N$43+(ROW($N$9:$N$43)-ROW($N$9))/1000,0)),"")} -> 2 | W23: {=IFERROR(INDEX($K$9:$K$43,MATCH(LARGE($N$9:$N$43+(ROW($N$9:$N$43)-ROW($N$9))/1000,16),$N$9:$N$43+(ROW($N$9:$N$43)-ROW($N$9))/1000,0)),"")} -> 4 | X23: {=IFERROR(INDEX($M$9:$M$43,MATCH(LARGE($N$9:$N$43+(ROW($N$9:$N$43)-ROW($N$9))/1000,16),$N$9:$N$43+(ROW($N$9:$N$43)-ROW($N$9))/1000,0)),"")} -> 2 | Y23: =IF(R23="","",IF(COUNTIF(Portfolio!$C$5:$C$19,R23)>0,"YES","-")) -> -
A24: 16 | B24: Idexx Laboratories | C24: IDXX | D24: =Universe!G20 -> 0.5016 | E24: =IF(D24="","",MAX(1,MIN(5,1+INT(IFERROR(PERCENTRANK(D$9:D$43,D24),0.5)*5)))) -> 5 | F24: =Universe!H20 -> 0.6182 | G24: =IF(F24="","",MAX(1,MIN(5,1+INT(IFERROR(PERCENTRANK(F$9:F$43,F24),0.5)*5)))) -> 3 | H24: =Universe!I20 -> 0.44 | I24: =IF(H24="","",MAX(1,MIN(5,5-INT(IFERROR(PERCENTRANK(H$9:H$43,H24),0.5)*5)))) -> 3 | J24: =Universe!J20 -> 0.9943 | K24: =IF(J24="","",MAX(1,MIN(5,1+INT(IFERROR(PERCENTRANK(J$9:J$43,J24),0.5)*5)))) -> 4 | L24: =Universe!K20 -> 44.09 | M24: =IF(L24="","",MAX(1,MIN(5,1+INT(IFERROR(PERCENTRANK(L$9:L$43,L24),0.5)*5)))) -> 4 | N24: =IF(COUNTA(D24,F24,H24,J24,L24)<5,"",E24*C5+G24*E5+I24*G5+K24*I5+M24*K5) -> 3.9 | P24: 17 | Q24: {=IFERROR(INDEX($B$9:$B$43,MATCH(LARGE($N$9:$N$43+(ROW($N$9:$N$43)-ROW($N$9))/1000,17),$N$9:$N$43+(ROW($N$9:$N$43)-ROW($N$9))/1000,0)),"")} -> Accenture plc | R24: {=IFERROR(INDEX($C$9:$C$43,MATCH(LARGE($N$9:$N$43+(ROW($N$9:$N$43)-ROW($N$9))/1000,17),$N$9:$N$43+(ROW($N$9:$N$43)-ROW($N$9))/1000,0)),"")} -> ACN | S24: {=IFERROR(INDEX($N$9:$N$43,MATCH(LARGE($N$9:$N$43+(ROW($N$9:$N$43)-ROW($N$9))/1000,17),$N$9:$N$43+(ROW($N$9:$N$43)-ROW($N$9))/1000,0)),"")} -> 3 | T24: {=IFERROR(INDEX($E$9:$E$43,MATCH(LARGE($N$9:$N$43+(ROW($N$9:$N$43)-ROW($N$9))/1000,17),$N$9:$N$43+(ROW($N$9:$N$43)-ROW($N$9))/1000,0)),"")} -> 3 | U24: {=IFERROR(INDEX($G$9:$G$43,MATCH(LARGE($N$9:$N$43+(ROW($N$9:$N$43)-ROW($N$9))/1000,17),$N$9:$N$43+(ROW($N$9:$N$43)-ROW($N$9))/1000,0)),"")} -> 1 | V24: {=IFERROR(INDEX($I$9:$I$43,MATCH(LARGE($N$9:$N$43+(ROW($N$9:$N$43)-ROW($N$9))/1000,17),$N$9:$N$43+(ROW($N$9:$N$43)-ROW($N$9))/1000,0)),"")} -> 4 | W24: {=IFERROR(INDEX($K$9:$K$43,MATCH(LARGE($N$9:$N$43+(ROW($N$9:$N$43)-ROW($N$9))/1000,17),$N$9:$N$43+(ROW($N$9:$N$43)-ROW($N$9))/1000,0)),"")} -> 3 | X24: {=IFERROR(INDEX($M$9:$M$43,MATCH(LARGE($N$9:$N$43+(ROW($N$9:$N$43)-ROW($N$9))/1000,17),$N$9:$N$43+(ROW($N$9:$N$43)-ROW($N$9))/1000,0)),"")} -> 5 | Y24: =IF(R24="","",IF(COUNTIF(Portfolio!$C$5:$C$19,R24)>0,"YES","-")) -> -
A25: 17 | B25: Danaher Corporation | C25: DHR | D25: =Universe!G21 -> 0.0522 | E25: =IF(D25="","",MAX(1,MIN(5,1+INT(IFERROR(PERCENTRANK(D$9:D$43,D25),0.5)*5)))) -> 1 | F25: =Universe!H21 -> 0.5923 | G25: =IF(F25="","",MAX(1,MIN(5,1+INT(IFERROR(PERCENTRANK(F$9:F$43,F25),0.5)*5)))) -> 2 | H25: =Universe!I21 -> 1.79 | I25: =IF(H25="","",MAX(1,MIN(5,5-INT(IFERROR(PERCENTRANK(H$9:H$43,H25),0.5)*5)))) -> 1 | J25: =Universe!J21 -> 1.2172 | K25: =IF(J25="","",MAX(1,MIN(5,1+INT(IFERROR(PERCENTRANK(J$9:J$43,J25),0.5)*5)))) -> 5 | L25: =Universe!K21 -> 36.3 | M25: =IF(L25="","",MAX(1,MIN(5,1+INT(IFERROR(PERCENTRANK(L$9:L$43,L25),0.5)*5)))) -> 3 | N25: =IF(COUNTA(D25,F25,H25,J25,L25)<5,"",E25*C5+G25*E5+I25*G5+K25*I5+M25*K5) -> 2.2 | P25: 18 | Q25: {=IFERROR(INDEX($B$9:$B$43,MATCH(LARGE($N$9:$N$43+(ROW($N$9:$N$43)-ROW($N$9))/1000,18),$N$9:$N$43+(ROW($N$9:$N$43)-ROW($N$9))/1000,0)),"")} -> Microsoft Corporation | R25: {=IFERROR(INDEX($C$9:$C$43,MATCH(LARGE($N$9:$N$43+(ROW($N$9:$N$43)-ROW($N$9))/1000,18),$N$9:$N$43+(ROW($N$9:$N$43)-ROW($N$9))/1000,0)),"")} -> MSFT | S25: {=IFERROR(INDEX($N$9:$N$43,MATCH(LARGE($N$9:$N$43+(ROW($N$9:$N$43)-ROW($N$9))/1000,18),$N$9:$N$43+(ROW($N$9:$N$43)-ROW($N$9))/1000,0)),"")} -> 3 | T25: {=IFERROR(INDEX($E$9:$E$43,MATCH(LARGE($N$9:$N$43+(ROW($N$9:$N$43)-ROW($N$9))/1000,18),$N$9:$N$43+(ROW($N$9:$N$43)-ROW($N$9))/1000,0)),"")} -> 3 | U25: {=IFERROR(INDEX($G$9:$G$43,MATCH(LARGE($N$9:$N$43+(ROW($N$9:$N$43)-ROW($N$9))/1000,18),$N$9:$N$43+(ROW($N$9:$N$43)-ROW($N$9))/1000,0)),"")} -> 4 | V25: {=IFERROR(INDEX($I$9:$I$43,MATCH(LARGE($N$9:$N$43+(ROW($N$9:$N$43)-ROW($N$9))/1000,18),$N$9:$N$43+(ROW($N$9:$N$43)-ROW($N$9))/1000,0)),"")} -> 4 | W25: {=IFERROR(INDEX($K$9:$K$43,MATCH(LARGE($N$9:$N$43+(ROW($N$9:$N$43)-ROW($N$9))/1000,18),$N$9:$N$43+(ROW($N$9:$N$43)-ROW($N$9))/1000,0)),"")} -> 1 | X25: {=IFERROR(INDEX($M$9:$M$43,MATCH(LARGE($N$9:$N$43+(ROW($N$9:$N$43)-ROW($N$9))/1000,18),$N$9:$N$43+(ROW($N$9:$N$43)-ROW($N$9))/1000,0)),"")} -> 3 | Y25: =IF(R25="","",IF(COUNTIF(Portfolio!$C$5:$C$19,R25)>0,"YES","-")) -> -
A26: 18 | B26: Align Technology | C26: ALGN | D26: =Universe!G22 -> 0.1017 | E26: =IF(D26="","",MAX(1,MIN(5,1+INT(IFERROR(PERCENTRANK(D$9:D$43,D26),0.5)*5)))) -> 2 | F26: =Universe!H22 -> 0.698 | G26: =IF(F26="","",MAX(1,MIN(5,1+INT(IFERROR(PERCENTRANK(F$9:F$43,F26),0.5)*5)))) -> 4 | H26: =Universe!I22 -> -1.29 | I26: =IF(H26="","",MAX(1,MIN(5,5-INT(IFERROR(PERCENTRANK(H$9:H$43,H26),0.5)*5)))) -> 5 | J26: =Universe!J22 -> 1.196 | K26: =IF(J26="","",MAX(1,MIN(5,1+INT(IFERROR(PERCENTRANK(J$9:J$43,J26),0.5)*5)))) -> 4 | L26: =Universe!K22 -> 51.32 | M26: =IF(L26="","",MAX(1,MIN(5,1+INT(IFERROR(PERCENTRANK(L$9:L$43,L26),0.5)*5)))) -> 4 | N26: =IF(COUNTA(D26,F26,H26,J26,L26)<5,"",E26*C5+G26*E5+I26*G5+K26*I5+M26*K5) -> 3.6 | P26: 19 | Q26: {=IFERROR(INDEX($B$9:$B$43,MATCH(LARGE($N$9:$N$43+(ROW($N$9:$N$43)-ROW($N$9))/1000,19),$N$9:$N$43+(ROW($N$9:$N$43)-ROW($N$9))/1000,0)),"")} -> Taiwan Semiconductor | R26: {=IFERROR(INDEX($C$9:$C$43,MATCH(LARGE($N$9:$N$43+(ROW($N$9:$N$43)-ROW($N$9))/1000,19),$N$9:$N$43+(ROW($N$9:$N$43)-ROW($N$9))/1000,0)),"")} -> TSM | S26: {=IFERROR(INDEX($N$9:$N$43,MATCH(LARGE($N$9:$N$43+(ROW($N$9:$N$43)-ROW($N$9))/1000,19),$N$9:$N$43+(ROW($N$9:$N$43)-ROW($N$9))/1000,0)),"")} -> 2.9 | T26: {=IFERROR(INDEX($E$9:$E$43,MATCH(LARGE($N$9:$N$43+(ROW($N$9:$N$43)-ROW($N$9))/1000,19),$N$9:$N$43+(ROW($N$9:$N$43)-ROW($N$9))/1000,0)),"")} -> 4 | U26: {=IFERROR(INDEX($G$9:$G$43,MATCH(LARGE($N$9:$N$43+(ROW($N$9:$N$43)-ROW($N$9))/1000,19),$N$9:$N$43+(ROW($N$9:$N$43)-ROW($N$9))/1000,0)),"")} -> 2 | V26: {=IFERROR(INDEX($I$9:$I$43,MATCH(LARGE($N$9:$N$43+(ROW($N$9:$N$43)-ROW($N$9))/1000,19),$N$9:$N$43+(ROW($N$9:$N$43)-ROW($N$9))/1000,0)),"")} -> 5 | W26: {=IFERROR(INDEX($K$9:$K$43,MATCH(LARGE($N$9:$N$43+(ROW($N$9:$N$43)-ROW($N$9))/1000,19),$N$9:$N$43+(ROW($N$9:$N$43)-ROW($N$9))/1000,0)),"")} -> 1 | X26: {=IFERROR(INDEX($M$9:$M$43,MATCH(LARGE($N$9:$N$43+(ROW($N$9:$N$43)-ROW($N$9))/1000,19),$N$9:$N$43+(ROW($N$9:$N$43)-ROW($N$9))/1000,0)),"")} -> 1 | Y26: =IF(R26="","",IF(COUNTIF(Portfolio!$C$5:$C$19,R26)>0,"YES","-")) -> -
A27: 19 | B27: West Pharmaceutical Services | C27: WST | D27: =Universe!G23 -> 0.1532 | E27: =IF(D27="","",MAX(1,MIN(5,1+INT(IFERROR(PERCENTRANK(D$9:D$43,D27),0.5)*5)))) -> 3 | F27: =Universe!H23 -> 0.3592 | G27: =IF(F27="","",MAX(1,MIN(5,1+INT(IFERROR(PERCENTRANK(F$9:F$43,F27),0.5)*5)))) -> 1 | H27: =Universe!I23 -> -0.72 | I27: =IF(H27="","",MAX(1,MIN(5,5-INT(IFERROR(PERCENTRANK(H$9:H$43,H27),0.5)*5)))) -> 4 | J27: =Universe!J23 -> 0.8258 | K27: =IF(J27="","",MAX(1,MIN(5,1+INT(IFERROR(PERCENTRANK(J$9:J$43,J27),0.5)*5)))) -> 3 | L27: =Universe!K23 -> 39.18 | M27: =IF(L27="","",MAX(1,MIN(5,1+INT(IFERROR(PERCENTRANK(L$9:L$43,L27),0.5)*5)))) -> 3 | N27: =IF(COUNTA(D27,F27,H27,J27,L27)<5,"",E27*C5+G27*E5+I27*G5+K27*I5+M27*K5) -> 2.8 | P27: 20 | Q27: {=IFERROR(INDEX($B$9:$B$43,MATCH(LARGE($N$9:$N$43+(ROW($N$9:$N$43)-ROW($N$9))/1000,20),$N$9:$N$43+(ROW($N$9:$N$43)-ROW($N$9))/1000,0)),"")} -> L'Oréal S.A. | R27: {=IFERROR(INDEX($C$9:$C$43,MATCH(LARGE($N$9:$N$43+(ROW($N$9:$N$43)-ROW($N$9))/1000,20),$N$9:$N$43+(ROW($N$9:$N$43)-ROW($N$9))/1000,0)),"")} -> OR | S27: {=IFERROR(INDEX($N$9:$N$43,MATCH(LARGE($N$9:$N$43+(ROW($N$9:$N$43)-ROW($N$9))/1000,20),$N$9:$N$43+(ROW($N$9:$N$43)-ROW($N$9))/1000,0)),"")} -> 2.9 | T27: {=IFERROR(INDEX($E$9:$E$43,MATCH(LARGE($N$9:$N$43+(ROW($N$9:$N$43)-ROW($N$9))/1000,20),$N$9:$N$43+(ROW($N$9:$N$43)-ROW($N$9))/1000,0)),"")} -> 2 | U27: {=IFERROR(INDEX($G$9:$G$43,MATCH(LARGE($N$9:$N$43+(ROW($N$9:$N$43)-ROW($N$9))/1000,20),$N$9:$N$43+(ROW($N$9:$N$43)-ROW($N$9))/1000,0)),"")} -> 4 | V27: {=IFERROR(INDEX($I$9:$I$43,MATCH(LARGE($N$9:$N$43+(ROW($N$9:$N$43)-ROW($N$9))/1000,20),$N$9:$N$43+(ROW($N$9:$N$43)-ROW($N$9))/1000,0)),"")} -> 3 | W27: {=IFERROR(INDEX($K$9:$K$43,MATCH(LARGE($N$9:$N$43+(ROW($N$9:$N$43)-ROW($N$9))/1000,20),$N$9:$N$43+(ROW($N$9:$N$43)-ROW($N$9))/1000,0)),"")} -> 2 | X27: {=IFERROR(INDEX($M$9:$M$43,MATCH(LARGE($N$9:$N$43+(ROW($N$9:$N$43)-ROW($N$9))/1000,20),$N$9:$N$43+(ROW($N$9:$N$43)-ROW($N$9))/1000,0)),"")} -> 5 | Y27: =IF(R27="","",IF(COUNTIF(Portfolio!$C$5:$C$19,R27)>0,"YES","-")) -> -
A28: 20 | B28: LVMH Moët Hennessy | C28: MC | D28: =Universe!G24 -> 0.1159 | E28: =IF(D28="","",MAX(1,MIN(5,1+INT(IFERROR(PERCENTRANK(D$9:D$43,D28),0.5)*5)))) -> 2 | F28: =Universe!H24 -> 0.6624 | G28: =IF(F28="","",MAX(1,MIN(5,1+INT(IFERROR(PERCENTRANK(F$9:F$43,F28),0.5)*5)))) -> 3 | H28: =Universe!I24 -> 0.94 | I28: =IF(H28="","",MAX(1,MIN(5,5-INT(IFERROR(PERCENTRANK(H$9:H$43,H28),0.5)*5)))) -> 2 | J28: =Universe!J24 -> 0.7662 | K28: =IF(J28="","",MAX(1,MIN(5,1+INT(IFERROR(PERCENTRANK(J$9:J$43,J28),0.5)*5)))) -> 2 | L28: =Universe!K24 -> 157.79 | M28: =IF(L28="","",MAX(1,MIN(5,1+INT(IFERROR(PERCENTRANK(L$9:L$43,L28),0.5)*5)))) -> 5 | N28: =IF(COUNTA(D28,F28,H28,J28,L28)<5,"",E28*C5+G28*E5+I28*G5+K28*I5+M28*K5) -> 2.5
A29: 21 | B29: Hermès International | C29: RMS | D29: =Universe!G25 -> 0.226 | E29: =IF(D29="","",MAX(1,MIN(5,1+INT(IFERROR(PERCENTRANK(D$9:D$43,D29),0.5)*5)))) -> 3 | F29: =Universe!H25 -> 0.6655 | G29: =IF(F29="","",MAX(1,MIN(5,1+INT(IFERROR(PERCENTRANK(F$9:F$43,F29),0.5)*5)))) -> 4 | H29: =Universe!I25 -> -1.32 | I29: =IF(H29="","",MAX(1,MIN(5,5-INT(IFERROR(PERCENTRANK(H$9:H$43,H29),0.5)*5)))) -> 5 | J29: =Universe!J25 -> 0.3674 | K29: =IF(J29="","",MAX(1,MIN(5,1+INT(IFERROR(PERCENTRANK(J$9:J$43,J29),0.5)*5)))) -> 1 | L29: =Universe!K25 -> 144.1 | M29: =IF(L29="","",MAX(1,MIN(5,1+INT(IFERROR(PERCENTRANK(L$9:L$43,L29),0.5)*5)))) -> 5 | N29: =IF(COUNTA(D29,F29,H29,J29,L29)<5,"",E29*C5+G29*E5+I29*G5+K29*I5+M29*K5) -> 3.4 | P29: Amber rank = primary shortlist (top 15). Divider line separates top 15 from reserve candidates (16-20). 'In Portfolio?' updates live when tickers are entered in Portfolio tab.
A30: 22 | B30: L'Oréal S.A. | C30: OR | D30: =Universe!G26 -> 0.1456 | E30: =IF(D30="","",MAX(1,MIN(5,1+INT(IFERROR(PERCENTRANK(D$9:D$43,D30),0.5)*5)))) -> 2 | F30: =Universe!H26 -> 0.7432 | G30: =IF(F30="","",MAX(1,MIN(5,1+INT(IFERROR(PERCENTRANK(F$9:F$43,F30),0.5)*5)))) -> 4 | H30: =Universe!I26 -> 0.19 | I30: =IF(H30="","",MAX(1,MIN(5,5-INT(IFERROR(PERCENTRANK(H$9:H$43,H30),0.5)*5)))) -> 3 | J30: =Universe!J26 -> 0.5295 | K30: =IF(J30="","",MAX(1,MIN(5,1+INT(IFERROR(PERCENTRANK(J$9:J$43,J30),0.5)*5)))) -> 2 | L30: =Universe!K26 -> 85.6 | M30: =IF(L30="","",MAX(1,MIN(5,1+INT(IFERROR(PERCENTRANK(L$9:L$43,L30),0.5)*5)))) -> 5 | N30: =IF(COUNTA(D30,F30,H30,J30,L30)<5,"",E30*C5+G30*E5+I30*G5+K30*I5+M30*K5) -> 2.9
A31: 23 | B31: Ferrari N.V. | C31: RACE | D31: =Universe!G27 -> 0.2806 | E31: =IF(D31="","",MAX(1,MIN(5,1+INT(IFERROR(PERCENTRANK(D$9:D$43,D31),0.5)*5)))) -> 4 | F31: =Universe!H27 -> 0.5246 | G31: =IF(F31="","",MAX(1,MIN(5,1+INT(IFERROR(PERCENTRANK(F$9:F$43,F31),0.5)*5)))) -> 2 | H31: =Universe!I27 -> 0.48 | I31: =IF(H31="","",MAX(1,MIN(5,5-INT(IFERROR(PERCENTRANK(H$9:H$43,H31),0.5)*5)))) -> 3 | J31: =Universe!J27 -> 0.8356 | K31: =IF(J31="","",MAX(1,MIN(5,1+INT(IFERROR(PERCENTRANK(J$9:J$43,J31),0.5)*5)))) -> 3 | L31: =Universe!K27 -> 37.78 | M31: =IF(L31="","",MAX(1,MIN(5,1+INT(IFERROR(PERCENTRANK(L$9:L$43,L31),0.5)*5)))) -> 3 | N31: =IF(COUNTA(D31,F31,H31,J31,L31)<5,"",E31*C5+G31*E5+I31*G5+K31*I5+M31*K5) -> 3.1
A32: 24 | B32: Diageo plc | C32: DGE | D32: =Universe!G28 -> 0.0785 | E32: =IF(D32="","",MAX(1,MIN(5,1+INT(IFERROR(PERCENTRANK(D$9:D$43,D32),0.5)*5)))) -> 2 | F32: =Universe!H28 -> 0.6049 | G32: =IF(F32="","",MAX(1,MIN(5,1+INT(IFERROR(PERCENTRANK(F$9:F$43,F32),0.5)*5)))) -> 3 | H32: =Universe!I28 -> 3.16 | I32: =IF(H32="","",MAX(1,MIN(5,5-INT(IFERROR(PERCENTRANK(H$9:H$43,H32),0.5)*5)))) -> 1 | J32: =Universe!J28 -> 0.1644 | K32: =IF(J32="","",MAX(1,MIN(5,1+INT(IFERROR(PERCENTRANK(J$9:J$43,J32),0.5)*5)))) -> 1 | L32: =Universe!K28 -> 9.07 | M32: =IF(L32="","",MAX(1,MIN(5,1+INT(IFERROR(PERCENTRANK(L$9:L$43,L32),0.5)*5)))) -> 1 | N32: =IF(COUNTA(D32,F32,H32,J32,L32)<5,"",E32*C5+G32*E5+I32*G5+K32*I5+M32*K5) -> 1.7
A33: 25 | B33: ASML Holding N.V. | C33: ASML | D33: =Universe!G29 -> 0.428 | E33: =IF(D33="","",MAX(1,MIN(5,1+INT(IFERROR(PERCENTRANK(D$9:D$43,D33),0.5)*5)))) -> 5 | F33: =Universe!H29 -> 0.5156 | G33: =IF(F33="","",MAX(1,MIN(5,1+INT(IFERROR(PERCENTRANK(F$9:F$43,F33),0.5)*5)))) -> 2 | H33: =Universe!I29 -> -0.72 | I33: =IF(H33="","",MAX(1,MIN(5,5-INT(IFERROR(PERCENTRANK(H$9:H$43,H33),0.5)*5)))) -> 4 | J33: =Universe!J29 -> 0.8882 | K33: =IF(J33="","",MAX(1,MIN(5,1+INT(IFERROR(PERCENTRANK(J$9:J$43,J33),0.5)*5)))) -> 3 | L33: =Universe!K29 -> 64.86 | M33: =IF(L33="","",MAX(1,MIN(5,1+INT(IFERROR(PERCENTRANK(L$9:L$43,L33),0.5)*5)))) -> 4 | N33: =IF(COUNTA(D33,F33,H33,J33,L33)<5,"",E33*C5+G33*E5+I33*G5+K33*I5+M33*K5) -> 3.7
A34: 26 | B34: Fastenal Company | C34: FAST | D34: =Universe!G30 -> 0.3076 | E34: =IF(D34="","",MAX(1,MIN(5,1+INT(IFERROR(PERCENTRANK(D$9:D$43,D34),0.5)*5)))) -> 4 | F34: =Universe!H30 -> 0.4296 | G34: =IF(F34="","",MAX(1,MIN(5,1+INT(IFERROR(PERCENTRANK(F$9:F$43,F34),0.5)*5)))) -> 1 | H34: =Universe!I30 -> -0.08 | I34: =IF(H34="","",MAX(1,MIN(5,5-INT(IFERROR(PERCENTRANK(H$9:H$43,H34),0.5)*5)))) -> 4 | J34: =Universe!J30 -> 0.0369 | K34: =IF(J34="","",MAX(1,MIN(5,1+INT(IFERROR(PERCENTRANK(J$9:J$43,J34),0.5)*5)))) -> 1 | L34: =Universe!K30 -> 6.28 | M34: =IF(L34="","",MAX(1,MIN(5,1+INT(IFERROR(PERCENTRANK(L$9:L$43,L34),0.5)*5)))) -> 1 | N34: =IF(COUNTA(D34,F34,H34,J34,L34)<5,"",E34*C5+G34*E5+I34*G5+K34*I5+M34*K5) -> 2.5
A35: 27 | B35: Copart Inc. | C35: CPRT | D35: =Universe!G31 -> 0.1838 | E35: =IF(D35="","",MAX(1,MIN(5,1+INT(IFERROR(PERCENTRANK(D$9:D$43,D35),0.5)*5)))) -> 3 | F35: =Universe!H31 -> 0.4467 | G35: =IF(F35="","",MAX(1,MIN(5,1+INT(IFERROR(PERCENTRANK(F$9:F$43,F35),0.5)*5)))) -> 1 | H35: =Universe!I31 -> -2.5 | I35: =IF(H35="","",MAX(1,MIN(5,5-INT(IFERROR(PERCENTRANK(H$9:H$43,H35),0.5)*5)))) -> 5 | J35: =Universe!J31 -> 0.7928 | K35: =IF(J35="","",MAX(1,MIN(5,1+INT(IFERROR(PERCENTRANK(J$9:J$43,J35),0.5)*5)))) -> 2 | L35: =Universe!K31 -> 3.91 | M35: =IF(L35="","",MAX(1,MIN(5,1+INT(IFERROR(PERCENTRANK(L$9:L$43,L35),0.5)*5)))) -> 1 | N35: =IF(COUNTA(D35,F35,H35,J35,L35)<5,"",E35*C5+G35*E5+I35*G5+K35*I5+M35*K5) -> 2.6
A36: 28 | B36: Roper Technologies | C36: ROP | D36: =Universe!G32 -> 0.0566 | E36: =IF(D36="","",MAX(1,MIN(5,1+INT(IFERROR(PERCENTRANK(D$9:D$43,D36),0.5)*5)))) -> 1 | F36: =Universe!H32 -> 0.6924 | G36: =IF(F36="","",MAX(1,MIN(5,1+INT(IFERROR(PERCENTRANK(F$9:F$43,F36),0.5)*5)))) -> 4 | H36: =Universe!I32 -> 2.87 | I36: =IF(H36="","",MAX(1,MIN(5,5-INT(IFERROR(PERCENTRANK(H$9:H$43,H36),0.5)*5)))) -> 1 | J36: =Universe!J32 -> 1.3916 | K36: =IF(J36="","",MAX(1,MIN(5,1+INT(IFERROR(PERCENTRANK(J$9:J$43,J36),0.5)*5)))) -> 5 | L36: =Universe!K32 -> 60.06 | M36: =IF(L36="","",MAX(1,MIN(5,1+INT(IFERROR(PERCENTRANK(L$9:L$43,L36),0.5)*5)))) -> 4 | N36: =IF(COUNTA(D36,F36,H36,J36,L36)<5,"",E36*C5+G36*E5+I36*G5+K36*I5+M36*K5) -> 2.7
A37: 29 | B37: Rational AG | C37: RAA | D37: =Universe!G33 -> 0.2766 | E37: =IF(D37="","",MAX(1,MIN(5,1+INT(IFERROR(PERCENTRANK(D$9:D$43,D37),0.5)*5)))) -> 4 | F37: =Universe!H33 -> 0.5902 | G37: =IF(F37="","",MAX(1,MIN(5,1+INT(IFERROR(PERCENTRANK(F$9:F$43,F37),0.5)*5)))) -> 2 | H37: =Universe!I33 -> -1.39 | I37: =IF(H37="","",MAX(1,MIN(5,5-INT(IFERROR(PERCENTRANK(H$9:H$43,H37),0.5)*5)))) -> 5 | J37: =Universe!J33 -> 0.2348 | K37: =IF(J37="","",MAX(1,MIN(5,1+INT(IFERROR(PERCENTRANK(J$9:J$43,J37),0.5)*5)))) -> 1 | L37: =Universe!K33 -> 109.69 | M37: =IF(L37="","",MAX(1,MIN(5,1+INT(IFERROR(PERCENTRANK(L$9:L$43,L37),0.5)*5)))) -> 5 | N37: =IF(COUNTA(D37,F37,H37,J37,L37)<5,"",E37*C5+G37*E5+I37*G5+K37*I5+M37*K5) -> 3.3
