Workbook

Sheet Cover
C7: COMPREHENSIVE VALUATION MODEL
C8: Duolingo, Inc.
C9: NASDAQ: DUOL | Technology — Education Software
C13: Rating | D13: Price Target | E13: Enterprise Value | F13: Scenario Range
C14: BUY | D14: 164.5 | E14: $7,286mm | F14: $60 – $165
C15: Initiating Coverage | D15: DCF (5-Year) | E15: Equity: $8,164mm | F15: Bear | Base | Bull
C18: Model Details
C19: Date | D19: 45689
C20: Analyst | D20: [Analyst Name]
C21: WACC | D21: 11.14% (Rf: 4.05% | ERP: 4.46% | β: 1.59x | TGR: 2.5%)
C22: Methodology | D22: 5-Year DCF | Bull / Base / Bear Scenario Analysis | Sensitivity Testing
C23: Status | D23: Complete — All integration checks passed ✓
C26: CONFIDENTIAL
C27: This document is proprietary and intended solely for the use of the intended recipient(s). Do not distribute.

Sheet TOC
B1: [DUOLINGO] ([DUOL-US])
B2: Comprehensive Valuation Model — Table of Contents
B4: Tab # | C4: Tab Name | D4: Description | E4: Status
B5: SECTION 1: EXECUTIVE SUMMARY & OVERVIEW
B6: 1 | C6: Cover | D6: Title page, version control, confidentiality notice | E6: Complete
B7: 2 | C7: TOC | D7: Table of contents & model map | E7: Complete
B8: 3 | C8: Executive Summary | D8: Valuation, key metrics, scenario analysis, sensitivity, charts | E8: Complete
B9: 4 | C9: Key Metrics | D9: KPI dashboard, operating metrics, key ratios | E9: Pending
B10: 5 | C10: Investment Highlights | D10: Bull/bear case, catalysts, risks | E10: Pending
B12: SECTION 2: HISTORICAL FINANCIALS & ANALYSIS
B13: 6 | C13: Historical Financials | D13: Historical IS + BS + CF (vertical 3-statement) | E13: Complete
B14: 7 | C14: Historical Analysis | D14: Margins, growth rates, ratio analysis, trends | E14: Complete
B16: SECTION 3: ASSUMPTIONS & SUPPORTING SCHEDULES
B17: 8 | C17: Master Assumptions | D17: Key drivers: revenue growth, margins, CapEx, tax, WACC | E17: Complete
B18: 9 | C18: Supporting Schedules | D18: Supporting analysis, Bull/Bear cases | E18: Complete
B20: SECTION 4: FORECASTS & PROJECTIONS
B21: 11 | C21: Forecast Model | D21: Projected IS + BS + CF (vertical 3-statement model) | E21: Complete
B22: 12 | C22: Integration Check | D22: BS balances, CF reconciliation, error checks | E22: Complete
B24: SECTION 5: VALUATION
B25: 13 | C25: DCF Valuation | D25: Discounted Cash Flow analysis (WACC, terminal value) | E25: Complete
B27: SECTION 6: OUTPUTS & ANALYSIS
B28: 17 | C28: Sensitivity Analysis | D28: WACC vs. growth, revenue vs. margin data tables | E28: Complete
B29: 18 | C29: Scenario Analysis | D29: Bull / Base / Bear case outputs | E29: Complete
B31: SECTION 7: REFERENCE & DATA
B32: 19 | C32: Sources & Footnotes | D32: Data sources, market inputs, methodology, revision log, disclaimers | E32: Complete
B35: COLOR CODING LEGEND
B36: 🔵 | C36: BLUE cells | D36: Hardcoded inputs / assumptions (user changes these)
B37: ⬛ | C37: BLACK cells | D37: Formulas & calculations (model calculates these)
B38: 🟢 | C38: GREEN cells | D38: Links from other worksheets within workbook
B39: 🟡 | C39: YELLOW cells | D39: Flags / checks / key assumptions needing attention
B40: 🔴 | C40: RED cells | D40: External links to other files

Sheet Executive Summary
A1: DUOLINGO, INC. (NASDAQ: DUOL) | EQUITY RESEARCH | INITIATING COVERAGE
A2: Technology — Education Software | February 2025
B4: RATING | C4: PRICE TARGET | D4: METHODOLOGY | E4: WACC | F4: TGR | G4: EV ($mm) | H4: EQUITY ($mm) | I4: TV / EV | J4: SHARES (FD) | K4: SCENARIO
B5: BUY | C5: 164.5 | D5: DCF (5-Yr) | E5: 0.111 | F5: 0.025 | G5: 7286 | H5: 8164 | I5: 0.755 | J5: 49.62mm | K5: $60 – $165
B7: 🐂 BULL | C7: 25% Prob | E7: 📊 BASE | F7: 50% Prob | H7: 🐻 BEAR | I7: 25% Prob | K7: PROB-WTD
B8: 165 | C8: EV: $7.3B | E8: 97 | F8: EV: $3.9B | H8: 60 | I8: EV: $2.1B | K8: 105
A10: SENSITIVITY: WACC vs TGR ($) | H10: DCF VALUATION BRIDGE ($mm)
B11: 0.015 | C11: 0.02 | D11: 0.025 | E11: 0.03 | F11: 0.035 | H11: PV of FCFs ('25E–'29E) | J11: 1786 | K11: 0.245
A12: 0.091 | B12: 190 | C12: 200 | D12: 212 | E12: 226 | F12: 242 | H12: PV of Terminal Value | J12: 5500 | K12: 0.755
A13: 0.101 | B13: 169 | C13: 177 | D13: 185 | E13: 195 | F13: 206 | H13: Enterprise Value | J13: 7286
A14: 0.111 | B14: 152 | C14: 158 | D14: 165 | E14: 172 | F14: 180 | H14: (+) Net Cash | J14: 878
A15: 0.121 | B15: 138 | C15: 143 | D15: 148 | E15: 154 | F15: 160 | H15: Equity Value | J15: 8164
A16: 0.131 | B16: 127 | C16: 131 | D16: 135 | E16: 140 | F16: 145 | H16: Implied Share Price | J16: 164.5
A38: Source: Company 10-K/10-Q, DCF Model, Scenario Analysis. See Sources & Footnotes tab.

Sheet Historical Financials
B4: INCOME STATEMENT
B7: All figures in millions of | F7: 2020A | G7: 2021A | H7: 2022A | I7: 2023A | J7: 2024A
B8: U.S. Dollars unless stated
B10: Revenue | F10: 161.696 | G10: 250.772 | H10: 369.495 | I10: 531.109 | J10: 748.024
B11: COGS (excl. D&A) | F11: -44.277 | G11: -67.153 | H11: -98.561 | I11: -140.085 | J11: -198.335
B12: Gross Profit (excl. D&A) | F12: =SUM(F10:F11) -> 117.419 | G12: =SUM(G10:G11) -> 183.619 | H12: =SUM(H10:H11) -> 270.934 | I12: =SUM(I10:I11) -> 391.024 | J12: =SUM(J10:J11) -> 549.689
B14: R&D Expense | F14: -53.024 | G14: -103.787 | H14: -148.944 | I14: -192.702 | J14: -232.94
B15: SG&A Expense | F15: -77.868 | G15: -133.204 | H15: -181.679 | I15: -204.148 | J15: -242.326
B16: D&A Expense | F16: -2.256 | G16: -2.726 | H16: -4.87 | I16: -7.095 | J16: -10.854
B17: EBIT | F17: =SUM(F12:F16) -> -15.729 | G17: =SUM(G12:G16) -> -56.098 | H17: =SUM(H12:H16) -> -64.559 | I17: =SUM(I12:I16) -> -12.921 | J17: =SUM(J12:J16) -> 63.569
B19: Interest Income | F19: 0 | G19: 0 | H19: 7.235 | I19: 31.091 | J19: 42.697
B20: Unusual Expense | F20: -0.282 | G20: -3.909 | H20: -0.636 | I20: -0.338 | J20: -0.974
B21: Other Income | F21: 0.303 | G21: 0.049 | H21: -0.676 | I21: -0.055 | J21: -2.986
B22: EBT | F22: =SUM(F17:F21) -> -15.708 | G22: =SUM(G17:G21) -> -59.958 | H22: =SUM(H17:H21) -> -58.636 | I22: =SUM(I17:I21) -> 17.777 | J22: =SUM(J17:J21) -> 102.306
B24: Income Taxes | F24: -0.068 | G24: -0.177 | H24: -0.938 | I24: -1.71 | J24: -13.732
B25: Equity in Affiliates | F25: 0 | G25: 0 | H25: 0 | I25: 0 | J25: 0
B26: Net Income | F26: =SUM(F22:F25) -> -15.776 | G26: =SUM(G22:G25) -> -60.135 | H26: =SUM(H22:H25) -> -59.574 | I26: =SUM(I22:I25) -> 16.067 | J26: =SUM(J22:J25) -> 88.574
B29: BALANCE STATEMENT
B33: All figures in millions of | F33: 2020A | G33: 2021A | H33: 2022A | I33: 2023A | J33: 2024A
B34: U.S. Dollars unless stated
B36: Assets
B37: Cash & Short-Term Investments | F37: 120.49 | G37: 553.922 | H37: 608.18 | I37: 747.61 | J37: 877.645
B38: Accounts Receivable | F38: 20.45 | G38: 33.163 | H38: 46.728 | I38: 88.975 | J38: 128.923
B39: Other Receivables | F39: 13.585 | G39: 24.219 | H39: 35.041 | I39: 53.931 | J39: 80.162
B40: Inventories | F40: 0 | G40: 0 | H40: 0 | I40: 0 | J40: 0
B41: Other Current Assets | F41: 3.855 | G41: 7.967 | H41: 7.234 | I41: 7.282 | J41: 14.858
B42: Total Current Assets | F42: =SUM(F37:F41) -> 158.38 | G42: =SUM(G37:G41) -> 619.271 | H42: =SUM(H37:H41) -> 697.183 | I42: =SUM(I37:I41) -> 897.798 | J42: =SUM(J37:J41) -> 1101.588
B44: Net PP&E | F44: 14.501 | G44: 36.58 | H44: 35.477 | I44: 30.895 | J44: 66.438
B45: Goodwill | F45: 0 | G45: 0 | H45: 4.05 | I45: 4.05 | J45: 10.538
B46: Other Intangible Assets | F46: 2.296 | G46: 4.566 | H46: 8.497 | I46: 15.995 | J46: 19.899
B47: Long-Term Investments | F47: 0 | G47: 0 | H47: 0 | I47: 2.735 | J47: 101.027
B48: Deferred Tax Assets | F48: 0 | G48: 0 | H48: 10.247 | I48: 11.038 | J48: 0.675
B49: Other Non-Current Assets | F49: 0.562 | G49: 0.894 | H49: 1.507 | I49: 1.718 | J49: 1.563
B50: Total Non-Current Assets | F50: =SUM(F44:F49) -> 17.359 | G50: =SUM(G44:G49) -> 42.04 | H50: =SUM(H44:H49) -> 59.778 | I50: =SUM(I44:I49) -> 66.431 | J50: =SUM(J44:J49) -> 200.14
B52: Total Assets | F52: =F42+F50 -> 175.739 | G52: =G42+G50 -> 661.311 | H52: =H42+H50 -> 756.961 | I52: =I42+I50 -> 964.229 | J52: =J42+J50 -> 1301.728
B54: Liabilities
B55: Accounts Payable | F55: 2.196 | G55: 7.818 | H55: 1.177 | I55: 2.447 | J55: 6.381
B56: Short-Term Debt & Curr. LT Portion | F56: 1.111 | G56: 3.336 | H56: 4.903 | I56: 3.944 | J56: 2.581
B57: Income Tax Payable | F57: 0.068 | G57: 0.113 | H57: 1.069 | I57: 0.792 | J57: 6.591
B58: Other Current Liabilities | F58: 62.315 | G58: 107.864 | H58: 174.617 | I58: 270.179 | J58: 406.678
...

Sheet Historical Analysis
B3: SECTION A: GROWTH AND MARGIN ANALYSIS
B5: REVENUE GROWTH:
F6: 2020A | G6: 2021A | H6: 2022A | I6: 2023A | J6: 2024A | L6: Trend
B7: Total Revenue ($M) | F7: 161.696 | G7: 250.772 | H7: 369.495 | I7: 531.109 | J7: 748.024
B8: YoY Growth % | G8: =(G7/F7-1) -> 0.55088561 | H8: =(H7/G7-1) -> 0.47343005 | I8: =(I7/H7-1) -> 0.43739157 | J8: =(J7/I7-1) -> 0.40841899
B9: 5Y CAGR | J9: =(J7/F7)^(1/5)-1 -> 0.35844873
B11: GROSS MARGIN:
F12: 2020A | G12: 2021A | H12: 2022A | I12: 2023A | J12: 2024A | L12: Trend
B13: Gross Profit ($M) | F13: ='Historical Financials'!F12 -> 117.419 | G13: ='Historical Financials'!G12 -> 183.619 | H13: ='Historical Financials'!H12 -> 270.934 | I13: ='Historical Financials'!I12 -> 391.024 | J13: ='Historical Financials'!J12 -> 549.689
B14: Gross Profit % | F14: =F13/'Historical Financials'!F10 -> 0.72617133 | G14: =G13/'Historical Financials'!G10 -> 0.73221492 | H14: =H13/'Historical Financials'!H10 -> 0.73325485 | I14: =I13/'Historical Financials'!I10 -> 0.73624058 | J14: =J13/'Historical Financials'!J10 -> 0.73485476
B17: OPEX ANALYSIS:
F18: 2020A | G18: 2021A | H18: 2022A | I18: 2023A | J18: 2024A | L18: Trend
B19: R&D % of Revenue | F19: ='Historical Financials'!F14*-1/'Historical Financials'!F10 -> 0.32792401 | G19: ='Historical Financials'!G14*-1/'Historical Financials'!G10 -> 0.41386997 | H19: ='Historical Financials'!H14*-1/'Historical Financials'!H10 -> 0.40310153 | I19: ='Historical Financials'!I14*-1/'Historical Financials'!I10 -> 0.36282948 | J19: ='Historical Financials'!J14*-1/'Historical Financials'!J10 -> 0.31140712
B20: SG&A % of Revenue | F20: ='Historical Financials'!F15*-1/'Historical Financials'!F10 -> 0.48157035 | G20: ='Historical Financials'!G15*-1/'Historical Financials'!G10 -> 0.53117573 | H20: ='Historical Financials'!H15*-1/'Historical Financials'!H10 -> 0.49169542 | I20: ='Historical Financials'!I15*-1/'Historical Financials'!I10 -> 0.38438061 | J20: ='Historical Financials'!J15*-1/'Historical Financials'!J10 -> 0.32395485
B21: D&A % of Revenue | F21: ='Historical Financials'!F16*-1/'Historical Financials'!F10 -> 0.013952108 | G21: ='Historical Financials'!G16*-1/'Historical Financials'!G10 -> 0.010870432 | H21: ='Historical Financials'!H16*-1/'Historical Financials'!H10 -> 0.013180151 | I21: ='Historical Financials'!I16*-1/'Historical Financials'!I10 -> 0.01335884 | J21: ='Historical Financials'!J16*-1/'Historical Financials'!J10 -> 0.01451023
B22: Total Opex % of Revenue | F22: =SUM('Historical Financials'!F14:F16)*-1/'Historical Financials'!F10 -> 0.82344647 | G22: =SUM('Historical Financials'!G14:G16)*-1/'Historical Financials'!G10 -> 0.95591613 | H22: =SUM('Historical Financials'!H14:H16)*-1/'Historical Financials'!H10 -> 0.9079771 | I22: =SUM('Historical Financials'!I14:I16)*-1/'Historical Financials'!I10 -> 0.76056892 | J22: =SUM('Historical Financials'!J14:J16)*-1/'Historical Financials'!J10 -> 0.6498722
B25: PROFITABILITY:
F26: 2020A | G26: 2021A | H26: 2022A | I26: 2023A | J26: 2024A | L26: Trend
B27: Operating Margin % | F27: ='Historical Financials'!F17/'Historical Financials'!F10 -> -0.097275134 | G27: ='Historical Financials'!G17/'Historical Financials'!G10 -> -0.22370121 | H27: ='Historical Financials'!H17/'Historical Financials'!H10 -> -0.17472226 | I27: ='Historical Financials'!I17/'Historical Financials'!I10 -> -0.024328339 | J27: ='Historical Financials'!J17/'Historical Financials'!J10 -> 0.084982567
B28: EBITDA Margin % | F28: =('Historical Financials'!F17-'Historical Financials'!F16)/'Historical Financials'!F10 -> -0.083323026 | G28: =('Historical Financials'!G17-'Historical Financials'!G16)/'Historical Financials'!G10 -> -0.21283078 | H28: =('Historical Financials'!H17-'Historical Financials'!H16)/'Historical Financials'!H10 -> -0.1615421 | I28: =('Historical Financials'!I17-'Historical Financials'!I16)/'Historical Financials'!I10 -> -0.0109695 | J28: =('Historical Financials'!J17-'Historical Financials'!J16)/'Historical Financials'!J10 -> 0.099492797
B29: Net Margin % | F29: ='Historical Financials'!F26/'Historical Financials'!F10 -> -0.097565802 | G29: ='Historical Financials'!G26/'Historical Financials'!G10 -> -0.2397995 | H29: ='Historical Financials'!H26/'Historical Financials'!H10 -> -0.16123087 | I29: ='Historical Financials'!I26/'Historical Financials'!I10 -> 0.030251794 | J29: ='Historical Financials'!J26/'Historical Financials'!J10 -> 0.11841064
B32: SECTION B: CASH GENERATION AND CAPITAL EFFICIENCY
B35: CASH FLOW QUALITY:
F36: 2020A | G36: 2021A | H36: 2022A | I36: 2023A | J36: 2024A | L36: Trend
B37: OCF | F37: ='Historical Financials'!F96 -> 17.708 | G37: ='Historical Financials'!G96 -> 9.17 | H37: ='Historical Financials'!H96 -> 53.656 | I37: ='Historical Financials'!I96 -> 153.614 | J37: ='Historical Financials'!J96 -> 285.513
B38: FCF | F38: ='Historical Financials'!F96-ABS('Historical Financials'!F99) -> 13.694 | G38: ='Historical Financials'!G96-ABS('Historical Financials'!G99) -> 2.964 | H38: ='Historical Financials'!H96-ABS('Historical Financials'!H99) -> 43.532 | I38: ='Historical Financials'!I96-ABS('Historical Financials'!I99) -> 139.93 | J38: ='Historical Financials'!J96-ABS('Historical Financials'!J99) -> 264.373
B41: WC DYNAMICS:
F42: 2020A | G42: 2021A | H42: 2022A | I42: 2023A | J42: 2024A | L42: Trend
B43: Changes in WC ($M):
B44: Changes in AR | F44: ='Historical Financials'!F91 -> 18.04 | G44: ='Historical Financials'!G91 -> 30.762 | H44: ='Historical Financials'!H91 -> 45.718 | I44: ='Historical Financials'!I91 -> 49.395 | J44: ='Historical Financials'!J91 -> 83.775
B45: Changes in AP | F45: ='Historical Financials'!F93 -> -1.615 | G45: ='Historical Financials'!G93 -> 5.622 | H45: ='Historical Financials'!H93 -> -6.655 | I45: ='Historical Financials'!I93 -> 1.261 | J45: ='Historical Financials'!J93 -> 3.934
B46: Changes in Accurals | F46: {='Historical Financials'!F95:J95} -> 6.213 | G46: 3.708 | H46: 8.72 | I46: 3.444 | J46: 16.85
B47: Other WC changes | F47: ='Historical Financials'!F94 -> -8.441 | G47: ='Historical Financials'!G94 -> -14.317 | H47: ='Historical Financials'!H94 -> -13.243 | I47: ='Historical Financials'!I94 -> -19.202 | J47: ='Historical Financials'!J94 -> -28.638
B49: Net WC Impact | F49: =SUM(F44:F47) -> 14.197 | G49: =SUM(G44:G47) -> 25.775 | H49: =SUM(H44:H47) -> 34.54 | I49: =SUM(I44:I47) -> 34.898 | J49: =SUM(J44:J47) -> 75.921
B51: DSO | F51: =(365*'Historical Financials'!F38)/'Historical Financials'!F10 -> 46.162243 | G51: =(365*'Historical Financials'!G38)/'Historical Financials'!G10 -> 48.268926 | H51: =(365*'Historical Financials'!H38)/'Historical Financials'!H10 -> 46.159542 | I51: =(365*'Historical Financials'!I38)/'Historical Financials'!I10 -> 61.147288 | J51: =(365*'Historical Financials'!J38)/'Historical Financials'!J10 -> 62.908269
B52: DPO | F52: =(365*'Historical Financials'!F55)/'Historical Financials'!F11*-1 -> 18.102852 | G52: =(365*'Historical Financials'!G55)/'Historical Financials'!G11*-1 -> 42.493559 | H52: =(365*'Historical Financials'!H55)/'Historical Financials'!H11*-1 -> 4.3587727 | I52: =(365*'Historical Financials'!I55)/'Historical Financials'!I11*-1 -> 6.3758075 | J52: =(365*'Historical Financials'!J55)/'Historical Financials'!J11*-1 -> 11.743086
B54: CCC | F54: =F51-F52 -> 28.05939 | G54: =G51-G52 -> 5.7753661 | H54: =H51-H52 -> 41.800769 | I54: =I51-I52 -> 54.77148 | J54: =J51-J52 -> 51.165183
B56: CAPEX REQUIREMENTS:
F57: 2020A | G57: 2021A | H57: 2022A | I57: 2023A | J57: 2024A
B59: CapEx ($M) | F59: ='Historical Financials'!F99*-1 -> 4.014 | G59: ='Historical Financials'!G99*-1 -> 6.206 | H59: ='Historical Financials'!H99*-1 -> 10.124 | I59: ='Historical Financials'!I99*-1 -> 13.684 | J59: ='Historical Financials'!J99*-1 -> 21.14
...

Sheet Master Assumptions
B2: MASTER ASSUMPTIONS
B3: Duolingo, Inc. (DUOL) | Scenario-Driven Forecast Assumptions
B5: SCENARIO SELECTOR
B6: Active Scenario: | C6: Bull
B7: Scenario Code: | C7: =IF(C6="Bull",1,IF(C6="Base",2,3)) -> 1 | D7: (1=Bull, 2=Base, 3=Bear)
B9: ACTIVE ASSUMPTIONS | F9: 2025E | G9: 2026E | H9: 2027E | I9: 2028E | J9: 2029E
B10: REVENUE & MARGINS
B11: Revenue Growth % | F11: =CHOOSE($C$7,'Supporting Schedules'!C9,'Supporting Schedules'!C11,'Supporting Schedules'!C13) -> 0.35 | G11: =CHOOSE($C$7,'Supporting Schedules'!D9,'Supporting Schedules'!D11,'Supporting Schedules'!D13) -> 0.3 | H11: =CHOOSE($C$7,'Supporting Schedules'!E9,'Supporting Schedules'!E11,'Supporting Schedules'!E13) -> 0.27 | I11: =CHOOSE($C$7,'Supporting Schedules'!F9,'Supporting Schedules'!F11,'Supporting Schedules'!F13) -> 0.24 | J11: =CHOOSE($C$7,'Supporting Schedules'!G9,'Supporting Schedules'!G11,'Supporting Schedules'!G13) -> 0.22
B12: Gross Margin % | F12: =CHOOSE($C$7,'Supporting Schedules'!C52,'Supporting Schedules'!C54,'Supporting Schedules'!C56) -> 0.745 | G12: =CHOOSE($C$7,'Supporting Schedules'!D52,'Supporting Schedules'!D54,'Supporting Schedules'!D56) -> 0.75 | H12: =CHOOSE($C$7,'Supporting Schedules'!E52,'Supporting Schedules'!E54,'Supporting Schedules'!E56) -> 0.755 | I12: =CHOOSE($C$7,'Supporting Schedules'!F52,'Supporting Schedules'!F54,'Supporting Schedules'!F56) -> 0.758 | J12: =CHOOSE($C$7,'Supporting Schedules'!G52,'Supporting Schedules'!G54,'Supporting Schedules'!G56) -> 0.76
B14: OPERATING EXPENSES (% of Revenue)
B15: R&D % | F15: =CHOOSE($C$7,'Supporting Schedules'!C67,'Supporting Schedules'!C69,'Supporting Schedules'!C71) -> 0.30140712 | G15: =CHOOSE($C$7,'Supporting Schedules'!D67,'Supporting Schedules'!D69,'Supporting Schedules'!D71) -> 0.29140712 | H15: =CHOOSE($C$7,'Supporting Schedules'!E67,'Supporting Schedules'!E69,'Supporting Schedules'!E71) -> 0.28140712 | I15: =CHOOSE($C$7,'Supporting Schedules'!F67,'Supporting Schedules'!F69,'Supporting Schedules'!F71) -> 0.27140712 | J15: =CHOOSE($C$7,'Supporting Schedules'!G67,'Supporting Schedules'!G69,'Supporting Schedules'!G71) -> 0.26140712
B16: SG&A % | F16: =CHOOSE($C$7,'Supporting Schedules'!C79,'Supporting Schedules'!C81,'Supporting Schedules'!C83) -> 0.31895485 | G16: =CHOOSE($C$7,'Supporting Schedules'!D79,'Supporting Schedules'!D81,'Supporting Schedules'!D83) -> 0.31395485 | H16: =CHOOSE($C$7,'Supporting Schedules'!E79,'Supporting Schedules'!E81,'Supporting Schedules'!E83) -> 0.30895485 | I16: =CHOOSE($C$7,'Supporting Schedules'!F79,'Supporting Schedules'!F81,'Supporting Schedules'!F83) -> 0.30395485 | J16: =CHOOSE($C$7,'Supporting Schedules'!G79,'Supporting Schedules'!G81,'Supporting Schedules'!G83) -> 0.29895485
B17: D&A % | F17: ='Supporting Schedules'!C93 -> 0.015 | G17: ='Supporting Schedules'!D93 -> 0.015 | H17: ='Supporting Schedules'!E93 -> 0.015 | I17: ='Supporting Schedules'!F93 -> 0.015 | J17: ='Supporting Schedules'!G93 -> 0.015
B19: TAX & OTHER
B20: Effective Tax Rate % | F20: ='Supporting Schedules'!C107 -> 0.15 | G20: ='Supporting Schedules'!D107 -> 0.17 | H20: ='Supporting Schedules'!E107 -> 0.18 | I20: ='Supporting Schedules'!F107 -> 0.19 | J20: ='Supporting Schedules'!G107 -> 0.2
B22: BALANCE SHEET & CAPEX
B23: DSO (Days) | F23: ='Supporting Schedules'!C122 -> 62.027779 | G23: ='Supporting Schedules'!D122 -> 62.027779 | H23: ='Supporting Schedules'!E122 -> 62.027779 | I23: ='Supporting Schedules'!F122 -> 62.027779 | J23: ='Supporting Schedules'!G122 -> 62.027779
B24: DPO (Days) | F24: ='Supporting Schedules'!C123 -> 11.743086 | G24: ='Supporting Schedules'!D123 -> 11.743086 | H24: ='Supporting Schedules'!E123 -> 11.743086 | I24: ='Supporting Schedules'!F123 -> 11.743086 | J24: ='Supporting Schedules'!G123 -> 11.743086
B25: Other Receivables % of Revenue | F25: ='Supporting Schedules'!C157 -> 0.096827486 | G25: ='Supporting Schedules'!D157 -> 0.096827486 | H25: ='Supporting Schedules'!E157 -> 0.096827486 | I25: ='Supporting Schedules'!F157 -> 0.096827486 | J25: ='Supporting Schedules'!G157 -> 0.096827486
B26: Other Current Assets % of Revenue | F26: ='Supporting Schedules'!C158 -> 0.021752587 | G26: ='Supporting Schedules'!D158 -> 0.021752587 | H26: ='Supporting Schedules'!E158 -> 0.021752587 | I26: ='Supporting Schedules'!F158 -> 0.021752587 | J26: ='Supporting Schedules'!G158 -> 0.021752587
B27: Income Tax Payable % of Tax Expense | F27: ='Supporting Schedules'!C215 -> 0.47997378 | G27: ='Supporting Schedules'!D215*-1 -> 0.47997378 | H27: ='Supporting Schedules'!E215*-1 -> 0.47997378 | I27: ='Supporting Schedules'!F215*-1 -> 0.47997378 | J27: ='Supporting Schedules'!G215*-1 -> 0.47997378
B28: Other CL % of Revenue | F28: ='Supporting Schedules'!C230 -> 0.54366972 | G28: ='Supporting Schedules'!D230 -> 0.54366972 | H28: ='Supporting Schedules'!E230 -> 0.54366972 | I28: ='Supporting Schedules'!F230 -> 0.54366972 | J28: ='Supporting Schedules'!G230 -> 0.54366972
B29: SBC % of Revenue | F29: ='Supporting Schedules'!$C$247 -> 0.10532728 | G29: ='Supporting Schedules'!$C$247 -> 0.10532728 | H29: ='Supporting Schedules'!$C$247 -> 0.10532728 | I29: ='Supporting Schedules'!$C$247 -> 0.10532728 | J29: ='Supporting Schedules'!$C$247 -> 0.10532728
B31: INTEREST INCOME
B32: Interest Income | F32: 0.045 | G32: 0.045 | H32: 0.045 | I32: 0.045 | J32: 0.045
B34: VALUATION PARAMETERS
B35: Terminal Growth Rate | J35: 0.025

Sheet Supporting Schedules
B2: SUPPORTING SCHEDULES
B3: Duolingo, Inc. (DUOL)
B5: REVENUE SCHEDULE
B7: Scenario Assumptions — Revenue Growth Rates
C8: 2025E | D8: 2026E | E8: 2027E | F8: 2028E | G8: 2029E | H8: Avg | I8: Logic
B9: Bull Case | C9: 0.35 | D9: 0.3 | E9: 0.27 | F9: 0.24 | G9: 0.22 | H9: =AVERAGE(C9:G9) -> 0.276 | I9: ~5 ppt/yr decel
B10: Deceleration (ppt) | C10: =C9-$G$19 -> -0.058397665 | D10: =D9-C9 -> -0.05 | E10: =E9-D9 -> -0.03 | F10: =F9-E9 -> -0.03 | G10: =G9-F9 -> -0.02 | H10: =AVERAGE(D10:G10) -> -0.0325
B11: Base Case | C11: 0.28 | D11: 0.24 | E11: 0.21 | F11: 0.18 | G11: 0.16 | H11: =AVERAGE(C11:G11) -> 0.214 | I11: ~6-7 ppt/yr decel
B12: Deceleration (ppt) | C12: =C11-$G$19 -> -0.12839767 | D12: =D11-C11 -> -0.04 | E12: =E11-D11 -> -0.03 | F12: =F11-E11 -> -0.03 | G12: =G11-F11 -> -0.02 | H12: =AVERAGE(D12:G12) -> -0.03
B13: Bear Case | C13: 0.2 | D13: 0.17 | E13: 0.14 | F13: 0.12 | G13: 0.1 | H13: =AVERAGE(C13:G13) -> 0.146 | I13: ~8-10 ppt/yr decel
B14: Deceleration (ppt) | C14: =C13-$G$19 -> -0.20839767 | D14: =D13-C13 -> -0.03 | E14: =E13-D13 -> -0.03 | F14: =F13-E13 -> -0.02 | G14: =G13-F13 -> -0.02 | H14: =AVERAGE(D14:G14) -> -0.025
B16: Historical Analysis
C17: 2020A | D17: 2021A | E17: 2022A | F17: 2023A | G17: 2024A | H17: 5Y CAGR
B18: Revenue ($M) | C18: 161.7 | D18: 250.8 | E18: 369.5 | F18: 531.1 | G18: 748 | H18: =(G18/C18)^(1/4)-1 -> 0.46655345
B19: YoY Growth % | D19: =(D18-C18)/C18 -> 0.55102041 | E19: =(E18-D18)/D18 -> 0.47328549 | F19: =(F18-E18)/E18 -> 0.43734777 | G19: =(G18-F18)/F18 -> 0.40839767
B20: Growth Deceleration (ppt) | E20: =E19-D19 -> -0.077734922 | F20: =F19-E19 -> -0.035937719 | G20: =G19-F19 -> -0.028950102 | H20: =AVERAGE(E20:G20) -> -0.047540914 | I20: avg
B21: Observation: Revenue growth decelerating ~5-8 ppt/year from 55% to 41%. Classic high-growth SaaS deceleration pattern as base grows.
B23: Driver-Based Revenue Build-Up
B24: Revenue = MAU × Paid Conversion % × ARPPU
C26: 2020A | D26: 2021A | E26: 2022A | F26: 2023A | G26: 2024A | H26: 4Y CAGR | I26: Trend
B27: MAU (M) | C27: 37 | D27: 42 | E27: 60 | F27: 88 | G27: 117 | H27: =(G27/C27)^(1/4)-1 -> 0.33350926 | I27: Slowing (33%→33%)
B28: YoY Growth % | D28: =(D27-C27)/C27 -> 0.13513514 | E28: =(E27-D27)/D27 -> 0.42857143 | F28: =(F27-E27)/E27 -> 0.46666667 | G28: =(G27-F27)/F27 -> 0.32954545
B29: DAU (M) | C29: 9 | D29: 11 | E29: 16 | F29: 27 | G29: 37 | H29: =(G29/C29)^(1/4)-1 -> 0.42393382 | I29: Faster than MAU
B30: DAU/MAU Ratio | C30: =C29/C27 -> 0.24324324 | D30: =D29/D27 -> 0.26190476 | E30: =E29/E27 -> 0.26666667 | F30: =F29/F27 -> 0.30681818 | G30: =G29/G27 -> 0.31623932 | H30: =G30-C30 -> 0.072996073 | I30: Improving engagement
B31: Paid Subscribers (M) | C31: 1.8 | D31: 2.9 | E31: 4.8 | F31: 7.6 | G31: 12.1 | H31: =(G31/C31)^(1/4)-1 -> 0.61019405 | I31: Strong sub growth
B32: Paid Conversion % | C32: =C31/C27 -> 0.048648649 | D32: =D31/D27 -> 0.069047619 | E32: =E31/E27 -> 0.08 | F32: =F31/F27 -> 0.086363636 | G32: =G31/G27 -> 0.1034188 | H32: =G32-C32 -> 0.054770155 | I32: Key driver: conversion ↑
B33: ARPPU ($/yr) | C33: =C18/C31 -> 89.833333 | D33: =D18/D31 -> 86.482759 | E33: =E18/E31 -> 76.979167 | F33: =F18/F31 -> 69.881579 | G33: =G18/G31 -> 61.818182 | H33: =(G33/C33)^(1/4)-1 -> -0.089207012 | I33: Declining (mix shift)
B35: Key Insight: Revenue growth driven by MAU growth + conversion improvement, partially offset by ARPPU decline (international mix shift).
B37: Scenario Rationale
B39: Bull Case (27.6% avg growth) | E39: Base Case (21.4% avg growth) | H39: Bear Case (14.6% avg growth)
B40: • Duolingo Max (AI tier) drives 2-3 ppt conversion uplift annually | E40: • Continues historical deceleration | H40: • Competitive pressure from free alternatives (ChatGPT, YouTube)
B41: • New verticals (Math, Music) expand TAM by 20-30% | E41: • Paid subscriber growth moderates | H41: • Macro headwinds reduce discretionary ed-tech spend
B42: • International expansion in Asia-Pacific accelerates MAU growth | E42: • ARPPU stable as geographic mix stabilizes | H42: • Conversion rate plateaus as casual users dominate growth
B43: • Gamification moat sustains engagement vs competitors | H43: • New verticals underperform vs core language learning
B45: Key Sensitivity: Each 1 ppt change in growth rate = ~$15M revenue impact in Year 1, compounding to ~$100M by Year 5
B48: GROSS MARGIN ASSUMPTIONS
B50: Scenario Assumptions — Gross Margin
C51: 2025E | D51: 2026E | E51: 2027E | F51: 2028E | G51: 2029E | H51: Avg | I51: Logic
B52: Bull Case | C52: 0.745 | D52: 0.75 | E52: 0.755 | F52: 0.758 | G52: 0.76 | H52: =AVERAGE(C52:G52) -> 0.7536 | I52: Scale leverage on AI/hosting
D53: =D52-C52 -> 0.005 | E53: =E52-D52 -> 0.005 | F53: =F52-E52 -> 0.003 | G53: =G52-F52 -> 0.002 | H53: =AVERAGE(D53:G53) -> 0.00375 | I53: ~50bps/yr expansion
...

Sheet Forecast Model
B3: INCOME STATEMENT
B5: All figures in millions of euros | E5: 2022A | F5: 2023A | G5: 2024A | H5: 2025E | I5: 2026E | J5: 2027E | K5: 2028E | L5: 2029E
B6: unless stated otherwise
B8: Revenue | E8: 369.495 | F8: 531.109 | G8: 748.024 | H8: =G8*(1+'Master Assumptions'!F11) -> 1009.8324 | I8: =H8*(1+'Master Assumptions'!G11) -> 1312.7821 | J8: =I8*(1+'Master Assumptions'!H11) -> 1667.2333 | K8: =J8*(1+'Master Assumptions'!I11) -> 2067.3693 | L8: =K8*(1+'Master Assumptions'!J11) -> 2522.1905
B9: COGS (excl. D&A) | E9: -98.561 | F9: -140.085 | G9: -198.335 | H9: =H10-H8 -> -257.50726 | I9: =I10-I8 -> -328.19553 | J9: =J10-J8 -> -408.47216 | K9: =K10-K8 -> -500.30337 | L9: =L10-L8 -> -605.32573
B10: Gross Profit (excl. D&A) | E10: =SUM(E8:E9) -> 270.934 | F10: =SUM(F8:F9) -> 391.024 | G10: =SUM(G8:G9) -> 549.689 | H10: =H8*'Master Assumptions'!F12 -> 752.32514 | I10: =I8*'Master Assumptions'!G12 -> 984.58659 | J10: =J8*'Master Assumptions'!H12 -> 1258.7611 | K10: =K8*'Master Assumptions'!I12 -> 1567.0659 | L10: =L8*'Master Assumptions'!J12 -> 1916.8648
B12: R&D Expense | E12: -148.944 | F12: -192.702 | G12: -232.94 | H12: =-H8*'Master Assumptions'!F15 -> -304.37068 | I12: =-I8*'Master Assumptions'!G15 -> -382.55406 | J12: =-J8*'Master Assumptions'!H15 -> -469.17132 | K12: =-K8*'Master Assumptions'!I15 -> -561.09874 | L12: =-L8*'Master Assumptions'!J15 -> -659.31856
B13: SG&A Expense | E13: -181.679 | F13: -204.148 | G13: -242.326 | H13: =-H8*'Master Assumptions'!F16 -> -322.09094 | I13: =-I8*'Master Assumptions'!G16 -> -412.15431 | J13: =-J8*'Master Assumptions'!H16 -> -515.09981 | K13: =-K8*'Master Assumptions'!I16 -> -628.38691 | L13: =-L8*'Master Assumptions'!J16 -> -754.02108
B14: D&A Expense | E14: -4.87 | F14: -7.095 | G14: -10.854 | H14: =-H8*'Master Assumptions'!F17 -> -15.147486 | I14: =-I8*'Master Assumptions'!G17 -> -19.691732 | J14: =-J8*'Master Assumptions'!H17 -> -25.008499 | K14: =-K8*'Master Assumptions'!I17 -> -31.010539 | L14: =-L8*'Master Assumptions'!J17 -> -37.832858
B15: EBIT | E15: =SUM(E10:E14) -> -64.559 | F15: =SUM(F10:F14) -> -12.921 | G15: =SUM(G10:G14) -> 63.569 | H15: =SUM(H10:H14) -> 110.71604 | I15: =SUM(I10:I14) -> 170.18649 | J15: =SUM(J10:J14) -> 249.48151 | K15: =SUM(K10:K14) -> 346.56972 | L15: =SUM(L10:L14) -> 465.6923
B17: Interest Income | E17: 7.235 | F17: 31.091 | G17: 42.697 | H17: ='Supporting Schedules'!C275 -> 39.494025 | I17: ='Supporting Schedules'!D275 -> 53.840805 | J17: ='Supporting Schedules'!E275 -> 72.368858 | K17: ='Supporting Schedules'!F275 -> 96.602102 | L17: ='Supporting Schedules'!G275 -> 127.49171
B18: Unusual Expense | E18: -0.636 | F18: -0.338 | G18: -0.974 | H18: =AVERAGE(E18:G18) -> -0.64933333 | I18: =AVERAGE(F18:H18) -> -0.65377778 | J18: =AVERAGE(G18:I18) -> -0.75903704 | K18: =AVERAGE(H18:J18) -> -0.68738272 | L18: =AVERAGE(I18:K18) -> -0.70006584
B19: Other Income | E19: -0.676 | F19: -0.055 | G19: -2.986 | H19: =AVERAGE(E19:G19) -> -1.239 | I19: =H19 -> -1.239 | J19: =I19 -> -1.239 | K19: =J19 -> -1.239 | L19: =K19 -> -1.239
B20: EBT | E20: =SUM(E15:E19) -> -58.636 | F20: =SUM(F15:F19) -> 17.777 | G20: =SUM(G15:G19) -> 102.306 | H20: =SUM(H15:H19) -> 148.32173 | I20: =SUM(I15:I19) -> 222.13452 | J20: =SUM(J15:J19) -> 319.85233 | K20: =SUM(K15:K19) -> 441.24544 | L20: =SUM(L15:L19) -> 591.24494
B22: Income Taxes | E22: -0.938 | F22: -1.71 | G22: -13.732 | H22: =-H20*'Master Assumptions'!F20 -> -22.248259 | I22: =-I20*'Master Assumptions'!G20 -> -37.762868 | J22: =-J20*'Master Assumptions'!H20 -> -57.57342 | K22: =-K20*'Master Assumptions'!I20 -> -83.836634 | L22: =-L20*'Master Assumptions'!J20 -> -118.24899
B23: Equity in Affiliates | E23: 0 | F23: 0 | G23: 0 | H23: =G23 -> 0 | I23: =H23 -> 0 | J23: =I23 -> 0 | K23: =J23 -> 0 | L23: =K23 -> 0
B24: Net Income | E24: =SUM(E20:E23) -> -59.574 | F24: =SUM(F20:F23) -> 16.067 | G24: =SUM(G20:G23) -> 88.574 | H24: =SUM(H20:H23) -> 126.07347 | I24: =SUM(I20:I23) -> 184.37165 | J24: =SUM(J20:J23) -> 262.27891 | K24: =SUM(K20:K23) -> 357.40881 | L24: =SUM(L20:L23) -> 472.99595
B28: BALANCE SHEET
B30: All figures in millions of euros | E30: 2022A | F30: 2023A | G30: 2024A | H30: 2025E | I30: 2026E | J30: 2027E | K30: 2028E | L30: 2029E
B31: unless stated otherwise
B33: Assets
B34: Cash & Short-Term Investments | E34: 608.18 | F34: 747.61 | G34: 877.645 | H34: =G34+H110 -> 1196.4623 | I34: =H34+I110 -> 1608.1969 | J34: =I34+J110 -> 2146.7134 | K34: =J34+K110 -> 2833.1491 | L34: =K34+L110 -> 3696.272
B35: Accounts Receivable | E35: 46.728 | F35: 88.975 | G35: 128.923 | H35: ='Supporting Schedules'!H131 -> 171.61003 | I35: ='Supporting Schedules'!I131 -> 223.09304 | J35: ='Supporting Schedules'!J131 -> 283.32816 | K35: ='Supporting Schedules'!K131 -> 351.32691 | L35: ='Supporting Schedules'!L131 -> 428.61884
B36: Other Receivables | E36: 35.041 | F36: 53.931 | G36: 80.162 | H36: ='Master Assumptions'!F25*'Forecast Model'!H8 -> 97.779533 | I36: ='Master Assumptions'!G25*'Forecast Model'!I8 -> 127.11339 | J36: ='Master Assumptions'!H25*'Forecast Model'!J8 -> 161.43401 | K36: ='Master Assumptions'!I25*'Forecast Model'!K8 -> 200.17817 | L36: ='Master Assumptions'!J25*'Forecast Model'!L8 -> 244.21737
B37: Inventories | E37: 0 | F37: 0 | G37: 0 | H37: =G37 -> 0 | I37: =H37 -> 0 | J37: =I37 -> 0 | K37: =J37 -> 0 | L37: =K37 -> 0
B38: Other Current Assets | E38: 7.234 | F38: 7.282 | G38: 14.858 | H38: ='Master Assumptions'!F26*'Forecast Model'!H8 -> 21.966467 | I38: ='Master Assumptions'!G26*'Forecast Model'!I8 -> 28.556407 | J38: ='Master Assumptions'!H26*'Forecast Model'!J8 -> 36.266637 | K38: ='Master Assumptions'!I26*'Forecast Model'!K8 -> 44.97063 | L38: ='Master Assumptions'!J26*'Forecast Model'!L8 -> 54.864169
B39: Total Current Assets | E39: =SUM(E34:E38) -> 697.183 | F39: =SUM(F34:F38) -> 897.798 | G39: =SUM(G34:G38) -> 1101.588 | H39: =SUM(H34:H38) -> 1487.8184 | I39: =SUM(I34:I38) -> 1986.9597 | J39: =SUM(J34:J38) -> 2627.7422 | K39: =SUM(K34:K38) -> 3429.6248 | L39: =SUM(L34:L38) -> 4423.9723
B41: Net PP&E | E41: 35.477 | F41: 30.895 | G41: 66.438 | H41: ='Supporting Schedules'!D188 -> 77.747634 | I41: ='Supporting Schedules'!E188 -> 92.450159 | J41: ='Supporting Schedules'!F188 -> 111.12237 | K41: ='Supporting Schedules'!G188 -> 134.2759 | L41: ='Supporting Schedules'!H188 -> 162.52322
B42: Goodwill | E42: 4.05 | F42: 4.05 | G42: 10.538 | H42: =G42 -> 10.538 | I42: =H42 -> 10.538 | J42: =I42 -> 10.538 | K42: =J42 -> 10.538 | L42: =K42 -> 10.538
B43: Other Intangible Assets | E43: 8.497 | F43: 15.995 | G43: 19.899 | H43: =G43 -> 19.899 | I43: =H43 -> 19.899 | J43: =I43 -> 19.899 | K43: =J43 -> 19.899 | L43: =K43 -> 19.899
B44: Long-Term Investments | E44: 0 | F44: 2.735 | G44: 101.027 | H44: =G44 -> 101.027 | I44: =H44 -> 101.027 | J44: =I44 -> 101.027 | K44: =J44 -> 101.027 | L44: =K44 -> 101.027
B45: Deferred Tax Assets | E45: 10.247 | F45: 11.038 | G45: 0.675 | H45: =G45 -> 0.675 | I45: =H45 -> 0.675 | J45: =I45 -> 0.675 | K45: =J45 -> 0.675 | L45: =K45 -> 0.675
B46: Other Non-Current Assets | E46: 1.507 | F46: 1.718 | G46: 1.563 | H46: =G46 -> 1.563 | I46: =H46 -> 1.563 | J46: =I46 -> 1.563 | K46: =J46 -> 1.563 | L46: =K46 -> 1.563
B47: Total Non-Current Assets | E47: =SUM(E41:E46) -> 59.778 | F47: =SUM(F41:F46) -> 66.431 | G47: =SUM(G41:G46) -> 200.14 | H47: =SUM(H41:H46) -> 211.44963 | I47: =SUM(I41:I46) -> 226.15216 | J47: =SUM(J41:J46) -> 244.82437 | K47: =SUM(K41:K46) -> 267.9779 | L47: =SUM(L41:L46) -> 296.22522
B49: Total Assets | E49: =E39+E47 -> 756.961 | F49: =F39+F47 -> 964.229 | G49: =G39+G47 -> 1301.728 | H49: =H47+H39 -> 1699.268 | I49: =I47+I39 -> 2213.1119 | J49: =J47+J39 -> 2872.5666 | K49: =K47+K39 -> 3697.6027 | L49: =L47+L39 -> 4720.1975
B51: Liabilities
B52: Accounts Payable | E52: 1.177 | F52: 2.447 | G52: 6.381 | H52: ='Supporting Schedules'!H139 -> 8.2847397 | I52: ='Supporting Schedules'!I139 -> 10.558982 | J52: ='Supporting Schedules'!J139 -> 13.141709 | K52: ='Supporting Schedules'!K139 -> 16.09618 | L52: ='Supporting Schedules'!L139 -> 19.475047
B53: Short-Term Debt & Curr. LT Portion | E53: 4.903 | F53: 3.944 | G53: 2.581 | H53: ='Supporting Schedules'!D203 -> 2.581 | I53: ='Supporting Schedules'!E203 -> 2.581 | J53: ='Supporting Schedules'!F203 -> 2.581 | K53: ='Supporting Schedules'!G203 -> 2.581 | L53: ='Supporting Schedules'!H203 -> 2.581
B54: Income Tax Payable | E54: 1.069 | F54: 0.792 | G54: 6.591 | H54: ='Master Assumptions'!F27*'Forecast Model'!H22*-1 -> 10.678581 | I54: ='Master Assumptions'!G27*'Forecast Model'!I22*-1 -> 18.125187 | J54: ='Master Assumptions'!H27*'Forecast Model'!J22*-1 -> 27.633732 | K54: ='Master Assumptions'!I27*'Forecast Model'!K22*-1 -> 40.239386 | L54: ='Master Assumptions'!J27*'Forecast Model'!L22*-1 -> 56.756414
B55: Other Current Liabilities | E55: 174.617 | F55: 270.179 | G55: 406.678 | H55: ='Master Assumptions'!F28*'Forecast Model'!H8 -> 549.0153 | I55: ='Master Assumptions'!G28*'Forecast Model'!I8 -> 713.71989 | J55: ='Master Assumptions'!H28*'Forecast Model'!J8 -> 906.42426 | K55: ='Master Assumptions'!I28*'Forecast Model'!K8 -> 1123.9661 | L55: ='Master Assumptions'!J28*'Forecast Model'!L8 -> 1371.2386
...

Sheet Integration Check
B2: INTEGRATION CHECK
B3: Duolingo, Inc. (DUOL)
B5: STATUS | C5: =IF(COUNTIF(D9:D15,"✗ FAIL")=0,"✓ ALL CHECKS PASSED",COUNTIF(D9:D15,"✗ FAIL")&" CHECK(S) FAILED") -> ✓ ALL CHECKS PASSED
B7: CHECK | C7: DESCRIPTION | D7: STATUS | E7: 2025E | F7: 2026E | G7: 2027E | H7: 2028E | I7: 2028E
B9: Balance Sheet Balances | C9: Assets = Liabilities + Equity | D9: =IF(AND(ABS(E9)<0.01,ABS(F9)<0.01,ABS(G9)<0.01,ABS(H9)<0.01,ABS(I9)<0.01),"✓ OK","✗ FAIL") -> ✓ OK | E9: ='Forecast Model'!H49-'Forecast Model'!H72 -> 0.004 | F9: ='Forecast Model'!I49-'Forecast Model'!I72 -> 0.004 | G9: ='Forecast Model'!J49-'Forecast Model'!J72 -> 0.004 | H9: ='Forecast Model'!K49-'Forecast Model'!K72 -> 0.004 | I9: ='Forecast Model'!L49-'Forecast Model'!L72 -> 0.004
B11: Net Income → Cash Flow | C11: NI (IS) = NI (CF Statement) | D11: =IF(AND(ABS(E11)<0.01,ABS(F11)<0.01,ABS(G11)<0.01,ABS(H11)<0.01,ABS(I11)<0.01),"✓ OK","✗ FAIL") -> ✓ OK
B13: D&A Consistency | C13: D&A (IS) = D&A (CF add-back) | D13: =IF(AND(ABS(E13)<0.01,ABS(F13)<0.01,ABS(G13)<0.01,ABS(H13)<0.01,ABS(I13)<0.01),"✓ OK","✗ FAIL") -> ✓ OK
B15: Cash Flow Foots | C15: CFO + CFI + CFF = Net Δ Cash | D15: =IF(AND(ABS(E15)<0.01,ABS(F15)<0.01,ABS(G15)<0.01,ABS(H15)<0.01,ABS(I15)<0.01),"✓ OK","✗ FAIL") -> ✓ OK
B18: Note: | C18: Differences should be 0.000 (small rounding OK). Non-zero = broken link.

Sheet DCF Valuation
B3: DCF VALUATION
B5: SECTION 1: CAPITAL STRUCTURE
B7: Cost of Equity (CAPM): | H7: Cost of Debt:
B9: Risk-Free Rate (Rf) | E9: 0.0405 | H9: Pre-tax Cost of Debt (Kd) | K9: 0
B10: Equity risk premium (ERP) | E10: 0.0446 | H10: Tax rate | K10: 0
B11: Beta (Levered) | E11: 1.59 | H11: After-Tax Cost of Debt | K11: 0
B12: Cost of Equity(Ke) | E12: =E9+E10*E11 -> 0.111414
B15: Weight of Equity | E15: 1 | H15: Weight of Debt | K15: 0
B18: Weighted Average Cost of Capital | E18: =IF('Sensitivity Analysis'!K8="",E15*E12,'Sensitivity Analysis'!K8) -> 0.111414
B21: SECTION 2: FREE CASH FLOW SCHEDULE
E24: 2025E | F24: 2026E | G24: 2027E | H24: 2028E | I24: 2029E
B26: EBIT | E26: ='Forecast Model'!H15 -> 110.71604 | F26: ='Forecast Model'!I15 -> 170.18649 | G26: ='Forecast Model'!J15 -> 249.48151 | H26: ='Forecast Model'!K15 -> 346.56972 | I26: ='Forecast Model'!L15 -> 465.6923
B27: % Margin | E27: =E26/'Forecast Model'!H8 -> 0.10963803 | F27: =F26/'Forecast Model'!I8 -> 0.12963803 | G27: =G26/'Forecast Model'!J8 -> 0.14963803 | H27: =H26/'Forecast Model'!K8 -> 0.16763803 | I27: =I26/'Forecast Model'!L8 -> 0.18463803
B28: Less: Taxes on EBIT | E28: =-(E26*'Master Assumptions'!F20) -> -16.607406 | F28: =-(F26*'Master Assumptions'!G20) -> -28.931704 | G28: =-(G26*'Master Assumptions'!H20) -> -44.906672 | H28: =-(H26*'Master Assumptions'!I20) -> -65.848247 | I28: =-(I26*'Master Assumptions'!J20) -> -93.138459
B29: NOPAT (EBIT x (1-Tax rate) | E29: =E26+E28 -> 94.108632 | F29: =F26+F28 -> 141.25479 | G29: =G26+G28 -> 204.57484 | H29: =H26+H28 -> 280.72147 | I29: =I26+I28 -> 372.55384
B32: Plus: D&A | E32: =-'Forecast Model'!H14 -> 15.147486 | F32: =-'Forecast Model'!I14 -> 19.691732 | G32: =-'Forecast Model'!J14 -> 25.008499 | H32: =-'Forecast Model'!K14 -> 31.010539 | I32: =-'Forecast Model'!L14 -> 37.832858
B33: Less: CapEx | E33: ='Forecast Model'!H95 -> -26.45712 | F33: ='Forecast Model'!I95 -> -34.394257 | G33: ='Forecast Model'!J95 -> -43.680706 | H33: ='Forecast Model'!K95 -> -54.164075 | I33: ='Forecast Model'!L95 -> -66.080172
B34: Less: Change in NWC | E34: =SUM('Forecast Model'!H87:H91) -> 80.915592 | F34: =SUM('Forecast Model'!I87:I91) -> 87.018629 | G34: =SUM('Forecast Model'!J87:J91) -> 102.52968 | H34: =SUM('Forecast Model'!K87:K91) -> 117.65503 | I34: =SUM('Forecast Model'!L87:L91) -> 135.94378
B35: Plus: SBC | E35: ='Forecast Model'!H85 -> 106.3629 | F35: ='Forecast Model'!I85 -> 138.27177 | G35: ='Forecast Model'!J85 -> 175.60515 | H35: ='Forecast Model'!K85 -> 217.75038 | I35: ='Forecast Model'!L85 -> 265.65547
B37: Unlevered Free Cash Flow | E37: =SUM(E29:E35) -> 270.07749 | F37: =SUM(F29:F35) -> 351.84266 | G37: =SUM(G29:G35) -> 464.03746 | H37: =SUM(H29:H35) -> 592.97336 | I37: =SUM(I29:I35) -> 745.90577
B38: % Conversion (UCF/NOPAT) | E38: =E37/E29 -> 2.8698482 | F38: =F37/F29 -> 2.4908371 | G38: =G37/G29 -> 2.2683017 | H38: =H37/H29 -> 2.1123192 | I38: =I37/I29 -> 2.0021422
B42: SECTION 3: DISCOUNTING & PRESENT VALUE
E43: 2025E | F43: 2026E | G43: 2027E | H43: 2028E | I43: 2029E
B44: Discount Period (Mid Year Convention) | E44: 0.5 | F44: 1.5 | G44: 2.5 | H44: 3.5 | I44: 4.5
B45: Discount Factor | E45: =1/(1+$E$18)^E44 -> 0.94855402 | F45: =1/(1+$E$18)^F44 -> 0.85346596 | G45: =1/(1+$E$18)^G44 -> 0.76791003 | H45: =1/(1+$E$18)^H44 -> 0.69093068 | I45: =1/(1+$E$18)^I44 -> 0.62166815
B47: PV of FCF | E47: =E45*E37 -> 256.18309 | F47: =F45*F37 -> 300.28574 | G47: =G45*G37 -> 356.33902 | H47: =H45*H37 -> 409.70349 | I47: =I45*I37 -> 463.70586
B49: Sum of FCF | E49: =SUM(E47:I47) -> 1786.2172
B52: SECTION 4: TERMINAL VALUE CALCULATION
B53: Perpetual Growth Method
B55: Terminal Year FCF (2029E) | E55: =I37 -> 745.90577
B56: Perpetual Growth Rate | E56: =IF('Sensitivity Analysis'!K9="",0.025,'Sensitivity Analysis'!K9) -> 0.025
B57: Terminal Value (Perpetuity) | E57: =E55*(1+E56)/(E18-E56) -> 8847.5642
B58: PV of Terminal Value | E58: =E57/(1+$E$18)^I44 -> 5500.2489
B61: SECTION 5: ENTERPRISE VALUE TO EQUITY VALUE
B64: Sum of PV of FCF | E64: =E49 -> 1786.2172
B65: PV of Terminal Value | E65: =E58 -> 5500.2489
B66: Enterprise Value | E66: =SUM(E64:E65) -> 7286.466
B68: Less: Total Debt | E68: 0
B69: Plus: Cash & Equivalents | E69: ='Historical Financials'!J37 -> 877.645
B70: Less: Minority Interest | E70: =0 -> 0
...

Sheet Sensitivity Analysis
B2: SENSITIVITY ANALYSIS
B4: WACC vs. PERPETUAL GROWTH RATE
B5: Implied Diluted Share Price across WACC and Perpetual Growth Rate assumptions
D7: Implied Price (Diluted) | E7: GROWTH RATE
D8: ='DCF Valuation'!E79 -> 164.53267 | E8: 0.015 | F8: 0.02 | G8: 0.025 | H8: 0.03 | I8: 0.035
C9: WACC | D9: 0.0914 | E9: 190.30429 | F9: 200.44952 | G9: 212.12264 | H9: 225.69693 | I9: 241.678
D10: 0.1014 | E10: 168.95747 | F10: 176.57916 | G10: 185.19846 | H10: 195.02493 | I10: 206.3313
D11: 0.1114 | E11: 152.0875 | F11: 157.98174 | G11: 164.55818 | H11: 171.94254 | I11: 180.29344
D12: 0.1214 | E12: 138.4302 | F12: 143.09524 | G12: 148.24421 | H12: 153.95653 | I12: 160.32999
D13: 0.1314 | E13: 127.15589 | F13: 130.91862 | G13: 135.03498 | H13: 139.5573 | I13: 144.54873
B18: TERMINAL EBIT MARGIN vs. REVENUE CAGR
B19: Implied Diluted Share Price across Terminal EBIT Margin and Revenue CAGR (2024-2029E)
C21: EBIT Margin | D21: Implied Price (Diluted) | E21: REVENUE CAGR
D22: ='DCF Valuation'!E79 -> 164.53267 | E22: 0.2 | F22: 0.24 | G22: 0.275 | H22: 0.31 | I22: 0.35
D23: 0.12 | E23: =('DCF Valuation'!$E$49+(('Forecast Model'!$G$8*(1+E$22)^5*$D23*(1-'Master Assumptions'!$J$20)+'Forecast Model'!$G$8*(1+E$22)^5*SUM('DCF Valuation'!$I$32:$I$35)/'Forecast Model'!$L$8)*(1+'DCF Valuation'!$E$56)/('DCF Valuation'!$E$18-'DCF Valuation'!$E$56))/(1+'DCF Valuation'!$E$18)^'DCF Valuation'!$I$44+SUM('DCF Valuation'!$E$68:$E$72))/'DCF Valuation'!$E$78 -> 121.18482 | F23: =('DCF Valuation'!$E$49+(('Forecast Model'!$G$8*(1+F$22)^5*$D23*(1-'Master Assumptions'!$J$20)+'Forecast Model'!$G$8*(1+F$22)^5*SUM('DCF Valuation'!$I$32:$I$35)/'Forecast Model'!$L$8)*(1+'DCF Valuation'!$E$56)/('DCF Valuation'!$E$18-'DCF Valuation'!$E$56))/(1+'DCF Valuation'!$E$18)^'DCF Valuation'!$I$44+SUM('DCF Valuation'!$E$68:$E$72))/'DCF Valuation'!$E$78 -> 133.21016 | G23: =('DCF Valuation'!$E$49+(('Forecast Model'!$G$8*(1+G$22)^5*$D23*(1-'Master Assumptions'!$J$20)+'Forecast Model'!$G$8*(1+G$22)^5*SUM('DCF Valuation'!$I$32:$I$35)/'Forecast Model'!$L$8)*(1+'DCF Valuation'!$E$56)/('DCF Valuation'!$E$18-'DCF Valuation'!$E$56))/(1+'DCF Valuation'!$E$18)^'DCF Valuation'!$I$44+SUM('DCF Valuation'!$E$68:$E$72))/'DCF Valuation'!$E$78 -> 145.08515 | H23: =('DCF Valuation'!$E$49+(('Forecast Model'!$G$8*(1+H$22)^5*$D23*(1-'Master Assumptions'!$J$20)+'Forecast Model'!$G$8*(1+H$22)^5*SUM('DCF Valuation'!$I$32:$I$35)/'Forecast Model'!$L$8)*(1+'DCF Valuation'!$E$56)/('DCF Valuation'!$E$18-'DCF Valuation'!$E$56))/(1+'DCF Valuation'!$E$18)^'DCF Valuation'!$I$44+SUM('DCF Valuation'!$E$68:$E$72))/'DCF Valuation'!$E$78 -> 158.33815 | I23: =('DCF Valuation'!$E$49+(('Forecast Model'!$G$8*(1+I$22)^5*$D23*(1-'Master Assumptions'!$J$20)+'Forecast Model'!$G$8*(1+I$22)^5*SUM('DCF Valuation'!$I$32:$I$35)/'Forecast Model'!$L$8)*(1+'DCF Valuation'!$E$56)/('DCF Valuation'!$E$18-'DCF Valuation'!$E$56))/(1+'DCF Valuation'!$E$18)^'DCF Valuation'!$I$44+SUM('DCF Valuation'!$E$68:$E$72))/'DCF Valuation'!$E$78 -> 175.32167
D24: 0.14 | E24: =('DCF Valuation'!$E$49+(('Forecast Model'!$G$8*(1+E$22)^5*$D24*(1-'Master Assumptions'!$J$20)+'Forecast Model'!$G$8*(1+E$22)^5*SUM('DCF Valuation'!$I$32:$I$35)/'Forecast Model'!$L$8)*(1+'DCF Valuation'!$E$56)/('DCF Valuation'!$E$18-'DCF Valuation'!$E$56))/(1+'DCF Valuation'!$E$18)^'DCF Valuation'!$I$44+SUM('DCF Valuation'!$E$68:$E$72))/'DCF Valuation'!$E$78 -> 125.61053 | F24: =('DCF Valuation'!$E$49+(('Forecast Model'!$G$8*(1+F$22)^5*$D24*(1-'Master Assumptions'!$J$20)+'Forecast Model'!$G$8*(1+F$22)^5*SUM('DCF Valuation'!$I$32:$I$35)/'Forecast Model'!$L$8)*(1+'DCF Valuation'!$E$56)/('DCF Valuation'!$E$18-'DCF Valuation'!$E$56))/(1+'DCF Valuation'!$E$18)^'DCF Valuation'!$I$44+SUM('DCF Valuation'!$E$68:$E$72))/'DCF Valuation'!$E$78 -> 138.42434 | G24: =('DCF Valuation'!$E$49+(('Forecast Model'!$G$8*(1+G$22)^5*$D24*(1-'Master Assumptions'!$J$20)+'Forecast Model'!$G$8*(1+G$22)^5*SUM('DCF Valuation'!$I$32:$I$35)/'Forecast Model'!$L$8)*(1+'DCF Valuation'!$E$56)/('DCF Valuation'!$E$18-'DCF Valuation'!$E$56))/(1+'DCF Valuation'!$E$18)^'DCF Valuation'!$I$44+SUM('DCF Valuation'!$E$68:$E$72))/'DCF Valuation'!$E$78 -> 151.07792 | H24: =('DCF Valuation'!$E$49+(('Forecast Model'!$G$8*(1+H$22)^5*$D24*(1-'Master Assumptions'!$J$20)+'Forecast Model'!$G$8*(1+H$22)^5*SUM('DCF Valuation'!$I$32:$I$35)/'Forecast Model'!$L$8)*(1+'DCF Valuation'!$E$56)/('DCF Valuation'!$E$18-'DCF Valuation'!$E$56))/(1+'DCF Valuation'!$E$18)^'DCF Valuation'!$I$44+SUM('DCF Valuation'!$E$68:$E$72))/'DCF Valuation'!$E$78 -> 165.19988 | I24: =('DCF Valuation'!$E$49+(('Forecast Model'!$G$8*(1+I$22)^5*$D24*(1-'Master Assumptions'!$J$20)+'Forecast Model'!$G$8*(1+I$22)^5*SUM('DCF Valuation'!$I$32:$I$35)/'Forecast Model'!$L$8)*(1+'DCF Valuation'!$E$56)/('DCF Valuation'!$E$18-'DCF Valuation'!$E$56))/(1+'DCF Valuation'!$E$18)^'DCF Valuation'!$I$44+SUM('DCF Valuation'!$E$68:$E$72))/'DCF Valuation'!$E$78 -> 183.29695
D25: 0.16 | E25: =('DCF Valuation'!$E$49+(('Forecast Model'!$G$8*(1+E$22)^5*$D25*(1-'Master Assumptions'!$J$20)+'Forecast Model'!$G$8*(1+E$22)^5*SUM('DCF Valuation'!$I$32:$I$35)/'Forecast Model'!$L$8)*(1+'DCF Valuation'!$E$56)/('DCF Valuation'!$E$18-'DCF Valuation'!$E$56))/(1+'DCF Valuation'!$E$18)^'DCF Valuation'!$I$44+SUM('DCF Valuation'!$E$68:$E$72))/'DCF Valuation'!$E$78 -> 130.03625 | F25: =('DCF Valuation'!$E$49+(('Forecast Model'!$G$8*(1+F$22)^5*$D25*(1-'Master Assumptions'!$J$20)+'Forecast Model'!$G$8*(1+F$22)^5*SUM('DCF Valuation'!$I$32:$I$35)/'Forecast Model'!$L$8)*(1+'DCF Valuation'!$E$56)/('DCF Valuation'!$E$18-'DCF Valuation'!$E$56))/(1+'DCF Valuation'!$E$18)^'DCF Valuation'!$I$44+SUM('DCF Valuation'!$E$68:$E$72))/'DCF Valuation'!$E$78 -> 143.63851 | G25: =('DCF Valuation'!$E$49+(('Forecast Model'!$G$8*(1+G$22)^5*$D25*(1-'Master Assumptions'!$J$20)+'Forecast Model'!$G$8*(1+G$22)^5*SUM('DCF Valuation'!$I$32:$I$35)/'Forecast Model'!$L$8)*(1+'DCF Valuation'!$E$56)/('DCF Valuation'!$E$18-'DCF Valuation'!$E$56))/(1+'DCF Valuation'!$E$18)^'DCF Valuation'!$I$44+SUM('DCF Valuation'!$E$68:$E$72))/'DCF Valuation'!$E$78 -> 157.0707 | H25: =('DCF Valuation'!$E$49+(('Forecast Model'!$G$8*(1+H$22)^5*$D25*(1-'Master Assumptions'!$J$20)+'Forecast Model'!$G$8*(1+H$22)^5*SUM('DCF Valuation'!$I$32:$I$35)/'Forecast Model'!$L$8)*(1+'DCF Valuation'!$E$56)/('DCF Valuation'!$E$18-'DCF Valuation'!$E$56))/(1+'DCF Valuation'!$E$18)^'DCF Valuation'!$I$44+SUM('DCF Valuation'!$E$68:$E$72))/'DCF Valuation'!$E$78 -> 172.06161 | I25: =('DCF Valuation'!$E$49+(('Forecast Model'!$G$8*(1+I$22)^5*$D25*(1-'Master Assumptions'!$J$20)+'Forecast Model'!$G$8*(1+I$22)^5*SUM('DCF Valuation'!$I$32:$I$35)/'Forecast Model'!$L$8)*(1+'DCF Valuation'!$E$56)/('DCF Valuation'!$E$18-'DCF Valuation'!$E$56))/(1+'DCF Valuation'!$E$18)^'DCF Valuation'!$I$44+SUM('DCF Valuation'!$E$68:$E$72))/'DCF Valuation'!$E$78 -> 191.27223
D26: 0.185 | E26: =('DCF Valuation'!$E$49+(('Forecast Model'!$G$8*(1+E$22)^5*$D26*(1-'Master Assumptions'!$J$20)+'Forecast Model'!$G$8*(1+E$22)^5*SUM('DCF Valuation'!$I$32:$I$35)/'Forecast Model'!$L$8)*(1+'DCF Valuation'!$E$56)/('DCF Valuation'!$E$18-'DCF Valuation'!$E$56))/(1+'DCF Valuation'!$E$18)^'DCF Valuation'!$I$44+SUM('DCF Valuation'!$E$68:$E$72))/'DCF Valuation'!$E$78 -> 135.56839 | F26: =('DCF Valuation'!$E$49+(('Forecast Model'!$G$8*(1+F$22)^5*$D26*(1-'Master Assumptions'!$J$20)+'Forecast Model'!$G$8*(1+F$22)^5*SUM('DCF Valuation'!$I$32:$I$35)/'Forecast Model'!$L$8)*(1+'DCF Valuation'!$E$56)/('DCF Valuation'!$E$18-'DCF Valuation'!$E$56))/(1+'DCF Valuation'!$E$18)^'DCF Valuation'!$I$44+SUM('DCF Valuation'!$E$68:$E$72))/'DCF Valuation'!$E$78 -> 150.15623 | G26: =('DCF Valuation'!$E$49+(('Forecast Model'!$G$8*(1+G$22)^5*$D26*(1-'Master Assumptions'!$J$20)+'Forecast Model'!$G$8*(1+G$22)^5*SUM('DCF Valuation'!$I$32:$I$35)/'Forecast Model'!$L$8)*(1+'DCF Valuation'!$E$56)/('DCF Valuation'!$E$18-'DCF Valuation'!$E$56))/(1+'DCF Valuation'!$E$18)^'DCF Valuation'!$I$44+SUM('DCF Valuation'!$E$68:$E$72))/'DCF Valuation'!$E$78 -> 164.56167 | H26: =('DCF Valuation'!$E$49+(('Forecast Model'!$G$8*(1+H$22)^5*$D26*(1-'Master Assumptions'!$J$20)+'Forecast Model'!$G$8*(1+H$22)^5*SUM('DCF Valuation'!$I$32:$I$35)/'Forecast Model'!$L$8)*(1+'DCF Valuation'!$E$56)/('DCF Valuation'!$E$18-'DCF Valuation'!$E$56))/(1+'DCF Valuation'!$E$18)^'DCF Valuation'!$I$44+SUM('DCF Valuation'!$E$68:$E$72))/'DCF Valuation'!$E$78 -> 180.63877 | I26: =('DCF Valuation'!$E$49+(('Forecast Model'!$G$8*(1+I$22)^5*$D26*(1-'Master Assumptions'!$J$20)+'Forecast Model'!$G$8*(1+I$22)^5*SUM('DCF Valuation'!$I$32:$I$35)/'Forecast Model'!$L$8)*(1+'DCF Valuation'!$E$56)/('DCF Valuation'!$E$18-'DCF Valuation'!$E$56))/(1+'DCF Valuation'!$E$18)^'DCF Valuation'!$I$44+SUM('DCF Valuation'!$E$68:$E$72))/'DCF Valuation'!$E$78 -> 201.24133
D27: 0.21 | E27: =('DCF Valuation'!$E$49+(('Forecast Model'!$G$8*(1+E$22)^5*$D27*(1-'Master Assumptions'!$J$20)+'Forecast Model'!$G$8*(1+E$22)^5*SUM('DCF Valuation'!$I$32:$I$35)/'Forecast Model'!$L$8)*(1+'DCF Valuation'!$E$56)/('DCF Valuation'!$E$18-'DCF Valuation'!$E$56))/(1+'DCF Valuation'!$E$18)^'DCF Valuation'!$I$44+SUM('DCF Valuation'!$E$68:$E$72))/'DCF Valuation'!$E$78 -> 141.10053 | F27: =('DCF Valuation'!$E$49+(('Forecast Model'!$G$8*(1+F$22)^5*$D27*(1-'Master Assumptions'!$J$20)+'Forecast Model'!$G$8*(1+F$22)^5*SUM('DCF Valuation'!$I$32:$I$35)/'Forecast Model'!$L$8)*(1+'DCF Valuation'!$E$56)/('DCF Valuation'!$E$18-'DCF Valuation'!$E$56))/(1+'DCF Valuation'!$E$18)^'DCF Valuation'!$I$44+SUM('DCF Valuation'!$E$68:$E$72))/'DCF Valuation'!$E$78 -> 156.67395 | G27: =('DCF Valuation'!$E$49+(('Forecast Model'!$G$8*(1+G$22)^5*$D27*(1-'Master Assumptions'!$J$20)+'Forecast Model'!$G$8*(1+G$22)^5*SUM('DCF Valuation'!$I$32:$I$35)/'Forecast Model'!$L$8)*(1+'DCF Valuation'!$E$56)/('DCF Valuation'!$E$18-'DCF Valuation'!$E$56))/(1+'DCF Valuation'!$E$18)^'DCF Valuation'!$I$44+SUM('DCF Valuation'!$E$68:$E$72))/'DCF Valuation'!$E$78 -> 172.05264 | H27: =('DCF Valuation'!$E$49+(('Forecast Model'!$G$8*(1+H$22)^5*$D27*(1-'Master Assumptions'!$J$20)+'Forecast Model'!$G$8*(1+H$22)^5*SUM('DCF Valuation'!$I$32:$I$35)/'Forecast Model'!$L$8)*(1+'DCF Valuation'!$E$56)/('DCF Valuation'!$E$18-'DCF Valuation'!$E$56))/(1+'DCF Valuation'!$E$18)^'DCF Valuation'!$I$44+SUM('DCF Valuation'!$E$68:$E$72))/'DCF Valuation'!$E$78 -> 189.21593 | I27: =('DCF Valuation'!$E$49+(('Forecast Model'!$G$8*(1+I$22)^5*$D27*(1-'Master Assumptions'!$J$20)+'Forecast Model'!$G$8*(1+I$22)^5*SUM('DCF Valuation'!$I$32:$I$35)/'Forecast Model'!$L$8)*(1+'DCF Valuation'!$E$56)/('DCF Valuation'!$E$18-'DCF Valuation'!$E$56))/(1+'DCF Valuation'!$E$18)^'DCF Valuation'!$I$44+SUM('DCF Valuation'!$E$68:$E$72))/'DCF Valuation'!$E$78 -> 211.21043
D28: 0.23 | E28: =('DCF Valuation'!$E$49+(('Forecast Model'!$G$8*(1+E$22)^5*$D28*(1-'Master Assumptions'!$J$20)+'Forecast Model'!$G$8*(1+E$22)^5*SUM('DCF Valuation'!$I$32:$I$35)/'Forecast Model'!$L$8)*(1+'DCF Valuation'!$E$56)/('DCF Valuation'!$E$18-'DCF Valuation'!$E$56))/(1+'DCF Valuation'!$E$18)^'DCF Valuation'!$I$44+SUM('DCF Valuation'!$E$68:$E$72))/'DCF Valuation'!$E$78 -> 145.52625 | F28: =('DCF Valuation'!$E$49+(('Forecast Model'!$G$8*(1+F$22)^5*$D28*(1-'Master Assumptions'!$J$20)+'Forecast Model'!$G$8*(1+F$22)^5*SUM('DCF Valuation'!$I$32:$I$35)/'Forecast Model'!$L$8)*(1+'DCF Valuation'!$E$56)/('DCF Valuation'!$E$18-'DCF Valuation'!$E$56))/(1+'DCF Valuation'!$E$18)^'DCF Valuation'!$I$44+SUM('DCF Valuation'!$E$68:$E$72))/'DCF Valuation'!$E$78 -> 161.88812 | G28: =('DCF Valuation'!$E$49+(('Forecast Model'!$G$8*(1+G$22)^5*$D28*(1-'Master Assumptions'!$J$20)+'Forecast Model'!$G$8*(1+G$22)^5*SUM('DCF Valuation'!$I$32:$I$35)/'Forecast Model'!$L$8)*(1+'DCF Valuation'!$E$56)/('DCF Valuation'!$E$18-'DCF Valuation'!$E$56))/(1+'DCF Valuation'!$E$18)^'DCF Valuation'!$I$44+SUM('DCF Valuation'!$E$68:$E$72))/'DCF Valuation'!$E$78 -> 178.04541 | H28: =('DCF Valuation'!$E$49+(('Forecast Model'!$G$8*(1+H$22)^5*$D28*(1-'Master Assumptions'!$J$20)+'Forecast Model'!$G$8*(1+H$22)^5*SUM('DCF Valuation'!$I$32:$I$35)/'Forecast Model'!$L$8)*(1+'DCF Valuation'!$E$56)/('DCF Valuation'!$E$18-'DCF Valuation'!$E$56))/(1+'DCF Valuation'!$E$18)^'DCF Valuation'!$I$44+SUM('DCF Valuation'!$E$68:$E$72))/'DCF Valuation'!$E$78 -> 196.07766 | I28: =('DCF Valuation'!$E$49+(('Forecast Model'!$G$8*(1+I$22)^5*$D28*(1-'Master Assumptions'!$J$20)+'Forecast Model'!$G$8*(1+I$22)^5*SUM('DCF Valuation'!$I$32:$I$35)/'Forecast Model'!$L$8)*(1+'DCF Valuation'!$E$56)/('DCF Valuation'!$E$18-'DCF Valuation'!$E$56))/(1+'DCF Valuation'!$E$18)^'DCF Valuation'!$I$44+SUM('DCF Valuation'!$E$68:$E$72))/'DCF Valuation'!$E$78 -> 219.18571
D29: 0.25 | E29: =('DCF Valuation'!$E$49+(('Forecast Model'!$G$8*(1+E$22)^5*$D29*(1-'Master Assumptions'!$J$20)+'Forecast Model'!$G$8*(1+E$22)^5*SUM('DCF Valuation'!$I$32:$I$35)/'Forecast Model'!$L$8)*(1+'DCF Valuation'!$E$56)/('DCF Valuation'!$E$18-'DCF Valuation'!$E$56))/(1+'DCF Valuation'!$E$18)^'DCF Valuation'!$I$44+SUM('DCF Valuation'!$E$68:$E$72))/'DCF Valuation'!$E$78 -> 149.95196 | F29: =('DCF Valuation'!$E$49+(('Forecast Model'!$G$8*(1+F$22)^5*$D29*(1-'Master Assumptions'!$J$20)+'Forecast Model'!$G$8*(1+F$22)^5*SUM('DCF Valuation'!$I$32:$I$35)/'Forecast Model'!$L$8)*(1+'DCF Valuation'!$E$56)/('DCF Valuation'!$E$18-'DCF Valuation'!$E$56))/(1+'DCF Valuation'!$E$18)^'DCF Valuation'!$I$44+SUM('DCF Valuation'!$E$68:$E$72))/'DCF Valuation'!$E$78 -> 167.1023 | G29: =('DCF Valuation'!$E$49+(('Forecast Model'!$G$8*(1+G$22)^5*$D29*(1-'Master Assumptions'!$J$20)+'Forecast Model'!$G$8*(1+G$22)^5*SUM('DCF Valuation'!$I$32:$I$35)/'Forecast Model'!$L$8)*(1+'DCF Valuation'!$E$56)/('DCF Valuation'!$E$18-'DCF Valuation'!$E$56))/(1+'DCF Valuation'!$E$18)^'DCF Valuation'!$I$44+SUM('DCF Valuation'!$E$68:$E$72))/'DCF Valuation'!$E$78 -> 184.03819 | H29: =('DCF Valuation'!$E$49+(('Forecast Model'!$G$8*(1+H$22)^5*$D29*(1-'Master Assumptions'!$J$20)+'Forecast Model'!$G$8*(1+H$22)^5*SUM('DCF Valuation'!$I$32:$I$35)/'Forecast Model'!$L$8)*(1+'DCF Valuation'!$E$56)/('DCF Valuation'!$E$18-'DCF Valuation'!$E$56))/(1+'DCF Valuation'!$E$18)^'DCF Valuation'!$I$44+SUM('DCF Valuation'!$E$68:$E$72))/'DCF Valuation'!$E$78 -> 202.93939 | I29: =('DCF Valuation'!$E$49+(('Forecast Model'!$G$8*(1+I$22)^5*$D29*(1-'Master Assumptions'!$J$20)+'Forecast Model'!$G$8*(1+I$22)^5*SUM('DCF Valuation'!$I$32:$I$35)/'Forecast Model'!$L$8)*(1+'DCF Valuation'!$E$56)/('DCF Valuation'!$E$18-'DCF Valuation'!$E$56))/(1+'DCF Valuation'!$E$18)^'DCF Valuation'!$I$44+SUM('DCF Valuation'!$E$68:$E$72))/'DCF Valuation'!$E$78 -> 227.16099
C30: Summary | D30: MIN / BASE / MAX | E30: =MIN(E23:I29) -> 121.18482 | G30: =G26 -> 164.56167 | I30: =MAX(E23:I29) -> 227.16099
E31: MIN | G31: BASE | I31: MAX

Sheet Scenario Analysis
B3: SCENARIO ANALYSIS
B5: This analysis compares Bull, Base, and Bear scenarios for Duolingo's DCF valuation.
B8: SCENARIO VALUATION SUMMARY | J8: VALUATION AT A GLANCE
B10: Scenario | C10: Implied Share Price | D10: Enterprise Value | E10: Equity Value | F10: Terminal Value | G10: PV of FCFs | H10: 2029E Revenue | I10: 2029E EBIT Margin | J10: Current Stock: | K10: ~$112
B11: 🐂 Bull Case | C11: 165 | D11: $7,286M | E11: $8,164M | F11: $5,500M | G11: $1,786M | H11: $2,522M | I11: 0.185
B12: 📊 Base Case | C12: 97 | D12: $3,935M | E12: $4,813M | F12: $2,702M | G12: $1,234M | H12: $1,899M | I12: 0.113 | J12: Bull Upside: | K12: 0.47
B13: 🐻 Bear Case | C13: 60 | D13: $2,103M | E13: $2,981M | F13: $1,426M | G13: $677M | H13: $1,475M | I13: 0.015 | J13: Bear Downside: | K13: -0.46
J14: Base vs Current: | K14: -0.13
B16: CHART DATA - SHARE PRICE BY SCENARIO
B18: Scenario | C18: Share Price ($)
B19: Bull | C19: 165
B20: Base | C20: 97
B21: Bear | C21: 60
B24: CHART DATA - REVENUE TRAJECTORY ($M)
B26: Year | C26: Bull | D26: Base | E26: Bear
B27: 2024A | C27: 748 | D27: 748 | E27: 748
B28: 2025E | C28: 1010 | D28: 957 | E28: 898
B29: 2026E | C29: 1313 | D29: 1187 | E29: 1050
B30: 2027E | C30: 1667 | D30: 1437 | E30: 1197
B31: 2028E | C31: 2068 | D31: 1695 | E31: 1341
B32: 2029E | C32: 2522 | D32: 1963 | E32: 1475
B35: CHART DATA - EBIT MARGIN TRAJECTORY (%)
B37: Year | C37: Bull | D37: Base | E37: Bear
B38: 2025E | C38: 0.11 | D38: 0.064 | E38: 0.035
B39: 2026E | C39: 0.13 | D39: 0.079 | E39: 0.03
B40: 2027E | C40: 0.15 | D40: 0.095 | E40: 0.024
B41: 2028E | C41: 0.168 | D41: 0.108 | E41: 0.019
B42: 2029E | C42: 0.185 | D42: 0.118 | E42: 0.015
B45: CHART DATA - VALUE BRIDGE ($M)
B47: Component | C47: Bull | D47: Base | E47: Bear
B48: PV of FCFs | C48: 1786 | D48: 1234 | E48: 677
B49: PV of Terminal Value | C49: 5500 | D49: 2702 | E49: 1426
B70: KEY ASSUMPTIONS COMPARISON
B72: Assumption | C72: Bull | D72: Base | E72: Bear | G72: PROBABILITY-WEIGHTED VALUATION
B73: 5-Year Revenue CAGR | C73: 0.276 | D73: 0.214 | E73: 0.146
B74: Terminal EBIT Margin | C74: 0.185 | D74: 0.113 | E74: 0.015 | G74: Scenario | H74: Probability | I74: Share Price | J74: Weighted
B75: R&D % (2029E) | C75: 0.261 | D75: 0.286 | E75: 0.33 | G75: Bull | H75: 0.25 | I75: 165 | J75: =H75*I75 -> 41.25
B76: SG&A % (2029E) | C76: 0.299 | D76: 0.324 | E76: 0.35 | G76: Base | H76: 0.5 | I76: 97 | J76: =H76*I76 -> 48.5
B77: Gross Margin (2029E) | C77: 0.76 | D77: 0.745 | E77: 0.71 | G77: Bear | H77: 0.25 | I77: 60 | J77: =H77*I77 -> 15
G79: Expected Value | H79: =SUM(H75:H77) -> 1 | J79: =SUM(J75:J77) -> 104.75
...

Sheet Sources & Footnotes
B2: SOURCES & FOOTNOTES
B3: Duolingo, Inc. (DUOL) | Data Sources, Market Inputs, Methodology & Audit Trail
B5: SECTION 1: PRIMARY DATA SOURCES
B6: # | C6: Source Name | D6: Type | E6: Data Used For | F6: Tabs Referenced | G6: Access Date | H6: URL / Reference
B7: S1 | C7: SEC EDGAR — DUOL 10-K (FY2024) | D7: SEC Filing | E7: Full-year audited financial statements (IS, BS, CF); MD&A; risk factors | F7: Historical Financials | G7: 45689 | H7: https://www.sec.gov/cgi-bin/browse-edgar?action=getcompany&CIK=DUOL&type=10-K
B8: S2 | C8: SEC EDGAR — DUOL 10-K (FY2023) | D8: SEC Filing | E8: Prior-year audited financials; year-over-year growth derivation | F8: Historical Financials | G8: 45323 | H8: https://www.sec.gov/cgi-bin/browse-edgar?action=getcompany&CIK=DUOL&type=10-K
B9: S3 | C9: SEC EDGAR — DUOL 10-K (FY2020–2022) | D9: SEC Filing | E9: Historical trend analysis; 5-year CAGR computation; margin trajectory | F9: Historical Financials | G9: Various | H9: https://www.sec.gov/cgi-bin/browse-edgar?action=getcompany&CIK=DUOL&type=10-K
B10: S4 | C10: FactSet — CAPM Market Data | D10: Terminal / Data Provider | E10: Risk-free rate, equity risk premium, levered beta (5Y monthly regression) | F10: DCF Valuation | G10: 45689 | H10: FactSet Research Systems (subscription terminal)
