Workbook

Sheet Cover
B6: Intertek Group plc
B8: Equity Valuation & Financial Analysis
B11: ITRK-GB | LONDON | Business Services
D17: Prepared by | H17: Group - F ( Divij , Mona, Duarte, Nacho, Alberto, Lucas )
D18: Date | H18: 45717
D19: Version | H19: v1.0
D20: Sources | H20: Company Filings, FactSet, Bloomberg - Please note some sources use penny(1/100) we are using GBP
D21: Model Type | H21: DCF Valuation | Trading Comps | Scenario Analysis

Sheet TOC
B1: Intertek Group Plc
B2: Comprehensive Valuation Model — Table of Contents
B4: Tab # | C4: Tab Name | D4: Description | E4: Status
B5: SECTION 1: EXECUTIVE SUMMARY & OVERVIEW
B6: 1 | C6: Cover | D6: Title page, version control | E6: Complete
B7: 2 | C7: TOC | D7: Table of contents & model map | E7: Complete
B8: 3 | C8: Executive Summary | D8: Investment thesis, highlights, key findings, target price | E8: Complete
B10: SECTION 2: HISTORICAL FINANCIALS & ANALYSIS
B11: 4 | C11: Historical Financials | D11: Historical IS + BS + CF (vertical 3-statement model) | E11: Complete
B12: 5 | C12: Historical Analysis | D12: Margins, growth rates, ratio analysis, trends | E12: Complete
B14: SECTION 3: ASSUMPTIONS & OTHER INPUTS
B15: 6 | C15: Master Assumptions | D15: Key drivers: revenue growth, margins, CapEx, tax, WACC | E15: Complete
B16: 7 | C16: Supporting Schedules | D16: Supporting analysis: TAM, benchmarks, comps backup | E16: Complete
B18: SECTION 4: FORECASTS & PROJECTIONS
B19: 8 | C19: Forecast Model | D19: Projected IS + BS + CF (vertical 3-statement model) | E19: Complete
B21: SECTION 5: VALUATION
B22: 9 | C22: DCF Valuation | D22: Discounted Cash Flow analysis (WACC, terminal value) | E22: Complete
B23: 10 | C23: Trading Comps | D23: Public comparable company analysis (EV/Revenue, EV/EBITDA) | E23: Complete
B24: 11 | C24: Valuation Summary | D24: Combined valuation range across all methodologies | E24: Complete
B26: SECTION 6: POTENTIAL DEAL SCENARIOS
B27: 12 | C27: Deal Scenario A | D27: Potential M&A , strategic acquisition modelling | E27: Complete
B28: 13 | C28: Deal Scenario B | D28: PE Take Private Scenario | E28: Complete
B30: SECTION 7: OUTPUTS & ANALYSIS
B31: 14 | C31: Sensitivity Tables | D31: WACC vs. growth, revenue vs. margin data tables | E31: Complete
B33: SECTION 7: REFERENCE & DATA
B34: 15 | C34: Sources & Footnotes | D34: Data sources, methodology notes, disclaimers | E34: Complete
B37: COLOR CODING LEGEND
B38: 🔵 | C38: BLUE cells | D38: Hardcoded inputs / assumptions (user changes these)
B39: ⬛ | C39: BLACK cells | D39: Formulas & calculations (model calculates these)
B40: 🟢 | C40: GREEN cells | D40: Links from other worksheets within workbook
B41: 🟡 | C41: YELLOW cells | D41: Flags / checks / key assumptions needing attention
B42: 🔴 | C42: RED cells | D42: External links to other files

Sheet Executive Summary
B1: INTERTEK GROUP PLC | N1: ITRK.L | LSE
B2: Equity Research | Executive Summary | Valuation Analysis | N2: Testing, Inspection & Certification
B6: CURRENT PRICE | D6: MARKET CAP (£mm) | F6: ENTERPRISE VALUE (£mm) | J6: LTM REVENUE (£mm) | L6: WACC | N6: DCF TARGET PRICE
B7: £37.34 | D7: £5,802 | F7: £6,844 | J7: £3,393 | L7: 7.4% | N7: £50.65 - £63.52
B8: ITRK.L | D8: 155.4mm shares | F8: Net Debt: £570mm | J8: FY2024A | L8: Ke: 7.9% | Kd: 4.1% | N8: +35.6% to +70.1% upside
B11: REVENUE & EBITDA TRAJECTORY (£mm) | J11: MARGIN EVOLUTION (%)
C12: 2021A | D12: 2022A | E12: 2023A | F12: 2024A | G12: 2025E | H12: 2026E | K12: 2021A | L12: 2022A | M12: 2023A | N12: 2024A | O12: 2025E | P12: 2026E
B13: Revenue | C13: 2786.3 | D13: 3192.9 | E13: 3328.7 | F13: 3393.2 | G13: 3614 | H13: 3831 | J13: Gross Margin | K13: 0.231 | L13: 0.219 | M13: 0.217 | N13: 0.22 | O13: 0.219 | P13: 0.219
B14: Revenue Growth % | C14: — | G14: 0.065 | H14: 0.06 | J14: EBITDA Margin | K14: 0.231 | L14: 0.219 | M14: 0.217 | N14: 0.22 | O14: 0.219 | P14: 0.219
B15: EBITDA | C15: 644 | D15: 700 | E15: 723 | F15: 748 | G15: 791 | H15: 838 | J15: EBIT Margin | K15: 0.16 | L15: 0.152 | M15: 0.154 | N15: 0.163 | O15: 0.161 | P15: 0.17
B16: EBIT | C16: 445 | D16: 485 | E16: 514 | F16: 554 | G16: 582 | H16: 653 | J16: Net Margin | K16: 0.103 | L16: 0.09 | M16: 0.089 | N16: 0.102 | O16: 0.1 | P16: 0.107
B17: Net Income | C17: 288 | D17: 289 | E17: 297 | F17: 345 | G17: 361 | H17: 410 | J17: Return on Equity | K17: 0.259 | L17: 0.219 | M17: 0.219 | N17: 0.239 | O17: 0.218 | P17: 0.217
L31: 5.50%
B32: FREE CASH FLOW BRIDGE — 2025E (£mm) | F32: KEY RETURN & CREDIT METRICS | J32: PEER COMPARISON — KEY MULTIPLES | P32: 2.5%
B33: FCF Component | C33: 2025E | D33: 2026E | F33: Metric | G33: 2024A | H33: 2025E | J33: Company | K33: Ticker | L33: 7.9% | M33: EV/Revenue | N33: EV/EBITDA | O33: EV/EBIT | P33: P/E
B34: EBIT | C34: 582 | D34: 653 | F34: FCF Yield | G34: =434/5802 -> 0.074801792 | H34: =434/5802 -> 0.074801792 | J34: Intertek | K34: ITRK GB | L34: 7.4% | M34: 2.57x | N34: 11.2x | O34: 15.1x | P34: 21.2x
B35: Less: Taxes on EBIT | C35: -149 | D35: -167 | F35: Net Debt / EBITDA | G35: 0.76 | H35: 0.72 | J35: SGS | K35: SGSN SW | L35: 18521 | M35: 2.52x | N35: 13.5x | O35: 19.5x | P35: 26.1x
B36: Plus: D&A | C36: 209 | D36: 186 | F36: ROIC | G36: 0.166 | H36: 0.163 | J36: Bureau Veritas | K36: BVI FP | L36: 14060 | M36: 2.14x | N36: 11.4x | O36: 15.2x | P36: 20.6x
B37: Less: CapEx | C37: -132 | D37: -140 | F37: Dividend Payout % | G37: 0.597 | H37: 0.422 | J37: Eurofins | K37: ERF FP | L37: 12971 | M37: 2.15x | N37: 9.8x | O37: 18.5x | P37: 23.6x
B38: Less: Δ Working Capital | C38: -76 | D38: -101 | F38: CapEx / Revenue | G38: 0.04 | H38: 0.037 | J38: Wolters Kluwer | K38: WLK NL | L38: 16514 | M38: 3.92x | N38: 9.6x | O38: 12.5x | P38: 15.6x
B39: Unlevered FCF | C39: 434 | D39: 430 | F39: Cash Conversion | G39: 0.803 | H39: 0.847 | J39: Mean | M39: 2.77x | N39: 12.3x | O39: 18.1x | P39: 23.0x
B41: VALUATION FOOTBALL FIELD — IMPLIED SHARE PRICE (£) | F41: VALUATION UPSIDE SUMMARY | J41: DCF KEY ASSUMPTIONS & OUTPUT
C42: Low | D42: High | F42: Methodology | G42: Midpoint (£) | H42: Upside | J42: CAPITAL STRUCTURE | N42: TERMINAL VALUE
B43: DCF Valuation | C43: 42.5 | D43: 73.6 | F43: DCF Perpetuity | G43: 50.65 | H43: =(G43-37.34)/37.34 -> 0.3564542 | J43: Equity Risk Premium | L43: 0.055 | N43: Exit EV/EBITDA | P43: 12.0x
B44: Trading Comps | C44: 44.05 | D44: 80.77 | F44: DCF Exit Multiple | G44: 63.52 | H44: =(G44-37.34)/37.34 -> 0.7011248 | J44: Levered Beta | L44: 0.71x | N44: Terminal Growth Rate | P44: 0.025
F45: Trading Comps | G45: 57.29 | H45: =(G45-37.34)/37.34 -> 0.53427959 | J45: Cost of Equity (Ke) | L45: 0.079 | N45: PV of Terminal Value | P45: £6,532 - £8,507
J46: WACC | L46: 0.074
F47: Blended (Equal Wt.) | G47: =AVERAGE(G43:G45) -> 57.153333 | H47: =(G47-37.34)/37.34 -> 0.53061953 | N47: IMPLIED SHARE PRICE
J48: TRADING COMPS SUMMARY | N48: DCF Perpetuity | P48: £50.65
J49: EV/Revenue (Mean) | L49: 2.77x | N49: DCF Exit Multiple | P49: £63.52
J50: EV/EBITDA (Mean) | L50: 12.3x | N50: Comps Mean | P50: £57.29
J51: EV/EBIT (Mean) | L51: 18.1x
J52: P/E (Mean) | L52: 23.0x
B70: KEY INVESTMENT HIGHLIGHTS
B71: ▎ Market Leader | F71: ▎ Resilient Cash Generation | J71: ▎ Significant Undervaluation
B72: Global #1 in TIC sector with diversified end-market exposure across 100+ countries | F72: Consistent UFCF of ~£430mm p.a. with low capex intensity (3.7% of revenue) | J72: All valuation methods imply 36-70% upside; trading at discount to peers on EV/EBITDA
C80: 2021A | D80: 2022A | E80: 2023A | F80: 2024A | G80: 2025E | H80: 2026E | K80: 2021A | L80: 2022A | M80: 2023A | N80: 2024A | O80: 2025E | P80: 2026E
B81: Revenue | C81: 2786 | D81: 3193 | E81: 3329 | F81: 3393 | G81: 3614 | H81: 3831 | J81: Gross Margin | K81: 0.231 | L81: 0.219 | M81: 0.217 | N81: 0.22 | O81: 0.219 | P81: 0.219
B82: EBITDA | C82: 644 | D82: 700 | E82: 723 | F82: 748 | G82: 791 | H82: 838 | J82: EBIT Margin | K82: 0.16 | L82: 0.152 | M82: 0.154 | N82: 0.163 | O82: 0.161 | P82: 0.17
B83: Net Income | C83: 288 | D83: 289 | E83: 297 | F83: 345 | G83: 361 | H83: 410 | J83: Net Margin | K83: 0.103 | L83: 0.09 | M83: 0.089 | N83: 0.102 | O83: 0.1 | P83: 0.107
...

Sheet Historical Financials
B4: INCOME STATEMENT
E7: 2021A | F7: 2022A | G7: 2023A | H7: 2024A
B10: Revenue | E10: 2786.3 | F10: 3192.9 | G10: 3328.7 | H10: 3393.2
B11: COGS | E11: -2142.3 | F11: -2492.7 | G11: -2605.5 | H11: -2645.3
B12: Gross Profit | E12: =SUM(E10:E11) -> 644 | F12: =SUM(F10:F11) -> 700.2 | G12: =SUM(G10:G11) -> 723.2 | H12: =SUM(H10:H11) -> 747.9
B14: D&A Expense | E14: -198.6 | F14: -215.3 | G14: -209.5 | H14: -194
B15: EBIT | E15: =SUM(E12:E14) -> 445.4 | F15: =SUM(F12:F14) -> 484.9 | G15: =SUM(G12:G14) -> 513.7 | H15: =SUM(H12:H14) -> 553.9
B17: Unusual Expense | E17: -20 | F17: -33.6 | G17: -50.7 | H17: -25.5
B18: Interest Expense | E18: -14.9 | F18: -42.8 | G18: -46.2 | H18: -43.4
B19: Other Income (Expense) | E19: 2.9 | F19: 11.3 | G19: 5.5 | H19: 5
B20: EBT | E20: =SUM(E15:E19) -> 413.4 | F20: =SUM(F15:F19) -> 419.8 | G20: =SUM(G15:G19) -> 422.3 | H20: =SUM(H15:H19) -> 490
B22: Income Taxes | E22: -106.7 | F22: -113 | G22: -104.2 | H22: -122.8
B23: ETR % | E23: =-E22/E20 -> 0.25810353 | F23: =-F22/F20 -> 0.2691758 | G23: =-G22/G20 -> 0.24674402 | H23: =-H22/H20 -> 0.25061224
B24: Consolidated Net Income | E24: =SUM(E20:E22) -> 306.7 | F24: =SUM(F20:F22) -> 306.8 | G24: =SUM(G20:G22) -> 318.1 | H24: =SUM(H20:H22) -> 367.2
B26: Minority Interest | E26: -18.6 | F26: -18 | G26: -20.7 | H26: -21.8
B27: Net Income | E27: =SUM(E24:E26) -> 288.1 | F27: =SUM(F24:F26) -> 288.8 | G27: =SUM(G24:G26) -> 297.4 | H27: =SUM(H24:H26) -> 345.4
B29: BALANCE STATEMENT
E33: 2021A | F33: 2022A | G33: 2023A | H33: 2024A
B36: Assets
B37: Cash & Short-Term Investments | E37: 265.9 | F37: 321.6 | G37: 299.3 | H37: 343
B38: Accounts Receivable | E38: 559 | F38: 619.6 | G38: 619.9 | H38: 634.2
B39: Other Receivables | E39: 78.5 | F39: 91.3 | G39: 82 | H39: 102.7
B40: Inventories | E40: 14.9 | F40: 16.9 | G40: 17.2 | H40: 19
B41: Other Current Assets | E41: 45 | F41: 47.4 | G41: 53.2 | H41: 60.4
B42: Total Current Assets | E42: 963.3 | F42: 1096.8 | G42: 1071.6 | H42: 1159.3
B44: Net PP&E | E44: 641.8 | F44: 694.4 | G44: 669.6 | H44: 692.8
B45: Goodwill | E45: 1241.4 | F45: 1418.4 | G45: 1385.8 | H45: 1365.9
B46: Other Intangible Assets | E46: 358.5 | F46: 362.9 | G46: 330.9 | H46: 304.2
B47: Long-Term Investments | E47: 0 | F47: 21.5 | G47: 21.8 | H47: 15.4
B48: Deferred Tax Assets | E48: 39.3 | F48: 45 | G48: 36.4 | H48: 34.5
B49: Other Non-Current Assets | E49: 5.4 | F49: 21.3 | G49: 21.8 | H49: 27.2
... B51: Total Assets | E51: 3249.7 | F51: 3660.3 | G51: 3537.9 | H51: 3599.3
B53: Liabilities
B54: Accounts Payable | E54: 153.4 | F54: 172.1 | G54: 204.8 | H54: 223
B55: Short-Term Debt | E55: 525.5 | F55: 333 | G55: 167.4 | H55: 171.4
B56: Income Tax Payable | E56: 59.1 | F56: 71 | G56: 60.5 | H56: 67.2
B57: Other Current Liabilities | E57: 527.6 | F57: 566.9 | G57: 548.8 | H57: 588.5
B58: Total Current Liabilities | E58: 1265.6 | F58: 1143 | G58: 981.5 | H58: 1050.1
B60: Long-Term Debt | E60: 537.2 | F60: 797.1 | G60: 812.4 | H60: 741.5
B61: Deferred Tax Liabilities | E61: 67.4 | F61: 99.2 | G61: 75.3 | H61: 69.9
...

Sheet Historical Analysis
B3: SECTION A: GROWTH AND MARGIN ANALYSIS
B5: REVENUE GROWTH:
F6: 2021A | G6: 2022A | H6: 2023A | I6: 2024A | K6: Trend
B7: Total Revenue ($M) | F7: ='Historical Financials'!E10 -> 2786.3 | G7: ='Historical Financials'!F10 -> 3192.9 | H7: ='Historical Financials'!G10 -> 3328.7 | I7: ='Historical Financials'!H10 -> 3393.2
B8: YoY Growth % | G8: =(G7-F7)/F7 -> 0.14592829 | H8: =(H7-G7)/G7 -> 0.042531868 | I8: =(I7-H7)/H7 -> 0.019376934
B9: 5Y CAGR | I9: =(I7/F7)^0.333333-1 -> 0.067891589 | K9: YoY Growth
B11: GROSS MARGIN:
F12: 2021A | G12: 2022A | H12: 2023A | I12: 2024A | K12: Trend
B13: Gross Profit ($M) | F13: ='Historical Financials'!E12 -> 644 | G13: ='Historical Financials'!F12 -> 700.2 | H13: ='Historical Financials'!G12 -> 723.2 | I13: ='Historical Financials'!H12 -> 747.9
B14: Gross Profit % | F14: =F13/F7 -> 0.23113089 | G14: =G13/G7 -> 0.21929907 | H14: =H13/H7 -> 0.21726199 | I14: =I13/I7 -> 0.22041141
B17: OPEX ANALYSIS:
F18: 2021A | G18: 2022A | H18: 2023A | I18: 2024A | K18: Trend
B19: D&A % of Revenue | F19: ='Historical Financials'!E85/'Historical Analysis'!F7 -> 0.071277321 | G19: ='Historical Financials'!F85/'Historical Analysis'!G7 -> 0.067430862 | H19: ='Historical Financials'!G85/'Historical Analysis'!H7 -> 0.062937483 | I19: ='Historical Financials'!H85/'Historical Analysis'!I7 -> 0.05717317
B20: Total Opex % of Revenue | F20: =F19 -> 0.071277321 | G20: =G19 -> 0.067430862 | H20: =H19 -> 0.062937483 | I20: =I19 -> 0.05717317
B23: PROFITABILITY:
F24: 2021A | G24: 2022A | H24: 2023A | I24: 2024A | K24: Trend
B25: Operating Margin % | F25: ='Historical Financials'!E15/'Historical Financials'!E10 -> 0.15985357 | G25: ='Historical Financials'!F15/'Historical Financials'!F10 -> 0.15186821 | H25: ='Historical Financials'!G15/'Historical Financials'!G10 -> 0.15432451 | I25: ='Historical Financials'!H15/'Historical Financials'!H10 -> 0.16323824
B26: EBITDA Margin % | F26: =('Historical Financials'!E15+'Historical Financials'!E14)/'Historical Financials'!E10 -> 0.088576248 | G26: =('Historical Financials'!F15+'Historical Financials'!F14)/'Historical Financials'!F10 -> 0.084437345 | H26: =('Historical Financials'!G15+'Historical Financials'!G14)/'Historical Financials'!G10 -> 0.091387028 | I26: =('Historical Financials'!H15+'Historical Financials'!H14)/'Historical Financials'!H10 -> 0.10606507
B27: Net Margin % | F27: ='Historical Financials'!E27/'Historical Financials'!E10 -> 0.10339877 | G27: ='Historical Financials'!F27/'Historical Financials'!F10 -> 0.090450687 | H27: ='Historical Financials'!G27/'Historical Financials'!G10 -> 0.089344188 | I27: ='Historical Financials'!H27/'Historical Financials'!H10 -> 0.10179182
B31: SECTION B: CASH GENERATION AND CAPITAL EFFICIENCY
B34: CASH FLOW QUALITY:
F35: 2021A | G35: 2022A | H35: 2023A | I35: 2024A | K35: Trend
B36: OCF | F36: ='Historical Financials'!E93 -> 551.7 | G36: ='Historical Financials'!F93 -> 562.1 | H36: ='Historical Financials'!G93 -> 538.5 | I36: ='Historical Financials'!H93 -> 599.8
B37: FCF | F37: =F36+'Historical Financials'!E96 -> 454.6 | G37: =G36+'Historical Financials'!F96 -> 445.6 | H37: =H36+'Historical Financials'!G96 -> 421.6 | I37: =I36+'Historical Financials'!H96 -> 464.8
B40: WC DYNAMICS:
F41: 2021A | G41: 2022A | H41: 2023A | I41: 2024A | K41: Trend
B42: Changes in WC ($M):
B43: Changes in AR | F43: ='Historical Financials'!E89 -> -29.2 | G43: ='Historical Financials'!F89 -> -54.3 | H43: ='Historical Financials'!G89 -> -41.2 | I43: ='Historical Financials'!H89 -> -45.6
B44: Changes in AP | F44: ='Historical Financials'!E91 -> 62 | G44: ='Historical Financials'!F91 -> 61.1 | H44: ='Historical Financials'!G91 -> 47.7 | I44: ='Historical Financials'!H91 -> 69.8
B45: Changes in Inventory | F45: ='Historical Financials'!E90 -> 0.6 | G45: ='Historical Financials'!F90 -> -0.8 | H45: ='Historical Financials'!G90 -> -1.2 | I45: ='Historical Financials'!H90 -> -2.2
B46: Other WC changes | F46: ='Historical Financials'!E92 -> -4.7 | G46: ='Historical Financials'!F92 -> -2 | H46: ='Historical Financials'!G92 -> 4.3 | I46: ='Historical Financials'!H92 -> -3.3
B48: Net WC Impact | F48: =SUM(F43:F46) -> 28.7 | G48: =SUM(G43:G46) -> 4 | H48: =SUM(H43:H46) -> 9.6 | I48: =SUM(I43:I46) -> 18.7
B50: DSO | F50: ='Historical Financials'!E38/('Historical Financials'!E10/365) -> 73.227937 | G50: ='Historical Financials'!F38/('Historical Financials'!F10/365) -> 70.83028 | H50: ='Historical Financials'!G38/('Historical Financials'!G10/365) -> 67.973533 | I50: ='Historical Financials'!H38/('Historical Financials'!H10/365) -> 68.219675
B51: DPO | F51: ='Historical Financials'!E54/(-'Historical Financials'!E11/365) -> 26.135929 | G51: ='Historical Financials'!F54/(-'Historical Financials'!F11/365) -> 25.200185 | H51: ='Historical Financials'!G54/(-'Historical Financials'!G11/365) -> 28.690079 | I51: ='Historical Financials'!H54/(-'Historical Financials'!H11/365) -> 30.769667
B52: DIO | F52: ='Historical Financials'!E40/(-'Historical Financials'!E11/365) -> 2.5386267 | G52: ='Historical Financials'!F40/(-'Historical Financials'!F11/365) -> 2.4746259 | H52: ='Historical Financials'!G40/(-'Historical Financials'!G11/365) -> 2.4095183 | I52: ='Historical Financials'!H40/(-'Historical Financials'!H11/365) -> 2.6216308
B54: CCC | F54: =F50+F52-F51 -> 49.630635 | G54: =G50+G52-G51 -> 48.104721 | H54: =H50+H52-H51 -> 41.692973 | I54: =I50+I52-I51 -> 40.071639
B56: CAPEX REQUIREMENTS:
F57: 2021A | G57: 2022A | H57: 2023A | I57: 2024A
B59: CapEx ($M) | F59: =-'Historical Financials'!E96 -> 97.1 | G59: =-'Historical Financials'!F96 -> 116.5 | H59: =-'Historical Financials'!G96 -> 116.9 | I59: =-'Historical Financials'!H96 -> 135
B60: as % of Revenue
...

Sheet Master Assumptions
B2: MASTER ASSUMPTIONS
B3: Intertek Group plc - ITRK-GB (London)
B5: SCENARIO SELECTOR
B6: Active Scenario: | C6: Base
B7: Scenario Code: | C7: =IF(C6="Bull",1,IF(C6="Base",2,3)) -> 2 | D7: (1=Bull, 2=Base, 3=Bear)
B9: ACTIVE ASSUMPTIONS | F9: 2025E | G9: 2026E | H9: 2027E | I9: 2028E | J9: 2029E
B10: REVENUE & MARGINS
B11: Revenue Growth % (LFL Bridge Framework ) | F11: ='Supporting Schedules'!C30 -> 0.065 | G11: ='Supporting Schedules'!D30 -> 0.06 | H11: ='Supporting Schedules'!E30 -> 0.053 | I11: ='Supporting Schedules'!F30 -> 0.053 | J11: ='Supporting Schedules'!G30 -> 0.05
B12: Gross Margin % | F12: ='Supporting Schedules'!C46 -> 0.2188367 | G12: ='Supporting Schedules'!D46 -> 0.2188367 | H12: ='Supporting Schedules'!E46 -> 0.2188367 | I12: ='Supporting Schedules'!F46 -> 0.2188367 | J12: ='Supporting Schedules'!G46 -> 0.2188367
B14: Depreciation (% of Beg. PPE )
B15: Depreciation % | F15: ='Supporting Schedules'!D83 -> 0.30098277 | G15: =F15 -> 0.30098277 | H15: =G15 -> 0.30098277 | I15: =H15 -> 0.30098277 | J15: =I15 -> 0.30098277
B17: TAX & OTHER
B18: Effective Tax Rate % | F18: ='Supporting Schedules'!C119*-1 -> 0.2561589 | G18: =F18 -> 0.2561589 | H18: =G18 -> 0.2561589 | I18: =H18 -> 0.2561589 | J18: =I18 -> 0.2561589
B20: BALANCE SHEET & CAPEX
B21: DSO (Days) | F21: ='Supporting Schedules'!H186 -> 68.096604 | G21: ='Supporting Schedules'!I186 -> 68.096604 | H21: ='Supporting Schedules'!J186 -> 68.096604 | I21: ='Supporting Schedules'!K186 -> 68.096604 | J21: ='Supporting Schedules'!L186 -> 68.096604
B22: DIO (Days) | F22: ='Supporting Schedules'!H195 -> 2.5155746 | G22: ='Supporting Schedules'!I195 -> 2.5155746 | H22: ='Supporting Schedules'!J195 -> 2.5155746 | I22: ='Supporting Schedules'!K195 -> 2.5155746 | J22: ='Supporting Schedules'!L195 -> 2.5155746
B23: DPO (Days) | F23: ='Supporting Schedules'!H203 -> 29.71776 | G23: ='Supporting Schedules'!I203 -> 29.71776 | H23: ='Supporting Schedules'!J203 -> 29.71776 | I23: ='Supporting Schedules'!K203 -> 29.71776 | J23: ='Supporting Schedules'!L203 -> 29.71776
B24: Other Current Assets % of Revenue | F24: ='Supporting Schedules'!C150 -> 0.016194603 | G24: =F24 -> 0.016194603 | H24: =G24 -> 0.016194603 | I24: =H24 -> 0.016194603 | J24: =I24 -> 0.016194603
B25: Income Tax Payable % of Tax Expense | F25: =-'Supporting Schedules'!C171 -> 0.57751337 | G25: =F25 -> 0.57751337 | H25: =G25 -> 0.57751337 | I25: =H25 -> 0.57751337 | J25: =I25 -> 0.57751337
B26: Other CL % of Revenue | F26: ='Supporting Schedules'!C161 -> 0.17630238 | G26: =F26 -> 0.17630238 | H26: =G26 -> 0.17630238 | I26: =H26 -> 0.17630238 | J26: =I26 -> 0.17630238
B27: Capex as % of Revenue | F27: ='Supporting Schedules'!C73 -> 0.036560139 | G27: =F27 -> 0.036560139 | H27: =G27 -> 0.036560139 | I27: =H27 -> 0.036560139 | J27: =I27 -> 0.036560139
B29: Other Assumptions
B30: Divident Payout % | F30: ='Supporting Schedules'!F216 -> 0.4224804 | G30: =F30 -> 0.4224804 | H30: =G30 -> 0.4224804 | I30: =H30 -> 0.4224804 | J30: =I30 -> 0.4224804

Sheet Supporting Schedules
B2: SUPPORTING SCHEDULES
B3: Intertek Group plc ( ITRK-GB)
B5: REVENUE SCHEDULE
B7: SECTION 1: HISTORICAL LFL BRIDGE (Management Framework)
C8: 2021A | D8: 2022A | E8: 2023A | F8: 2024A
B9: Prior Year Revenue (£m) | D9: =C18 -> 2786.3 | E9: =D18 -> 3192.9 | F9: =E18 -> 3328.7
B10: LFL / Organic Growth (%) | C10: 0.056 | D10: 0.049 | E10: 0.062 | F10: 0.063
B11: LFL Revenue Impact (£m) | C11: =C18*C10 -> 156.0328 | D11: =D9*D10 -> 136.5287 | E11: =E9*E10 -> 197.9598 | F11: =F9*F10 -> 209.7081
B12: FX Impact (%) | C12: 0.003 | D12: 0.041 | E12: -0.029 | F12: -0.047
B13: FX Revenue Impact (£m) | C13: =C18*C12 -> 8.3589 | D13: =D9*D12 -> 114.2383 | E13: =E9*E12 -> -92.5941 | F13: =F9*F12 -> -156.4489
B14: M&A Contribution (%) | C14: 0.087 | D14: 0.056 | E14: 0.01 | F14: 0.003
B15: M&A Revenue Impact (£m) | C15: =C18*C14 -> 242.4081 | D15: =D9*D14 -> 156.0328 | E15: =E9*E14 -> 31.929 | F15: =F9*F14 -> 9.9861
B16: Total Reported Growth (%) | C16: =C10+C12+C14 -> 0.146 | D16: =D10+D12+D14 -> 0.146 | E16: =E10+E12+E14 -> 0.043 | F16: =F10+F12+F14 -> 0.019
B17: Reported Revenue (£m) — Check | C17: =C18+C11+C13+C15 -> 3193.0998 | D17: =D9+D11+D13+D15 -> 3193.0998 | E17: =E9+E11+E13+E15 -> 3330.1947 | F17: =F9+F11+F13+F15 -> 3391.9453
B18: Actual Revenue (£m) | C18: 2786.3 | D18: 3192.9 | E18: 3328.7 | F18: 3393.2
B20: SECTION 2: FORECAST ASSUMPTIONS (2025E–2029E)
C21: 2025E | D21: 2026E | E21: 2027E | F21: 2028E | G21: 2029E | H21: Notes
B22: LFL / Organic Growth (%) | C22: 0.06 | D22: 0.055 | E22: 0.05 | F22: 0.05 | G22: 0.05 | H22: Mgmt guides MSD LFL at CCY. 4-yr avg = 5.8%. Slight taper to terminal ~5%.
B23: Consumer Products | C23: 0.055 | D23: 0.05 | E23: 0.05 | F23: 0.05 | G23: 0.05 | H23: Low-mid single digit. Mgmt guidance. Softlines headwinds offset by Electrical growth.
B24: Industry & Infrastructure | C24: 0.04 | D24: 0.04 | E24: 0.04 | F24: 0.04 | G24: 0.04 | H24: Below group avg. FY24 LFL 1.7%. Infrastructure cycle recovering — low-mid.
B25: World of Energy | C25: 0.065 | D25: 0.065 | E25: 0.06 | F25: 0.055 | G25: 0.05 | H25: Above group avg. FY24 LFL 8.0%. Energy transition + O&G capex strong. Tapers to group.
B26: Corporate Assurance | C26: 0.075 | D26: 0.07 | E26: 0.065 | F26: 0.06 | G26: 0.06 | H26: Fastest growing. FY24 LFL 7.8%. ESG/supply chain tailwinds structural.
B27: Health & Safety | C27: 0.075 | D27: 0.07 | E27: 0.065 | F27: 0.065 | G27: 0.065 | H27: FY24 LFL 7.9%. Strong momentum; smallest division (10% of rev).
B28: FX Impact (%) | C28: 0 | D28: 0 | E28: 0 | F28: 0 | G28: 0 | H28: Modelled at constant currency (0%). Adjust for GBP/USD views. 2024: -470bps headwind.
B29: M&A Contribution (%) | C29: 0.005 | D29: 0.005 | E29: 0.003 | F29: 0.003 | G29: 0 | H29: Intertek bolt-ons £15-30m/yr. FY24 M&A = 0.3% of rev. Fades to 0 by Year 5.
B30: Total Reported Growth (%) | C30: =C22+C28+C29 -> 0.065 | D30: =D22+D28+D29 -> 0.06 | E30: =E22+E28+E29 -> 0.053 | F30: =F22+F28+F29 -> 0.053 | G30: =G22+G28+G29 -> 0.05
B33: GROSS MARGIN ASSUMPTIONS
B36: SECTION 1: Historical Analysis
C37: 2021A | D37: 2022A | E37: 2023A | F37: 2024A
B39: Revenue | C39: ='Historical Financials'!E10 -> 2786.3 | D39: ='Historical Financials'!F10 -> 3192.9 | E39: ='Historical Financials'!G10 -> 3328.7 | F39: ='Historical Financials'!H10 -> 3393.2
B40: Gross Profit | C40: ='Historical Financials'!E12 -> 644 | D40: ='Historical Financials'!F12 -> 700.2 | E40: ='Historical Financials'!G12 -> 723.2 | F40: ='Historical Financials'!H12 -> 747.9
B41: Gross Margin | C41: =C40/C39 -> 0.23113089 | D41: =D40/D39 -> 0.21929907 | E41: =E40/E39 -> 0.21726199 | F41: =F40/F39 -> 0.22041141
B44: SECTION 2: Forecast Assumptions
C45: 2025E | D45: 2026E | E45: 2027E | F45: 2028E | G45: 2029E | H45: Notes
B46: Gross Margin | C46: =AVERAGE(E41:F41) -> 0.2188367 | D46: =C46 -> 0.2188367 | E46: =D46 -> 0.2188367 | F46: =E46 -> 0.2188367 | G46: =F46 -> 0.2188367 | H46: * Stable so taking it as avg. of last 2 years
B50: DEPRECIATION SCHEDULE
B53: SECTION 1: DEPRECIATION AS % OF BEG. PPE
C54: 2021A | D54: 2022A | E54: 2023A | F54: 2024A
B56: BEG. PPE | D56: ='Forecast Model'!G41 -> 694.4 | E56: ='Forecast Model'!H41 -> 669.6 | F56: ='Forecast Model'!I41 -> 692.8
B57: Dep. | D57: =-'Historical Financials'!F14 -> 215.3 | E57: =-'Historical Financials'!G14 -> 209.5 | F57: =-'Historical Financials'!H14 -> 194
...

Sheet Forecast Model
B3: INCOME STATEMENT
B5: All figures in millions of pounds | F5: 2021A | G5: 2022A | H5: 2023A | I5: 2024A | J5: 2025E | K5: 2026E | L5: 2027E | M5: 2028E | N5: 2029E
B6: unless stated otherwise
B8: Revenue | F8: 2786.3 | G8: 3192.9 | H8: 3328.7 | I8: 3393.2 | J8: =I8*(1+'Master Assumptions'!F11) -> 3613.758 | K8: =J8*(1+'Master Assumptions'!G11) -> 3830.5835 | L8: =K8*(1+'Master Assumptions'!H11) -> 4033.6044 | M8: =L8*(1+'Master Assumptions'!I11) -> 4247.3854 | N8: =M8*(1+'Master Assumptions'!J11) -> 4459.7547
B9: COGS | F9: -2142.3 | G9: -2492.7 | H9: -2605.5 | I9: -2645.3 | J9: =J10-J8 -> -2822.9351 | K9: =K10-K8 -> -2992.3112 | L9: =L10-L8 -> -3150.9037 | M9: =M10-M8 -> -3317.9016 | N9: =N10-N8 -> -3483.7967
B10: Gross Profit | F10: =SUM(F8:F9) -> 644 | G10: =SUM(G8:G9) -> 700.2 | H10: =SUM(H8:H9) -> 723.2 | I10: =SUM(I8:I9) -> 747.9 | J10: =J8*'Master Assumptions'!F12 -> 790.82288 | K10: =K8*'Master Assumptions'!G12 -> 838.27226 | L10: =L8*'Master Assumptions'!H12 -> 882.70069 | M10: =M8*'Master Assumptions'!I12 -> 929.48382 | N10: =N8*'Master Assumptions'!J12 -> 975.95802
B12: D&A Expense | F12: -198.6 | G12: -215.3 | H12: -209.5 | I12: -194 | J12: ='Supporting Schedules'!D91 -> -208.52086 | K12: ='Supporting Schedules'!E91 -> -185.52537 | L12: ='Supporting Schedules'!F91 -> -171.83706 | M12: ='Supporting Schedules'!G91 -> -164.50274 | N12: ='Supporting Schedules'!H91 -> -161.72836
B13: EBIT | F13: =SUM(F10:F12) -> 445.4 | G13: =SUM(G10:G12) -> 484.9 | H13: =SUM(H10:H12) -> 513.7 | I13: =SUM(I10:I12) -> 553.9 | J13: =SUM(J10:J12) -> 582.30203 | K13: =SUM(K10:K12) -> 652.74689 | L13: =SUM(L10:L12) -> 710.86363 | M13: =SUM(M10:M12) -> 764.98109 | N13: =SUM(N10:N12) -> 814.22966
B15: Unusual Expense | F15: -20 | G15: -33.6 | H15: -50.7 | I15: -25.5 | J15: =I15*(1+'Supporting Schedules'!C106) -> -25.242147 | K15: =J15*(1+'Supporting Schedules'!D106) -> -25.242147 | L15: =K15*(1+'Supporting Schedules'!E106) -> -25.242147 | M15: =L15*(1+'Supporting Schedules'!F106) -> -25.242147 | N15: =M15*(1+'Supporting Schedules'!G106) -> -25.242147
B16: Interest Expense | F16: -14.9 | G16: -42.8 | H16: -46.2 | I16: -43.4 | J16: =I16 -> -43.4 | K16: =J16 -> -43.4 | L16: =K16 -> -43.4 | M16: =L16 -> -43.4 | N16: =M16 -> -43.4
B17: Other Income (Expense) | F17: 2.9 | G17: 11.3 | H17: 5.5 | I17: 5 | J17: ='Forecast Model'!I17*(1+'Supporting Schedules'!C107) -> 5.0096322 | K17: ='Forecast Model'!J17*(1+'Supporting Schedules'!D107) -> 5.0096322 | L17: ='Forecast Model'!K17*(1+'Supporting Schedules'!E107) -> 5.0096322 | M17: ='Forecast Model'!L17*(1+'Supporting Schedules'!F107) -> 5.0096322 | N17: ='Forecast Model'!M17*(1+'Supporting Schedules'!G107) -> 5.0096322
B18: EBT | F18: =SUM(F13:F17) -> 413.4 | G18: =SUM(G13:G17) -> 419.8 | H18: =SUM(H13:H17) -> 422.3 | I18: =SUM(I13:I17) -> 490 | J18: =SUM(J13:J17) -> 518.66951 | K18: =SUM(K13:K17) -> 589.11438 | L18: =SUM(L13:L17) -> 647.23111 | M18: =SUM(M13:M17) -> 701.34857 | N18: =SUM(N13:N17) -> 750.59714
B20: Income Taxes | F20: -106.7 | G20: -113 | H20: -104.2 | I20: -122.8 | J20: ='Supporting Schedules'!$C$119*'Forecast Model'!J18 -> -132.86181 | K20: ='Supporting Schedules'!$C$119*'Forecast Model'!K18 -> -150.90689 | L20: ='Supporting Schedules'!$C$119*'Forecast Model'!L18 -> -165.79401 | M20: ='Supporting Schedules'!$C$119*'Forecast Model'!M18 -> -179.65668 | N20: ='Supporting Schedules'!$C$119*'Forecast Model'!N18 -> -192.27214
B21: Consolidated Net Income | F21: =SUM(F18:F20) -> 306.7 | G21: =SUM(G18:G20) -> 306.8 | H21: =SUM(H18:H20) -> 318.1 | I21: =SUM(I18:I20) -> 367.2 | J21: =SUM(J18:J20) -> 385.8077 | K21: =SUM(K18:K20) -> 438.20749 | L21: =SUM(L18:L20) -> 481.4371 | M21: =SUM(M18:M20) -> 521.69189 | N21: =SUM(N18:N20) -> 558.32501
B23: Minority Interest | F23: -18.6 | G23: -18 | H23: -20.7 | I23: -21.8 | J23: ='Supporting Schedules'!$C$129*'Forecast Model'!J21 -> -25.039522 | K23: ='Supporting Schedules'!$C$129*'Forecast Model'!K21 -> -28.44035 | L23: ='Supporting Schedules'!$C$129*'Forecast Model'!L21 -> -31.246019 | M23: ='Supporting Schedules'!$C$129*'Forecast Model'!M21 -> -33.858618 | N23: ='Supporting Schedules'!$C$129*'Forecast Model'!N21 -> -36.236164
B24: Net Income | F24: =SUM(F21:F23) -> 288.1 | G24: =SUM(G21:G23) -> 288.8 | H24: =SUM(H21:H23) -> 297.4 | I24: =SUM(I21:I23) -> 345.4 | J24: =SUM(J21:J23) -> 360.76818 | K24: =SUM(K21:K23) -> 409.76714 | L24: =SUM(L21:L23) -> 450.19108 | M24: =SUM(M21:M23) -> 487.83328 | N24: =SUM(N21:N23) -> 522.08884
B27: BALANCE SHEET
B29: All figures in millions of pounds | F29: 2021A | G29: 2022A | H29: 2023A | I29: 2024A | J29: 2025E | K29: 2026E | L29: 2027E | M29: 2028E | N29: 2029E
B30: unless stated otherwise
B33: Assets
B34: Cash & Short-Term Investments | F34: 265.9 | G34: 321.6 | H34: 299.3 | I34: 343 | J34: =I34+J105 -> 703.60638 | K34: =J34+K105 -> 1086.4885 | L34: =K34+L105 -> 1492.9081 | M34: =L34+M105 -> 1929.1643 | N34: =M34+N105 -> 2403.7899
B35: Accounts Receivable | F35: 559 | G35: 619.6 | H35: 619.9 | I35: 634.2 | J35: ='Supporting Schedules'!H183 -> 674.20451 | K35: ='Supporting Schedules'!I183 -> 714.65678 | L35: ='Supporting Schedules'!J183 -> 752.53359 | M35: ='Supporting Schedules'!K183 -> 792.41787 | N35: ='Supporting Schedules'!L183 -> 832.03877
B36: Other Receivables | F36: 78.5 | G36: 91.3 | H36: 82 | I36: 102.7 | J36: =I36*(1+'Supporting Schedules'!$C$140) -> 105.5671 | K36: =J36*(1+'Supporting Schedules'!$C$140) -> 108.51424 | L36: =K36*(1+'Supporting Schedules'!$C$140) -> 111.54366 | M36: =L36*(1+'Supporting Schedules'!$C$140) -> 114.65765 | N36: =M36*(1+'Supporting Schedules'!$C$140) -> 117.85857
B37: Inventories | F37: 14.9 | G37: 16.9 | H37: 17.2 | I37: 19 | J37: ='Supporting Schedules'!H192 -> 19.455627 | K37: ='Supporting Schedules'!I192 -> 20.622964 | L37: ='Supporting Schedules'!J192 -> 21.715982 | M37: ='Supporting Schedules'!K192 -> 22.866929 | N37: ='Supporting Schedules'!L192 -> 24.010275
B38: Other Current Assets | F38: 45 | G38: 47.4 | H38: 53.2 | I38: 60.4 | J38: =I38*(1+'Supporting Schedules'!$C$150) -> 61.378154 | K38: =J38*(1+'Supporting Schedules'!$C$150) -> 62.372149 | L38: =K38*(1+'Supporting Schedules'!$C$150) -> 63.382241 | M38: =L38*(1+'Supporting Schedules'!$C$150) -> 64.408691 | N38: =M38*(1+'Supporting Schedules'!$C$150) -> 65.451764
B39: Total Current Assets | F39: 963.3 | G39: 1096.8 | H39: 1071.6 | I39: 1159.3 | J39: =SUM(J34:J38) -> 1564.2118 | K39: =SUM(K34:K38) -> 1992.6546 | L39: =SUM(L34:L38) -> 2442.0836 | M39: =SUM(M34:M38) -> 2923.5154 | N39: =SUM(N34:N38) -> 3443.1493
B41: Net PP&E | F41: 641.8 | G41: 694.4 | H41: 669.6 | I41: 692.8 | J41: ='Supporting Schedules'!D92 -> 616.39864 | K41: ='Supporting Schedules'!E92 -> 570.91994 | L41: ='Supporting Schedules'!F92 -> 546.55201 | M41: ='Supporting Schedules'!G92 -> 537.33428 | N41: ='Supporting Schedules'!H92 -> 538.65518
B42: Goodwill | F42: 1241.4 | G42: 1418.4 | H42: 1385.8 | I42: 1365.9 | J42: =I42 -> 1365.9 | K42: =J42 -> 1365.9 | L42: =K42 -> 1365.9 | M42: =L42 -> 1365.9 | N42: =M42 -> 1365.9
B43: Other Intangible Assets | F43: 358.5 | G43: 362.9 | H43: 330.9 | I43: 304.2 | J43: =I43 -> 304.2 | K43: =J43 -> 304.2 | L43: =K43 -> 304.2 | M43: =L43 -> 304.2 | N43: =M43 -> 304.2
B44: Long-Term Investments | F44: 0 | G44: 21.5 | H44: 21.8 | I44: 15.4 | J44: =I44 -> 15.4 | K44: =J44 -> 15.4 | L44: =K44 -> 15.4 | M44: =L44 -> 15.4 | N44: =M44 -> 15.4
B45: Deferred Tax Assets | F45: 39.3 | G45: 45 | H45: 36.4 | I45: 34.5 | J45: =I45 -> 34.5 | K45: =J45 -> 34.5 | L45: =K45 -> 34.5 | M45: =L45 -> 34.5 | N45: =M45 -> 34.5
B46: Other Non-Current Assets | F46: 5.4 | G46: 21.3 | H46: 21.8 | I46: 27.2 | J46: =I46 -> 27.2 | K46: =J46 -> 27.2 | L46: =K46 -> 27.2 | M46: =L46 -> 27.2 | N46: =M46 -> 27.2
B47: Total Non-Current Assets | F47: 2286.4 | G47: 2563.5 | H47: 2466.3 | I47: 2440 | J47: =SUM(J41:J46) -> 2363.5986 | K47: =SUM(K41:K46) -> 2318.1199 | L47: =SUM(L41:L46) -> 2293.752 | M47: =SUM(M41:M46) -> 2284.5343 | N47: =SUM(N41:N46) -> 2285.8552
B48: Total Assets | F48: 3249.7 | G48: 3660.3 | H48: 3537.9 | I48: 3599.3 | J48: =SUM(J47+J39) -> 3927.8104 | K48: =SUM(K47+K39) -> 4310.7746 | L48: =SUM(L47+L39) -> 4735.8356 | M48: =SUM(M47+M39) -> 5208.0497 | N48: =SUM(N47+N39) -> 5729.0045
B50: Liabilities
B51: Accounts Payable | F51: 153.4 | G51: 172.1 | H51: 204.8 | I51: 223 | J51: ='Supporting Schedules'!H200 -> 229.8763 | K51: ='Supporting Schedules'!I200 -> 243.72459 | L51: ='Supporting Schedules'!J200 -> 256.63091 | M51: ='Supporting Schedules'!K200 -> 270.23235 | N51: ='Supporting Schedules'!L200 -> 283.73866
B52: Short-Term Debt | F52: 525.5 | G52: 333 | H52: 167.4 | I52: 171.4 | J52: =I52 -> 171.4 | K52: =J52 -> 171.4 | L52: =K52 -> 171.4 | M52: =L52 -> 171.4 | N52: =M52 -> 171.4
B53: Income Tax Payable | F53: 59.1 | G53: 71 | H53: 60.5 | I53: 67.2 | J53: ='Supporting Schedules'!$C$171*'Forecast Model'!J20 -> 76.729472 | K53: ='Supporting Schedules'!$C$171*'Forecast Model'!K20 -> 87.150746 | L53: ='Supporting Schedules'!$C$171*'Forecast Model'!L20 -> 95.748256 | M53: ='Supporting Schedules'!$C$171*'Forecast Model'!M20 -> 103.75413 | N53: ='Supporting Schedules'!$C$171*'Forecast Model'!N20 -> 111.03973
B54: Other Current Liabilities | F54: 527.6 | G54: 566.9 | H54: 548.8 | I54: 588.5 | J54: =I54*(1+'Supporting Schedules'!$C$161) -> 692.25395 | K54: =J54*(1+'Supporting Schedules'!$C$161) -> 814.29997 | L54: =K54*(1+'Supporting Schedules'!$C$161) -> 957.86299 | M54: =L54*(1+'Supporting Schedules'!$C$161) -> 1126.7365 | N54: =M54*(1+'Supporting Schedules'!$C$161) -> 1325.3828
B55: Total Current Liabilities | F55: 1265.6 | G55: 1143 | H55: 981.5 | I55: 1050.1 | J55: =SUM(J51:J54) -> 1170.2597 | K55: =SUM(K51:K54) -> 1316.5753 | L55: =SUM(L51:L54) -> 1481.6422 | M55: =SUM(M51:M54) -> 1672.123 | N55: =SUM(N51:N54) -> 1891.5612
...

Sheet DCF Valuation
B3: DCF VALUATION - INTERTEK GROUP PLC
B5: SECTION 1: WACC CALCULATION
B7: COST OF EQUITY (CAPM) | H7: COST OF DEBT
B9: Risk-Free Rate (Rf) | E9: 0.0455 | H9: Pre-tax Cost of Debt (Kd) | K9: 0.055
B10: Source: UK 10Y Gilt (Mar 2026) | H10: Credit Rating: Moody's Baa2 / S&P BBB (Stable)
B11: Equity Risk Premium (ERP) | E11: 0.055 | H11: Marginal Tax Rate | K11: =ABS('Supporting Schedules'!$C$119) -> 0.2561589
B12: Source: Damodaran (Jan 2026) | H12: After-Tax Cost of Debt | K12: =K9*(1-K11) -> 0.040911261
H13: Formula: Kd × (1 - Tax Rate)
B14: BETA ANALYSIS (MULTIPLE SOURCES) | H14: COST OF DEBT METHODOLOGY
C15: Source | E15: Beta | F15: Notes | H15: Method 1: Credit Spread Approach (Primary)
B16: 1 | C16: Yahoo Finance (5Y Monthly) | E16: 0.66 | F16: Primary source - vs FTSE All-Share | H16: Rf (UK 10Y Gilt) + Baa2/BBB spread ≈ 4.55% + ~95bps = 5.50%
B17: 2 | C17: Bloomberg (2Y Weekly) | E17: 0.72 | F17: 2Y weekly regression | H17: Source: Intertek FY2024 Annual Report, Note 14 (Borrowings)
B18: 3 | C18: Peer Group Median (TIC Sector) | E18: 0.75 | F18: SGS, Bureau Veritas, Eurofins | H18: Method 2: Implied Cost of Debt (Cross-Check)
H19: Adj. Net Finance Costs incl. IFRS 16 lease interest, fees & FX
B20: Selected Levered Beta | E20: =AVERAGE(E16:E18) -> 0.71 | F20: Average of sources | H20: £42.3m all-in / £555m avg. debt ≈ 7.6% : but overstates pure borrowing cost
H21: 5.50% selected: marginal Kd on new issuance (excl. lease & non-cash items)
B22: UNLEVERING & RELEVERING BETA
B23: Current D/E Ratio (Market Values) | E23: =('Historical Financials'!H55+'Historical Financials'!H60)/('Historical Financials'!H71*160*0.01) -> 0.39488027 | H23: Target D/E Ratio | K23: 0.2
B24: Unlevered Beta (Asset Beta) | E24: =E20/(1+(1-K11)*E23) -> 0.54880153 | H24: Relevered Beta (at Target D/E) | K24: =E24*(1+(1-K11)*K23) -> 0.63044576
B25: Formula: βL / [1+(1-T)×D/E] | H25: Formula: βU × [1+(1-T)×D/E]
B27: COST OF EQUITY CALCULATION | H27: CAPITAL STRUCTURE WEIGHTS
B28: Cost of Equity (Ke) | E28: =E9+K24*E11 -> 0.080174517 | H28: Weight of Equity (E/V) | K28: =1/(1+K23) -> 0.83333333
B29: Formula: Rf + β × ERP | H29: Weight of Debt (D/V) | K29: =K23/(1+K23) -> 0.16666667
B31: WACC CALCULATION
B32: WACC = (E/V × Ke) + (D/V × Kd × (1-T)) | E32: =IF('Sensitivity Tables'!K10="",(K28*E28)+(K29*K12),'Sensitivity Tables'!K10) -> 0.073630641
B34: SECTION 2: FREE CASH FLOW PROJECTIONS
B36: (£ in millions) | E36: 2025E | F36: 2026E | G36: 2027E | H36: 2028E | I36: 2029E
B37: EBIT | E37: ='Forecast Model'!J13 -> 582.30203 | F37: ='Forecast Model'!K13 -> 652.74689 | G37: ='Forecast Model'!L13 -> 710.86363 | H37: ='Forecast Model'!M13 -> 764.98109 | I37: ='Forecast Model'!N13 -> 814.22966
B38: Less: Taxes on EBIT | E38: =-E37*$K$11 -> -149.16185 | F38: =-F37*$K$11 -> -167.20693 | G38: =-G37*$K$11 -> -182.09404 | H38: =-H37*$K$11 -> -195.95671 | I38: =-I37*$K$11 -> -208.57217
B39: NOPAT | E39: =SUM(E37:E38) -> 433.14018 | F39: =SUM(F37:F38) -> 485.53997 | G39: =SUM(G37:G38) -> 528.76958 | H39: =SUM(H37:H38) -> 569.02437 | I39: =SUM(I37:I38) -> 605.65748
B40: Plus: D&A | E40: ='Forecast Model'!J81 -> 208.52086 | F40: ='Forecast Model'!K81 -> 185.52537 | G40: ='Forecast Model'!L81 -> 171.83706 | H40: ='Forecast Model'!M81 -> 164.50274 | I40: ='Forecast Model'!N81 -> 161.72836
B41: Less: CapEx | E41: ='Forecast Model'!J92 -> -132.1195 | F41: ='Forecast Model'!K92 -> -140.04667 | G41: ='Forecast Model'!L92 -> -147.46914 | H41: ='Forecast Model'!M92 -> -155.285 | I41: ='Forecast Model'!N92 -> -163.04925
B42: Less: Δ Working Capital | E42: =-SUM('Forecast Model'!J85:J88) -> -75.854325 | F42: =-SUM('Forecast Model'!K85:K88) -> -100.75485 | G42: =-SUM('Forecast Model'!L85:L88) -> -122.05751 | H42: =-SUM('Forecast Model'!M85:M88) -> -145.30517 | I42: =-SUM('Forecast Model'!N85:N88) -> -174.43
B43: Unlevered Free Cash Flow | E43: =SUM(E39:E42) -> 433.68722 | F43: =SUM(F39:F42) -> 430.26382 | G43: =SUM(G39:G42) -> 431.07999 | H43: =SUM(H39:H42) -> 432.93693 | I43: =SUM(I39:I42) -> 429.90659
B44: Discount Period | E44: 0.5 | F44: 1.5 | G44: 2.5 | H44: 3.5 | I44: 4.5
B45: Discount Factor | E45: =1/(1+$E$32)^E44 -> 0.96510052 | F45: =1/(1+$E$32)^F44 -> 0.89891298 | G45: =1/(1+$E$32)^G44 -> 0.83726465 | H45: =1/(1+$E$32)^H44 -> 0.77984422 | I45: =1/(1+$E$32)^I44 -> 0.72636174
B46: PV of Unlevered Free Cash Flow | E46: =E43*E45 -> 418.55176 | F46: =F43*F45 -> 386.76973 | G46: =G43*G45 -> 360.92804 | H46: =H43*H45 -> 337.62337 | I46: =I43*I45 -> 312.2677
B47: Sum of Present Value of FCF | E47: =SUM(E46:I46) -> 1816.1406
B49: SECTION 3: TERMINAL VALUE (TWO METHODS)
B51: METHOD 1: PERPETUITY GROWTH | H51: METHOD 2: EXIT MULTIPLE
...

Sheet Trading Comps
B4: Figures in GBP, all obtained from Factset | D4: Geography | G4: Operations | I4: Equity Value | M4: Enterprise value | P4: Financial metrics (millions) | V4: Ratios
D5: Market | E5: Scope | G5: Industry | I5: Share price | J5: Shares | K5: Market Cap | M5: (millions)
B6: Company Name | C6: Ticker | J6: (millions) | K6: (million) | P6: Revenue | Q6: EBITDA | R6: EBIT | S6: Net Income | T6: Total Debt / EV | V6: EV/Revenue | W6: EV/EBITDA | X6: EV/EBIT | Y6: P/E
B8: Larger Companies universe
B9: Intertek | C9: ITRK GB | D9: United Kingdom | E9: International | G9: Testing, Inspection and Certification | I9: 37.34 | J9: 155.39 | K9: 5802.31 | M9: 6843.7 | P9: 3396.4 | Q9: 763.9 | R9: 568.2 | S9: 343.5 | T9: 0.19 | V9: 2.57 | W9: 11.2 | X9: 15.09 | Y9: 21.21
B10: SGS | C10: SGSN SW | D10: Switzerland | E10: International | G10: Testing, Inspection and Certification | I10: 85.8 | J10: 195.08 | K10: 16738.57 | M10: 18520.7 | P10: 6345.4 | Q10: 1387.9 | R10: 962.1 | S10: 668 | T10: 0.24 | V10: 2.52 | W10: 13.49 | X10: 19.46 | Y10: 26.12
B11: Bureau Veritas | C11: BVI FP | D11: France | E11: International | G11: Testing, Inspection and Certification | I11: 24.33 | J11: 447.7 | K11: 10096.15 | M11: 14059.85 | P11: 6466.4 | Q11: 1036 | R11: 779.5 | S11: 503.5 | T11: 0.22 | V11: 2.14 | W11: 11.42 | X11: 15.18 | Y11: 20.6
B12: Eurofins Scientific | C12: ERF FP | D12: Luxembourg | E12: International | G12: Testing, Inspection and Certification | I12: 53.15 | J12: 183.32 | K12: 9742.9 | M12: 12971.1 | P12: 6248 | Q12: 1319.8 | R12: 700.8 | S12: 406.6 | T12: 0.35 | V12: 2.15 | W12: 9.83 | X12: 18.51 | Y12: 23.63
B13: ALS limited | C13: ALQ AU | D13: Australia | E13: International | G13: Testing, Inspection and Certification | I13: 11.44 | J13: 510.03 | K13: 5836.1 | M13: 6387.7 | P13: 1575.7 | Q13: 376.2 | R13: 254.9 | S13: 133.7 | T13: 0.22 | V13: 3.1 | W13: 16.98 | X13: 25.06 | Y13: 29.12
B14: Wolters Kluwer | C14: WLK NL | D14: Netherlands | E14: International | G14: Testing, Inspection and Certification | I14: 58.14 | J14: 226.71 | K14: 13181.45 | M14: 16514.3 | P14: 5245.2 | Q14: 1719.6 | R14: 1323.1 | S14: 1120.1 | T14: 0.21 | V14: 3.92 | W14: 9.6 | X14: 12.48 | Y14: 15.6
B16: Maximum | V16: 3.92 | W16: 16.98 | X16: 25.06 | Y16: 29.12
B17: 75th Percentile | V17: 3.1 | W17: 13.49 | X17: 19.46 | Y17: 26.12
B18: Mean | V18: 2.766 | W18: 12.264 | X18: 18.138 | Y18: 23.014
B19: 25th Percentile | V19: 2.15 | W19: 9.83 | X19: 15.18 | Y19: 20.6
B20: Minimum | V20: 2.14 | W20: 9.6 | X20: 12.48 | Y20: 15.6

Sheet Valuation Summary
B2: VALUATION SUMMARY - INTERTEK GROUP PLC
B3: Football Field Analysis
B6: ENTERPRISE VALUE (£ millions) | I6: Offset | J6: Range
B7: Methodology | C7: Low | D7: Mid | E7: High | F7: Source | H7: Trading Comps | I7: 7334 | J7: 5639
B8: DCF - Perpetuity Growth | C8: 7095 | D8: 8347 | E8: 9599 | F8: WACC ±1%, TGR ±0.5% | H8: DCF - Exit Multiple | I8: 8774 | J8: 3096
B9: DCF - Exit Multiple | C9: 8774 | D9: 10322 | E9: 11870 | F9: Exit Multiple 10x-14x | H9: DCF - Perpetuity Growth | I9: 7095 | J9: 2504
B10: Trading Comps (EV/EBITDA) | C10: 7333 | D10: 9365 | E10: 12971 | F10: Peer range 9.6x-17.0x | H10: Current Market EV | I10: 6844 | J10: 0
B11: Current Market EV | D11: 6844 | F11: As of current price
N16: ◀ Current EV
B21: IMPLIED SHARE PRICE (£) | I21: Offset | J21: Range
B22: Methodology | C22: Low | D22: Mid | E22: High | F22: Source | H22: Trading Comps | I22: 44.04 | J22: 36.73
B23: DCF - Perpetuity Growth | C23: 42.500489 | D23: 50.655247 | E23: 58.810005 | F23: WACC ±1%, TGR ±0.5% | H23: DCF - Exit Multiple | I23: 53.44 | J23: 20.19
B24: DCF - Exit Multiple | C24: 53.436462 | D24: 63.519182 | E24: 73.601902 | F24: Exit Multiple 10x-14x | H24: DCF - Perpetuity Growth | I24: 42.49 | J24: 16.32
B25: Trading Comps (EV/EBITDA) | C25: 44.050674 | D25: 57.285872 | E25: 80.773139 | F25: Peer range 9.6x-17.0x | H25: Current Share Price | I25: 37.34 | J25: 0
B26: Current Share Price | D26: 37.34 | F26: Market price
B35: VALUATION SUMMARY
B36: Methodology | C36: Midpoint EV (£mm) | D36: Midpoint Price (£) | E36: Upside to Current
B37: DCF - Perpetuity Growth | C37: 8347 | D37: 50.65 | E37: =(D37-37.34)/37.34 -> 0.3564542
B38: DCF - Exit Multiple | C38: 10322 | D38: 63.52 | E38: =(D38-37.34)/37.34 -> 0.7011248
B39: Trading Comps (Mean) | C39: 9369 | D39: 57.3 | E39: =(D39-37.34)/37.34 -> 0.5345474
B41: Blended Valuation (Equal Weight) | C41: =AVERAGE(C37:C39) -> 9346 | D41: =AVERAGE(D37:D39) -> 57.156667 | E41: =(D41-37.34)/37.34 -> 0.5307088
B43: KEY TAKEAWAY
B44: All valuation methodologies suggest significant upside to the current market price.
B45: Implied valuation range: £7,095mm - £12,973mm EV | £42.50 - £80.77 per share
B47: Notes:
B48: • DCF ranges based on WACC sensitivity (±1%) and terminal growth rate sensitivity (±0.5%)
B49: • Trading Comps based on peer EV/EBITDA multiples ranging from 9.6x (minimum) to 17.0x (maximum)
B50: • Current market data as of latest available trading date

Sheet Sensitivity Tables
B3: SENSITIVITY ANALYSIS
B5: WACC vs. PERPETUAL GROWTH RATE
E8: Implied Price (Diluted) | F8: GROWTH RATE
E9: ='DCF Valuation'!E72 -> 50.986672 | F9: 0.015 | G9: 0.02 | H9: 0.025 | I9: 0.03 | J9: 0.035
D10: WACC | E10: =E11-1% -> 0.0539 | F10: 66.339776 | G10: 75.174717 | H10: 87.066731 | I10: 103.93448 | J10: 129.72697
E11: =E12-1% -> 0.0639 | F11: 52.357667 | G11: 57.608457 | H11: 64.209064 | I11: 72.756753 | J11: 84.262121
E12: 0.0739 | F12: 43.120434 | G12: 46.556593 | H12: 50.695444 | I12: 55.777086 | J12: 62.165062
E13: =E12+1% -> 0.0839 | F13: 36.562174 | G13: 38.960833 | H13: 41.766735 | I13: 45.093212 | J13: 49.09995
E14: =E13+1% -> 0.0939 | F14: 31.664336 | G14: 33.418248 | H14: 35.426719 | I14: 37.749504 | J14: 40.466651
B18: WACC vs EXIT MULTIPLE
E21: Implied Price (Diluted) | F21: EXIT MULTIPLE (EV/EBITDA)
E22: ='DCF Valuation'!F72 -> 63.600187 | F22: 10 | G22: 11 | H22: 12 | I22: 13 | J22: 14
D23: WACC | E23: =E24-1% -> 0.0539 | F23: 58.910485 | G23: 63.936549 | H23: 68.962612 | I23: 73.988675 | J23: 79.014739
E24: =E25-1% -> 0.0639 | F24: 56.544158 | G24: 61.361102 | H24: 66.178047 | I24: 70.994991 | J24: 75.811935
E25: 0.0739 | F25: 54.293878 | G25: 58.91224 | H25: 63.530603 | I25: 68.148965 | J25: 72.767327
E26: =E25+1% -> 0.0839 | F26: 52.15289 | G26: 56.582585 | H26: 61.01228 | I26: 65.441974 | J26: 69.871669
E27: =E26+1% -> 0.0939 | F27: 50.114888 | G27: 54.36525 | H27: 58.615613 | I27: 62.865976 | J27: 67.116338

Sheet Deal Scenario A - M&A
B2: DEAL SCENARIO A : STRATEGIC ANALYSIS / M&A
B5: SECTION 1: TIC SECTOR M&A LANDSCAPE : CONSOLIDATION WAVE UNDERWAY
B7: Key Sector Dynamics
B8: Metric | C8: Detail | D8: Source
B9: Global TIC Market Size (2024) | C9: $246 billion | D9: SkyQuest / MarketsandMarkets
B10: Projected Market Size (2033) | C10: $345B (CAGR: 3.8%) | D10: SkyQuest Research
B11: Top 4 Combined Market Share | C11: 20–25% | D11: ZKB Analyst / Aventis
B12: Avg. Annual M&A Deals (2015–2025) | C12: ~131 deals per year | D12: Aventis Advisors / Capital IQ
B13: PE Share of TIC Deal Flow (H1 2025) | C13: 36% (up from 22% in 2015) | D13: Aventis Advisors
B14: Peak TIC EV/EBITDA Valuation | C14: 17.2x | D14: Aventis Advisors
B15: Key Growth Drivers | C15: AI compliance, ESG, regulation, digitalization | D15: EY TIC Study 2025 / BCG
B17: SECTION 2: PRECEDENT TIC M&A TRANSACTIONS
B19: Date | C19: Target | D19: Acquirer | E19: Deal Type | F19: EV ($mm) | G19: Revenue ($mm) | H19: EV/Revenue | I19: EV/EBITDA | J19: Premium | K19: Status | L19: Key Strategic Rationale
B20: 45658 | C20: SGS + Bureau Veritas | D20: Merger of Equals | E20: Strategic Merger | F20: ~$33,000 | G20: ~$13,000 | H20: 2.5x | I20: ~15x | J20: n/a | K20: Collapsed (Jan 27) | L20: Create $30B+ TIC champion; €400mm synergies targeted
B21: Late 2024 | C21: Intertek Group | D21: Bureau Veritas | E21: Strategic Merger | F21: ~£8,000 | G21: £3,393 | H21: 2.4x | I21: ~11x | J21: n/a | K21: Collapsed (Fall 2024) | L21: Anglo-French TIC champion; Wendel pivoted to SGS
B22: 45444 | C22: Applus+ Services | D22: TDR Capital / I Squared | E22: PE Take-Private | F22: ~€2,400 | G22: 2100 | H22: 1.1x | I22: ~12x | J22: ~30% | K22: Completed | L22: Take-private; energy/auto TIC platform; beat Apollo bid
B23: 44562 | C23: Element Materials Tech | D23: Temasek (from Bridgepoint) | E23: PE → Sovereign Wealth | F23: ~$7,000 | G23: ~$1,000 | H23: 7.0x | I23: ~20x+ | J23: Significant | K23: Completed | L23: Lab-based TIC leader; life sciences & connected tech
B24: 44986 | C24: Applus+ Services | D24: Apollo Global Mgmt | E24: PE Tender Offer | F24: ~€1,400 | G24: 2100 | H24: 0.7x | I24: ~10x | J24: €9.50/sh | K24: Cancelled (May 2024) | L24: Initial €9.50/sh offer; outbid by TDR/I Squared consortium
B25: 44317 | C25: SAI Global Assurance | D25: Intertek Group | E25: Strategic Bolt-on | F25: n/d | G25: n/d | H25: n/d | I25: n/d | J25: n/a | K25: Completed | L25: Quality Assurance; Food, QSR, Forestry; Australia/US/Canada
B26: 2024 | C26: BV Food Testing Business | D26: Mérieux NutriSciences | E26: Divestiture | F26: 360 | G26: ~€133 | H26: 2.7x | I26: n/d | J26: n/a | K26: Completed | L26: Portfolio optimization; non-core divestiture at 2.7x revenue
B28: KEY INSIGHT: | C28: Bureau Veritas held direct merger talks with Intertek in late 2024 before pivoting to SGS. Both mega-deals collapsed, leaving Intertek as a confirmed M&A target and the TIC sector primed for consolidation.
B30: SECTION 3: INTERTEK AS STRATEGIC ACQUISITION TARGET : INVESTMENT THESIS
B32: 3A. CONFIRMED M&A INTEREST IN INTERTEK
B33: Event | C33: Date | D33: Detail
B34: Bureau Veritas – Intertek Merger Talks | C34: Late 2024 | D34: BV held "long-running" merger discussions with Intertek before pivoting to SGS (per FT/Bloomberg)
B35: SGS – Bureau Veritas Merger Collapse | C35: 45684 | D35: BV stated "strong belief in the value of consolidation in TIC" — Intertek remains viable partner
B36: Wendel (BV's 26.5% shareholder) Strategy | C36: 2024–2025 | D36: Wendel actively seeking strategic combinations; sold 9% BV stake; exploring options
B37: RBC Capital Markets View | C37: 45658 | D37: Intertek could benefit from SGS-BV deal via new contracts or acquiring divested units
B39: 3B. VALUATION DISCOUNT — INTERTEK TRADES CHEAPLY VS. PEERS
B40: Company | C40: Ticker | D40: EV (£mm) | E40: Revenue (£mm) | F40: EBITDA (£mm) | G40: EV/Revenue | H40: EV/EBITDA | I40: P/E
B41: Intertek Group | C41: ITRK LN | D41: 6844 | E41: 3396 | F41: 764 | G41: 2.01x | H41: 8.96x | I41: 21.2x
B42: SGS SA | C42: SGSN SW | D42: 18521 | E42: 6345 | F42: 1388 | G42: 2.92x | H42: 13.3x | I42: 26.1x
B43: Bureau Veritas | C43: BVI FP | D43: 14060 | E43: 6466 | F43: 1036 | G43: 2.17x | H43: 13.6x | I43: 20.6x
B44: Eurofins Scientific | C44: ERF FP | D44: 12971 | E44: 6248 | F44: 1320 | G44: 2.08x | H44: 9.8x | I44: 23.6x
B45: ALS Limited | C45: ALQ AU | D45: 6388 | E45: 1576 | F45: 376 | G45: 4.05x | H45: 17.0x | I45: 29.1x
B46: Wolters Kluwer | C46: WLK NA | D46: 16514 | E46: 5245 | F46: 1720 | G46: 3.15x | H46: 9.6x | I46: 15.6x
B48: Peer Mean (ex-Intertek) | G48: 2.87x | H48: 12.7x | I48: 23.0x
B49: Intertek Discount to Peers | G49: -0.3 | H49: -0.29 | I49: -0.08
B51: 3C. STRATEGIC RATIONALE : WHY INTERTEK IS ATTRACTIVE
B52: Factor | C52: Detail | D52: Supporting Evidence
...

Sheet Deal Scenario B - PE
B1: DEAL SCENARIO B: PRIVATE EQUITY TAKE-PRIVATE — BUY, BUILD, EXIT
B2: If strategic mega-mergers keep collapsing due to regulatory/cultural complexity, PE becomes the natural alternative buyer. A sponsor takes Intertek private, runs the operational playbook for 5 years, then exits to a strategic at a premium.
B4: SECTION 1: PE ENTRY : LBO AFFORDABILITY ANALYSIS
B6: 1A. LBO ENTRY ASSUMPTIONS
B7: Assumption | C7: Value | D7: Rationale
B8: Entry Premium to Current Price | C8: 0.3 | D8: 30% base case control premium; consistent with TIC precedents
B9: Entry Share Price (£) | C9: ='Deal Scenario A - M&A'!C76*(1+C8) -> 48.542
B10: Entry Equity Value (£mm) | C10: =C9*'Deal Scenario A - M&A'!C77 -> 7452.6533
B11: Entry Enterprise Value (£mm) | C11: =C10+'Deal Scenario A - M&A'!C79 -> 8022.5533
B12: Entry EV / LTM EBITDA | C12: =C11/'Deal Scenario A - M&A'!C82 -> 10.500724
B13: Entry EV / 2025E EBITDA | C13: =C11/'Deal Scenario A - M&A'!C86 -> 10.144564
B15: Total Leverage at Entry (x EBITDA) | C15: 4.5 | D15: Comfortable for asset-light TIC; strong cash conversion supports
B16: Total Debt at Entry (£mm) | C16: =C15*'Deal Scenario A - M&A'!C86 -> 3558.703
B17: Equity Required (£mm) | C17: =C11-C16 -> 4463.8503
B18: Equity / Total Capitalisation | C18: =C17/C11 -> 0.55641267
B19: Cost of Debt (pre-tax) | C19: 0.065 | D19: Leveraged finance market; Baa2/BBB rated; ~SOFR + 350-400bps
B20: Bolt-on M&A Budget (£mm/year) | C20: 150 | D20: Consistent with Intertek's recent pace; high-margin targets
B23: SECTION 2: 5-YEAR PE VALUE CREATION MODEL
B25: 2A. OPERATING ASSUMPTIONS
B26: Assumption | C26: Value | D26: Rationale
B27: Organic Revenue Growth (p.a.) | C27: 0.05 | D27: Mid-single-digit per management guidance; TIC market growth 4-5%
B28: Bolt-on Revenue Contribution (p.a., £mm) | C28: 75 | D28: ~50% of £150mm annual bolt-on spend converts to incremental revenue in Year 1
B29: Entry EBITDA Margin | C29: 0.225 | D29: LTM EBITDA margin = £764mm / £3,393mm; includes D&A add-back
B30: Annual Margin Expansion (bps) | C30: 30 | D30: PE operational playbook: procurement, pricing, lab utilisation; conservative vs. 50bps achievable
B31: CapEx (% of Revenue) | C31: 0.04 | D31: Consistent with Intertek's historical 4.0% capex intensity
B32: Tax Rate | C32: 0.25 | D32: UK corporate tax rate
B33: D&A (% of Revenue) | C33: 0.05 | D33: Consistent with recent Intertek levels
B34: ΔWC (% of Revenue Increase) | C34: 0.15 | D34: Modest working capital build on growth
B37: 2B. 5-YEAR PROJECTED FINANCIALS UNDER PE OWNERSHIP (£mm)
C38: Entry (Year 0) | D38: Year 1 | E38: Year 2 | F38: Year 3 | G38: Year 4 | H38: Year 5
B39: Revenue | C39: ='Deal Scenario A - M&A'!C81 -> 3393 | D39: =C39*(1+$C$27)+$C$28 -> 3637.65 | E39: =D39*(1+$C$27)+$C$28 -> 3894.5325 | F39: =E39*(1+$C$27)+$C$28 -> 4164.2591 | G39: =F39*(1+$C$27)+$C$28 -> 4447.4721 | H39: =G39*(1+$C$27)+$C$28 -> 4744.8457
B40: Revenue Growth % | D40: =D39/C39-1 -> 0.072104332 | E40: =E39/D39-1 -> 0.070617706 | F40: =F39/E39-1 -> 0.069257767 | G40: =G39/F39-1 -> 0.068010407 | H40: =H39/G39-1 -> 0.066863512
B41: EBITDA Margin | C41: =$C$29 -> 0.225 | D41: =C41+$C$30/10000 -> 0.228 | E41: =D41+$C$30/10000 -> 0.231 | F41: =E41+$C$30/10000 -> 0.234 | G41: =F41+$C$30/10000 -> 0.237 | H41: =G41+$C$30/10000 -> 0.24
B42: EBITDA | C42: =C39*C41 -> 763.425 | D42: =D39*D41 -> 829.3842 | E42: =E39*E41 -> 899.63701 | F42: =F39*F41 -> 974.43664 | G42: =G39*G41 -> 1054.0509 | H42: =H39*H41 -> 1138.763
B43: Less: D&A | C43: =-C39*$C$33 -> -169.65 | D43: =-D39*$C$33 -> -181.8825 | E43: =-E39*$C$33 -> -194.72663 | F43: =-F39*$C$33 -> -208.21296 | G43: =-G39*$C$33 -> -222.3736 | H43: =-H39*$C$33 -> -237.24228
B44: EBIT | C44: =C42+C43 -> 593.775 | D44: =D42+D43 -> 647.5017 | E44: =E42+E43 -> 704.91038 | F44: =F42+F43 -> 766.22368 | G44: =G42+G43 -> 831.67728 | H44: =H42+H43 -> 901.52068
B45: Less: Interest Expense | C45: =-C60*$C$19 -> -231.31569 | D45: =-D60*$C$19 -> -211.44035 | E45: =-E60*$C$19 -> -199.95323 | F45: =-F60*$C$19 -> -185.05972 | G45: =-G60*$C$19 -> -166.40105 | H45: =-H60*$C$19 -> -143.5893
B46: Less: Taxes | C46: =-(C44+C45)*$C$32 -> -90.614827 | D46: =-(D44+D45)*$C$32 -> -109.01534 | E46: =-(E44+E45)*$C$32 -> -126.23929 | F46: =-(F44+F45)*$C$32 -> -145.29099 | G46: =-(G44+G45)*$C$32 -> -166.31906 | H46: =-(H44+H45)*$C$32 -> -189.48284
B47: Net Income | C47: =C44+C45+C46 -> 271.84448 | D47: =D44+D45+D46 -> 327.04601 | E47: =E44+E45+E46 -> 378.71787 | F47: =F44+F45+F46 -> 435.87297 | G47: =G44+G45+G46 -> 498.95717 | H47: =H44+H45+H46 -> 568.44853
B49: FREE CASH FLOW
...

Sheet Sources & Footnotes
B2: SOURCES & FOOTNOTES
B3: Intertek Group Plc | Data Sources, Market Inputs, Methodology & Audit Trail
B5: SECTION 1: PRIMARY DATA SOURCES
B6: # | C6: Source Name | D6: Type | E6: Data Used For | F6: Tabs Referenced | G6: Access Date | H6: URL / Reference
B7: S1 | C7: Intertek Group plc — Annual Report & Accounts 2024 | D7: Company Filing | E7: IS, BS, CF statements; KPIs; segment data | F7: Historical Financials | G7: Mar 2026 | H7: https://www.intertek.com/investors/results-presentations-announcements/
B8: S2 | C8: Intertek Group plc — Annual Report & Accounts 2023 | D8: Company Filing | E8: Prior-year IS, BS, CF; revenue bridge | F8: Historical Financials | G8: Mar 2026 | H8: https://www.intertek.com/investors/results-presentations-announcements/
B9: S3 | C9: Intertek Group plc — Annual Report & Accounts 2022 | D9: Company Filing | E9: Historical IS, BS, CF data (FY2021–2022) | F9: Historical Financials | G9: Mar 2026 | H9: https://www.intertek.com/investors/results-presentations-announcements/
B10: S4 | C10: Intertek Group plc — Investor Relations | D10: Company IR | E10: Earnings releases, investor presentations, share data | F10: Master Assumptions, Cover | G10: Mar 2026 | H10: https://www.intertek.com/investors/results-presentations-announcements/
B11: S5 | C11: FactSet | D11: Terminal / Database | E11: Peer comps, multiples, share prices, EV, financial metrics | F11: Trading Comps | G11: Mar 2026 | H11: FactSet — https://www.factset.com
B12: S6 | C12: Yahoo Finance — ITRK.L (5Y Monthly) | D12: Market Data | E12: Levered beta (primary); 5Y monthly regression vs FTSE All-Share - please note it is in penny | F12: DCF Valuation | G12: Mar 2026 | H12: https://finance.yahoo.com/quote/ITRK.L/
B13: S7 | C13: Bloomberg Terminal (2Y Weekly) | D13: Terminal | E13: Levered beta (secondary); 2Y weekly regression | F13: DCF Valuation | G13: Mar 2026 | H13: ITRK LN Equity — Beta screen
B14: S8 | C14: Damodaran Online — Implied ERP | D14: Academic | E14: Equity Risk Premium (5.50%); sector unlevered betas | F14: DCF Valuation | G14: Jan 2026 | H14: https://pages.stern.nyu.edu/~adamodar/New_Home_Page/datafile/ctryprem.html
B15: S9 | C15: Bank of England — UK Gilt Yields | D15: Government | E15: Risk-free rate: UK 10Y Gilt yield (4.55%) | F15: DCF Valuation | G15: Mar 2026 | H15: https://www.bankofengland.co.uk/statistics/yield-curves
B16: S10 | C16: Intertek Group plc — FY2024 Annual Report, Note 14 (Borrowings) & Moody's/S&P Rating | D16: Company Filing / Rating Agency | E16: Pre-tax Kd derivation: Baa2/BBB credit spread over UK Gilt; cross-checked via implied Kd from FY2024 net finance costs / avg. debt | F16: DCF Valuation | G16: Mar 2026 | H16: https://www.intertek.com/siteassets/investors/2024/intertek-financial-report-2024.pdf
B18: SECTION 2: EXTERNAL MARKET INPUTS USED
B19: Input | D19: Value Used | E19: Source / Basis | F19: Feeds Into | G19: As-Of Date | H19: Source Ref
B20: Risk-Free Rate (Rf) | D20: 0.0455 | E20: UK 10-Year Gilt yield at close | F20: DCF: WACC → Ke | G20: Mar 2026 | H20: S9
B21: Equity Risk Premium (ERP) | D21: 0.055 | E21: Damodaran implied ERP for UK market, Jan 2026 | F21: DCF: WACC → Ke | G21: Jan 2026 | H21: S8
B22: Levered Beta | D22: 0.707 | E22: Average of 3 sources: Yahoo (0.65), Bloomberg (0.72), Peer median (0.75) | F22: DCF: WACC → Ke | G22: Mar 2026 | H22: S6, S7
B23: Terminal Growth Rate (g) | D23: 0.025 | E23: UK long-run nominal GDP growth proxy (BoE inflation target + real growth) | F23: DCF: Terminal Value | G23: Mar 2026 | H23: S9
B24: Marginal Tax Rate | D24: 0.2562 | E24: Effective tax rate from FY2024 actuals (Intertek Annual Report) | F24: DCF: NOPAT, FCF | G24: FY2024 | H24: S1
B25: Exit EV/EBITDA Multiple | D25: 12.0x | E25: TIC sector peer trading comps median (FactSet) | F25: DCF: Terminal Value | G25: Mar 2026 | H25: S5
B26: Pre-tax Cost of Debt (Kd) | D26: 0.055 | E26: Credit spread approach: Rf (UK 10Y Gilt, 4.55%) + Baa2/BBB spread (~95bps). Cross-checked via implied Kd (Net Finance Costs / Avg. Debt). Source: Intertek FY2024 Annual Report, Note 14 | F26: DCF: WACC → Kd | G26: Mar 2026 | H26: S10
B27: Shares Outstanding (mm) | D27: 153.53 | E27: Diluted share count from Intertek FY2024 Annual Report | F27: DCF: Equity bridge | G27: FY2024 | H27: S1
B29: SECTION 3: FOOTNOTES & ADJUSTMENTS
B30: Ref # | C30: Tab / Cell | D30: Footnote Description | E30: Source Ref | F30: Impact on Model
B31: [1] | C31: Historical Financials | D31: All historical IS, BS, CF data sourced from Intertek Annual Reports FY2021–2024. Figures reported in GBP millions as filed. | E31: S1, S2, S3 | F31: Foundation for all historical analysis and ratio calculations
B32: [2] | C32: DCF Valuation, E16:E18 | D32: Beta averaged from 3 sources: Yahoo Finance 5Y monthly (0.65), Bloomberg 2Y weekly (0.72), and peer group median (0.75). Average = 0.707. | E32: S6, S7, S8 | F32: Drives Ke (7.9%) and WACC (7.4%)
B33: [3] | C33: DCF Valuation, E9 | D33: Risk-free rate set at 4.55% based on UK 10-Year Gilt yield. Chosen over US Treasury as Intertek is UK-domiciled and LSE-listed. | E33: S9 | F33: Directly impacts Ke and WACC
