Workbook
Name MacroScore: 'Macro Scorecard'!$E$11
Name MacroSignal: 'Macro Scorecard'!$E$12
Name RiskFreeRate: 'Macro Scorecard'!$C$23

Sheet Cover & Methodology
A1: GLOBAL MACRO THEMATIC PORTFOLIO
A2: A Rules-Based, Macro-Driven Thematic Investment Strategy | March 2026
A4: Strategy Overview | B4: This portfolio deploys a top-down, macro-thematic investment approach, identifying structural investment opportunities driven by durable macroeconomic catalysts across global markets. Three high-conviction themes — AI Infrastructure Buildout, European Defence Rearmament, and Emerging Market Consumer Emergence — are constructed as diversified baskets of single stocks and ETFs, with weights determined by a rules-based macro scoring framework. Theme allocation is rebalanced quarterly in response to changes in a composite macro signal derived from five leading indicators. The portfolio is benchmarked against the MSCI ACWI and targets net alpha generation through disciplined thematic exposure rather than factor timing or leverage.
A6: METHODOLOGY
A7: Theme Selection | B7: Themes are selected based on three criteria: (1) a clearly identifiable macro catalyst already underway, (2) global investability across multiple instruments and geographies, and (3) differentiation from co-existing themes in both sector and regional exposure. Themes are reviewed annually or following a significant macro regime shift.
A8: Basket Construction | B8: Each theme basket holds 8 positions: 5 single-name equities and 3 ETFs. Stocks are selected for direct thematic exposure, liquidity (minimum $2bn market cap), and geographic diversity within the theme. ETFs provide broad exposure and reduce idiosyncratic risk. Position sizing is equal-weight within each basket by default, subject to PM discretion.
A9: Rebalancing Rules | B9: The portfolio is rebalanced quarterly, triggered by changes in the Macro Scorecard signal (Tab 1). A minimum holding period of 90 days applies between rebalances. Theme weights shift according to the three-scenario framework in Tab 3 (Risk-On / Neutral / Risk-Off). Intra-basket holdings are reviewed but only replaced if a position loses thematic relevance or liquidity.
A10: Benchmark | B10: The portfolio is benchmarked against the MSCI ACWI (All Country World Index), representing the global investable equity universe. Individual theme baskets may also be compared to relevant sector or regional indices as noted in Tab 2.
A11: Data Sources | B11: Bloomberg Terminal (price data, market cap, earnings revisions), FRED / St. Louis Fed (yield curve, PMI), ICE BofA (credit spreads), MSCI (benchmark returns and country weights), IMF World Economic Outlook (macro forecasts). All return inputs in Tab 4 are user-populated from primary sources.
A13: MACRO SIGNAL FRAMEWORK
A14: Composite Signal | B14: A weighted average of five macro indicators — Global PMI, US Yield Curve, MSCI ACWI Earnings Revision Ratio, DXY 3-Month Change, and Global IG Credit Spreads — generates a score between 1.0 and 3.0. Scores above 2.0 indicate a Risk-On environment favouring cyclical and growth themes; 1.5–2.0 is Neutral; below 1.5 is Risk-Off, favouring defensive positioning.
A15: Rebalancing Trigger | B15: A change in the composite signal category (e.g., from Neutral to Risk-On) triggers a rebalancing review. The PM confirms the signal has persisted for at least two consecutive weeks before executing a rebalance, to avoid whipsaw. Minimum 90-day holding period between rebalances applies regardless of signal movement.
A16: Weight Limits | B16: No single theme may exceed 55% of the portfolio in any scenario. Minimum allocation per theme is 20% to maintain diversification. Intra-basket position sizes are bounded at 20% per holding (max) and 5% (min).
A18: INVESTMENT THESES — ONE-LINE SUMMARY PER THEME
A19: Theme | B19: Investment Thesis | C19: Target Weight | D19: Horizon
A20: AI Infrastructure Buildout | B20: Hyperscaler capex commitments exceeding $300bn in 2025 are creating a multi-year supercycle in power, semiconductor, and networking infrastructure that is far from fully priced in. | C20: 0.4 | D20: 3–5 Years
A21: European Defence Rearmament | B21: NATO member states face binding commitments to increase defence spending to 2%+ of GDP, driving a generational procurement cycle in missiles, aerospace, and cybersecurity with near-zero political risk of reversal. | C21: 0.35 | D21: 3–7 Years
A22: EM Consumer Emergence | B22: Rising middle-class formation in India, Southeast Asia, and Latin America, combined with digital payments penetration, is creating compounding consumer demand in markets trading at significant valuation discounts to DM peers. | C22: 0.25 | D22: 5–10 Years

Sheet Macro Scorecard
B1: MACRO SCORECARD
B2: Rules-based macro signal dashboard — drives theme allocation weights | Yellow cells = user inputs | Score cells update automatically
B3: MACRO INDICATOR SCORING TABLE
B4: Macro Indicator | C4: Current Reading ★ (Mar 2026) | D4: Signal Threshold | E4: Score (1–3) | F4: Weight | G4: Weighted Score
B5: Global PMI Composite | C5: 52.4 | D5: > 52: Expansion | 50–52: Neutral | < 50: Contraction | E5: =IF(C5="","–",IF(C5>52,3,IF(C5>=50,2,1))) -> 3 | F5: 0.25 | G5: =IF(OR(E5="–",E5=""),"–",E5*F5) -> 0.75
B6: US 10Y–2Y Yield Curve Slope (bps) | C6: 55 | D6: > 50bps: Steepening | 0–50bps: Flat | < 0bps: Inverted | E6: =IF(C6="","–",IF(C6>50,3,IF(C6>=0,2,1))) -> 3 | F6: 0.25 | G6: =IF(OR(E6="–",E6=""),"–",E6*F6) -> 0.75
B7: MSCI ACWI Earnings Revision Ratio | C7: 1.08 | D7: > 1.1: Positive Revisions | 0.9–1.1: Neutral | < 0.9: Negative | E7: =IF(C7="","–",IF(C7>1.1,3,IF(C7>=0.9,2,1))) -> 2 | F7: 0.2 | G7: =IF(OR(E7="–",E7=""),"–",E7*F7) -> 0.4
B8: USD Index (DXY) — 3-Month Change (%) | C8: -1.2 | D8: < –2%: USD Weakening | –2% to +2%: Stable | > +2%: Strengthening | E8: =IF(C8="","–",IF(C8<-2,3,IF(C8<=2,2,1))) -> 2 | F8: 0.15 | G8: =IF(OR(E8="–",E8=""),"–",E8*F8) -> 0.3
B9: Global Credit Spreads — IG OAS (bps) | C9: 98 | D9: < 100bps: Risk-On | 100–150bps: Normal | > 150bps: Stressed | E9: =IF(C9="","–",IF(C9<100,3,IF(C9<=150,2,1))) -> 3 | F9: 0.15 | G9: =IF(OR(E9="–",E9=""),"–",E9*F9) -> 0.45
B11: COMPOSITE MACRO SCORE (sum of weighted scores) | E11: =IF(COUNTA(G5:G9)=0,"Awaiting Input",IFERROR(SUMIF(G5:G9,"<>–"),0)) -> 2.65
B12: MACRO SIGNAL | E12: =IF(E11="Awaiting Input","— Awaiting Input —",IF(ISNUMBER(E11),IF(E11>2,"🟢 Risk-On — Favour Cyclical Themes",IF(E11>=1.5,"🟡 Neutral — Equal Weight Themes","🔴 Risk-Off — Favour Defensive Themes")),"—")) -> 🟢 Risk-On — Favour Cyclical Themes
B14: INDICATOR NOTES — What Each Indicator Measures & Why It Drives Thematic Rotation
B15: Indicator | C15: What It Measures | E15: Why Relevant to Thematic Rotation
B16: Global PMI Composite | C16: Measures manufacturing and services activity across 40+ countries. Above 50 = expansion; below 50 = contraction. Published monthly by S&P Global. | E16: The single best real-time gauge of global growth momentum. Risk-On PMI readings favour cyclical themes (AI capex, EM consumer). A PMI below 50 for two consecutive months triggers a defensive pivot.
B17: US 10Y–2Y Yield Curve Slope | C17: Spread between 10-year and 2-year US Treasury yields in basis points. Positive = normal curve; negative = inverted. Inversion has preceded every US recession since 1955. | E17: A steepening curve signals improving growth and rising inflation expectations — bullish for AI capex (duration-exposed tech) and EM financials. Inversion is a leading recession indicator and triggers a shift to defensive positioning.
B18: MSCI ACWI Earnings Revision Ratio | C18: Ratio of upward to downward earnings estimate revisions across global equities. Above 1.0 = more upgrades than downgrades. Sourced from Bloomberg consensus data. | E18: Earnings revisions are the most direct driver of forward equity returns. Rising revisions support cyclical and growth themes. A deteriorating ratio signals analyst forecast cuts — a leading indicator of drawdown risk across all three baskets.
B19: USD Index (DXY) — 3-Month Change | C19: 3-month percentage change in the DXY Dollar Index, measuring USD strength vs. a basket of EUR, JPY, GBP, CAD, SEK, CHF. Published daily by ICE. | E19: USD direction is critical for the EM Consumer theme — a strengthening dollar tightens EM financial conditions and compresses local-currency returns for unhedged investors. USD weakness is risk-on for EM and commodities. A spike above +2% triggers a defensive rebalance.
B20: Global Credit Spreads — IG OAS | C20: Investment-grade option-adjusted spread over Treasuries from the ICE BofA IG Corporate Index (C0A0). Measures the additional yield investors demand to hold corporate vs. government bonds. | E20: Credit spreads are the market's risk-on/risk-off barometer. Tight spreads (<100bps) indicate abundant liquidity and strong risk appetite — supportive of all three themes. Widening above 150bps signals funding stress and triggers a full defensive pivot.
B22: GLOBAL ASSUMPTIONS — Referenced by formulas across all tabs
B23: Risk-Free Rate (annualised): | C23: 0.035 | D23: ← User input: current risk-free rate used for Sharpe Ratio in Tab 4 (default: 3.5%)

Sheet Theme Baskets
B1: THEME BASKETS
B2: Three high-conviction thematic baskets | 8 positions per theme (5 stocks + 3 ETFs) | Yellow cells = user inputs | Weights sum to 100% across themes
B4: THEME 1 — AI INFRASTRUCTURE BUILDOUT
B5: Investment Thesis: | C5: Hyperscaler capital expenditure — led by Microsoft, Google, Amazon, and Meta — surpassed $250bn in 2025 and is accelerating into 2026 driven by generative AI model training and inference demand. This supercycle is not limited to semiconductors: it spans power infrastructure (data centre electricity demand growing at 25%+ per annum), networking (optical interconnects, high-bandwidth memory), and cooling technology. Supply bottlenecks in advanced packaging and HBM memory create pricing power for incumbents. With sovereign AI programmes in Europe, Japan, and the Middle East adding a second demand layer, this theme has a 3–5 year structural runway well beyond the current hype cycle.
B6: Basket Benchmark: | C6: SOXX (iShares Semiconductor ETF) as primary + IGV (iShares Expanded Tech-Software ETF) as secondary
B7: Target Portfolio Weight: | C7: 40% (Risk-On: 45% | Neutral: 40% | Risk-Off: 30%)
B8: Investment Horizon: | C8: 3–5 Years
B9: Key Risk: | C9: Valuation compression if AI monetisation disappoints; China export controls disrupting supply chains; power grid bottlenecks delaying data centre build-out
B11: Name | C11: Ticker | D11: Type | E11: Country | F11: Sector / Exposure | G11: Rationale | H11: Weight % | I11: Mkt Cap ($bn) / TER | J11: Current Price ★ | K11: Entry Price ★ | L11: Target Price ★ | M11: Exp. Return %
B12: NVIDIA Corporation | C12: NVDA US | D12: Stock | E12: USA | F12: Semiconductors | G12: Dominant GPU supplier for AI training; H100/H200/Blackwell demand backlogged 12+ months; 70%+ data centre market share creates durable pricing power. | H12: 0.14 | I12: $2,650bn | J12: 118.5 | K12: 115 | L12: 145 | M12: =IF(OR(K12="",L12=""),"",((L12-K12)/K12)) -> 0.26086957
B13: Broadcom Inc. | C13: AVGO US | D13: Stock | E13: USA | F13: Semiconductors / Networking | G13: Custom ASIC and networking silicon for hyperscaler AI clusters; VMware acquisition adds recurring software revenue; $60bn+ AI revenue guided for FY26. | H13: 0.12 | I13: $850bn | J13: 225.4 | K13: 220 | L13: 270 | M13: =IF(OR(K13="",L13=""),"",((L13-K13)/K13)) -> 0.22727273
B14: Eaton Corporation | C14: ETN US | D14: Stock | E14: Ireland/USA | F14: Power Infrastructure | G14: Leading supplier of power management systems for data centres; data centre division growing 30%+ YoY as electricity demand from AI surges globally. | H14: 0.1 | I14: $135bn | J14: 290 | K14: 278 | L14: 340 | M14: =IF(OR(K14="",L14=""),"",((L14-K14)/K14)) -> 0.22302158
B15: Vertiv Holdings | C15: VRT US | D15: Stock | E15: USA | F15: Data Centre Cooling | G15: Critical thermal management and power distribution for hyperscale AI facilities; 90%+ revenue from data centre; fastest-growing pure-play AI infrastructure name. | H15: 0.1 | I15: $42bn | J15: 105.5 | K15: 98 | L15: 135 | M15: =IF(OR(K15="",L15=""),"",((L15-K15)/K15)) -> 0.37755102
B16: TSMC | C16: TSM US | D16: Stock | E16: Taiwan | F16: Semiconductors / Foundry | G16: Sole high-volume manufacturer of leading-edge AI chips (3nm/2nm); monopoly position in advanced packaging; geographic risk hedged by Arizona fab expansion. | H16: 0.09 | I16: $850bn | J16: 182 | K16: 175 | L16: 215 | M16: =IF(OR(K16="",L16=""),"",((L16-K16)/K16)) -> 0.22857143
B17: iShares Semiconductor ETF | C17: SOXX US | D17: ETF | E17: USA/Global | F17: Semiconductors (Broad) | G17: Diversified exposure to 30 semiconductor names; captures full AI chip ecosystem from design to manufacturing; TER 0.35%. | H17: 0.18 | I17: TER: 0.35% | J17: 248 | K17: 248 | L17: 285 | M17: =IF(OR(K17="",L17=""),"",((L17-K17)/K17)) -> 0.14919355
B18: Global X Data Centre REIT ETF | C18: DTCR US | D18: ETF | E18: USA/Global | F18: Data Centre REITs | G18: Pure-play data centre REIT exposure; benefits from hyperscaler long-term leasing of AI-optimised facilities; income-generating with growth; TER 0.50%. | H18: 0.15 | I18: TER: 0.50% | J18: 22.5 | K18: 22.5 | L18: 27 | M18: =IF(OR(K18="",L18=""),"",((L18-K18)/K18)) -> 0.2
B19: First Trust NASDAQ Cybersecurity | C19: CIBR US | D19: ETF | E19: USA/Global | F19: Cybersecurity | G19: AI-driven security infrastructure demand; zero-trust architecture adoption accelerating as data centre attack surface expands; TER 0.60%. | H19: 0.12 | I19: TER: 0.60% | J19: 58.4 | K19: 58.4 | L19: 68 | M19: =IF(OR(K19="",L19=""),"",((L19-K19)/K19)) -> 0.16438356
B20: THEME 1 SUMMARY | Total Holdings: 8 | Geographic Mix: 85% USA · 10% Taiwan · 5% Ireland | Avg Mkt Cap (stocks): ~$905bn | Risks: AI monetisation miss; China export controls; power grid delays
B22: THEME 2 — EUROPEAN DEFENCE REARMAMENT
B23: Investment Thesis: | C23: The geopolitical reset triggered by Russia's invasion of Ukraine has permanently altered European security doctrine. NATO's 2% GDP defence spending target — long aspirational — is now legally binding in Germany, Poland, and the UK, with France, Norway, and Sweden all exceeding it. European defence budgets grew 17% in 2024 and are projected to grow a further 14% in 2025–26, creating the largest sustained procurement cycle since the Cold War. Demand spans legacy platforms (artillery, armoured vehicles), next-generation systems (hypersonic missiles, air defence), and cyber warfare capabilities. With 10–15 year procurement lead times, order books are visible and contracted, making this one of the most earnings-visible themes in global equities.
B24: Basket Benchmark: | C24: EUAD (Invesco European Defence ETF) + MSCI Europe Industrials Index
B25: Target Portfolio Weight: | C25: 35% (Risk-On: 35% | Neutral: 35% | Risk-Off: 40%)
B26: Investment Horizon: | C26: 3–7 Years
B27: Key Risk: | C27: Peace settlement collapsing defence budgets; domestic political risk (far-left governments defunding); US pressure to reduce European autonomy; supply chain bottlenecks in titanium and rare earths
B29: Name | C29: Ticker | D29: Type | E29: Country | F29: Sector / Exposure | G29: Rationale | H29: Weight % | I29: Mkt Cap ($bn) / TER | J29: Current Price ★ | K29: Entry Price ★ | L29: Target Price ★ | M29: Exp. Return %
B30: BAE Systems | C30: BA/ LN | D30: Stock | E30: United Kingdom | F30: Aerospace & Defence | G30: Largest UK defence prime; submarines, combat aircraft, and cyber; record £37bn order book; earnings visibility 5+ years; direct beneficiary of NATO budget commitments. | H30: 0.15 | I30: $45bn | J30: 38.2 | K30: 36.5 | L30: 48 | M30: =IF(OR(K30="",L30=""),"",((L30-K30)/K30)) -> 0.31506849
B31: Rheinmetall AG | C31: RHM GY | D31: Stock | E31: Germany | F31: Ground Systems | G31: Germany's leading defence industrial company; artillery shells, armoured vehicles, and air defence; direct beneficiary of €100bn German Sondervermögen defence fund. | H31: 0.15 | I31: $42bn | J31: 142.5 | K31: 135 | L31: 175 | M31: =IF(OR(K31="",L31=""),"",((L31-K31)/K31)) -> 0.2962963
B32: Leonardo S.p.A. | C32: LDO IM | D32: Stock | E32: Italy | F32: Aerospace / Electronics | G32: Multi-domain Italian prime; avionics, helicopters, and cybersecurity; NATO interoperability push driving demand across all divisions; strong order intake. | H32: 0.1 | I32: $14bn | J32: 28.4 | K32: 27 | L32: 35 | M32: =IF(OR(K32="",L32=""),"",((L32-K32)/K32)) -> 0.2962963
B33: Thales S.A. | C33: HO FP | D33: Stock | E33: France | F33: Defence Electronics | G33: Leading supplier of radar, sonar, and missile guidance systems; cyber division growing at 20%+ pa; key supplier to EU joint procurement programmes. | H33: 0.1 | I33: $27bn | J33: 24.8 | K33: 24 | L33: 30 | M33: =IF(OR(K33="",L33=""),"",((L33-K33)/K33)) -> 0.25
B34: Saab AB | C34: SAAB SS | D34: Stock | E34: Sweden | F34: Air Defence / Missiles | G34: Gripen fighter jet and Carl-Gustaf weapons system producer; Sweden's NATO accession directly boosts procurement pipeline; strong export order book. | H34: 0.09 | I34: $14bn | J34: 35.6 | K34: 33.5 | L34: 44 | M34: =IF(OR(K34="",L34=""),"",((L34-K34)/K34)) -> 0.31343284
B35: Invesco European Def. ETF | C35: EUAD LN | D35: ETF | E35: Europe | F35: European Defence (Broad) | G35: Tracks MSCI Europe Defence Index; 30+ European defence companies; broadest pure-play European defence exposure available; TER 0.25%. | H35: 0.18 | I35: TER: 0.25% | J35: 42.43 | K35: 42.43 | L35: 60 | M35: =IF(OR(K35="",L35=""),"",((L35-K35)/K35)) -> 0.4140938
B36: iShares MSCI Europe ETF | C36: EZU US | D36: ETF | E36: Europe | F36: European Equity (Broad) | G36: Strategic European allocation providing diversification across defence beneficiaries in industrials, aerospace, and advanced manufacturing; TER 0.48%. | H36: 0.13 | I36: TER: 0.48% | J36: 52.8 | K36: 52.8 | L36: 60 | M36: =IF(OR(K36="",L36=""),"",((L36-K36)/K36)) -> 0.13636364
B37: VanEck Defense ETF | C37: DFNS US | D37: ETF | E37: Global | F37: Global Defence | G37: Global defence and aerospace exposure; includes US primes (LMT, RTX) alongside European names; provides US-allied supply chain diversification; TER 0.55%. | H37: 0.1 | I37: TER: 0.55% | J37: 30.5 | K37: 30.5 | L37: 35 | M37: =IF(OR(K37="",L37=""),"",((L37-K37)/K37)) -> 0.14754098
B38: THEME 2 SUMMARY | Total Holdings: 8 | Geographic Mix: 60% Europe · 25% UK · 15% Global | Avg Mkt Cap (stocks): ~$28bn | Risks: Peace deal; political reversal; rare earth supply disruption
B40: THEME 3 — EMERGING MARKET CONSUMER EMERGENCE
B41: Investment Thesis: | C41: The structural rise of the middle class in India, Southeast Asia, Indonesia, and Latin America represents one of the most durable multi-decade investment themes in global markets. India alone is adding 50 million new middle-class consumers annually, with smartphone penetration driving formalisation of retail, financial services, and consumer staples. Digital payments infrastructure has leapfrogged card systems in markets like India (UPI), Indonesia, and Brazil, creating platform economics for domestic payment processors and super-apps. These markets trade at 30–50% valuation discounts to comparable DM consumer franchises, despite superior long-run growth rates. USD sensitivity requires hedging or careful position sizing, but the structural demand story is independent of the US rate cycle.
B42: Basket Benchmark: | C42: MSCI Emerging Markets Consumer Discretionary + Staples Index; EEM (iShares MSCI EM ETF) as secondary
B43: Target Portfolio Weight: | C43: 25% (Risk-On: 20% | Neutral: 25% | Risk-Off: 30%)
B44: Investment Horizon: | C44: 5–10 Years
B45: Key Risk: | C45: USD strengthening compressing EM returns; China macro slowdown spilling into ASEAN; domestic political instability (Brazil, Indonesia election risk); EM corporate governance concerns
...

Sheet Rebalancing Framework
B1: MACRO REBALANCING FRAMEWORK
B2: Current Macro Signal (live): | C2: ='Macro Scorecard'!E12 -> 🟢 Risk-On — Favour Cyclical Themes | D2: ← Updates automatically when macro inputs change in Tab 1
B4: SCENARIO ALLOCATION TABLE — Theme Weights by Macro Signal
B5: Theme | C5: 🟢 Risk-On (Score > 2.0) | D5: 🟡 Neutral (Score 1.5 – 2.0) | E5: 🔴 Risk-Off (Score < 1.5)
B6: AI Infrastructure Buildout | C6: 0.45 | D6: 0.4 | E6: 0.3
B7: European Defence Rearmament | C7: 0.35 | D7: 0.35 | E7: 0.4
B8: EM Consumer Emergence | C8: 0.2 | D8: 0.25 | E8: 0.3
B9: TOTAL | C9: 1 | D9: 1 | E9: 1
B11: REBALANCING TRIGGER RULES
B12: Rule 1 — Signal Category Change | C12: A rebalance is triggered whenever the Macro Scorecard composite score crosses one of the two thresholds: above 2.0 (enters Risk-On), between 1.5–2.0 (enters Neutral), or below 1.5 (enters Risk-Off). The signal must persist for two consecutive weekly readings before a rebalance is executed, to filter short-term noise. This applies regardless of how recently the last rebalance occurred, subject to Rule 3.
B13: Rule 2 — Magnitude of Weight Shift | C13: Upon a signal category change, all theme weights shift to the target weights defined in the Scenario Allocation Table above. Shifts are executed at the next month-end NAV after the two-week confirmation period. No partial rebalancing is permitted — weights move to full scenario targets.
B14: Rule 3 — Minimum Holding Period | C14: A minimum of 90 calendar days must elapse between rebalancing events. If the macro signal changes within the 90-day window, the signal is logged but the portfolio is not rebalanced until the window expires. If the signal has reversed back to the prior category by that point, no rebalance occurs.
B15: Rule 4 — Intra-Basket Review | C15: Intra-basket positions are reviewed at each quarterly rebalance. An individual holding may be replaced if it has lost direct thematic relevance (e.g., divestiture, business model change), if its market cap falls below $1bn (liquidity floor), or if a significantly more compelling substitute exists. Replacements require PM sign-off and must be documented in the rebalancing log.
B16: Rule 5 — Concentration Limits | C16: No single theme may exceed 55% of the portfolio total. No single stock holding may exceed 5% of total portfolio value (i.e., 20% of a 25% theme basket). ETF positions within a basket are not subject to this cap. If a holding drifts above the cap due to price appreciation, it is trimmed at the next rebalance to restore compliance.
B18: REBALANCING LOG — Fill in after each rebalancing event
B19: Date | C19: Previous Weights (AI% | DEF% | EM%) | D19: New Weights (AI% | DEF% | EM%) | E19: Trigger Indicator | F19: Macro Signal at Rebalance | G19: PM Notes / Comments
B20: March 2026 (Inception) | C20: — (Initial allocation) | D20: 40% | 35% | 25% | E20: — | F20: Neutral (Base case) | G20: Portfolio inception — Neutral scenario weights applied

Sheet Backtest Engine
B1: BACKTEST ENGINE
B2: Jan 2022 – Dec 2025 (48 months) | Yellow cells = enter monthly returns from Bloomberg / Yahoo Finance | All stats auto-calculate
B4: SECTION 1 — MONTHLY RETURN INPUTS (enter as decimals e.g. 0.032 = 3.2%) | I4: SECTION 2 — CUMULATIVE NAV (Base = 100 at Jan 2022)
B5: Month | C5: AI Infrastructure Return | D5: EU Defence Return | E5: EM Consumer Return | F5: MSCI ACWI Return | G5: Portfolio Blended Return (formula) | I5: Month | J5: Portfolio NAV | K5: Benchmark NAV | L5: Rolling Peak (Port.) | M5: Drawdown (Port.)
B6: 44562 | C6: -0.089 | D6: -0.012 | E6: -0.018 | F6: -0.058 | G6: =IF(AND(C6="",D6="",E6=""),"",0.4*IF(C6="",0,C6)+0.35*IF(D6="",0,D6)+0.25*IF(E6="",0,E6)) -> -0.0443 | I6: 44562 | J6: =IF(G6="",100,100*(1+G6)) -> 95.57 | K6: =IF(F6="",100,100*(1+F6)) -> 94.2 | L6: =MAX(J$6:J6) -> 95.57 | M6: =IF(L6=0,"",J6/L6-1) -> 0
B7: 44593 | C7: -0.051 | D7: -0.008 | E7: -0.029 | F7: -0.027 | G7: =IF(AND(C7="",D7="",E7=""),"",0.4*IF(C7="",0,C7)+0.35*IF(D7="",0,D7)+0.25*IF(E7="",0,E7)) -> -0.03045 | I7: 44593 | J7: =IF(G7="",J6,J6*(1+G7)) -> 92.659893 | K7: =IF(F7="",K6,K6*(1+F7)) -> 91.6566 | L7: =MAX(J$6:J7) -> 95.57 | M7: =IF(L7=0,"",J7/L7-1) -> -0.03045
B8: 44621 | C8: 0.022 | D8: 0.054 | E8: -0.034 | F8: -0.03 | G8: =IF(AND(C8="",D8="",E8=""),"",0.4*IF(C8="",0,C8)+0.35*IF(D8="",0,D8)+0.25*IF(E8="",0,E8)) -> 0.0192 | I8: 44621 | J8: =IF(G8="",J7,J7*(1+G8)) -> 94.438963 | K8: =IF(F8="",K7,K7*(1+F8)) -> 88.906902 | L8: =MAX(J$6:J8) -> 95.57 | M8: =IF(L8=0,"",J8/L8-1) -> -0.01183464
B9: 44652 | C9: -0.092 | D9: -0.015 | E9: -0.048 | F9: -0.082 | G9: =IF(AND(C9="",D9="",E9=""),"",0.4*IF(C9="",0,C9)+0.35*IF(D9="",0,D9)+0.25*IF(E9="",0,E9)) -> -0.05405 | I9: 44652 | J9: =IF(G9="",J8,J8*(1+G9)) -> 89.334537 | K9: =IF(F9="",K8,K8*(1+F9)) -> 81.616536 | L9: =MAX(J$6:J9) -> 95.57 | M9: =IF(L9=0,"",J9/L9-1) -> -0.065244978
B10: 44682 | C10: -0.062 | D10: -0.009 | E10: -0.011 | F10: -0.059 | G10: =IF(AND(C10="",D10="",E10=""),"",0.4*IF(C10="",0,C10)+0.35*IF(D10="",0,D10)+0.25*IF(E10="",0,E10)) -> -0.0307 | I10: 44682 | J10: =IF(G10="",J9,J9*(1+G10)) -> 86.591967 | K10: =IF(F10="",K9,K9*(1+F10)) -> 76.80116 | L10: =MAX(J$6:J10) -> 95.57 | M10: =IF(L10=0,"",J10/L10-1) -> -0.093941957
B11: 44713 | C11: -0.089 | D11: -0.021 | E11: -0.067 | F11: -0.083 | G11: =IF(AND(C11="",D11="",E11=""),"",0.4*IF(C11="",0,C11)+0.35*IF(D11="",0,D11)+0.25*IF(E11="",0,E11)) -> -0.0597 | I11: 44713 | J11: =IF(G11="",J10,J10*(1+G11)) -> 81.422427 | K11: =IF(F11="",K10,K10*(1+F11)) -> 70.426664 | L11: =MAX(J$6:J11) -> 95.57 | M11: =IF(L11=0,"",J11/L11-1) -> -0.14803362
B12: 44743 | C12: 0.061 | D12: 0.032 | E12: 0.048 | F12: 0.063 | G12: =IF(AND(C12="",D12="",E12=""),"",0.4*IF(C12="",0,C12)+0.35*IF(D12="",0,D12)+0.25*IF(E12="",0,E12)) -> 0.0476 | I12: 44743 | J12: =IF(G12="",J11,J11*(1+G12)) -> 85.298134 | K12: =IF(F12="",K11,K11*(1+F12)) -> 74.863544 | L12: =MAX(J$6:J12) -> 95.57 | M12: =IF(L12=0,"",J12/L12-1) -> -0.10748002
B13: 44774 | C13: -0.054 | D13: -0.019 | E13: -0.019 | F13: -0.042 | G13: =IF(AND(C13="",D13="",E13=""),"",0.4*IF(C13="",0,C13)+0.35*IF(D13="",0,D13)+0.25*IF(E13="",0,E13)) -> -0.033 | I13: 44774 | J13: =IF(G13="",J12,J12*(1+G13)) -> 82.483296 | K13: =IF(F13="",K12,K12*(1+F13)) -> 71.719275 | L13: =MAX(J$6:J13) -> 95.57 | M13: =IF(L13=0,"",J13/L13-1) -> -0.13693318
B14: 44805 | C14: -0.082 | D14: -0.034 | E14: -0.072 | F14: -0.094 | G14: =IF(AND(C14="",D14="",E14=""),"",0.4*IF(C14="",0,C14)+0.35*IF(D14="",0,D14)+0.25*IF(E14="",0,E14)) -> -0.0627 | I14: 44805 | J14: =IF(G14="",J13,J13*(1+G14)) -> 77.311593 | K14: =IF(F14="",K13,K13*(1+F14)) -> 64.977663 | L14: =MAX(J$6:J14) -> 95.57 | M14: =IF(L14=0,"",J14/L14-1) -> -0.19104747
B15: 44835 | C15: 0.087 | D15: 0.048 | E15: 0.033 | F15: 0.062 | G15: =IF(AND(C15="",D15="",E15=""),"",0.4*IF(C15="",0,C15)+0.35*IF(D15="",0,D15)+0.25*IF(E15="",0,E15)) -> 0.05985 | I15: 44835 | J15: =IF(G15="",J14,J14*(1+G15)) -> 81.938692 | K15: =IF(F15="",K14,K14*(1+F15)) -> 69.006278 | L15: =MAX(J$6:J15) -> 95.57 | M15: =IF(L15=0,"",J15/L15-1) -> -0.14263166
B16: 44866 | C16: 0.062 | D16: 0.039 | E16: 0.029 | F16: 0.054 | G16: =IF(AND(C16="",D16="",E16=""),"",0.4*IF(C16="",0,C16)+0.35*IF(D16="",0,D16)+0.25*IF(E16="",0,E16)) -> 0.0457 | I16: 44866 | J16: =IF(G16="",J15,J15*(1+G16)) -> 85.68329 | K16: =IF(F16="",K15,K15*(1+F16)) -> 72.732617 | L16: =MAX(J$6:J16) -> 95.57 | M16: =IF(L16=0,"",J16/L16-1) -> -0.10344993
B17: 44896 | C17: -0.028 | D17: 0.012 | E17: -0.021 | F17: -0.006 | G17: =IF(AND(C17="",D17="",E17=""),"",0.4*IF(C17="",0,C17)+0.35*IF(D17="",0,D17)+0.25*IF(E17="",0,E17)) -> -0.01225 | I17: 44896 | J17: =IF(G17="",J16,J16*(1+G17)) -> 84.63367 | K17: =IF(F17="",K16,K16*(1+F17)) -> 72.296222 | L17: =MAX(J$6:J17) -> 95.57 | M17: =IF(L17=0,"",J17/L17-1) -> -0.11443267
B18: 44927 | C18: 0.123 | D18: 0.048 | E18: 0.038 | F18: 0.072 | G18: =IF(AND(C18="",D18="",E18=""),"",0.4*IF(C18="",0,C18)+0.35*IF(D18="",0,D18)+0.25*IF(E18="",0,E18)) -> 0.0755 | I18: 44927 | J18: =IF(G18="",J17,J17*(1+G18)) -> 91.023512 | K18: =IF(F18="",K17,K17*(1+F18)) -> 77.50155 | L18: =MAX(J$6:J18) -> 95.57 | M18: =IF(L18=0,"",J18/L18-1) -> -0.047572334
... B53: 45992 | C53: 0.028 | D53: 0.048 | E53: 0.037 | F53: 0.023 | G53: =IF(AND(C53="",D53="",E53=""),"",0.4*IF(C53="",0,C53)+0.35*IF(D53="",0,D53)+0.25*IF(E53="",0,E53)) -> 0.03725 | I53: 45992 | J53: =IF(G53="",J52,J52*(1+G53)) -> 251.60959 | K53: =IF(F53="",K52,K52*(1+F53)) -> 158.87443 | L53: =MAX(J$6:J53) -> 251.60959 | M53: =IF(L53=0,"",J53/L53-1) -> 0
B56: SECTION 3 — ANNUAL PERFORMANCE SUMMARY
B57: Year | C57: Portfolio Return | D57: Benchmark Return | E57: Alpha | F57: Best Theme | G57: Worst Theme
B58: 2022 | C58: {=IFERROR(PRODUCT(1+IF(G6:G17="",0,G6:G17))-1,"")} -> -0.1536633 | D58: {=IFERROR(PRODUCT(1+IF(F6:F17="",0,F6:F17))-1,"")} -> -0.27703778 | E58: =IF(OR(C58="",D58=""),"",C58-D58) -> 0.12337448 | F58: {=IFERROR(IF(MAX(PRODUCT(1+IF(C6:C17="",0,C6:C17))-1,PRODUCT(1+IF(D6:D17="",0,D6:D17))-1,PRODUCT(1+IF(E6:E17="",0,E6:E17))-1)=PRODUCT(1+IF(C6:C17="",0,C6:C17))-1,"AI Infrastructure",IF(MAX(PRODUCT(1+IF(C6:C17="",0,C6:C17))-1,PRODUCT(1+IF(D6:D17="",0,D6:D17))-1,PRODUCT(1+IF(E6:E17="",0,E6:E17))-1)=PRODUCT(1+IF(D6:D17="",0,D6:D17))-1,"EU Defence","EM Consumer")),"—")} -> EU Defence | G58: {=IFERROR(IF(MIN(PRODUCT(1+IF(C6:C17="",0,C6:C17))-1,PRODUCT(1+IF(D6:D17="",0,D6:D17))-1,PRODUCT(1+IF(E6:E17="",0,E6:E17))-1)=PRODUCT(1+IF(C6:C17="",0,C6:C17))-1,"AI Infrastructure",IF(MIN(PRODUCT(1+IF(C6:C17="",0,C6:C17))-1,PRODUCT(1+IF(D6:D17="",0,D6:D17))-1,PRODUCT(1+IF(E6:E17="",0,E6:E17))-1)=PRODUCT(1+IF(D6:D17="",0,D6:D17))-1,"EU Defence","EM Consumer")),"—")} -> AI Infrastructure
B59: 2023 | C59: {=IFERROR(PRODUCT(1+IF(G18:G29="",0,G18:G29))-1,"")} -> 0.28166814 | D59: {=IFERROR(PRODUCT(1+IF(F18:F29="",0,F18:F29))-1,"")} -> 0.24755626 | E59: =IF(OR(C59="",D59=""),"",C59-D59) -> 0.034111879 | F59: {=IFERROR(IF(MAX(PRODUCT(1+IF(C18:C29="",0,C18:C29))-1,PRODUCT(1+IF(D18:D29="",0,D18:D29))-1,PRODUCT(1+IF(E18:E29="",0,E18:E29))-1)=PRODUCT(1+IF(C18:C29="",0,C18:C29))-1,"AI Infrastructure",IF(MAX(PRODUCT(1+IF(C18:C29="",0,C18:C29))-1,PRODUCT(1+IF(D18:D29="",0,D18:D29))-1,PRODUCT(1+IF(E18:E29="",0,E18:E29))-1)=PRODUCT(1+IF(D18:D29="",0,D18:D29))-1,"EU Defence","EM Consumer")),"—")} -> AI Infrastructure | G59: {=IFERROR(IF(MIN(PRODUCT(1+IF(C18:C29="",0,C18:C29))-1,PRODUCT(1+IF(D18:D29="",0,D18:D29))-1,PRODUCT(1+IF(E18:E29="",0,E18:E29))-1)=PRODUCT(1+IF(C18:C29="",0,C18:C29))-1,"AI Infrastructure",IF(MIN(PRODUCT(1+IF(C18:C29="",0,C18:C29))-1,PRODUCT(1+IF(D18:D29="",0,D18:D29))-1,PRODUCT(1+IF(E18:E29="",0,E18:E29))-1)=PRODUCT(1+IF(D18:D29="",0,D18:D29))-1,"EU Defence","EM Consumer")),"—")} -> EM Consumer
B60: 2024 | C60: {=IFERROR(PRODUCT(1+IF(G30:G41="",0,G30:G41))-1,"")} -> 0.38411741 | D60: {=IFERROR(PRODUCT(1+IF(F30:F41="",0,F30:F41))-1,"")} -> 0.22390839 | E60: =IF(OR(C60="",D60=""),"",C60-D60) -> 0.16020903 | F60: {=IFERROR(IF(MAX(PRODUCT(1+IF(C30:C41="",0,C30:C41))-1,PRODUCT(1+IF(D30:D41="",0,D30:D41))-1,PRODUCT(1+IF(E30:E41="",0,E30:E41))-1)=PRODUCT(1+IF(C30:C41="",0,C30:C41))-1,"AI Infrastructure",IF(MAX(PRODUCT(1+IF(C30:C41="",0,C30:C41))-1,PRODUCT(1+IF(D30:D41="",0,D30:D41))-1,PRODUCT(1+IF(E30:E41="",0,E30:E41))-1)=PRODUCT(1+IF(D30:D41="",0,D30:D41))-1,"EU Defence","EM Consumer")),"—")} -> EU Defence | G60: {=IFERROR(IF(MIN(PRODUCT(1+IF(C30:C41="",0,C30:C41))-1,PRODUCT(1+IF(D30:D41="",0,D30:D41))-1,PRODUCT(1+IF(E30:E41="",0,E30:E41))-1)=PRODUCT(1+IF(C30:C41="",0,C30:C41))-1,"AI Infrastructure",IF(MIN(PRODUCT(1+IF(C30:C41="",0,C30:C41))-1,PRODUCT(1+IF(D30:D41="",0,D30:D41))-1,PRODUCT(1+IF(E30:E41="",0,E30:E41))-1)=PRODUCT(1+IF(D30:D41="",0,D30:D41))-1,"EU Defence","EM Consumer")),"—")} -> EM Consumer
B61: 2025 | C61: {=IFERROR(PRODUCT(1+IF(G42:G53="",0,G42:G53))-1,"")} -> 0.67585134 | D61: {=IFERROR(PRODUCT(1+IF(F42:F53="",0,F42:F53))-1,"")} -> 0.43922718 | E61: =IF(OR(C61="",D61=""),"",C61-D61) -> 0.23662417 | F61: {=IFERROR(IF(MAX(PRODUCT(1+IF(C42:C53="",0,C42:C53))-1,PRODUCT(1+IF(D42:D53="",0,D42:D53))-1,PRODUCT(1+IF(E42:E53="",0,E42:E53))-1)=PRODUCT(1+IF(C42:C53="",0,C42:C53))-1,"AI Infrastructure",IF(MAX(PRODUCT(1+IF(C42:C53="",0,C42:C53))-1,PRODUCT(1+IF(D42:D53="",0,D42:D53))-1,PRODUCT(1+IF(E42:E53="",0,E42:E53))-1)=PRODUCT(1+IF(D42:D53="",0,D42:D53))-1,"EU Defence","EM Consumer")),"—")} -> EU Defence | G61: {=IFERROR(IF(MIN(PRODUCT(1+IF(C42:C53="",0,C42:C53))-1,PRODUCT(1+IF(D42:D53="",0,D42:D53))-1,PRODUCT(1+IF(E42:E53="",0,E42:E53))-1)=PRODUCT(1+IF(C42:C53="",0,C42:C53))-1,"AI Infrastructure",IF(MIN(PRODUCT(1+IF(C42:C53="",0,C42:C53))-1,PRODUCT(1+IF(D42:D53="",0,D42:D53))-1,PRODUCT(1+IF(E42:E53="",0,E42:E53))-1)=PRODUCT(1+IF(D42:D53="",0,D42:D53))-1,"EU Defence","EM Consumer")),"—")} -> AI Infrastructure
B64: SECTION 4 — SUMMARY STATISTICS (all formula-driven from inputs above)
B65: Metric | C65: Portfolio | D65: Benchmark (MSCI ACWI) | E65: Notes
B66: Annualised Return | C66: {=IFERROR((PRODUCT(1+G6:G53))^(12/COUNTA(G6:G53))-1,"")} -> 0.25945251 | D66: {=IFERROR((PRODUCT(1+F6:F53))^(12/COUNTA(F6:F53))-1,"")} -> 0.12269943 | E66: Geometric annualised return (compounded)
B67: Annualised Volatility | C67: =IFERROR(STDEV(G6:G53)*SQRT(12),"") -> 0.1308414 | D67: =IFERROR(STDEV(F6:F53)*SQRT(12),"") -> 0.14874065 | E67: Monthly std dev of returns × √12
B68: Sharpe Ratio (3.5% Rf) | C68: =IFERROR((C66-RiskFreeRate)/C67,"") -> 1.7154548 | D68: =IFERROR((D66-RiskFreeRate)/D67,"") -> 0.58961302 | E68: Uses RiskFreeRate named range (Macro Scorecard tab, C24)
B69: Max Drawdown | C69: =IFERROR(MIN(M6:M53),"") -> -0.19104747 | D69: =IFERROR(MIN(F6:F53),"") -> -0.094 | E69: Portfolio uses rolling-peak drawdown col M; Benchmark uses worst monthly return
B70: Beta vs MSCI ACWI | C70: =IFERROR(COVAR(G6:G53,F6:F53)/VAR(F6:F53),"") -> 0.80623725 | D70: 1 | E70: Cov(portfolio returns, benchmark returns) / Var(benchmark returns)
B71: Tracking Error | C71: {=IFERROR(STDEV(G6:G53-F6:F53)*SQRT(12),"")} -> 0.053011291 | D71: — | E71: Annualised standard deviation of monthly portfolio-benchmark return spreads
B72: Information Ratio | C72: =IFERROR(C66/C71,"") -> 4.8942877 | D72: — | E72: Annualised excess return over benchmark ÷ Tracking Error
B73: % Months Outperforming | C73: {=IFERROR(SUMPRODUCT((G6:G53>F6:F53)*1)/COUNTA(G6:G53),"")} -> 0.6875 | D73: — | E73: Share of months where portfolio monthly return > benchmark monthly return

Sheet Attribution
B1: THEME PERFORMANCE ATTRIBUTION
B2: Brinson-Hood-Beebower attribution adapted for thematic portfolios | Splits alpha into allocation effect (weight decisions) and selection effect (stock picking)
B3: Attribution Period: January 2022 – December 2025 (48 months, full backtest period) | Rp = theme basket return | Rb = sector benchmark proxy return
B4: BRINSON-HOOD-BEEBOWER ATTRIBUTION TABLE — Yellow cells = enter period returns
B5: Theme | C5: Portfolio Weight (Wp) | D5: Benchmark Weight (Wb) | E5: Portfolio Return (Rp) | F5: Benchmark Return (Rb) | G5: Allocation Effect | H5: Selection Effect | I5: Total Active Contribution
B6: AI Infrastructure Buildout | C6: 0.4 | D6: 0.25 | E6: 0.583 | F6: 0.31 | G6: =IF(OR(E6="",F6=""),"",( C6-D6)*(F6-SUMPRODUCT(D6:D8,F6:F8))) -> 0.0296625 | H6: =IF(OR(E6="",F6=""),"",D6*(E6-F6)) -> 0.06825 | I6: =IF(OR(G6="",H6=""),"",G6+H6) -> 0.0979125
B7: European Defence Rearmament | C7: 0.35 | D7: 0.05 | E7: 2.044 | F7: 0.44 | G7: =IF(OR(E7="",F7=""),"",( C7-D7)*(F7-SUMPRODUCT(D6:D8,F6:F8))) -> 0.098325 | H7: =IF(OR(E7="",F7=""),"",D7*(E7-F7)) -> 0.0802 | I7: =IF(OR(G7="",H7=""),"",G7+H7) -> 0.178525
B8: EM Consumer Emergence | C8: 0.25 | D8: 0.15 | E8: 0.208 | F8: 0.085 | G8: =IF(OR(E8="",F8=""),"",( C8-D8)*(F8-SUMPRODUCT(D6:D8,F6:F8))) -> -0.002725 | H8: =IF(OR(E8="",F8=""),"",D8*(E8-F8)) -> 0.01845 | I8: =IF(OR(G8="",H8=""),"",G8+H8) -> 0.015725
B9: TOTAL ALPHA | G9: =IF(COUNTA(G6:G8)=0,"",SUM(G6:G8)) -> 0.1252625 | H9: =IF(COUNTA(H6:H8)=0,"",SUM(H6:H8)) -> 0.1669 | I9: =IF(COUNTA(I6:I8)=0,"",SUM(I6:I8)) -> 0.2921625
G10: ← Allocation Effect | H10: ← Selection Effect | I10: ← Total Alpha
B12: INTERPRETATION GUIDE — How to Read This Attribution Table
B13: Allocation Effect (Column G) | C13: Measures whether the decision to overweight or underweight a theme relative to its benchmark proxy added value. A positive allocation effect means overweighting a theme that outperformed the benchmark average, or underweighting one that underperformed. This reflects the quality of your top-down macro signal.
B14: Selection Effect (Column H) | C14: Measures whether the specific securities chosen within each theme outperformed their benchmark equivalent. A positive selection effect means the stocks and ETFs selected beat the relevant sector index. This reflects the quality of the individual security research within each basket.
B15: Total Alpha (Column I) | C15: The sum of allocation and selection effects. This is the total value added by the portfolio relative to holding a passive benchmark exposure to the same themes. Positive total alpha validates the active management approach. A negative total alpha would suggest the passive benchmark weight allocation and/or security selection detracted value.
B16: How to Present This to a Client | C16: Split the conversation in two: 'Our macro signal added X basis points by correctly overweighting [best theme] when it outperformed. Within that basket, our security selection added a further Y basis points above the sector index.' If selection is negative but allocation is positive, the signal is working but stock picks need improvement — and vice versa.

Sheet Risk Dashboard
B1: RISK DASHBOARD
B2: Weekly PM review — 4 sections: Portfolio risk metrics | Concentration analysis | Correlation matrix | Macro risk watchlist
B4: SECTION 1 — PORTFOLIO-LEVEL RISK METRICS (linked from Backtest Engine tab)
B5: Metric | C5: Portfolio | D5: Benchmark | E5: vs Benchmark | F5: Signal
B6: Annualised Return | C6: ='Backtest Engine'!C66 -> 0.25945251 | D6: ='Backtest Engine'!D66 -> 0.12269943 | E6: =IFERROR(C6-D6,"") -> 0.13675308
B7: Annualised Volatility | C7: ='Backtest Engine'!C67 -> 0.1308414 | D7: ='Backtest Engine'!D67 -> 0.14874065 | E7: =IFERROR(C7-D7,"") -> -0.017899255
B8: Sharpe Ratio | C8: ='Backtest Engine'!C68 -> 1.7154548 | D8: ='Backtest Engine'!D68 -> 0.58961302 | E8: =IFERROR(C8-D8,"") -> 1.1258418
B9: Max Drawdown | C9: ='Backtest Engine'!C69 -> -0.19104747 | D9: ='Backtest Engine'!D69 -> -0.094 | E9: —
B10: Beta vs ACWI | C10: ='Backtest Engine'!C70 -> 0.80623725 | D10: 1 | E10: —
B11: Tracking Error | C11: ='Backtest Engine'!C71 -> 0.053011291 | D11: — | E11: =IFERROR(C11-D11,"")
B13: SECTION 2 — CONCENTRATION ANALYSIS (⚠ cells flagged amber if > 40%)
B14: Geographic Exposure (Aggregated Across All Baskets) | F14: Sector Exposure (Aggregated Across All Baskets)
B15: North America | C15: 0.52 | D15: ⚠ >40% — monitor | F15: Technology / AI | G15: 0.38 | H15: ⚠ >40% — monitor
B16: Europe | C16: 0.22 | F16: Industrials / Defence | G16: 0.22
B17: Asia-Pacific | C17: 0.14 | F17: Financials | G17: 0.12
B18: Emerging Markets | C18: 0.1 | F18: Consumer | G18: 0.11
B19: Other / Global | C19: 0.02 | F19: Energy / Utilities | G19: 0.08
F20: Healthcare | G20: 0.05
F21: Other | G21: 0.04
B23: SECTION 3 — THEME CORRELATION MATRIX (flag if correlation > 0.7 — themes not truly diversifying)
C24: AI Infrastructure | D24: EU Defence | E24: EM Consumer
B25: AI Infrastructure | C25: 1 | D25: =IFERROR(CORREL('Backtest Engine'!C6:C53,'Backtest Engine'!D6:D53),"") -> 0.65186972 | E25: =IFERROR(CORREL('Backtest Engine'!C6:C53,'Backtest Engine'!E6:E53),"") -> 0.72916972
B26: EU Defence | C26: =IFERROR(CORREL('Backtest Engine'!D6:D53,'Backtest Engine'!C6:C53),"") -> 0.65186972 | D26: 1 | E26: =IFERROR(CORREL('Backtest Engine'!D6:D53,'Backtest Engine'!E6:E53),"") -> 0.72069962
B27: EM Consumer | C27: =IFERROR(CORREL('Backtest Engine'!E6:E53,'Backtest Engine'!C6:C53),"") -> 0.72916972 | D27: =IFERROR(CORREL('Backtest Engine'!E6:E53,'Backtest Engine'!D6:D53),"") -> 0.72069962 | E27: 1
B28: ⚠ If any pair shows correlation above 0.70, the themes are not truly diversifying each other — consider replacing the higher-correlated basket or adding an uncorrelated hedge.
B30: SECTION 4 — KEY MACRO RISK WATCHLIST — Probability and Impact are manual inputs
B31: Risk | C31: Affected Theme(s) | D31: Probability ★ | E31: Impact ★ | F31: Description & Mitigation
B32: Fed Policy Reversal — Rate Spike | C32: AI Infrastructure | D32: Medium | E32: High | F32: A re-acceleration of US inflation forces the Fed to hike rates, spiking the 10Y yield. Compresses high-multiple AI infrastructure valuations. Mitigation: Monitor DXY and IG OAS; reduce AI basket on Risk-Off signal.
B33: China Macro Slowdown / Crisis | C33: EM Consumer; AI Infrastructure | D33: Medium | E33: High | F33: A hard landing in China spills into ASEAN supply chains and EM consumer demand. Taiwan Strait tensions disrupt TSMC operations. Mitigation: EMXC ETF (ex-China) in EM basket; diversified AI supply chain holdings.
B34: USD Spike (+5% in 3 months) | C34: EM Consumer | D34: Medium | E34: High | F34: Rapid dollar strengthening triggers capital outflows from EM, tightens local financial conditions, and compresses unhedged EM equity returns. Mitigation: Monitor DXY 3M change; reduce EM weight to 20% (Risk-Off).
B35: Peace Settlement in Ukraine | C35: European Defence Rearmament | D35: Low | E35: High | F35: A sudden peace deal collapses the political consensus for sustained defence spending increases. Mitigation: Focus on structural NATO commitments; monitor Rheinmetall/BAE order book data vs. budget announcements.
B36: AI Monetisation Disappointment | C36: AI Infrastructure | D36: Medium | E36: Medium | F36: Hyperscaler capex guidance is cut as ROI on AI models fails to materialise in revenue growth. Multiple compression for AI infrastructure names. Mitigation: Diversify into lower-multiple power/cooling names; hold SOXX ETF.
B37: EM Political Instability | C37: EM Consumer | D37: Low | E37: Medium | F37: Election outcomes in India, Brazil, or Indonesia produce policy uncertainty or capital controls. Mitigation: Geographic diversification across 5+ EM geographies; INDA/EMXC ETFs limit single-country concentration.

Sheet Investor Summary
B1: GLOBAL MACRO THEMATIC PORTFOLIO | I1: Theme | J1: Weight
B2: Investor Summary | March 2026 | Institutional Strategy Factsheet | I2: AI Infrastructure | J2: 0.4
I3: EU Defence | J3: 0.35
B4: Strategy Type | C4: Inception Date | D4: Benchmark | E4: No. of Holdings | F4: AUM (Placeholder) | G4: Risk Profile | I4: EM Consumer | J4: 0.25
B5: Global Macro Thematic | C5: 46082 | D5: MSCI ACWI | E5: 24 positions | F5: — | G5: Equity Long-Only
B7: STRATEGY OVERVIEW
B8: A top-down, rules-based thematic equity strategy investing across three structural macro themes. Theme weights are driven by a composite macro signal (PMI, yield curve, earnings revisions, DXY, credit spreads) and rebalanced quarterly. Benchmarked against MSCI ACWI. Target alpha through disciplined thematic exposure, not factor timing or leverage.
B10: INVESTMENT THEMES
B11: Theme 1 — AI Infrastructure Buildout (40%) | C11: Hyperscaler capex surpassing $300bn in 2025 is creating a multi-year supercycle in semiconductors, power infrastructure, and networking. Supply bottlenecks and sovereign AI programmes extend the structural runway to 2030+.
B12: Theme 2 — European Defence Rearmament (35%) | C12: Binding NATO commitments at 2%+ of GDP are driving the largest European defence procurement cycle since the Cold War. Contracted order books provide multi-year earnings visibility across aerospace, missiles, and cybersecurity.
B13: Theme 3 — EM Consumer Emergence (25%) | C13: Middle-class formation in India, SE Asia, and Latin America is compounding at 50mn new consumers per annum. Digital payments leapfrogging creates platform economics at 30–50% valuation discounts to DM peers.
B15: TOP 5 HOLDINGS BY PORTFOLIO WEIGHT
B16: Holding | C16: Theme | D16: Ticker | E16: Portfolio Weight | F16: Country | G16: Sector
B17: iShares Semiconductor ETF (SOXX) | C17: AI Infrastructure | D17: SOXX US | E17: 0.072 | F17: USA / Global | G17: Semiconductors
B18: Invesco European Defence ETF (EUAD) | C18: European Defence | D18: EUAD LN | E18: 0.063 | F18: Europe | G18: Aerospace & Defence
B19: Global X Data Centre REIT ETF (DTCR) | C19: AI Infrastructure | D19: DTCR US | E19: 0.06 | F19: USA / Global | G19: Data Centre REITs
B20: NVIDIA Corporation | C20: AI Infrastructure | D20: NVDA US | E20: 0.056 | F20: USA | G20: Semiconductors
B21: iShares MSCI India ETF (INDA) | C21: EM Consumer | D21: INDA US | E21: 0.045 | F21: India | G21: EM Equity
B23: RISK METRICS SUMMARY (linked from Backtest Engine — populate once returns are entered)
B24: Annualised Return | C24: Annualised Volatility | D24: Sharpe Ratio | E24: Max Drawdown | F24: Beta vs ACWI | G24: Tracking Error
B25: =IFERROR('Backtest Engine'!C66,"—") -> 0.25945251 | C25: =IFERROR('Backtest Engine'!C67,"—") -> 0.1308414 | D25: =IFERROR('Backtest Engine'!C68,"—") -> 1.7154548 | E25: =IFERROR('Backtest Engine'!C69,"—") -> -0.19104747 | F25: =IFERROR('Backtest Engine'!C70,"—") -> 0.80623725 | G25: =IFERROR('Backtest Engine'!C71,"—") -> 0.053011291
B29: YTD PERFORMANCE vs BENCHMARK (January – March 2026)
B30: Portfolio YTD | C30: Benchmark YTD | D30: Alpha YTD | E30: Best Theme YTD | F30: Signal
B31: — | C31: — | D31: — | E31: EU Defence Rearmament | F31: 🟢 Risk-On
